Workbook

Sheet Notes
A1: Reserve Analysis - Complete Analysis
A2: Workbook Information
A3: Created: | B3: April 27, 2026 08:14 PM
A4: Description: | B4: Complete actuarial reserve analysis combining selections, ultimates, and diagnostics
A6: Table of Contents
A7: Name | B7: Description
A8: Loss Selection | B8: Actuary-selected ultimates for loss measures. Compare CL/BF/IE methods and record final selection.
A9: Incurred CL | B9: Chain Ladder method results. Ultimate = Actual × CDF. IBNR = Ultimate − Actual. Unpaid = Ultimate − latest paid (proxy measure).
A10: Paid CL | B10: Chain Ladder method results. Ultimate = Actual × CDF. IBNR = Ultimate − Actual. Unpaid = Ultimate − latest paid (proxy measure).
A11: Incurred BF | B11: Bornhuetter-Ferguson method. Blends Initial Expected with emerged experience. % Unreported = 1 − 1/CDF. Ultimate = (IE × % Unreported) + Actual.
A12: Paid BF | B12: Bornhuetter-Ferguson method. Blends Initial Expected with emerged experience. % Unreported = 1 − 1/CDF. Ultimate = (IE × % Unreported) + Actual.
A13: Incurred IE | B13: Initial Expected method. Ultimate = Exposure × Selected Loss Rate (ELR). ELR back-calculated from IE ultimate and exposure.
A14: Paid IE | B14: Initial Expected method. Ultimate = Exposure × Selected Loss Rate (ELR). ELR back-calculated from IE ultimate and exposure.
A15: Count Selection | B15: Analysis results
A16: Closed CL | B16: Chain Ladder method results. Ultimate = Actual × CDF. IBNR = Ultimate − Actual. Unpaid = Ultimate − latest paid (proxy measure).
A17: Reported CL | B17: Chain Ladder method results. Ultimate = Actual × CDF. IBNR = Ultimate − Actual. Unpaid = Ultimate − latest paid (proxy measure).
A18: Reported BF | B18: Bornhuetter-Ferguson method. Blends Initial Expected with emerged experience. % Unreported = 1 − 1/CDF. Ultimate = (IE × % Unreported) + Actual.
... A37: Diagnostics | B37: Post-selection reasonableness checks. Severity = Ultimate Loss / Ultimate Count. Loss Rate and Frequency require Exposure.

Sheet Loss Selection
A1: Accident Period | B1: Current Age | C1: Incurred | D1: Paid | E1: Incurred CL | F1: Paid CL | G1: Initial Expected | H1: Incurred BF | I1: Paid BF | J1: Selected Ultimate | K1: IBNR | L1: Unpaid | M1: Selected Reasoning
A2: 2001 | B2: 287 | C2: ='Incurred CL'!C2 | D2: ='Paid CL'!C2 | E2: ='Incurred CL'!E2 | F2: ='Paid CL'!E2 | G2: ='Incurred IE'!D2 | H2: ='Incurred BF'!H2 | I2: ='Paid BF'!H2 | J2: =IF('/sessions/eloquent-hopeful-babbage/mnt/sample-run/selections\[Ultimates.xlsx]Losses'!O2<>"",'/sessions/eloquent-hopeful-babbage/mnt/sample-run/selections\[Ultimates.xlsx]Losses'!O2,'/sessions/eloquent-hopeful-babbage/mnt/sample-run/selections\[Ultimates.xlsx]Losses'!K2) | K2: =J2-C2 | L2: =J2-D2 | M2: =IF('/sessions/eloquent-hopeful-babbage/mnt/sample-run/selections\[Ultimates.xlsx]Losses'!O2<>"",'/sessions/eloquent-hopeful-babbage/mnt/sample-run/selections\[Ultimates.xlsx]Losses'!P2,'/sessions/eloquent-hopeful-babbage/mnt/sample-run/selections\[Ultimates.xlsx]Losses'!L2)
A3: 2002 | B3: 275 | C3: ='Incurred CL'!C3 | D3: ='Paid CL'!C3 | E3: ='Incurred CL'!E3 | F3: ='Paid CL'!E3 | G3: ='Incurred IE'!D3 | H3: ='Incurred BF'!H3 | I3: ='Paid BF'!H3 | J3: =IF('/sessions/eloquent-hopeful-babbage/mnt/sample-run/selections\[Ultimates.xlsx]Losses'!O3<>"",'/sessions/eloquent-hopeful-babbage/mnt/sample-run/selections\[Ultimates.xlsx]Losses'!O3,'/sessions/eloquent-hopeful-babbage/mnt/sample-run/selections\[Ultimates.xlsx]Losses'!K3) | K3: =J3-C3 | L3: =J3-D3 | M3: =IF('/sessions/eloquent-hopeful-babbage/mnt/sample-run/selections\[Ultimates.xlsx]Losses'!O3<>"",'/sessions/eloquent-hopeful-babbage/mnt/sample-run/selections\[Ultimates.xlsx]Losses'!P3,'/sessions/eloquent-hopeful-babbage/mnt/sample-run/selections\[Ultimates.xlsx]Losses'!L3)
A4: 2003 | B4: 263 | C4: ='Incurred CL'!C4 | D4: ='Paid CL'!C4 | E4: ='Incurred CL'!E4 | F4: ='Paid CL'!E4 | G4: ='Incurred IE'!D4 | H4: ='Incurred BF'!H4 | I4: ='Paid BF'!H4 | J4: =IF('/sessions/eloquent-hopeful-babbage/mnt/sample-run/selections\[Ultimates.xlsx]Losses'!O4<>"",'/sessions/eloquent-hopeful-babbage/mnt/sample-run/selections\[Ultimates.xlsx]Losses'!O4,'/sessions/eloquent-hopeful-babbage/mnt/sample-run/selections\[Ultimates.xlsx]Losses'!K4) | K4: =J4-C4 | L4: =J4-D4 | M4: =IF('/sessions/eloquent-hopeful-babbage/mnt/sample-run/selections\[Ultimates.xlsx]Losses'!O4<>"",'/sessions/eloquent-hopeful-babbage/mnt/sample-run/selections\[Ultimates.xlsx]Losses'!P4,'/sessions/eloquent-hopeful-babbage/mnt/sample-run/selections\[Ultimates.xlsx]Losses'!L4)
A5: 2004 | B5: 251 | C5: ='Incurred CL'!C5 | D5: ='Paid CL'!C5 | E5: ='Incurred CL'!E5 | F5: ='Paid CL'!E5 | G5: ='Incurred IE'!D5 | H5: ='Incurred BF'!H5 | I5: ='Paid BF'!H5 | J5: =IF('/sessions/eloquent-hopeful-babbage/mnt/sample-run/selections\[Ultimates.xlsx]Losses'!O5<>"",'/sessions/eloquent-hopeful-babbage/mnt/sample-run/selections\[Ultimates.xlsx]Losses'!O5,'/sessions/eloquent-hopeful-babbage/mnt/sample-run/selections\[Ultimates.xlsx]Losses'!K5) | K5: =J5-C5 | L5: =J5-D5 | M5: =IF('/sessions/eloquent-hopeful-babbage/mnt/sample-run/selections\[Ultimates.xlsx]Losses'!O5<>"",'/sessions/eloquent-hopeful-babbage/mnt/sample-run/selections\[Ultimates.xlsx]Losses'!P5,'/sessions/eloquent-hopeful-babbage/mnt/sample-run/selections\[Ultimates.xlsx]Losses'!L5)
A6: 2005 | B6: 239 | C6: ='Incurred CL'!C6 | D6: ='Paid CL'!C6 | E6: ='Incurred CL'!E6 | F6: ='Paid CL'!E6 | G6: ='Incurred IE'!D6 | H6: ='Incurred BF'!H6 | I6: ='Paid BF'!H6 | J6: =IF('/sessions/eloquent-hopeful-babbage/mnt/sample-run/selections\[Ultimates.xlsx]Losses'!O6<>"",'/sessions/eloquent-hopeful-babbage/mnt/sample-run/selections\[Ultimates.xlsx]Losses'!O6,'/sessions/eloquent-hopeful-babbage/mnt/sample-run/selections\[Ultimates.xlsx]Losses'!K6) | K6: =J6-C6 | L6: =J6-D6 | M6: =IF('/sessions/eloquent-hopeful-babbage/mnt/sample-run/selections\[Ultimates.xlsx]Losses'!O6<>"",'/sessions/eloquent-hopeful-babbage/mnt/sample-run/selections\[Ultimates.xlsx]Losses'!P6,'/sessions/eloquent-hopeful-babbage/mnt/sample-run/selections\[Ultimates.xlsx]Losses'!L6)
A7: 2006 | B7: 227 | C7: ='Incurred CL'!C7 | D7: ='Paid CL'!C7 | E7: ='Incurred CL'!E7 | F7: ='Paid CL'!E7 | G7: ='Incurred IE'!D7 | H7: ='Incurred BF'!H7 | I7: ='Paid BF'!H7 | J7: =IF('/sessions/eloquent-hopeful-babbage/mnt/sample-run/selections\[Ultimates.xlsx]Losses'!O7<>"",'/sessions/eloquent-hopeful-babbage/mnt/sample-run/selections\[Ultimates.xlsx]Losses'!O7,'/sessions/eloquent-hopeful-babbage/mnt/sample-run/selections\[Ultimates.xlsx]Losses'!K7) | K7: =J7-C7 | L7: =J7-D7 | M7: =IF('/sessions/eloquent-hopeful-babbage/mnt/sample-run/selections\[Ultimates.xlsx]Losses'!O7<>"",'/sessions/eloquent-hopeful-babbage/mnt/sample-run/selections\[Ultimates.xlsx]Losses'!P7,'/sessions/eloquent-hopeful-babbage/mnt/sample-run/selections\[Ultimates.xlsx]Losses'!L7)
A8: 2007 | B8: 215 | C8: ='Incurred CL'!C8 | D8: ='Paid CL'!C8 | E8: ='Incurred CL'!E8 | F8: ='Paid CL'!E8 | G8: ='Incurred IE'!D8 | H8: ='Incurred BF'!H8 | I8: ='Paid BF'!H8 | J8: =IF('/sessions/eloquent-hopeful-babbage/mnt/sample-run/selections\[Ultimates.xlsx]Losses'!O8<>"",'/sessions/eloquent-hopeful-babbage/mnt/sample-run/selections\[Ultimates.xlsx]Losses'!O8,'/sessions/eloquent-hopeful-babbage/mnt/sample-run/selections\[Ultimates.xlsx]Losses'!K8) | K8: =J8-C8 | L8: =J8-D8 | M8: =IF('/sessions/eloquent-hopeful-babbage/mnt/sample-run/selections\[Ultimates.xlsx]Losses'!O8<>"",'/sessions/eloquent-hopeful-babbage/mnt/sample-run/selections\[Ultimates.xlsx]Losses'!P8,'/sessions/eloquent-hopeful-babbage/mnt/sample-run/selections\[Ultimates.xlsx]Losses'!L8)
A9: 2008 | B9: 203 | C9: ='Incurred CL'!C9 | D9: ='Paid CL'!C9 | E9: ='Incurred CL'!E9 | F9: ='Paid CL'!E9 | G9: ='Incurred IE'!D9 | H9: ='Incurred BF'!H9 | I9: ='Paid BF'!H9 | J9: =IF('/sessions/eloquent-hopeful-babbage/mnt/sample-run/selections\[Ultimates.xlsx]Losses'!O9<>"",'/sessions/eloquent-hopeful-babbage/mnt/sample-run/selections\[Ultimates.xlsx]Losses'!O9,'/sessions/eloquent-hopeful-babbage/mnt/sample-run/selections\[Ultimates.xlsx]Losses'!K9) | K9: =J9-C9 | L9: =J9-D9 | M9: =IF('/sessions/eloquent-hopeful-babbage/mnt/sample-run/selections\[Ultimates.xlsx]Losses'!O9<>"",'/sessions/eloquent-hopeful-babbage/mnt/sample-run/selections\[Ultimates.xlsx]Losses'!P9,'/sessions/eloquent-hopeful-babbage/mnt/sample-run/selections\[Ultimates.xlsx]Losses'!L9)
A10: 2009 | B10: 191 | C10: ='Incurred CL'!C10 | D10: ='Paid CL'!C10 | E10: ='Incurred CL'!E10 | F10: ='Paid CL'!E10 | G10: ='Incurred IE'!D10 | H10: ='Incurred BF'!H10 | I10: ='Paid BF'!H10 | J10: =IF('/sessions/eloquent-hopeful-babbage/mnt/sample-run/selections\[Ultimates.xlsx]Losses'!O10<>"",'/sessions/eloquent-hopeful-babbage/mnt/sample-run/selections\[Ultimates.xlsx]Losses'!O10,'/sessions/eloquent-hopeful-babbage/mnt/sample-run/selections\[Ultimates.xlsx]Losses'!K10) | K10: =J10-C10 | L10: =J10-D10 | M10: =IF('/sessions/eloquent-hopeful-babbage/mnt/sample-run/selections\[Ultimates.xlsx]Losses'!O10<>"",'/sessions/eloquent-hopeful-babbage/mnt/sample-run/selections\[Ultimates.xlsx]Losses'!P10,'/sessions/eloquent-hopeful-babbage/mnt/sample-run/selections\[Ultimates.xlsx]Losses'!L10)
A11: 2010 | B11: 179 | C11: ='Incurred CL'!C11 | D11: ='Paid CL'!C11 | E11: ='Incurred CL'!E11 | F11: ='Paid CL'!E11 | G11: ='Incurred IE'!D11 | H11: ='Incurred BF'!H11 | I11: ='Paid BF'!H11 | J11: =IF('/sessions/eloquent-hopeful-babbage/mnt/sample-run/selections\[Ultimates.xlsx]Losses'!O11<>"",'/sessions/eloquent-hopeful-babbage/mnt/sample-run/selections\[Ultimates.xlsx]Losses'!O11,'/sessions/eloquent-hopeful-babbage/mnt/sample-run/selections\[Ultimates.xlsx]Losses'!K11) | K11: =J11-C11 | L11: =J11-D11 | M11: =IF('/sessions/eloquent-hopeful-babbage/mnt/sample-run/selections\[Ultimates.xlsx]Losses'!O11<>"",'/sessions/eloquent-hopeful-babbage/mnt/sample-run/selections\[Ultimates.xlsx]Losses'!P11,'/sessions/eloquent-hopeful-babbage/mnt/sample-run/selections\[Ultimates.xlsx]Losses'!L11)
A12: 2011 | B12: 167 | C12: ='Incurred CL'!C12 | D12: ='Paid CL'!C12 | E12: ='Incurred CL'!E12 | F12: ='Paid CL'!E12 | G12: ='Incurred IE'!D12 | H12: ='Incurred BF'!H12 | I12: ='Paid BF'!H12 | J12: =IF('/sessions/eloquent-hopeful-babbage/mnt/sample-run/selections\[Ultimates.xlsx]Losses'!O12<>"",'/sessions/eloquent-hopeful-babbage/mnt/sample-run/selections\[Ultimates.xlsx]Losses'!O12,'/sessions/eloquent-hopeful-babbage/mnt/sample-run/selections\[Ultimates.xlsx]Losses'!K12) | K12: =J12-C12 | L12: =J12-D12 | M12: =IF('/sessions/eloquent-hopeful-babbage/mnt/sample-run/selections\[Ultimates.xlsx]Losses'!O12<>"",'/sessions/eloquent-hopeful-babbage/mnt/sample-run/selections\[Ultimates.xlsx]Losses'!P12,'/sessions/eloquent-hopeful-babbage/mnt/sample-run/selections\[Ultimates.xlsx]Losses'!L12)
A13: 2012 | B13: 155 | C13: ='Incurred CL'!C13 | D13: ='Paid CL'!C13 | E13: ='Incurred CL'!E13 | F13: ='Paid CL'!E13 | G13: ='Incurred IE'!D13 | H13: ='Incurred BF'!H13 | I13: ='Paid BF'!H13 | J13: =IF('/sessions/eloquent-hopeful-babbage/mnt/sample-run/selections\[Ultimates.xlsx]Losses'!O13<>"",'/sessions/eloquent-hopeful-babbage/mnt/sample-run/selections\[Ultimates.xlsx]Losses'!O13,'/sessions/eloquent-hopeful-babbage/mnt/sample-run/selections\[Ultimates.xlsx]Losses'!K13) | K13: =J13-C13 | L13: =J13-D13 | M13: =IF('/sessions/eloquent-hopeful-babbage/mnt/sample-run/selections\[Ultimates.xlsx]Losses'!O13<>"",'/sessions/eloquent-hopeful-babbage/mnt/sample-run/selections\[Ultimates.xlsx]Losses'!P13,'/sessions/eloquent-hopeful-babbage/mnt/sample-run/selections\[Ultimates.xlsx]Losses'!L13)
... A25: 2024 | B25: 11 | C25: ='Incurred CL'!C25 | D25: ='Paid CL'!C25 | E25: ='Incurred CL'!E25 | F25: ='Paid CL'!E25 | G25: ='Incurred IE'!D25 | H25: ='Incurred BF'!H25 | I25: ='Paid BF'!H25 | J25: =IF('/sessions/eloquent-hopeful-babbage/mnt/sample-run/selections\[Ultimates.xlsx]Losses'!O25<>"",'/sessions/eloquent-hopeful-babbage/mnt/sample-run/selections\[Ultimates.xlsx]Losses'!O25,'/sessions/eloquent-hopeful-babbage/mnt/sample-run/selections\[Ultimates.xlsx]Losses'!K25) | K25: =J25-C25 | L25: =J25-D25 | M25: =IF('/sessions/eloquent-hopeful-babbage/mnt/sample-run/selections\[Ultimates.xlsx]Losses'!O25<>"",'/sessions/eloquent-hopeful-babbage/mnt/sample-run/selections\[Ultimates.xlsx]Losses'!P25,'/sessions/eloquent-hopeful-babbage/mnt/sample-run/selections\[Ultimates.xlsx]Losses'!L25)
A27: Total | C27: =SUM(C2:C25) | D27: =SUM(D2:D25) | E27: =SUM(E2:E25) | F27: =SUM(F2:F25) | G27: =SUM(G2:G25) | H27: =SUM(H2:H25) | I27: =SUM(I2:I25) | J27: =SUM(J2:J25) | ... L27: =SUM(L2:L25)

Sheet Incurred CL
A1: Accident Period | B1: Current Age | C1: Incurred | D1: CDF | E1: Ultimate | F1: IBNR | G1: Unpaid
A2: 2001 | B2: 287 | C2: ='/sessions/eloquent-hopeful-babbage/mnt/sample-run/selections\[Ultimates.xlsx]Losses'!C2 | D2: 1.0215514 | E2: =IF(AND(ISNUMBER(C2),ISNUMBER(D2)),C2*D2,"") | F2: =E2-C2 | G2: =E2-'Paid CL'!C2
A3: 2002 | B3: 275 | C3: ='/sessions/eloquent-hopeful-babbage/mnt/sample-run/selections\[Ultimates.xlsx]Losses'!C3 | D3: 1.0337078 | E3: =IF(AND(ISNUMBER(C3),ISNUMBER(D3)),C3*D3,"") | F3: =E3-C3 | G3: =E3-'Paid CL'!C3
A4: 2003 | B4: 263 | C4: ='/sessions/eloquent-hopeful-babbage/mnt/sample-run/selections\[Ultimates.xlsx]Losses'!C4 | D4: 1.0337078 | E4: =IF(AND(ISNUMBER(C4),ISNUMBER(D4)),C4*D4,"") | F4: =E4-C4 | G4: =E4-'Paid CL'!C4
A5: 2004 | B5: 251 | C5: ='/sessions/eloquent-hopeful-babbage/mnt/sample-run/selections\[Ultimates.xlsx]Losses'!C5 | D5: 1.0516943 | E5: =IF(AND(ISNUMBER(C5),ISNUMBER(D5)),C5*D5,"") | F5: =E5-C5 | G5: =E5-'Paid CL'!C5
A6: 2005 | B6: 239 | C6: ='/sessions/eloquent-hopeful-babbage/mnt/sample-run/selections\[Ultimates.xlsx]Losses'!C6 | D6: 1.058951 | E6: =IF(AND(ISNUMBER(C6),ISNUMBER(D6)),C6*D6,"") | F6: =E6-C6 | G6: =E6-'Paid CL'!C6
A7: 2006 | B7: 227 | C7: ='/sessions/eloquent-hopeful-babbage/mnt/sample-run/selections\[Ultimates.xlsx]Losses'!C7 | D7: 1.0683757 | E7: =IF(AND(ISNUMBER(C7),ISNUMBER(D7)),C7*D7,"") | F7: =E7-C7 | G7: =E7-'Paid CL'!C7
A8: 2007 | B8: 215 | C8: ='/sessions/eloquent-hopeful-babbage/mnt/sample-run/selections\[Ultimates.xlsx]Losses'!C8 | D8: 1.0683757 | E8: =IF(AND(ISNUMBER(C8),ISNUMBER(D8)),C8*D8,"") | F8: =E8-C8 | G8: =E8-'Paid CL'!C8
A9: 2008 | B9: 203 | C9: ='Incurred'!R10 | D9: 1.0705124 | E9: =IF(AND(ISNUMBER(C9),ISNUMBER(D9)),C9*D9,"") | F9: =E9-C9 | G9: =E9-'Paid CL'!C9
A10: 2009 | B10: 191 | C10: ='Incurred'!Q11 | D10: 1.0786483 | E10: =IF(AND(ISNUMBER(C10),ISNUMBER(D10)),C10*D10,"") | F10: =E10-C10 | G10: =E10-'Paid CL'!C10
A11: 2010 | B11: 179 | C11: ='Incurred'!P12 | D11: 1.0825315 | E11: =IF(AND(ISNUMBER(C11),ISNUMBER(D11)),C11*D11,"") | F11: =E11-C11 | G11: =E11-'Paid CL'!C11
A12: 2011 | B12: 167 | C12: ='Incurred'!O13 | D12: 1.1053729 | E12: =IF(AND(ISNUMBER(C12),ISNUMBER(D12)),C12*D12,"") | F12: =E12-C12 | G12: =E12-'Paid CL'!C12
A13: 2012 | B13: 155 | C13: ='Incurred'!N14 | D13: 1.105815 | E13: =IF(AND(ISNUMBER(C13),ISNUMBER(D13)),C13*D13,"") | F13: =E13-C13 | G13: =E13-'Paid CL'!C13
A14: 2013 | B14: 143 | C14: ='Incurred'!M15 | D14: 1.1082478 | E14: =IF(AND(ISNUMBER(C14),ISNUMBER(D14)),C14*D14,"") | F14: =E14-C14 | G14: =E14-'Paid CL'!C14
A15: 2014 | B15: 131 | C15: ='Incurred'!L16 | D15: 1.1470365 | E15: =IF(AND(ISNUMBER(C15),ISNUMBER(D15)),C15*D15,"") | F15: =E15-C15 | G15: =E15-'Paid CL'!C15
A16: 2015 | B16: 119 | C16: ='Incurred'!K17 | D16: 1.1564422 | E16: =IF(AND(ISNUMBER(C16),ISNUMBER(D16)),C16*D16,"") | F16: =E16-C16 | G16: =E16-'Paid CL'!C16
A17: 2016 | B17: 107 | C17: ='Incurred'!J18 | D17: 1.2125296 | E17: =IF(AND(ISNUMBER(C17),ISNUMBER(D17)),C17*D17,"") | F17: =E17-C17 | G17: =E17-'Paid CL'!C17
A18: 2017 | B18: 95 | C18: ='Incurred'!I19 | D18: 1.2302326 | E18: =IF(AND(ISNUMBER(C18),ISNUMBER(D18)),C18*D18,"") | F18: =E18-C18 | G18: =E18-'Paid CL'!C18
A19: 2018 | B19: 83 | C19: ='Incurred'!H20 | D19: 1.2382291 | E19: =IF(AND(ISNUMBER(C19),ISNUMBER(D19)),C19*D19,"") | F19: =E19-C19 | G19: =E19-'Paid CL'!C19
A20: 2019 | B20: 71 | C20: ='Incurred'!G21 | D20: 1.345955 | E20: =IF(AND(ISNUMBER(C20),ISNUMBER(D20)),C20*D20,"") | F20: =E20-C20 | G20: =E20-'Paid CL'!C20
A21: 2020 | B21: 59 | C21: ='Incurred'!F22 | D21: 1.4841846 | E21: =IF(AND(ISNUMBER(C21),ISNUMBER(D21)),C21*D21,"") | F21: =E21-C21 | G21: =E21-'Paid CL'!C21
A22: 2021 | B22: 47 | C22: ='Incurred'!E23 | D22: 1.5683379 | E22: =IF(AND(ISNUMBER(C22),ISNUMBER(D22)),C22*D22,"") | F22: =E22-C22 | G22: =E22-'Paid CL'!C22
A23: 2022 | B23: 35 | C23: ='Incurred'!D24 | D23: 1.8823191 | E23: =IF(AND(ISNUMBER(C23),ISNUMBER(D23)),C23*D23,"") | F23: =E23-C23 | G23: =E23-'Paid CL'!C23
A24: 2023 | B24: 23 | C24: ='Incurred'!C25 | D24: 2.3670163 | E24: =IF(AND(ISNUMBER(C24),ISNUMBER(D24)),C24*D24,"") | F24: =E24-C24 | G24: =E24-'Paid CL'!C24
A25: 2024 | B25: 11 | C25: ='Incurred'!B26 | D25: 4.0296085 | E25: =IF(AND(ISNUMBER(C25),ISNUMBER(D25)),C25*D25,"") | F25: =E25-C25 | G25: =E25-'Paid CL'!C25
A27: Total | C27: =SUM(C2:C25) | E27: =SUM(E2:E25) | F27: =SUM(F2:F25) | G27: =SUM(G2:G25)

Sheet Paid CL
A1: Accident Period | B1: Current Age | C1: Paid | D1: CDF | E1: Ultimate | F1: IBNR | G1: Unpaid
A2: 2001 | B2: 287 | C2: ='/sessions/eloquent-hopeful-babbage/mnt/sample-run/selections\[Ultimates.xlsx]Losses'!D2 | D2: 1.0039 | E2: =IF(AND(ISNUMBER(C2),ISNUMBER(D2)),C2*D2,"") | F2: =E2-C2 | G2: =E2-C2
A3: 2002 | B3: 275 | C3: ='/sessions/eloquent-hopeful-babbage/mnt/sample-run/selections\[Ultimates.xlsx]Losses'!D3 | D3: 1.0078152 | E3: =IF(AND(ISNUMBER(C3),ISNUMBER(D3)),C3*D3,"") | F3: =E3-C3 | G3: =E3-C3
A4: 2003 | B4: 263 | C4: ='/sessions/eloquent-hopeful-babbage/mnt/sample-run/selections\[Ultimates.xlsx]Losses'!D4 | D4: 1.015273 | E4: =IF(AND(ISNUMBER(C4),ISNUMBER(D4)),C4*D4,"") | F4: =E4-C4 | G4: =E4-C4
A5: 2004 | B5: 251 | C5: ='/sessions/eloquent-hopeful-babbage/mnt/sample-run/selections\[Ultimates.xlsx]Losses'!D5 | D5: 1.0215677 | E5: =IF(AND(ISNUMBER(C5),ISNUMBER(D5)),C5*D5,"") | F5: =E5-C5 | G5: =E5-C5
A6: 2005 | B6: 239 | C6: ='/sessions/eloquent-hopeful-babbage/mnt/sample-run/selections\[Ultimates.xlsx]Losses'!D6 | D6: 1.0270842 | E6: =IF(AND(ISNUMBER(C6),ISNUMBER(D6)),C6*D6,"") | F6: =E6-C6 | G6: =E6-C6
A7: 2006 | B7: 227 | C7: ='/sessions/eloquent-hopeful-babbage/mnt/sample-run/selections\[Ultimates.xlsx]Losses'!D7 | D7: 1.0296519 | E7: =IF(AND(ISNUMBER(C7),ISNUMBER(D7)),C7*D7,"") | F7: =E7-C7 | G7: =E7-C7
A8: 2007 | B8: 215 | C8: ='/sessions/eloquent-hopeful-babbage/mnt/sample-run/selections\[Ultimates.xlsx]Losses'!D8 | D8: 1.0344913 | E8: =IF(AND(ISNUMBER(C8),ISNUMBER(D8)),C8*D8,"") | F8: =E8-C8 | G8: =E8-C8
A9: 2008 | B9: 203 | C9: ='Paid'!R10 | D9: 1.0366637 | E9: =IF(AND(ISNUMBER(C9),ISNUMBER(D9)),C9*D9,"") | F9: =E9-C9 | G9: =E9-C9
A10: 2009 | B10: 191 | C10: ='Paid'!Q11 | D10: 1.0485853 | E10: =IF(AND(ISNUMBER(C10),ISNUMBER(D10)),C10*D10,"") | F10: =E10-C10 | G10: =E10-C10
A11: 2010 | B11: 179 | C11: ='Paid'!P12 | D11: 1.0649433 | E11: =IF(AND(ISNUMBER(C11),ISNUMBER(D11)),C11*D11,"") | F11: =E11-C11 | G11: =E11-C11
A12: 2011 | B12: 167 | C12: ='Paid'!O13 | D12: 1.080172 | E12: =IF(AND(ISNUMBER(C12),ISNUMBER(D12)),C12*D12,"") | F12: =E12-C12 | G12: =E12-C12
A13: 2012 | B13: 155 | C13: ='Paid'!N14 | D13: 1.0946463 | E13: =IF(AND(ISNUMBER(C13),ISNUMBER(D13)),C13*D13,"") | F13: =E13-C13 | G13: =E13-C13
A14: 2013 | B14: 143 | C14: ='Paid'!M15 | D14: 1.1138026 | E14: =IF(AND(ISNUMBER(C14),ISNUMBER(D14)),C14*D14,"") | F14: =E14-C14 | G14: =E14-C14
A15: 2014 | B15: 131 | C15: ='Paid'!L16 | D15: 1.1348534 | E15: =IF(AND(ISNUMBER(C15),ISNUMBER(D15)),C15*D15,"") | F15: =E15-C15 | G15: =E15-C15
A16: 2015 | B16: 119 | C16: ='Paid'!K17 | D16: 1.1442727 | E16: =IF(AND(ISNUMBER(C16),ISNUMBER(D16)),C16*D16,"") | F16: =E16-C16 | G16: =E16-C16
A17: 2016 | B17: 107 | C17: ='Paid'!J18 | D17: 1.2180783 | E17: =IF(AND(ISNUMBER(C17),ISNUMBER(D17)),C17*D17,"") | F17: =E17-C17 | G17: =E17-C17
A18: 2017 | B18: 95 | C18: ='Paid'!I19 | D18: 1.234157 | E18: =IF(AND(ISNUMBER(C18),ISNUMBER(D18)),C18*D18,"") | F18: =E18-C18 | G18: =E18-C18
A19: 2018 | B19: 83 | C19: ='Paid'!H20 | D19: 1.2746373 | E19: =IF(AND(ISNUMBER(C19),ISNUMBER(D19)),C19*D19,"") | F19: =E19-C19 | G19: =E19-C19
A20: 2019 | B20: 71 | C20: ='Paid'!G21 | D20: 1.4110235 | E20: =IF(AND(ISNUMBER(C20),ISNUMBER(D20)),C20*D20,"") | F20: =E20-C20 | G20: =E20-C20
A21: 2020 | B21: 59 | C21: ='Paid'!F22 | D21: 1.5792175 | E21: =IF(AND(ISNUMBER(C21),ISNUMBER(D21)),C21*D21,"") | F21: =E21-C21 | G21: =E21-C21
A22: 2021 | B22: 47 | C22: ='Paid'!E23 | D22: 1.733665 | E22: =IF(AND(ISNUMBER(C22),ISNUMBER(D22)),C22*D22,"") | F22: =E22-C22 | G22: =E22-C22
A23: 2022 | B23: 35 | C23: ='Paid'!D24 | D23: 2.0802246 | E23: =IF(AND(ISNUMBER(C23),ISNUMBER(D23)),C23*D23,"") | F23: =E23-C23 | G23: =E23-C23
A24: 2023 | B24: 23 | C24: ='Paid'!C25 | D24: 2.9589115 | E24: =IF(AND(ISNUMBER(C24),ISNUMBER(D24)),C24*D24,"") | F24: =E24-C24 | G24: =E24-C24
A25: 2024 | B25: 11 | C25: ='Paid'!B26 | D25: 7.7618165 | E25: =IF(AND(ISNUMBER(C25),ISNUMBER(D25)),C25*D25,"") | F25: =E25-C25 | G25: =E25-C25
A27: Total | C27: =SUM(C2:C25) | E27: =SUM(E2:E25) | F27: =SUM(F2:F25) | G27: =SUM(G2:G25)

Sheet Incurred BF
A1: Accident Period | B1: Current Age | C1: Initial Expected | D1: CDF | E1: % Unreported | F1: Unreported | G1: Incurred | H1: Ultimate | I1: IBNR | J1: Unpaid
A2: 2001 | B2: 287 | C2: ='Incurred IE'!D2 | D2: ='Incurred CL'!D2 | E2: =1-(1/D2) | F2: =C2*E2 | G2: ='Incurred CL'!C2 | H2: =F2+G2 | I2: =H2-G2 | J2: =H2-'Paid CL'!C2
A3: 2002 | B3: 275 | C3: ='Incurred IE'!D3 | D3: ='Incurred CL'!D3 | E3: =1-(1/D3) | F3: =C3*E3 | G3: ='Incurred CL'!C3 | H3: =F3+G3 | I3: =H3-G3 | J3: =H3-'Paid CL'!C3
A4: 2003 | B4: 263 | C4: ='Incurred IE'!D4 | D4: ='Incurred CL'!D4 | E4: =1-(1/D4) | F4: =C4*E4 | G4: ='Incurred CL'!C4 | H4: =F4+G4 | I4: =H4-G4 | J4: =H4-'Paid CL'!C4
A5: 2004 | B5: 251 | C5: ='Incurred IE'!D5 | D5: ='Incurred CL'!D5 | E5: =1-(1/D5) | F5: =C5*E5 | G5: ='Incurred CL'!C5 | H5: =F5+G5 | I5: =H5-G5 | J5: =H5-'Paid CL'!C5
A6: 2005 | B6: 239 | C6: ='Incurred IE'!D6 | D6: ='Incurred CL'!D6 | E6: =1-(1/D6) | F6: =C6*E6 | G6: ='Incurred CL'!C6 | H6: =F6+G6 | I6: =H6-G6 | J6: =H6-'Paid CL'!C6
A7: 2006 | B7: 227 | C7: ='Incurred IE'!D7 | D7: ='Incurred CL'!D7 | E7: =1-(1/D7) | F7: =C7*E7 | G7: ='Incurred CL'!C7 | H7: =F7+G7 | I7: =H7-G7 | J7: =H7-'Paid CL'!C7
A8: 2007 | B8: 215 | C8: ='Incurred IE'!D8 | D8: ='Incurred CL'!D8 | E8: =1-(1/D8) | F8: =C8*E8 | G8: ='Incurred CL'!C8 | H8: =F8+G8 | I8: =H8-G8 | J8: =H8-'Paid CL'!C8
A9: 2008 | B9: 203 | C9: ='Incurred IE'!D9 | D9: ='Incurred CL'!D9 | E9: =1-(1/D9) | F9: =C9*E9 | G9: ='Incurred CL'!C9 | H9: =F9+G9 | I9: =H9-G9 | J9: =H9-'Paid CL'!C9
A10: 2009 | B10: 191 | C10: ='Incurred IE'!D10 | D10: ='Incurred CL'!D10 | E10: =1-(1/D10) | F10: =C10*E10 | G10: ='Incurred CL'!C10 | H10: =F10+G10 | I10: =H10-G10 | J10: =H10-'Paid CL'!C10
A11: 2010 | B11: 179 | C11: ='Incurred IE'!D11 | D11: ='Incurred CL'!D11 | E11: =1-(1/D11) | F11: =C11*E11 | G11: ='Incurred CL'!C11 | H11: =F11+G11 | I11: =H11-G11 | J11: =H11-'Paid CL'!C11
A12: 2011 | B12: 167 | C12: ='Incurred IE'!D12 | D12: ='Incurred CL'!D12 | E12: =1-(1/D12) | F12: =C12*E12 | G12: ='Incurred CL'!C12 | H12: =F12+G12 | I12: =H12-G12 | J12: =H12-'Paid CL'!C12
A13: 2012 | B13: 155 | C13: ='Incurred IE'!D13 | D13: ='Incurred CL'!D13 | E13: =1-(1/D13) | F13: =C13*E13 | G13: ='Incurred CL'!C13 | H13: =F13+G13 | I13: =H13-G13 | J13: =H13-'Paid CL'!C13
... A25: 2024 | B25: 11 | C25: ='Incurred IE'!D25 | D25: ='Incurred CL'!D25 | E25: =1-(1/D25) | F25: =C25*E25 | G25: ='Incurred CL'!C25 | H25: =F25+G25 | I25: =H25-G25 | J25: =H25-'Paid CL'!C25
A27: Total | C27: =SUM(C2:C25) | E27: =SUM(F2:F25)/SUM(C2:C25) | F27: =SUM(F2:F25) | G27: =SUM(G2:G25) | H27: =SUM(H2:H25) | I27: =SUM(I2:I25) | J27: =SUM(J2:J25)

Sheet Paid BF
A1: Accident Period | B1: Current Age | C1: Initial Expected | D1: CDF | E1: % Unreported | F1: Unreported | G1: Paid | H1: Ultimate | I1: IBNR | J1: Unpaid
A2: 2001 | B2: 287 | C2: ='Paid IE'!D2 | D2: ='Paid CL'!D2 | E2: =1-(1/D2) | F2: =C2*E2 | G2: ='Paid CL'!C2 | H2: =F2+G2 | I2: =H2-G2 | J2: =H2-G2
A3: 2002 | B3: 275 | C3: ='Paid IE'!D3 | D3: ='Paid CL'!D3 | E3: =1-(1/D3) | F3: =C3*E3 | G3: ='Paid CL'!C3 | H3: =F3+G3 | I3: =H3-G3 | J3: =H3-G3
A4: 2003 | B4: 263 | C4: ='Paid IE'!D4 | D4: ='Paid CL'!D4 | E4: =1-(1/D4) | F4: =C4*E4 | G4: ='Paid CL'!C4 | H4: =F4+G4 | I4: =H4-G4 | J4: =H4-G4
A5: 2004 | B5: 251 | C5: ='Paid IE'!D5 | D5: ='Paid CL'!D5 | E5: =1-(1/D5) | F5: =C5*E5 | G5: ='Paid CL'!C5 | H5: =F5+G5 | I5: =H5-G5 | J5: =H5-G5
A6: 2005 | B6: 239 | C6: ='Paid IE'!D6 | D6: ='Paid CL'!D6 | E6: =1-(1/D6) | F6: =C6*E6 | G6: ='Paid CL'!C6 | H6: =F6+G6 | I6: =H6-G6 | J6: =H6-G6
A7: 2006 | B7: 227 | C7: ='Paid IE'!D7 | D7: ='Paid CL'!D7 | E7: =1-(1/D7) | F7: =C7*E7 | G7: ='Paid CL'!C7 | H7: =F7+G7 | I7: =H7-G7 | J7: =H7-G7
A8: 2007 | B8: 215 | C8: ='Paid IE'!D8 | D8: ='Paid CL'!D8 | E8: =1-(1/D8) | F8: =C8*E8 | G8: ='Paid CL'!C8 | H8: =F8+G8 | I8: =H8-G8 | J8: =H8-G8
A9: 2008 | B9: 203 | C9: ='Paid IE'!D9 | D9: ='Paid CL'!D9 | E9: =1-(1/D9) | F9: =C9*E9 | G9: ='Paid CL'!C9 | H9: =F9+G9 | I9: =H9-G9 | J9: =H9-G9
A10: 2009 | B10: 191 | C10: ='Paid IE'!D10 | D10: ='Paid CL'!D10 | E10: =1-(1/D10) | F10: =C10*E10 | G10: ='Paid CL'!C10 | H10: =F10+G10 | I10: =H10-G10 | J10: =H10-G10
A11: 2010 | B11: 179 | C11: ='Paid IE'!D11 | D11: ='Paid CL'!D11 | E11: =1-(1/D11) | F11: =C11*E11 | G11: ='Paid CL'!C11 | H11: =F11+G11 | I11: =H11-G11 | J11: =H11-G11
A12: 2011 | B12: 167 | C12: ='Paid IE'!D12 | D12: ='Paid CL'!D12 | E12: =1-(1/D12) | F12: =C12*E12 | G12: ='Paid CL'!C12 | H12: =F12+G12 | I12: =H12-G12 | J12: =H12-G12
A13: 2012 | B13: 155 | C13: ='Paid IE'!D13 | D13: ='Paid CL'!D13 | E13: =1-(1/D13) | F13: =C13*E13 | G13: ='Paid CL'!C13 | H13: =F13+G13 | I13: =H13-G13 | J13: =H13-G13
... A25: 2024 | B25: 11 | C25: ='Paid IE'!D25 | D25: ='Paid CL'!D25 | E25: =1-(1/D25) | F25: =C25*E25 | G25: ='Paid CL'!C25 | H25: =F25+G25 | I25: =H25-G25 | J25: =H25-G25
A27: Total | C27: =SUM(C2:C25) | E27: =SUM(F2:F25)/SUM(C2:C25) | F27: =SUM(F2:F25) | G27: =SUM(G2:G25) | H27: =SUM(H2:H25) | I27: =SUM(I2:I25) | J27: =SUM(J2:J25)

Sheet Incurred IE
A1: Accident Period | B1: Current Age | C1: Exposure | D1: IE Ultimate | E1: Selected Loss Rate
A2: 2001 | B2: 287 | C2: ='/sessions/eloquent-hopeful-babbage/mnt/sample-run/selections\[Chain Ladder Selections - LDFs.xlsx]Exposure'!B3 | D2: ='/sessions/eloquent-hopeful-babbage/mnt/sample-run/selections\[Ultimates.xlsx]Losses'!G2 | E2: =D2/C2
A3: 2002 | B3: 275 | C3: ='/sessions/eloquent-hopeful-babbage/mnt/sample-run/selections\[Chain Ladder Selections - LDFs.xlsx]Exposure'!B4 | D3: ='/sessions/eloquent-hopeful-babbage/mnt/sample-run/selections\[Ultimates.xlsx]Losses'!G3 | E3: =D3/C3
A4: 2003 | B4: 263 | C4: ='/sessions/eloquent-hopeful-babbage/mnt/sample-run/selections\[Chain Ladder Selections - LDFs.xlsx]Exposure'!B5 | D4: ='/sessions/eloquent-hopeful-babbage/mnt/sample-run/selections\[Ultimates.xlsx]Losses'!G4 | E4: =D4/C4
A5: 2004 | B5: 251 | C5: ='/sessions/eloquent-hopeful-babbage/mnt/sample-run/selections\[Chain Ladder Selections - LDFs.xlsx]Exposure'!B6 | D5: ='/sessions/eloquent-hopeful-babbage/mnt/sample-run/selections\[Ultimates.xlsx]Losses'!G5 | E5: =D5/C5
A6: 2005 | B6: 239 | C6: ='/sessions/eloquent-hopeful-babbage/mnt/sample-run/selections\[Chain Ladder Selections - LDFs.xlsx]Exposure'!B7 | D6: ='/sessions/eloquent-hopeful-babbage/mnt/sample-run/selections\[Ultimates.xlsx]Losses'!G6 | E6: =D6/C6
A7: 2006 | B7: 227 | C7: ='/sessions/eloquent-hopeful-babbage/mnt/sample-run/selections\[Chain Ladder Selections - LDFs.xlsx]Exposure'!B8 | D7: ='/sessions/eloquent-hopeful-babbage/mnt/sample-run/selections\[Ultimates.xlsx]Losses'!G7 | E7: =D7/C7
A8: 2007 | B8: 215 | C8: ='/sessions/eloquent-hopeful-babbage/mnt/sample-run/selections\[Chain Ladder Selections - LDFs.xlsx]Exposure'!B9 | D8: ='/sessions/eloquent-hopeful-babbage/mnt/sample-run/selections\[Ultimates.xlsx]Losses'!G8 | E8: =D8/C8
A9: 2008 | B9: 203 | C9: ='/sessions/eloquent-hopeful-babbage/mnt/sample-run/selections\[Chain Ladder Selections - LDFs.xlsx]Exposure'!B10 | D9: ='/sessions/eloquent-hopeful-babbage/mnt/sample-run/selections\[Ultimates.xlsx]Losses'!G9 | E9: =D9/C9
A10: 2009 | B10: 191 | C10: ='/sessions/eloquent-hopeful-babbage/mnt/sample-run/selections\[Chain Ladder Selections - LDFs.xlsx]Exposure'!B11 | D10: ='/sessions/eloquent-hopeful-babbage/mnt/sample-run/selections\[Ultimates.xlsx]Losses'!G10 | E10: =D10/C10
A11: 2010 | B11: 179 | C11: ='/sessions/eloquent-hopeful-babbage/mnt/sample-run/selections\[Chain Ladder Selections - LDFs.xlsx]Exposure'!B12 | D11: ='/sessions/eloquent-hopeful-babbage/mnt/sample-run/selections\[Ultimates.xlsx]Losses'!G11 | E11: =D11/C11
A12: 2011 | B12: 167 | C12: ='/sessions/eloquent-hopeful-babbage/mnt/sample-run/selections\[Chain Ladder Selections - LDFs.xlsx]Exposure'!B13 | D12: ='/sessions/eloquent-hopeful-babbage/mnt/sample-run/selections\[Ultimates.xlsx]Losses'!G12 | E12: =D12/C12
A13: 2012 | B13: 155 | C13: ='/sessions/eloquent-hopeful-babbage/mnt/sample-run/selections\[Chain Ladder Selections - LDFs.xlsx]Exposure'!B14 | D13: ='/sessions/eloquent-hopeful-babbage/mnt/sample-run/selections\[Ultimates.xlsx]Losses'!G13 | E13: =D13/C13
... A25: 2024 | B25: 11 | C25: ='/sessions/eloquent-hopeful-babbage/mnt/sample-run/selections\[Chain Ladder Selections - LDFs.xlsx]Exposure'!B26 | D25: ='/sessions/eloquent-hopeful-babbage/mnt/sample-run/selections\[Ultimates.xlsx]Losses'!G25 | E25: =D25/C25

Sheet Paid IE
A1: Accident Period | B1: Current Age | C1: Exposure | D1: IE Ultimate | E1: Selected Loss Rate
A2: 2001 | B2: 287 | C2: ='/sessions/eloquent-hopeful-babbage/mnt/sample-run/selections\[Chain Ladder Selections - LDFs.xlsx]Exposure'!B3 | D2: ='/sessions/eloquent-hopeful-babbage/mnt/sample-run/selections\[Ultimates.xlsx]Losses'!H2 | E2: =D2/C2
A3: 2002 | B3: 275 | C3: ='/sessions/eloquent-hopeful-babbage/mnt/sample-run/selections\[Chain Ladder Selections - LDFs.xlsx]Exposure'!B4 | D3: ='/sessions/eloquent-hopeful-babbage/mnt/sample-run/selections\[Ultimates.xlsx]Losses'!H3 | E3: =D3/C3
A4: 2003 | B4: 263 | C4: ='/sessions/eloquent-hopeful-babbage/mnt/sample-run/selections\[Chain Ladder Selections - LDFs.xlsx]Exposure'!B5 | D4: ='/sessions/eloquent-hopeful-babbage/mnt/sample-run/selections\[Ultimates.xlsx]Losses'!H4 | E4: =D4/C4
A5: 2004 | B5: 251 | C5: ='/sessions/eloquent-hopeful-babbage/mnt/sample-run/selections\[Chain Ladder Selections - LDFs.xlsx]Exposure'!B6 | D5: ='/sessions/eloquent-hopeful-babbage/mnt/sample-run/selections\[Ultimates.xlsx]Losses'!H5 | E5: =D5/C5
A6: 2005 | B6: 239 | C6: ='/sessions/eloquent-hopeful-babbage/mnt/sample-run/selections\[Chain Ladder Selections - LDFs.xlsx]Exposure'!B7 | D6: ='/sessions/eloquent-hopeful-babbage/mnt/sample-run/selections\[Ultimates.xlsx]Losses'!H6 | E6: =D6/C6
A7: 2006 | B7: 227 | C7: ='/sessions/eloquent-hopeful-babbage/mnt/sample-run/selections\[Chain Ladder Selections - LDFs.xlsx]Exposure'!B8 | D7: ='/sessions/eloquent-hopeful-babbage/mnt/sample-run/selections\[Ultimates.xlsx]Losses'!H7 | E7: =D7/C7
A8: 2007 | B8: 215 | C8: ='/sessions/eloquent-hopeful-babbage/mnt/sample-run/selections\[Chain Ladder Selections - LDFs.xlsx]Exposure'!B9 | D8: ='/sessions/eloquent-hopeful-babbage/mnt/sample-run/selections\[Ultimates.xlsx]Losses'!H8 | E8: =D8/C8
A9: 2008 | B9: 203 | C9: ='/sessions/eloquent-hopeful-babbage/mnt/sample-run/selections\[Chain Ladder Selections - LDFs.xlsx]Exposure'!B10 | D9: ='/sessions/eloquent-hopeful-babbage/mnt/sample-run/selections\[Ultimates.xlsx]Losses'!H9 | E9: =D9/C9
A10: 2009 | B10: 191 | C10: ='/sessions/eloquent-hopeful-babbage/mnt/sample-run/selections\[Chain Ladder Selections - LDFs.xlsx]Exposure'!B11 | D10: ='/sessions/eloquent-hopeful-babbage/mnt/sample-run/selections\[Ultimates.xlsx]Losses'!H10 | E10: =D10/C10
A11: 2010 | B11: 179 | C11: ='/sessions/eloquent-hopeful-babbage/mnt/sample-run/selections\[Chain Ladder Selections - LDFs.xlsx]Exposure'!B12 | D11: ='/sessions/eloquent-hopeful-babbage/mnt/sample-run/selections\[Ultimates.xlsx]Losses'!H11 | E11: =D11/C11
A12: 2011 | B12: 167 | C12: ='/sessions/eloquent-hopeful-babbage/mnt/sample-run/selections\[Chain Ladder Selections - LDFs.xlsx]Exposure'!B13 | D12: ='/sessions/eloquent-hopeful-babbage/mnt/sample-run/selections\[Ultimates.xlsx]Losses'!H12 | E12: =D12/C12
A13: 2012 | B13: 155 | C13: ='/sessions/eloquent-hopeful-babbage/mnt/sample-run/selections\[Chain Ladder Selections - LDFs.xlsx]Exposure'!B14 | D13: ='/sessions/eloquent-hopeful-babbage/mnt/sample-run/selections\[Ultimates.xlsx]Losses'!H13 | E13: =D13/C13
... A25: 2024 | B25: 11 | C25: ='/sessions/eloquent-hopeful-babbage/mnt/sample-run/selections\[Chain Ladder Selections - LDFs.xlsx]Exposure'!B26 | D25: ='/sessions/eloquent-hopeful-babbage/mnt/sample-run/selections\[Ultimates.xlsx]Losses'!H25 | E25: =D25/C25

Sheet Count Selection
A1: Accident Period | B1: Current Age | C1: Reported | D1: Reported CL | E1: Initial Expected | F1: Reported BF | G1: Selected Ultimate | H1: IBNR | I1: Unpaid | J1: Selected Reasoning
A2: 2001 | B2: 287 | C2: ='Reported CL'!C2 | D2: ='Reported CL'!E2 | E2: ='Reported IE'!D2 | F2: ='Reported BF'!H2 | G2: =IF('/sessions/eloquent-hopeful-babbage/mnt/sample-run/selections\[Ultimates.xlsx]Counts'!K2<>"",'/sessions/eloquent-hopeful-babbage/mnt/sample-run/selections\[Ultimates.xlsx]Counts'!K2,'/sessions/eloquent-hopeful-babbage/mnt/sample-run/selections\[Ultimates.xlsx]Counts'!G2) | H2: =G2-C2 | I2: =G2-C2 | J2: =IF('/sessions/eloquent-hopeful-babbage/mnt/sample-run/selections\[Ultimates.xlsx]Counts'!K2<>"",'/sessions/eloquent-hopeful-babbage/mnt/sample-run/selections\[Ultimates.xlsx]Counts'!L2,'/sessions/eloquent-hopeful-babbage/mnt/sample-run/selections\[Ultimates.xlsx]Counts'!H2)
A3: 2002 | B3: 275 | C3: ='Reported CL'!C3 | D3: ='Reported CL'!E3 | E3: ='Reported IE'!D3 | F3: ='Reported BF'!H3 | G3: =IF('/sessions/eloquent-hopeful-babbage/mnt/sample-run/selections\[Ultimates.xlsx]Counts'!K3<>"",'/sessions/eloquent-hopeful-babbage/mnt/sample-run/selections\[Ultimates.xlsx]Counts'!K3,'/sessions/eloquent-hopeful-babbage/mnt/sample-run/selections\[Ultimates.xlsx]Counts'!G3) | H3: =G3-C3 | I3: =G3-C3 | J3: =IF('/sessions/eloquent-hopeful-babbage/mnt/sample-run/selections\[Ultimates.xlsx]Counts'!K3<>"",'/sessions/eloquent-hopeful-babbage/mnt/sample-run/selections\[Ultimates.xlsx]Counts'!L3,'/sessions/eloquent-hopeful-babbage/mnt/sample-run/selections\[Ultimates.xlsx]Counts'!H3)
A4: 2003 | B4: 263 | C4: ='Reported CL'!C4 | D4: ='Reported CL'!E4 | E4: ='Reported IE'!D4 | F4: ='Reported BF'!H4 | G4: =IF('/sessions/eloquent-hopeful-babbage/mnt/sample-run/selections\[Ultimates.xlsx]Counts'!K4<>"",'/sessions/eloquent-hopeful-babbage/mnt/sample-run/selections\[Ultimates.xlsx]Counts'!K4,'/sessions/eloquent-hopeful-babbage/mnt/sample-run/selections\[Ultimates.xlsx]Counts'!G4) | H4: =G4-C4 | I4: =G4-C4 | J4: =IF('/sessions/eloquent-hopeful-babbage/mnt/sample-run/selections\[Ultimates.xlsx]Counts'!K4<>"",'/sessions/eloquent-hopeful-babbage/mnt/sample-run/selections\[Ultimates.xlsx]Counts'!L4,'/sessions/eloquent-hopeful-babbage/mnt/sample-run/selections\[Ultimates.xlsx]Counts'!H4)
A5: 2004 | B5: 251 | C5: ='Reported CL'!C5 | D5: ='Reported CL'!E5 | E5: ='Reported IE'!D5 | F5: ='Reported BF'!H5 | G5: =IF('/sessions/eloquent-hopeful-babbage/mnt/sample-run/selections\[Ultimates.xlsx]Counts'!K5<>"",'/sessions/eloquent-hopeful-babbage/mnt/sample-run/selections\[Ultimates.xlsx]Counts'!K5,'/sessions/eloquent-hopeful-babbage/mnt/sample-run/selections\[Ultimates.xlsx]Counts'!G5) | H5: =G5-C5 | I5: =G5-C5 | J5: =IF('/sessions/eloquent-hopeful-babbage/mnt/sample-run/selections\[Ultimates.xlsx]Counts'!K5<>"",'/sessions/eloquent-hopeful-babbage/mnt/sample-run/selections\[Ultimates.xlsx]Counts'!L5,'/sessions/eloquent-hopeful-babbage/mnt/sample-run/selections\[Ultimates.xlsx]Counts'!H5)
A6: 2005 | B6: 239 | C6: ='Reported CL'!C6 | D6: ='Reported CL'!E6 | E6: ='Reported IE'!D6 | F6: ='Reported BF'!H6 | G6: =IF('/sessions/eloquent-hopeful-babbage/mnt/sample-run/selections\[Ultimates.xlsx]Counts'!K6<>"",'/sessions/eloquent-hopeful-babbage/mnt/sample-run/selections\[Ultimates.xlsx]Counts'!K6,'/sessions/eloquent-hopeful-babbage/mnt/sample-run/selections\[Ultimates.xlsx]Counts'!G6) | H6: =G6-C6 | I6: =G6-C6 | J6: =IF('/sessions/eloquent-hopeful-babbage/mnt/sample-run/selections\[Ultimates.xlsx]Counts'!K6<>"",'/sessions/eloquent-hopeful-babbage/mnt/sample-run/selections\[Ultimates.xlsx]Counts'!L6,'/sessions/eloquent-hopeful-babbage/mnt/sample-run/selections\[Ultimates.xlsx]Counts'!H6)
A7: 2006 | B7: 227 | C7: ='Reported CL'!C7 | D7: ='Reported CL'!E7 | E7: ='Reported IE'!D7 | F7: ='Reported BF'!H7 | G7: =IF('/sessions/eloquent-hopeful-babbage/mnt/sample-run/selections\[Ultimates.xlsx]Counts'!K7<>"",'/sessions/eloquent-hopeful-babbage/mnt/sample-run/selections\[Ultimates.xlsx]Counts'!K7,'/sessions/eloquent-hopeful-babbage/mnt/sample-run/selections\[Ultimates.xlsx]Counts'!G7) | H7: =G7-C7 | I7: =G7-C7 | J7: =IF('/sessions/eloquent-hopeful-babbage/mnt/sample-run/selections\[Ultimates.xlsx]Counts'!K7<>"",'/sessions/eloquent-hopeful-babbage/mnt/sample-run/selections\[Ultimates.xlsx]Counts'!L7,'/sessions/eloquent-hopeful-babbage/mnt/sample-run/selections\[Ultimates.xlsx]Counts'!H7)
A8: 2007 | B8: 215 | C8: ='Reported CL'!C8 | D8: ='Reported CL'!E8 | E8: ='Reported IE'!D8 | F8: ='Reported BF'!H8 | G8: =IF('/sessions/eloquent-hopeful-babbage/mnt/sample-run/selections\[Ultimates.xlsx]Counts'!K8<>"",'/sessions/eloquent-hopeful-babbage/mnt/sample-run/selections\[Ultimates.xlsx]Counts'!K8,'/sessions/eloquent-hopeful-babbage/mnt/sample-run/selections\[Ultimates.xlsx]Counts'!G8) | H8: =G8-C8 | I8: =G8-C8 | J8: =IF('/sessions/eloquent-hopeful-babbage/mnt/sample-run/selections\[Ultimates.xlsx]Counts'!K8<>"",'/sessions/eloquent-hopeful-babbage/mnt/sample-run/selections\[Ultimates.xlsx]Counts'!L8,'/sessions/eloquent-hopeful-babbage/mnt/sample-run/selections\[Ultimates.xlsx]Counts'!H8)
A9: 2008 | B9: 203 | C9: ='Reported CL'!C9 | D9: ='Reported CL'!E9 | E9: ='Reported IE'!D9 | F9: ='Reported BF'!H9 | G9: =IF('/sessions/eloquent-hopeful-babbage/mnt/sample-run/selections\[Ultimates.xlsx]Counts'!K9<>"",'/sessions/eloquent-hopeful-babbage/mnt/sample-run/selections\[Ultimates.xlsx]Counts'!K9,'/sessions/eloquent-hopeful-babbage/mnt/sample-run/selections\[Ultimates.xlsx]Counts'!G9) | H9: =G9-C9 | I9: =G9-C9 | J9: =IF('/sessions/eloquent-hopeful-babbage/mnt/sample-run/selections\[Ultimates.xlsx]Counts'!K9<>"",'/sessions/eloquent-hopeful-babbage/mnt/sample-run/selections\[Ultimates.xlsx]Counts'!L9,'/sessions/eloquent-hopeful-babbage/mnt/sample-run/selections\[Ultimates.xlsx]Counts'!H9)
A10: 2009 | B10: 191 | C10: ='Reported CL'!C10 | D10: ='Reported CL'!E10 | E10: ='Reported IE'!D10 | F10: ='Reported BF'!H10 | G10: =IF('/sessions/eloquent-hopeful-babbage/mnt/sample-run/selections\[Ultimates.xlsx]Counts'!K10<>"",'/sessions/eloquent-hopeful-babbage/mnt/sample-run/selections\[Ultimates.xlsx]Counts'!K10,'/sessions/eloquent-hopeful-babbage/mnt/sample-run/selections\[Ultimates.xlsx]Counts'!G10) | H10: =G10-C10 | I10: =G10-C10 | J10: =IF('/sessions/eloquent-hopeful-babbage/mnt/sample-run/selections\[Ultimates.xlsx]Counts'!K10<>"",'/sessions/eloquent-hopeful-babbage/mnt/sample-run/selections\[Ultimates.xlsx]Counts'!L10,'/sessions/eloquent-hopeful-babbage/mnt/sample-run/selections\[Ultimates.xlsx]Counts'!H10)
A11: 2010 | B11: 179 | C11: ='Reported CL'!C11 | D11: ='Reported CL'!E11 | E11: ='Reported IE'!D11 | F11: ='Reported BF'!H11 | G11: =IF('/sessions/eloquent-hopeful-babbage/mnt/sample-run/selections\[Ultimates.xlsx]Counts'!K11<>"",'/sessions/eloquent-hopeful-babbage/mnt/sample-run/selections\[Ultimates.xlsx]Counts'!K11,'/sessions/eloquent-hopeful-babbage/mnt/sample-run/selections\[Ultimates.xlsx]Counts'!G11) | H11: =G11-C11 | I11: =G11-C11 | J11: =IF('/sessions/eloquent-hopeful-babbage/mnt/sample-run/selections\[Ultimates.xlsx]Counts'!K11<>"",'/sessions/eloquent-hopeful-babbage/mnt/sample-run/selections\[Ultimates.xlsx]Counts'!L11,'/sessions/eloquent-hopeful-babbage/mnt/sample-run/selections\[Ultimates.xlsx]Counts'!H11)
A12: 2011 | B12: 167 | C12: ='Reported CL'!C12 | D12: ='Reported CL'!E12 | E12: ='Reported IE'!D12 | F12: ='Reported BF'!H12 | G12: =IF('/sessions/eloquent-hopeful-babbage/mnt/sample-run/selections\[Ultimates.xlsx]Counts'!K12<>"",'/sessions/eloquent-hopeful-babbage/mnt/sample-run/selections\[Ultimates.xlsx]Counts'!K12,'/sessions/eloquent-hopeful-babbage/mnt/sample-run/selections\[Ultimates.xlsx]Counts'!G12) | H12: =G12-C12 | I12: =G12-C12 | J12: =IF('/sessions/eloquent-hopeful-babbage/mnt/sample-run/selections\[Ultimates.xlsx]Counts'!K12<>"",'/sessions/eloquent-hopeful-babbage/mnt/sample-run/selections\[Ultimates.xlsx]Counts'!L12,'/sessions/eloquent-hopeful-babbage/mnt/sample-run/selections\[Ultimates.xlsx]Counts'!H12)
A13: 2012 | B13: 155 | C13: ='Reported CL'!C13 | D13: ='Reported CL'!E13 | E13: ='Reported IE'!D13 | F13: ='Reported BF'!H13 | G13: =IF('/sessions/eloquent-hopeful-babbage/mnt/sample-run/selections\[Ultimates.xlsx]Counts'!K13<>"",'/sessions/eloquent-hopeful-babbage/mnt/sample-run/selections\[Ultimates.xlsx]Counts'!K13,'/sessions/eloquent-hopeful-babbage/mnt/sample-run/selections\[Ultimates.xlsx]Counts'!G13) | H13: =G13-C13 | I13: =G13-C13 | J13: =IF('/sessions/eloquent-hopeful-babbage/mnt/sample-run/selections\[Ultimates.xlsx]Counts'!K13<>"",'/sessions/eloquent-hopeful-babbage/mnt/sample-run/selections\[Ultimates.xlsx]Counts'!L13,'/sessions/eloquent-hopeful-babbage/mnt/sample-run/selections\[Ultimates.xlsx]Counts'!H13)
... A25: 2024 | B25: 11 | C25: ='Reported CL'!C25 | D25: ='Reported CL'!E25 | E25: ='Reported IE'!D25 | F25: ='Reported BF'!H25 | G25: =IF('/sessions/eloquent-hopeful-babbage/mnt/sample-run/selections\[Ultimates.xlsx]Counts'!K25<>"",'/sessions/eloquent-hopeful-babbage/mnt/sample-run/selections\[Ultimates.xlsx]Counts'!K25,'/sessions/eloquent-hopeful-babbage/mnt/sample-run/selections\[Ultimates.xlsx]Counts'!G25) | H25: =G25-C25 | I25: =G25-C25 | J25: =IF('/sessions/eloquent-hopeful-babbage/mnt/sample-run/selections\[Ultimates.xlsx]Counts'!K25<>"",'/sessions/eloquent-hopeful-babbage/mnt/sample-run/selections\[Ultimates.xlsx]Counts'!L25,'/sessions/eloquent-hopeful-babbage/mnt/sample-run/selections\[Ultimates.xlsx]Counts'!H25)
A27: Total | C27: =SUM(C2:C25) | D27: =SUM(D2:D25) | E27: =SUM(E2:E25) | F27: =SUM(F2:F25) | G27: =SUM(G2:G25) | H27: =SUM(H2:H25) | I27: =SUM(I2:I25)

Sheet Closed CL
A1: Accident Period | B1: Current Age | C1: Closed | D1: CDF | E1: Ultimate | F1: IBNR | G1: Unpaid
A2: 2001 | B2: None | E2: =IF(AND(ISNUMBER(C2),ISNUMBER(D2)),C2*D2,"") | F2: =E2-C2 | G2: =E2-C2
A3: 2002 | B3: None | E3: =IF(AND(ISNUMBER(C3),ISNUMBER(D3)),C3*D3,"") | F3: =E3-C3 | G3: =E3-C3
A4: 2003 | B4: None | E4: =IF(AND(ISNUMBER(C4),ISNUMBER(D4)),C4*D4,"") | F4: =E4-C4 | G4: =E4-C4
A5: 2004 | B5: None | E5: =IF(AND(ISNUMBER(C5),ISNUMBER(D5)),C5*D5,"") | F5: =E5-C5 | G5: =E5-C5
A6: 2005 | B6: None | E6: =IF(AND(ISNUMBER(C6),ISNUMBER(D6)),C6*D6,"") | F6: =E6-C6 | G6: =E6-C6
A7: 2006 | B7: None | E7: =IF(AND(ISNUMBER(C7),ISNUMBER(D7)),C7*D7,"") | F7: =E7-C7 | G7: =E7-C7
A8: 2007 | B8: None | E8: =IF(AND(ISNUMBER(C8),ISNUMBER(D8)),C8*D8,"") | F8: =E8-C8 | G8: =E8-C8
A9: 2008 | B9: None | E9: =IF(AND(ISNUMBER(C9),ISNUMBER(D9)),C9*D9,"") | F9: =E9-C9 | G9: =E9-C9
A10: 2009 | B10: None | E10: =IF(AND(ISNUMBER(C10),ISNUMBER(D10)),C10*D10,"") | F10: =E10-C10 | G10: =E10-C10
A11: 2010 | B11: None | E11: =IF(AND(ISNUMBER(C11),ISNUMBER(D11)),C11*D11,"") | F11: =E11-C11 | G11: =E11-C11
A12: 2011 | B12: None | E12: =IF(AND(ISNUMBER(C12),ISNUMBER(D12)),C12*D12,"") | F12: =E12-C12 | G12: =E12-C12
A13: 2012 | B13: None | E13: =IF(AND(ISNUMBER(C13),ISNUMBER(D13)),C13*D13,"") | F13: =E13-C13 | G13: =E13-C13
... A25: 2024 | B25: None | E25: =IF(AND(ISNUMBER(C25),ISNUMBER(D25)),C25*D25,"") | F25: =E25-C25 | G25: =E25-C25
A27: Total | C27: =SUM(C2:C25) | E27: =SUM(E2:E25) | F27: =SUM(F2:F25) | G27: =SUM(G2:G25)

Sheet Reported CL
A1: Accident Period | B1: Current Age | C1: Reported | D1: CDF | E1: Ultimate | F1: IBNR | G1: Unpaid
A2: 2001 | B2: 287 | C2: ='/sessions/eloquent-hopeful-babbage/mnt/sample-run/selections\[Ultimates.xlsx]Counts'!C2 | D2: 1 | E2: =IF(AND(ISNUMBER(C2),ISNUMBER(D2)),C2*D2,"") | F2: =E2-C2 | G2: =E2-'Closed CL'!C2
A3: 2002 | B3: 275 | C3: ='/sessions/eloquent-hopeful-babbage/mnt/sample-run/selections\[Ultimates.xlsx]Counts'!C3 | D3: 1 | E3: =IF(AND(ISNUMBER(C3),ISNUMBER(D3)),C3*D3,"") | F3: =E3-C3 | G3: =E3-'Closed CL'!C3
A4: 2003 | B4: 263 | C4: ='/sessions/eloquent-hopeful-babbage/mnt/sample-run/selections\[Ultimates.xlsx]Counts'!C4 | D4: 1 | E4: =IF(AND(ISNUMBER(C4),ISNUMBER(D4)),C4*D4,"") | F4: =E4-C4 | G4: =E4-'Closed CL'!C4
A5: 2004 | B5: 251 | C5: ='/sessions/eloquent-hopeful-babbage/mnt/sample-run/selections\[Ultimates.xlsx]Counts'!C5 | D5: 1 | E5: =IF(AND(ISNUMBER(C5),ISNUMBER(D5)),C5*D5,"") | F5: =E5-C5 | G5: =E5-'Closed CL'!C5
A6: 2005 | B6: 239 | C6: ='/sessions/eloquent-hopeful-babbage/mnt/sample-run/selections\[Ultimates.xlsx]Counts'!C6 | D6: 1 | E6: =IF(AND(ISNUMBER(C6),ISNUMBER(D6)),C6*D6,"") | F6: =E6-C6 | G6: =E6-'Closed CL'!C6
A7: 2006 | B7: 227 | C7: ='/sessions/eloquent-hopeful-babbage/mnt/sample-run/selections\[Ultimates.xlsx]Counts'!C7 | D7: 1 | E7: =IF(AND(ISNUMBER(C7),ISNUMBER(D7)),C7*D7,"") | F7: =E7-C7 | G7: =E7-'Closed CL'!C7
A8: 2007 | B8: 215 | C8: ='/sessions/eloquent-hopeful-babbage/mnt/sample-run/selections\[Ultimates.xlsx]Counts'!C8 | D8: 1 | E8: =IF(AND(ISNUMBER(C8),ISNUMBER(D8)),C8*D8,"") | F8: =E8-C8 | G8: =E8-'Closed CL'!C8
A9: 2008 | B9: 203 | C9: ='/sessions/eloquent-hopeful-babbage/mnt/sample-run/selections\[Ultimates.xlsx]Counts'!C9 | D9: 1 | E9: =IF(AND(ISNUMBER(C9),ISNUMBER(D9)),C9*D9,"") | F9: =E9-C9 | G9: =E9-'Closed CL'!C9
A10: 2009 | B10: 191 | C10: ='/sessions/eloquent-hopeful-babbage/mnt/sample-run/selections\[Ultimates.xlsx]Counts'!C10 | D10: 1 | E10: =IF(AND(ISNUMBER(C10),ISNUMBER(D10)),C10*D10,"") | F10: =E10-C10 | G10: =E10-'Closed CL'!C10
A11: 2010 | B11: 179 | C11: ='/sessions/eloquent-hopeful-babbage/mnt/sample-run/selections\[Ultimates.xlsx]Counts'!C11 | D11: 1 | E11: =IF(AND(ISNUMBER(C11),ISNUMBER(D11)),C11*D11,"") | F11: =E11-C11 | G11: =E11-'Closed CL'!C11
A12: 2011 | B12: 167 | C12: ='/sessions/eloquent-hopeful-babbage/mnt/sample-run/selections\[Ultimates.xlsx]Counts'!C12 | D12: 1 | E12: =IF(AND(ISNUMBER(C12),ISNUMBER(D12)),C12*D12,"") | F12: =E12-C12 | G12: =E12-'Closed CL'!C12
A13: 2012 | B13: 155 | C13: ='/sessions/eloquent-hopeful-babbage/mnt/sample-run/selections\[Ultimates.xlsx]Counts'!C13 | D13: 1 | E13: =IF(AND(ISNUMBER(C13),ISNUMBER(D13)),C13*D13,"") | F13: =E13-C13 | G13: =E13-'Closed CL'!C13
A14: 2013 | B14: 143 | C14: ='Reported'!M15 | D14: 1 | E14: =IF(AND(ISNUMBER(C14),ISNUMBER(D14)),C14*D14,"") | F14: =E14-C14 | G14: =E14-'Closed CL'!C14
A15: 2014 | B15: 131 | C15: ='Reported'!L16 | D15: 1 | E15: =IF(AND(ISNUMBER(C15),ISNUMBER(D15)),C15*D15,"") | F15: =E15-C15 | G15: =E15-'Closed CL'!C15
A16: 2015 | B16: 119 | C16: ='Reported'!K17 | D16: 1 | E16: =IF(AND(ISNUMBER(C16),ISNUMBER(D16)),C16*D16,"") | F16: =E16-C16 | G16: =E16-'Closed CL'!C16
A17: 2016 | B17: 107 | C17: ='Reported'!J18 | D17: 0.9977 | E17: =IF(AND(ISNUMBER(C17),ISNUMBER(D17)),C17*D17,"") | F17: =E17-C17 | G17: =E17-'Closed CL'!C17
A18: 2017 | B18: 95 | C18: ='Reported'!I19 | D18: 0.9977 | E18: =IF(AND(ISNUMBER(C18),ISNUMBER(D18)),C18*D18,"") | F18: =E18-C18 | G18: =E18-'Closed CL'!C18
A19: 2018 | B19: 83 | C19: ='Reported'!H20 | D19: 0.99700161 | E19: =IF(AND(ISNUMBER(C19),ISNUMBER(D19)),C19*D19,"") | F19: =E19-C19 | G19: =E19-'Closed CL'!C19
A20: 2019 | B20: 71 | C20: ='Reported'!G21 | D20: 0.99700161 | E20: =IF(AND(ISNUMBER(C20),ISNUMBER(D20)),C20*D20,"") | F20: =E20-C20 | G20: =E20-'Closed CL'!C20
A21: 2020 | B21: 59 | C21: ='Reported'!F22 | D21: 0.99620401 | E21: =IF(AND(ISNUMBER(C21),ISNUMBER(D21)),C21*D21,"") | F21: =E21-C21 | G21: =E21-'Closed CL'!C21
A22: 2021 | B22: 47 | C22: ='Reported'!E23 | D22: 0.99620401 | E22: =IF(AND(ISNUMBER(C22),ISNUMBER(D22)),C22*D22,"") | F22: =E22-C22 | G22: =E22-'Closed CL'!C22
A23: 2022 | B23: 35 | C23: ='Reported'!D24 | D23: 0.99700097 | E23: =IF(AND(ISNUMBER(C23),ISNUMBER(D23)),C23*D23,"") | F23: =E23-C23 | G23: =E23-'Closed CL'!C23
A24: 2023 | B24: 23 | C24: ='Reported'!C25 | D24: 0.99700097 | E24: =IF(AND(ISNUMBER(C24),ISNUMBER(D24)),C24*D24,"") | F24: =E24-C24 | G24: =E24-'Closed CL'!C24
A25: 2024 | B25: 11 | C25: ='Reported'!B26 | D25: 1.1146471 | E25: =IF(AND(ISNUMBER(C25),ISNUMBER(D25)),C25*D25,"") | F25: =E25-C25 | G25: =E25-'Closed CL'!C25
A27: Total | C27: =SUM(C2:C25) | E27: =SUM(E2:E25) | F27: =SUM(F2:F25) | G27: =SUM(G2:G25)

Sheet Reported BF
A1: Accident Period | B1: Current Age | C1: Initial Expected | D1: CDF | E1: % Unreported | F1: Unreported | G1: Reported | H1: Ultimate | I1: IBNR | J1: Unpaid
A2: 2001 | B2: 287 | C2: ='Reported IE'!D2 | D2: ='Reported CL'!D2 | E2: =1-(1/D2) | F2: =C2*E2 | G2: ='Reported CL'!C2 | H2: =F2+G2 | I2: =H2-G2 | J2: =H2-'Closed CL'!C2
A3: 2002 | B3: 275 | C3: ='Reported IE'!D3 | D3: ='Reported CL'!D3 | E3: =1-(1/D3) | F3: =C3*E3 | G3: ='Reported CL'!C3 | H3: =F3+G3 | I3: =H3-G3 | J3: =H3-'Closed CL'!C3
A4: 2003 | B4: 263 | C4: ='Reported IE'!D4 | D4: ='Reported CL'!D4 | E4: =1-(1/D4) | F4: =C4*E4 | G4: ='Reported CL'!C4 | H4: =F4+G4 | I4: =H4-G4 | J4: =H4-'Closed CL'!C4
A5: 2004 | B5: 251 | C5: ='Reported IE'!D5 | D5: ='Reported CL'!D5 | E5: =1-(1/D5) | F5: =C5*E5 | G5: ='Reported CL'!C5 | H5: =F5+G5 | I5: =H5-G5 | J5: =H5-'Closed CL'!C5
A6: 2005 | B6: 239 | C6: ='Reported IE'!D6 | D6: ='Reported CL'!D6 | E6: =1-(1/D6) | F6: =C6*E6 | G6: ='Reported CL'!C6 | H6: =F6+G6 | I6: =H6-G6 | J6: =H6-'Closed CL'!C6
A7: 2006 | B7: 227 | C7: ='Reported IE'!D7 | D7: ='Reported CL'!D7 | E7: =1-(1/D7) | F7: =C7*E7 | G7: ='Reported CL'!C7 | H7: =F7+G7 | I7: =H7-G7 | J7: =H7-'Closed CL'!C7
A8: 2007 | B8: 215 | C8: ='Reported IE'!D8 | D8: ='Reported CL'!D8 | E8: =1-(1/D8) | F8: =C8*E8 | G8: ='Reported CL'!C8 | H8: =F8+G8 | I8: =H8-G8 | J8: =H8-'Closed CL'!C8
A9: 2008 | B9: 203 | C9: ='Reported IE'!D9 | D9: ='Reported CL'!D9 | E9: =1-(1/D9) | F9: =C9*E9 | G9: ='Reported CL'!C9 | H9: =F9+G9 | I9: =H9-G9 | J9: =H9-'Closed CL'!C9
A10: 2009 | B10: 191 | C10: ='Reported IE'!D10 | D10: ='Reported CL'!D10 | E10: =1-(1/D10) | F10: =C10*E10 | G10: ='Reported CL'!C10 | H10: =F10+G10 | I10: =H10-G10 | J10: =H10-'Closed CL'!C10
A11: 2010 | B11: 179 | C11: ='Reported IE'!D11 | D11: ='Reported CL'!D11 | E11: =1-(1/D11) | F11: =C11*E11 | G11: ='Reported CL'!C11 | H11: =F11+G11 | I11: =H11-G11 | J11: =H11-'Closed CL'!C11
A12: 2011 | B12: 167 | C12: ='Reported IE'!D12 | D12: ='Reported CL'!D12 | E12: =1-(1/D12) | F12: =C12*E12 | G12: ='Reported CL'!C12 | H12: =F12+G12 | I12: =H12-G12 | J12: =H12-'Closed CL'!C12
A13: 2012 | B13: 155 | C13: ='Reported IE'!D13 | D13: ='Reported CL'!D13 | E13: =1-(1/D13) | F13: =C13*E13 | G13: ='Reported CL'!C13 | H13: =F13+G13 | I13: =H13-G13 | J13: =H13-'Closed CL'!C13
... A25: 2024 | B25: 11 | C25: ='Reported IE'!D25 | D25: ='Reported CL'!D25 | E25: =1-(1/D25) | F25: =C25*E25 | G25: ='Reported CL'!C25 | H25: =F25+G25 | I25: =H25-G25 | J25: =H25-'Closed CL'!C25
A27: Total | C27: =SUM(C2:C25) | E27: =SUM(F2:F25)/SUM(C2:C25) | F27: =SUM(F2:F25) | G27: =SUM(G2:G25) | H27: =SUM(H2:H25) | I27: =SUM(I2:I25) | J27: =SUM(J2:J25)

Sheet Closed IE
A1: Accident Period | B1: Current Age | C1: Exposure | D1: IE Ultimate | E1: Selected Loss Rate
A2: 2001 | B2: None | C2: ='/sessions/eloquent-hopeful-babbage/mnt/sample-run/selections\[Chain Ladder Selections - LDFs.xlsx]Exposure'!B3 | D2: 700.77587 | E2: =D2/C2
A3: 2002 | B3: None | C3: ='/sessions/eloquent-hopeful-babbage/mnt/sample-run/selections\[Chain Ladder Selections - LDFs.xlsx]Exposure'!B4 | D3: 683.16631 | E3: =D3/C3
A4: 2003 | B4: None | C4: ='/sessions/eloquent-hopeful-babbage/mnt/sample-run/selections\[Chain Ladder Selections - LDFs.xlsx]Exposure'!B5 | D4: 648.44326 | E4: =D4/C4
A5: 2004 | B5: None | C5: ='/sessions/eloquent-hopeful-babbage/mnt/sample-run/selections\[Chain Ladder Selections - LDFs.xlsx]Exposure'!B6 | D5: 627.83791 | E5: =D5/C5
A6: 2005 | B6: None | C6: ='/sessions/eloquent-hopeful-babbage/mnt/sample-run/selections\[Chain Ladder Selections - LDFs.xlsx]Exposure'!B7 | D6: 623.61427 | E6: =D6/C6
A7: 2006 | B7: None | C7: ='/sessions/eloquent-hopeful-babbage/mnt/sample-run/selections\[Chain Ladder Selections - LDFs.xlsx]Exposure'!B8 | D7: 606.74484 | E7: =D7/C7
A8: 2007 | B8: None | C8: ='/sessions/eloquent-hopeful-babbage/mnt/sample-run/selections\[Chain Ladder Selections - LDFs.xlsx]Exposure'!B9 | D8: 550.47161 | E8: =D8/C8
A9: 2008 | B9: None | C9: ='/sessions/eloquent-hopeful-babbage/mnt/sample-run/selections\[Chain Ladder Selections - LDFs.xlsx]Exposure'!B10 | D9: 444.09698 | E9: =D9/C9
A10: 2009 | B10: None | C10: ='/sessions/eloquent-hopeful-babbage/mnt/sample-run/selections\[Chain Ladder Selections - LDFs.xlsx]Exposure'!B11 | D10: 384.40191 | E10: =D10/C10
A11: 2010 | B11: None | C11: ='/sessions/eloquent-hopeful-babbage/mnt/sample-run/selections\[Chain Ladder Selections - LDFs.xlsx]Exposure'!B12 | D11: 314.2013 | E11: =D11/C11
A12: 2011 | B12: None | C12: ='/sessions/eloquent-hopeful-babbage/mnt/sample-run/selections\[Chain Ladder Selections - LDFs.xlsx]Exposure'!B13 | D12: 319.32834 | E12: =D12/C12
A13: 2012 | B13: None | C13: ='/sessions/eloquent-hopeful-babbage/mnt/sample-run/selections\[Chain Ladder Selections - LDFs.xlsx]Exposure'!B14 | D13: 298.96538 | E13: =D13/C13
... A25: 2024 | B25: None | C25: ='/sessions/eloquent-hopeful-babbage/mnt/sample-run/selections\[Chain Ladder Selections - LDFs.xlsx]Exposure'!B26 | D25: 292.35261 | E25: =D25/C25

Sheet Reported IE
A1: Accident Period | B1: Current Age | C1: Exposure | D1: IE Ultimate | E1: Selected Loss Rate
A2: 2001 | B2: 287 | C2: ='/sessions/eloquent-hopeful-babbage/mnt/sample-run/selections\[Chain Ladder Selections - LDFs.xlsx]Exposure'!B3 | D2: ='/sessions/eloquent-hopeful-babbage/mnt/sample-run/selections\[Ultimates.xlsx]Counts'!E2 | E2: =D2/C2
A3: 2002 | B3: 275 | C3: ='/sessions/eloquent-hopeful-babbage/mnt/sample-run/selections\[Chain Ladder Selections - LDFs.xlsx]Exposure'!B4 | D3: ='/sessions/eloquent-hopeful-babbage/mnt/sample-run/selections\[Ultimates.xlsx]Counts'!E3 | E3: =D3/C3
A4: 2003 | B4: 263 | C4: ='/sessions/eloquent-hopeful-babbage/mnt/sample-run/selections\[Chain Ladder Selections - LDFs.xlsx]Exposure'!B5 | D4: ='/sessions/eloquent-hopeful-babbage/mnt/sample-run/selections\[Ultimates.xlsx]Counts'!E4 | E4: =D4/C4
A5: 2004 | B5: 251 | C5: ='/sessions/eloquent-hopeful-babbage/mnt/sample-run/selections\[Chain Ladder Selections - LDFs.xlsx]Exposure'!B6 | D5: ='/sessions/eloquent-hopeful-babbage/mnt/sample-run/selections\[Ultimates.xlsx]Counts'!E5 | E5: =D5/C5
A6: 2005 | B6: 239 | C6: ='/sessions/eloquent-hopeful-babbage/mnt/sample-run/selections\[Chain Ladder Selections - LDFs.xlsx]Exposure'!B7 | D6: ='/sessions/eloquent-hopeful-babbage/mnt/sample-run/selections\[Ultimates.xlsx]Counts'!E6 | E6: =D6/C6
A7: 2006 | B7: 227 | C7: ='/sessions/eloquent-hopeful-babbage/mnt/sample-run/selections\[Chain Ladder Selections - LDFs.xlsx]Exposure'!B8 | D7: ='/sessions/eloquent-hopeful-babbage/mnt/sample-run/selections\[Ultimates.xlsx]Counts'!E7 | E7: =D7/C7
A8: 2007 | B8: 215 | C8: ='/sessions/eloquent-hopeful-babbage/mnt/sample-run/selections\[Chain Ladder Selections - LDFs.xlsx]Exposure'!B9 | D8: ='/sessions/eloquent-hopeful-babbage/mnt/sample-run/selections\[Ultimates.xlsx]Counts'!E8 | E8: =D8/C8
A9: 2008 | B9: 203 | C9: ='/sessions/eloquent-hopeful-babbage/mnt/sample-run/selections\[Chain Ladder Selections - LDFs.xlsx]Exposure'!B10 | D9: ='/sessions/eloquent-hopeful-babbage/mnt/sample-run/selections\[Ultimates.xlsx]Counts'!E9 | E9: =D9/C9
A10: 2009 | B10: 191 | C10: ='/sessions/eloquent-hopeful-babbage/mnt/sample-run/selections\[Chain Ladder Selections - LDFs.xlsx]Exposure'!B11 | D10: ='/sessions/eloquent-hopeful-babbage/mnt/sample-run/selections\[Ultimates.xlsx]Counts'!E10 | E10: =D10/C10
A11: 2010 | B11: 179 | C11: ='/sessions/eloquent-hopeful-babbage/mnt/sample-run/selections\[Chain Ladder Selections - LDFs.xlsx]Exposure'!B12 | D11: ='/sessions/eloquent-hopeful-babbage/mnt/sample-run/selections\[Ultimates.xlsx]Counts'!E11 | E11: =D11/C11
A12: 2011 | B12: 167 | C12: ='/sessions/eloquent-hopeful-babbage/mnt/sample-run/selections\[Chain Ladder Selections - LDFs.xlsx]Exposure'!B13 | D12: ='/sessions/eloquent-hopeful-babbage/mnt/sample-run/selections\[Ultimates.xlsx]Counts'!E12 | E12: =D12/C12
A13: 2012 | B13: 155 | C13: ='/sessions/eloquent-hopeful-babbage/mnt/sample-run/selections\[Chain Ladder Selections - LDFs.xlsx]Exposure'!B14 | D13: ='/sessions/eloquent-hopeful-babbage/mnt/sample-run/selections\[Ultimates.xlsx]Counts'!E13 | E13: =D13/C13
... A25: 2024 | B25: 11 | C25: ='/sessions/eloquent-hopeful-babbage/mnt/sample-run/selections\[Chain Ladder Selections - LDFs.xlsx]Exposure'!B26 | D25: ='/sessions/eloquent-hopeful-babbage/mnt/sample-run/selections\[Ultimates.xlsx]Counts'!E25 | E25: =D25/C25

Sheet Incurred
A1: Incurred Loss
B2: 11 | C2: 23 | D2: 35 | E2: 47 | F2: 59 | G2: 71 | H2: 83 | I2: 95 | J2: 107 | K2: 119 | L2: 131 | M2: 143 | N2: 155 | O2: 167 | P2: 179 | Q2: 191 | R2: 203
A3: 2001 | B3: 567331.67 | C3: 1554404.3 | D3: 1902287.9 | E3: 2093441.2 | F3: 2250668.9 | G3: 2402988.2 | H3: 2397333.6 | I3: 2419690.9 | J3: 2437307.6 | K3: 2457834.5 | L3: 2510536.4 | M3: 2562761.5 | N3: 2559991 | O3: 2618542.6 | P3: 2663167.9 | Q3: 2804776.8 | R3: 2871037.9
A4: 2002 | B4: 927838.47 | C4: 1327207.5 | D4: 1342822.3 | E4: 1604244.3 | F4: 1625396 | G4: 1727293.4 | H4: 1760101.3 | I4: 1760466.7 | J4: 1799039.5 | K4: 1816376.1 | L4: 1835002.2 | M4: 1897241.7 | N4: 1899757.6 | O4: 1975947.9 | P4: 2028039.1 | Q4: 2057884.5 | R4: 2166744.8
A5: 2003 | B5: 1009363.4 | C5: 1458693.8 | D5: 1578930.4 | E5: 1876931.2 | F5: 1703633 | G5: 1819224.4 | H5: 1814195.5 | I5: 1800500.4 | J5: 1797139.9 | K5: 1801084.9 | L5: 1797322.9 | M5: 1783419.2 | N5: 1774330.2 | O5: 1774330.1 | P5: 1774330.1 | Q5: 1774330.1 | R5: 1778091.6
A6: 2004 | B6: 706990.22 | C6: 807081.88 | D6: 891146.73 | E6: 933370.1 | F6: 1055144 | G6: 1061000.5 | H6: 1080582 | I6: 1088885.1 | J6: 1114748.9 | K6: 1104800.8 | L6: 1130298 | M6: 1117525.7 | N6: 1117975.7 | O6: 1118300.3 | P6: 1118299.7 | Q6: 1122581.1 | R6: 1122581.1
A7: 2005 | B7: 1249691.6 | C7: 1628222 | D7: 1779408.1 | E7: 1735781.6 | F7: 1800284.1 | G7: 1829678.4 | H7: 1866913.8 | I7: 1877458.5 | J7: 1901705.9 | K7: 1953627 | L7: 1976524.6 | M7: 2212537.7 | N7: 2212549.6 | O7: 2171748.9 | P7: 2193366.7 | Q7: 2208705.5 | R7: 2242149.1
A8: 2006 | B8: 765985.34 | C8: 1158099.9 | D8: 1006637.1 | E8: 1076536.3 | F8: 1086240.5 | G8: 1141033.2 | H8: 1191316.1 | I8: 1169378.1 | J8: 1199839.2 | K8: 1244365.6 | L8: 1347851.3 | M8: 1428877.4 | N8: 1468194.3 | O8: 1484004.2 | P8: 1484861.9 | Q8: 1502016.7 | R8: 1506635.3
A9: 2007 | B9: 1724656.9 | C9: 1877762.6 | D9: 2045106.8 | E9: 2291428.8 | F9: 2554191.5 | G9: 3049073.8 | H9: 3243034.4 | I9: 3598222.1 | J9: 3855992.6 | K9: 4247900.6 | L9: 4378240.1 | M9: 4504737.6 | N9: 4577330.2 | O9: 4581600.1 | P9: 4781468.7 | Q9: 4781468.7 | R9: 4798643.3
A10: 2008 | B10: 556352.89 | C10: 770915.04 | D10: 933165.87 | E10: 1298006.8 | F10: 1258119.1 | G10: 1279315.3 | H10: 1286243.9 | I10: 1303173.6 | J10: 1310621.4 | K10: 1356059.2 | L10: 1362732 | M10: 1362957 | N10: 1343109.2 | O10: 1343439.1 | P10: 1343439.1 | Q10: 1350037.1 | R10: 1378427.9
A11: 2009 | B11: 357480.39 | C11: 872537.45 | D11: 822240.04 | E11: 842753.92 | F11: 898761.09 | G11: 944889.63 | H11: 979272.52 | I11: 1120353.6 | J11: 1120360.2 | K11: 1120361.9 | L11: 1120361.9 | M11: 1135537.3 | N11: 1169581.1 | O11: 1169581.1 | P11: 1169581.1 | Q11: 1169581.1
