Workbook

Sheet Notes
A1: Reserve Analysis Workbook
A2: Workbook Information
A3: Created: | B3: April 17, 2026 02:44 PM
A4: Description: | B4: Complete actuarial reserve analysis combining selections and projections
A6: Table of Contents
A7: Sheet Name | B7: Description
A8: CL - Closed Count | B8: Closed claim count projections
A9: CL - Incurred Loss | B9: Incurred loss projections and selections
A10: CL - Paid Loss | B10: Paid loss projections and selections
A11: CL - Reported Count | B11: Reported claim count projections
A12: CL - Diag - Rptd Claims | B12: Analysis results
A13: CL - Diag - Inc Severity | B13: Analysis results
A14: CL - Diag - Paid Severity | B14: Analysis results
A15: CL - Diag - Paid to Incurred | B15: Analysis results
A16: CL - Diag - Open Counts | B16: Analysis results
A17: CL - Diag - Avg Case Rsrv | B17: Analysis results
A18: CL - Diag - Clm Closure Rt | B18: Analysis results
... A36: CL - Avg Unpaid | B36: Analysis results

Sheet CL - Closed Count
A1: Closed Count
B2: 12 | C2: 24 | D2: 36 | E2: 48 | F2: 60 | G2: 72 | H2: 84 | I2: 96 | J2: 108 | K2: 120
A3: 2015 | B3: 1361 | C3: 2246 | D3: 2896 | E3: 3549 | F3: 4015 | G3: 4347 | H3: 4594 | I3: 4741 | J3: 4883 | K3: 4931
A4: 2016 | B4: 1290 | C4: 2196 | D4: 2900 | E4: 3535 | F4: 4011 | G4: 4343 | H4: 4594 | I4: 4739 | J4: 4888
A5: 2017 | B5: 1354 | C5: 2138 | D5: 2842 | E5: 3450 | F5: 3935 | G5: 4287 | H5: 4550 | I5: 4704
A6: 2018 | B6: 1413 | C6: 2292 | D6: 2995 | E6: 3589 | F6: 4049 | G6: 4399 | H6: 4672
A7: 2019 | B7: 1386 | C7: 2251 | D7: 2927 | E7: 3525 | F7: 4000 | G7: 4355
A8: 2020 | B8: 1389 | C8: 2338 | D8: 3006 | E8: 3554 | F8: 4018
A9: 2021 | B9: 1559 | C9: 2502 | D9: 3232 | E9: 3810
A10: 2022 | B10: 1565 | C10: 2418 | D10: 3118
A11: 2023 | B11: 1318 | C11: 2214
A12: 2024 | B12: 1306
A14: Age-to-Age Factors
B15: 12-24 | C15: 24-36 | D15: 36-48 | E15: 48-60 | F15: 60-72 | G15: 72-84 | H15: 84-96 | I15: 96-108 | J15: 108-120
A16: 2015 | B16: =C3/B3 | C16: =D3/C3 | D16: =E3/D3 | E16: =F3/E3 | F16: =G3/F3 | G16: =H3/G3 | H16: =I3/H3 | I16: =J3/I3 | J16: =K3/J3
A17: 2016 | B17: =C4/B4 | C17: =D4/C4 | D17: =E4/D4 | E17: =F4/E4 | F17: =G4/F4 | G17: =H4/G4 | H17: =I4/H4 | I17: =J4/I4
A18: 2017 | B18: =C5/B5 | C18: =D5/C5 | D18: =E5/D5 | E18: =F5/E5 | F18: =G5/F5 | G18: =H5/G5 | H18: =I5/H5
A19: 2018 | B19: =C6/B6 | C19: =D6/C6 | D19: =E6/D6 | E19: =F6/E6 | F19: =G6/F6 | G19: =H6/G6
A20: 2019 | B20: =C7/B7 | C20: =D7/C7 | D20: =E7/D7 | E20: =F7/E7 | F20: =G7/F7
A21: 2020 | B21: =C8/B8 | C21: =D8/C8 | D21: =E8/D8 | E21: =F8/E8
A22: 2021 | B22: =C9/B9 | C22: =D9/C9 | D22: =E9/D9
A23: 2022 | B23: =C10/B10 | C23: =D10/C10
A24: 2023 | B24: =C11/B11
A25: 2024
A27: Averages
A28: Metric | B28: 12-24 | C28: 24-36 | D28: 36-48 | E28: 48-60 | F28: 60-72 | G28: 72-84 | H28: 84-96 | I28: 96-108 | J28: 108-120 | K28: Tail
A29: simple_all | B29: =IFERROR(AVERAGE(B16:B24),AVERAGE(B16:B24)) | C29: =IFERROR(AVERAGE(C16:C24),AVERAGE(C16:C24)) | D29: =IFERROR(AVERAGE(D16:D24),AVERAGE(D16:D24)) | E29: =IFERROR(AVERAGE(E16:E24),AVERAGE(E16:E24)) | F29: =IFERROR(AVERAGE(F16:F24),AVERAGE(F16:F24)) | G29: =IFERROR(AVERAGE(G16:G24),AVERAGE(G16:G24)) | H29: =IFERROR(AVERAGE(H16:H24),AVERAGE(H16:H24)) | I29: =IFERROR(AVERAGE(I16:I24),AVERAGE(I16:I24)) | J29: =IFERROR(AVERAGE(J16:J24),AVERAGE(J16:J24))
A30: weighted_all | B30: =IFERROR(SUMPRODUCT(B16:B24,B3:B11)/SUMPRODUCT((B16:B24<>"")*B3:B11),SUMPRODUCT(B16:B24,B3:B11)/SUMPRODUCT((B16:B24<>"")*B3:B11)) | C30: =IFERROR(SUMPRODUCT(C16:C24,C3:C11)/SUMPRODUCT((C16:C24<>"")*C3:C11),SUMPRODUCT(C16:C24,C3:C11)/SUMPRODUCT((C16:C24<>"")*C3:C11)) | D30: =IFERROR(SUMPRODUCT(D16:D24,D3:D11)/SUMPRODUCT((D16:D24<>"")*D3:D11),SUMPRODUCT(D16:D24,D3:D11)/SUMPRODUCT((D16:D24<>"")*D3:D11)) | E30: =IFERROR(SUMPRODUCT(E16:E24,E3:E11)/SUMPRODUCT((E16:E24<>"")*E3:E11),SUMPRODUCT(E16:E24,E3:E11)/SUMPRODUCT((E16:E24<>"")*E3:E11)) | F30: =IFERROR(SUMPRODUCT(F16:F24,F3:F11)/SUMPRODUCT((F16:F24<>"")*F3:F11),SUMPRODUCT(F16:F24,F3:F11)/SUMPRODUCT((F16:F24<>"")*F3:F11)) | G30: =IFERROR(SUMPRODUCT(G16:G24,G3:G11)/SUMPRODUCT((G16:G24<>"")*G3:G11),SUMPRODUCT(G16:G24,G3:G11)/SUMPRODUCT((G16:G24<>"")*G3:G11)) | H30: =IFERROR(SUMPRODUCT(H16:H24,H3:H11)/SUMPRODUCT((H16:H24<>"")*H3:H11),SUMPRODUCT(H16:H24,H3:H11)/SUMPRODUCT((H16:H24<>"")*H3:H11)) | I30: =IFERROR(SUMPRODUCT(I16:I24,I3:I11)/SUMPRODUCT((I16:I24<>"")*I3:I11),SUMPRODUCT(I16:I24,I3:I11)/SUMPRODUCT((I16:I24<>"")*I3:I11)) | J30: =IFERROR(SUMPRODUCT(J16:J24,J3:J11)/SUMPRODUCT((J16:J24<>"")*J3:J11),SUMPRODUCT(J16:J24,J3:J11)/SUMPRODUCT((J16:J24<>"")*J3:J11))
A31: exclude_high_low_all | B31: =IFERROR(TRIMMEAN(B16:B24,2/COUNT(B16:B24)),AVERAGE(B16:B24)) | C31: =IFERROR(TRIMMEAN(C16:C24,2/COUNT(C16:C24)),AVERAGE(C16:C24)) | D31: =IFERROR(TRIMMEAN(D16:D24,2/COUNT(D16:D24)),AVERAGE(D16:D24)) | E31: =IFERROR(TRIMMEAN(E16:E24,2/COUNT(E16:E24)),AVERAGE(E16:E24)) | F31: =IFERROR(TRIMMEAN(F16:F24,2/COUNT(F16:F24)),AVERAGE(F16:F24)) | G31: =IFERROR(TRIMMEAN(G16:G24,2/COUNT(G16:G24)),AVERAGE(G16:G24)) | H31: =IFERROR(TRIMMEAN(H16:H24,2/COUNT(H16:H24)),AVERAGE(H16:H24)) | I31: =IFERROR(TRIMMEAN(I16:I24,2/COUNT(I16:I24)),AVERAGE(I16:I24)) | J31: =IFERROR(TRIMMEAN(J16:J24,2/COUNT(J16:J24)),AVERAGE(J16:J24))
A32: simple_3yr | B32: =IFERROR(AVERAGE(B22:B24),AVERAGE(B16:B24)) | C32: =IFERROR(AVERAGE(C22:C24),AVERAGE(C16:C24)) | D32: =IFERROR(AVERAGE(D22:D24),AVERAGE(D16:D24)) | E32: =IFERROR(AVERAGE(E22:E24),AVERAGE(E16:E24)) | F32: =IFERROR(AVERAGE(F22:F24),AVERAGE(F16:F24)) | G32: =IFERROR(AVERAGE(G22:G24),AVERAGE(G16:G24)) | H32: =IFERROR(AVERAGE(H22:H24),AVERAGE(H16:H24)) | I32: =IFERROR(AVERAGE(I22:I24),AVERAGE(I16:I24)) | J32: =IFERROR(AVERAGE(J22:J24),AVERAGE(J16:J24))
A33: weighted_3yr | B33: =IFERROR(SUMPRODUCT(B22:B24,B9:B11)/SUMPRODUCT((B22:B24<>"")*B9:B11),SUMPRODUCT(B16:B24,B3:B11)/SUMPRODUCT((B16:B24<>"")*B3:B11)) | C33: =IFERROR(SUMPRODUCT(C22:C24,C9:C11)/SUMPRODUCT((C22:C24<>"")*C9:C11),SUMPRODUCT(C16:C24,C3:C11)/SUMPRODUCT((C16:C24<>"")*C3:C11)) | D33: =IFERROR(SUMPRODUCT(D22:D24,D9:D11)/SUMPRODUCT((D22:D24<>"")*D9:D11),SUMPRODUCT(D16:D24,D3:D11)/SUMPRODUCT((D16:D24<>"")*D3:D11)) | E33: =IFERROR(SUMPRODUCT(E22:E24,E9:E11)/SUMPRODUCT((E22:E24<>"")*E9:E11),SUMPRODUCT(E16:E24,E3:E11)/SUMPRODUCT((E16:E24<>"")*E3:E11)) | F33: =IFERROR(SUMPRODUCT(F22:F24,F9:F11)/SUMPRODUCT((F22:F24<>"")*F9:F11),SUMPRODUCT(F16:F24,F3:F11)/SUMPRODUCT((F16:F24<>"")*F3:F11)) | G33: =IFERROR(SUMPRODUCT(G22:G24,G9:G11)/SUMPRODUCT((G22:G24<>"")*G9:G11),SUMPRODUCT(G16:G24,G3:G11)/SUMPRODUCT((G16:G24<>"")*G3:G11)) | H33: =IFERROR(SUMPRODUCT(H22:H24,H9:H11)/SUMPRODUCT((H22:H24<>"")*H9:H11),SUMPRODUCT(H16:H24,H3:H11)/SUMPRODUCT((H16:H24<>"")*H3:H11)) | I33: =IFERROR(SUMPRODUCT(I22:I24,I9:I11)/SUMPRODUCT((I22:I24<>"")*I9:I11),SUMPRODUCT(I16:I24,I3:I11)/SUMPRODUCT((I16:I24<>"")*I3:I11)) | J33: =IFERROR(SUMPRODUCT(J22:J24,J9:J11)/SUMPRODUCT((J22:J24<>"")*J9:J11),SUMPRODUCT(J16:J24,J3:J11)/SUMPRODUCT((J16:J24<>"")*J3:J11))
A34: exclude_high_low_3yr | B34: =IFERROR(TRIMMEAN(B22:B24,2/COUNT(B22:B24)),AVERAGE(B16:B24)) | C34: =IFERROR(TRIMMEAN(C22:C24,2/COUNT(C22:C24)),AVERAGE(C16:C24)) | D34: =IFERROR(TRIMMEAN(D22:D24,2/COUNT(D22:D24)),AVERAGE(D16:D24)) | E34: =IFERROR(TRIMMEAN(E22:E24,2/COUNT(E22:E24)),AVERAGE(E16:E24)) | F34: =IFERROR(TRIMMEAN(F22:F24,2/COUNT(F22:F24)),AVERAGE(F16:F24)) | G34: =IFERROR(TRIMMEAN(G22:G24,2/COUNT(G22:G24)),AVERAGE(G16:G24)) | H34: =IFERROR(TRIMMEAN(H22:H24,2/COUNT(H22:H24)),AVERAGE(H16:H24)) | I34: =IFERROR(TRIMMEAN(I22:I24,2/COUNT(I22:I24)),AVERAGE(I16:I24)) | J34: =IFERROR(TRIMMEAN(J22:J24,2/COUNT(J22:J24)),AVERAGE(J16:J24))
A35: simple_5yr | B35: =IFERROR(AVERAGE(B20:B24),AVERAGE(B16:B24)) | C35: =IFERROR(AVERAGE(C20:C24),AVERAGE(C16:C24)) | D35: =IFERROR(AVERAGE(D20:D24),AVERAGE(D16:D24)) | E35: =IFERROR(AVERAGE(E20:E24),AVERAGE(E16:E24)) | F35: =IFERROR(AVERAGE(F20:F24),AVERAGE(F16:F24)) | G35: =IFERROR(AVERAGE(G20:G24),AVERAGE(G16:G24)) | H35: =IFERROR(AVERAGE(H20:H24),AVERAGE(H16:H24)) | I35: =IFERROR(AVERAGE(I20:I24),AVERAGE(I16:I24)) | J35: =IFERROR(AVERAGE(J20:J24),AVERAGE(J16:J24))
A36: weighted_5yr | B36: =IFERROR(SUMPRODUCT(B20:B24,B7:B11)/SUMPRODUCT((B20:B24<>"")*B7:B11),SUMPRODUCT(B16:B24,B3:B11)/SUMPRODUCT((B16:B24<>"")*B3:B11)) | C36: =IFERROR(SUMPRODUCT(C20:C24,C7:C11)/SUMPRODUCT((C20:C24<>"")*C7:C11),SUMPRODUCT(C16:C24,C3:C11)/SUMPRODUCT((C16:C24<>"")*C3:C11)) | D36: =IFERROR(SUMPRODUCT(D20:D24,D7:D11)/SUMPRODUCT((D20:D24<>"")*D7:D11),SUMPRODUCT(D16:D24,D3:D11)/SUMPRODUCT((D16:D24<>"")*D3:D11)) | E36: =IFERROR(SUMPRODUCT(E20:E24,E7:E11)/SUMPRODUCT((E20:E24<>"")*E7:E11),SUMPRODUCT(E16:E24,E3:E11)/SUMPRODUCT((E16:E24<>"")*E3:E11)) | F36: =IFERROR(SUMPRODUCT(F20:F24,F7:F11)/SUMPRODUCT((F20:F24<>"")*F7:F11),SUMPRODUCT(F16:F24,F3:F11)/SUMPRODUCT((F16:F24<>"")*F3:F11)) | G36: =IFERROR(SUMPRODUCT(G20:G24,G7:G11)/SUMPRODUCT((G20:G24<>"")*G7:G11),SUMPRODUCT(G16:G24,G3:G11)/SUMPRODUCT((G16:G24<>"")*G3:G11)) | H36: =IFERROR(SUMPRODUCT(H20:H24,H7:H11)/SUMPRODUCT((H20:H24<>"")*H7:H11),SUMPRODUCT(H16:H24,H3:H11)/SUMPRODUCT((H16:H24<>"")*H3:H11)) | I36: =IFERROR(SUMPRODUCT(I20:I24,I7:I11)/SUMPRODUCT((I20:I24<>"")*I7:I11),SUMPRODUCT(I16:I24,I3:I11)/SUMPRODUCT((I16:I24<>"")*I3:I11)) | J36: =IFERROR(SUMPRODUCT(J20:J24,J7:J11)/SUMPRODUCT((J20:J24<>"")*J7:J11),SUMPRODUCT(J16:J24,J3:J11)/SUMPRODUCT((J16:J24<>"")*J3:J11))
A37: exclude_high_low_5yr | B37: =IFERROR(TRIMMEAN(B20:B24,2/COUNT(B20:B24)),AVERAGE(B16:B24)) | C37: =IFERROR(TRIMMEAN(C20:C24,2/COUNT(C20:C24)),AVERAGE(C16:C24)) | D37: =IFERROR(TRIMMEAN(D20:D24,2/COUNT(D20:D24)),AVERAGE(D16:D24)) | E37: =IFERROR(TRIMMEAN(E20:E24,2/COUNT(E20:E24)),AVERAGE(E16:E24)) | F37: =IFERROR(TRIMMEAN(F20:F24,2/COUNT(F20:F24)),AVERAGE(F16:F24)) | G37: =IFERROR(TRIMMEAN(G20:G24,2/COUNT(G20:G24)),AVERAGE(G16:G24)) | H37: =IFERROR(TRIMMEAN(H20:H24,2/COUNT(H20:H24)),AVERAGE(H16:H24)) | I37: =IFERROR(TRIMMEAN(I20:I24,2/COUNT(I20:I24)),AVERAGE(I16:I24)) | J37: =IFERROR(TRIMMEAN(J20:J24,2/COUNT(J20:J24)),AVERAGE(J16:J24))
A38: simple_10yr | B38: =IFERROR(AVERAGE(B16:B24),AVERAGE(B16:B24)) | C38: =IFERROR(AVERAGE(C16:C24),AVERAGE(C16:C24)) | D38: =IFERROR(AVERAGE(D16:D24),AVERAGE(D16:D24)) | E38: =IFERROR(AVERAGE(E16:E24),AVERAGE(E16:E24)) | F38: =IFERROR(AVERAGE(F16:F24),AVERAGE(F16:F24)) | G38: =IFERROR(AVERAGE(G16:G24),AVERAGE(G16:G24)) | H38: =IFERROR(AVERAGE(H16:H24),AVERAGE(H16:H24)) | I38: =IFERROR(AVERAGE(I16:I24),AVERAGE(I16:I24)) | J38: =IFERROR(AVERAGE(J16:J24),AVERAGE(J16:J24))
A39: weighted_10yr | B39: =IFERROR(SUMPRODUCT(B16:B24,B3:B11)/SUMPRODUCT((B16:B24<>"")*B3:B11),SUMPRODUCT(B16:B24,B3:B11)/SUMPRODUCT((B16:B24<>"")*B3:B11)) | C39: =IFERROR(SUMPRODUCT(C16:C24,C3:C11)/SUMPRODUCT((C16:C24<>"")*C3:C11),SUMPRODUCT(C16:C24,C3:C11)/SUMPRODUCT((C16:C24<>"")*C3:C11)) | D39: =IFERROR(SUMPRODUCT(D16:D24,D3:D11)/SUMPRODUCT((D16:D24<>"")*D3:D11),SUMPRODUCT(D16:D24,D3:D11)/SUMPRODUCT((D16:D24<>"")*D3:D11)) | E39: =IFERROR(SUMPRODUCT(E16:E24,E3:E11)/SUMPRODUCT((E16:E24<>"")*E3:E11),SUMPRODUCT(E16:E24,E3:E11)/SUMPRODUCT((E16:E24<>"")*E3:E11)) | F39: =IFERROR(SUMPRODUCT(F16:F24,F3:F11)/SUMPRODUCT((F16:F24<>"")*F3:F11),SUMPRODUCT(F16:F24,F3:F11)/SUMPRODUCT((F16:F24<>"")*F3:F11)) | G39: =IFERROR(SUMPRODUCT(G16:G24,G3:G11)/SUMPRODUCT((G16:G24<>"")*G3:G11),SUMPRODUCT(G16:G24,G3:G11)/SUMPRODUCT((G16:G24<>"")*G3:G11)) | H39: =IFERROR(SUMPRODUCT(H16:H24,H3:H11)/SUMPRODUCT((H16:H24<>"")*H3:H11),SUMPRODUCT(H16:H24,H3:H11)/SUMPRODUCT((H16:H24<>"")*H3:H11)) | I39: =IFERROR(SUMPRODUCT(I16:I24,I3:I11)/SUMPRODUCT((I16:I24<>"")*I3:I11),SUMPRODUCT(I16:I24,I3:I11)/SUMPRODUCT((I16:I24<>"")*I3:I11)) | J39: =IFERROR(SUMPRODUCT(J16:J24,J3:J11)/SUMPRODUCT((J16:J24<>"")*J3:J11),SUMPRODUCT(J16:J24,J3:J11)/SUMPRODUCT((J16:J24<>"")*J3:J11))
A40: exclude_high_low_10yr | B40: =IFERROR(TRIMMEAN(B16:B24,2/COUNT(B16:B24)),AVERAGE(B16:B24)) | C40: =IFERROR(TRIMMEAN(C16:C24,2/COUNT(C16:C24)),AVERAGE(C16:C24)) | D40: =IFERROR(TRIMMEAN(D16:D24,2/COUNT(D16:D24)),AVERAGE(D16:D24)) | E40: =IFERROR(TRIMMEAN(E16:E24,2/COUNT(E16:E24)),AVERAGE(E16:E24)) | F40: =IFERROR(TRIMMEAN(F16:F24,2/COUNT(F16:F24)),AVERAGE(F16:F24)) | G40: =IFERROR(TRIMMEAN(G16:G24,2/COUNT(G16:G24)),AVERAGE(G16:G24)) | H40: =IFERROR(TRIMMEAN(H16:H24,2/COUNT(H16:H24)),AVERAGE(H16:H24)) | I40: =IFERROR(TRIMMEAN(I16:I24,2/COUNT(I16:I24)),AVERAGE(I16:I24)) | J40: =IFERROR(TRIMMEAN(J16:J24,2/COUNT(J16:J24)),AVERAGE(J16:J24))
A42: LDF Selections
B43: 12-24 | C43: 24-36 | D43: 36-48 | E43: 48-60 | F43: 60-72 | G43: 72-84 | H43: 84-96 | I43: 96-108 | J43: 108-120 | K43: Tail
...

Sheet CL - Incurred Loss
A1: Incurred Loss
B2: 12 | C2: 24 | D2: 36 | E2: 48 | F2: 60 | G2: 72 | H2: 84 | I2: 96 | J2: 108 | K2: 120
A3: 2015 | B3: 11627268 | C3: 20653633 | D3: 26906901 | E3: 32368466 | F3: 36019781 | G3: 38691738 | H3: 41059068 | I3: 42724572 | J3: 44116940 | K3: 45008438
A4: 2016 | B4: 15659162 | C4: 27000294 | D4: 35836571 | E4: 43320371 | F4: 48820280 | G4: 52433700 | H4: 55594501 | I4: 57975404 | J4: 59922624
A5: 2017 | B5: 8748708.8 | C5: 16546772 | D5: 22307048 | E5: 26810590 | F5: 29894432 | G5: 32089211 | H5: 33883395 | I5: 35372412
A6: 2018 | B6: 14603978 | C6: 27127518 | D6: 36408877 | E6: 44313753 | F6: 48910946 | G6: 52335355 | H6: 55323529
A7: 2019 | B7: 11848186 | C7: 21551392 | D7: 28587865 | E7: 33824977 | F7: 37539642 | G7: 40379699
A8: 2020 | B8: 10527840 | C8: 19226888 | D8: 26322578 | E8: 31532413 | F8: 34927144
A9: 2021 | B9: 18975774 | C9: 35129946 | D9: 46173829 | E9: 55221806
A10: 2022 | B10: 11283552 | C10: 20133768 | D10: 27042042
A11: 2023 | B11: 12074753 | C11: 21336028
A12: 2024 | B12: 15929924
A14: Age-to-Age Factors
B15: 12-24 | C15: 24-36 | D15: 36-48 | E15: 48-60 | F15: 60-72 | G15: 72-84 | H15: 84-96 | I15: 96-108 | J15: 108-120
A16: 2015 | B16: =C3/B3 | C16: =D3/C3 | D16: =E3/D3 | E16: =F3/E3 | F16: =G3/F3 | G16: =H3/G3 | H16: =I3/H3 | I16: =J3/I3 | J16: =K3/J3
A17: 2016 | B17: =C4/B4 | C17: =D4/C4 | D17: =E4/D4 | E17: =F4/E4 | F17: =G4/F4 | G17: =H4/G4 | H17: =I4/H4 | I17: =J4/I4
A18: 2017 | B18: =C5/B5 | C18: =D5/C5 | D18: =E5/D5 | E18: =F5/E5 | F18: =G5/F5 | G18: =H5/G5 | H18: =I5/H5
A19: 2018 | B19: =C6/B6 | C19: =D6/C6 | D19: =E6/D6 | E19: =F6/E6 | F19: =G6/F6 | G19: =H6/G6
A20: 2019 | B20: =C7/B7 | C20: =D7/C7 | D20: =E7/D7 | E20: =F7/E7 | F20: =G7/F7
A21: 2020 | B21: =C8/B8 | C21: =D8/C8 | D21: =E8/D8 | E21: =F8/E8
A22: 2021 | B22: =C9/B9 | C22: =D9/C9 | D22: =E9/D9
A23: 2022 | B23: =C10/B10 | C23: =D10/C10
A24: 2023 | B24: =C11/B11
A25: 2024
A27: Averages
A28: Metric | B28: 12-24 | C28: 24-36 | D28: 36-48 | E28: 48-60 | F28: 60-72 | G28: 72-84 | H28: 84-96 | I28: 96-108 | J28: 108-120 | K28: Tail
A29: simple_all | B29: =IFERROR(AVERAGE(B16:B24),AVERAGE(B16:B24)) | C29: =IFERROR(AVERAGE(C16:C24),AVERAGE(C16:C24)) | D29: =IFERROR(AVERAGE(D16:D24),AVERAGE(D16:D24)) | E29: =IFERROR(AVERAGE(E16:E24),AVERAGE(E16:E24)) | F29: =IFERROR(AVERAGE(F16:F24),AVERAGE(F16:F24)) | G29: =IFERROR(AVERAGE(G16:G24),AVERAGE(G16:G24)) | H29: =IFERROR(AVERAGE(H16:H24),AVERAGE(H16:H24)) | I29: =IFERROR(AVERAGE(I16:I24),AVERAGE(I16:I24)) | J29: =IFERROR(AVERAGE(J16:J24),AVERAGE(J16:J24))
A30: weighted_all | B30: =IFERROR(SUMPRODUCT(B16:B24,B3:B11)/SUMPRODUCT((B16:B24<>"")*B3:B11),SUMPRODUCT(B16:B24,B3:B11)/SUMPRODUCT((B16:B24<>"")*B3:B11)) | C30: =IFERROR(SUMPRODUCT(C16:C24,C3:C11)/SUMPRODUCT((C16:C24<>"")*C3:C11),SUMPRODUCT(C16:C24,C3:C11)/SUMPRODUCT((C16:C24<>"")*C3:C11)) | D30: =IFERROR(SUMPRODUCT(D16:D24,D3:D11)/SUMPRODUCT((D16:D24<>"")*D3:D11),SUMPRODUCT(D16:D24,D3:D11)/SUMPRODUCT((D16:D24<>"")*D3:D11)) | E30: =IFERROR(SUMPRODUCT(E16:E24,E3:E11)/SUMPRODUCT((E16:E24<>"")*E3:E11),SUMPRODUCT(E16:E24,E3:E11)/SUMPRODUCT((E16:E24<>"")*E3:E11)) | F30: =IFERROR(SUMPRODUCT(F16:F24,F3:F11)/SUMPRODUCT((F16:F24<>"")*F3:F11),SUMPRODUCT(F16:F24,F3:F11)/SUMPRODUCT((F16:F24<>"")*F3:F11)) | G30: =IFERROR(SUMPRODUCT(G16:G24,G3:G11)/SUMPRODUCT((G16:G24<>"")*G3:G11),SUMPRODUCT(G16:G24,G3:G11)/SUMPRODUCT((G16:G24<>"")*G3:G11)) | H30: =IFERROR(SUMPRODUCT(H16:H24,H3:H11)/SUMPRODUCT((H16:H24<>"")*H3:H11),SUMPRODUCT(H16:H24,H3:H11)/SUMPRODUCT((H16:H24<>"")*H3:H11)) | I30: =IFERROR(SUMPRODUCT(I16:I24,I3:I11)/SUMPRODUCT((I16:I24<>"")*I3:I11),SUMPRODUCT(I16:I24,I3:I11)/SUMPRODUCT((I16:I24<>"")*I3:I11)) | J30: =IFERROR(SUMPRODUCT(J16:J24,J3:J11)/SUMPRODUCT((J16:J24<>"")*J3:J11),SUMPRODUCT(J16:J24,J3:J11)/SUMPRODUCT((J16:J24<>"")*J3:J11))
A31: exclude_high_low_all | B31: =IFERROR(TRIMMEAN(B16:B24,2/COUNT(B16:B24)),AVERAGE(B16:B24)) | C31: =IFERROR(TRIMMEAN(C16:C24,2/COUNT(C16:C24)),AVERAGE(C16:C24)) | D31: =IFERROR(TRIMMEAN(D16:D24,2/COUNT(D16:D24)),AVERAGE(D16:D24)) | E31: =IFERROR(TRIMMEAN(E16:E24,2/COUNT(E16:E24)),AVERAGE(E16:E24)) | F31: =IFERROR(TRIMMEAN(F16:F24,2/COUNT(F16:F24)),AVERAGE(F16:F24)) | G31: =IFERROR(TRIMMEAN(G16:G24,2/COUNT(G16:G24)),AVERAGE(G16:G24)) | H31: =IFERROR(TRIMMEAN(H16:H24,2/COUNT(H16:H24)),AVERAGE(H16:H24)) | I31: =IFERROR(TRIMMEAN(I16:I24,2/COUNT(I16:I24)),AVERAGE(I16:I24)) | J31: =IFERROR(TRIMMEAN(J16:J24,2/COUNT(J16:J24)),AVERAGE(J16:J24))
A32: simple_3yr | B32: =IFERROR(AVERAGE(B22:B24),AVERAGE(B16:B24)) | C32: =IFERROR(AVERAGE(C22:C24),AVERAGE(C16:C24)) | D32: =IFERROR(AVERAGE(D22:D24),AVERAGE(D16:D24)) | E32: =IFERROR(AVERAGE(E22:E24),AVERAGE(E16:E24)) | F32: =IFERROR(AVERAGE(F22:F24),AVERAGE(F16:F24)) | G32: =IFERROR(AVERAGE(G22:G24),AVERAGE(G16:G24)) | H32: =IFERROR(AVERAGE(H22:H24),AVERAGE(H16:H24)) | I32: =IFERROR(AVERAGE(I22:I24),AVERAGE(I16:I24)) | J32: =IFERROR(AVERAGE(J22:J24),AVERAGE(J16:J24))
A33: weighted_3yr | B33: =IFERROR(SUMPRODUCT(B22:B24,B9:B11)/SUMPRODUCT((B22:B24<>"")*B9:B11),SUMPRODUCT(B16:B24,B3:B11)/SUMPRODUCT((B16:B24<>"")*B3:B11)) | C33: =IFERROR(SUMPRODUCT(C22:C24,C9:C11)/SUMPRODUCT((C22:C24<>"")*C9:C11),SUMPRODUCT(C16:C24,C3:C11)/SUMPRODUCT((C16:C24<>"")*C3:C11)) | D33: =IFERROR(SUMPRODUCT(D22:D24,D9:D11)/SUMPRODUCT((D22:D24<>"")*D9:D11),SUMPRODUCT(D16:D24,D3:D11)/SUMPRODUCT((D16:D24<>"")*D3:D11)) | E33: =IFERROR(SUMPRODUCT(E22:E24,E9:E11)/SUMPRODUCT((E22:E24<>"")*E9:E11),SUMPRODUCT(E16:E24,E3:E11)/SUMPRODUCT((E16:E24<>"")*E3:E11)) | F33: =IFERROR(SUMPRODUCT(F22:F24,F9:F11)/SUMPRODUCT((F22:F24<>"")*F9:F11),SUMPRODUCT(F16:F24,F3:F11)/SUMPRODUCT((F16:F24<>"")*F3:F11)) | G33: =IFERROR(SUMPRODUCT(G22:G24,G9:G11)/SUMPRODUCT((G22:G24<>"")*G9:G11),SUMPRODUCT(G16:G24,G3:G11)/SUMPRODUCT((G16:G24<>"")*G3:G11)) | H33: =IFERROR(SUMPRODUCT(H22:H24,H9:H11)/SUMPRODUCT((H22:H24<>"")*H9:H11),SUMPRODUCT(H16:H24,H3:H11)/SUMPRODUCT((H16:H24<>"")*H3:H11)) | I33: =IFERROR(SUMPRODUCT(I22:I24,I9:I11)/SUMPRODUCT((I22:I24<>"")*I9:I11),SUMPRODUCT(I16:I24,I3:I11)/SUMPRODUCT((I16:I24<>"")*I3:I11)) | J33: =IFERROR(SUMPRODUCT(J22:J24,J9:J11)/SUMPRODUCT((J22:J24<>"")*J9:J11),SUMPRODUCT(J16:J24,J3:J11)/SUMPRODUCT((J16:J24<>"")*J3:J11))
A34: exclude_high_low_3yr | B34: =IFERROR(TRIMMEAN(B22:B24,2/COUNT(B22:B24)),AVERAGE(B16:B24)) | C34: =IFERROR(TRIMMEAN(C22:C24,2/COUNT(C22:C24)),AVERAGE(C16:C24)) | D34: =IFERROR(TRIMMEAN(D22:D24,2/COUNT(D22:D24)),AVERAGE(D16:D24)) | E34: =IFERROR(TRIMMEAN(E22:E24,2/COUNT(E22:E24)),AVERAGE(E16:E24)) | F34: =IFERROR(TRIMMEAN(F22:F24,2/COUNT(F22:F24)),AVERAGE(F16:F24)) | G34: =IFERROR(TRIMMEAN(G22:G24,2/COUNT(G22:G24)),AVERAGE(G16:G24)) | H34: =IFERROR(TRIMMEAN(H22:H24,2/COUNT(H22:H24)),AVERAGE(H16:H24)) | I34: =IFERROR(TRIMMEAN(I22:I24,2/COUNT(I22:I24)),AVERAGE(I16:I24)) | J34: =IFERROR(TRIMMEAN(J22:J24,2/COUNT(J22:J24)),AVERAGE(J16:J24))
A35: simple_5yr | B35: =IFERROR(AVERAGE(B20:B24),AVERAGE(B16:B24)) | C35: =IFERROR(AVERAGE(C20:C24),AVERAGE(C16:C24)) | D35: =IFERROR(AVERAGE(D20:D24),AVERAGE(D16:D24)) | E35: =IFERROR(AVERAGE(E20:E24),AVERAGE(E16:E24)) | F35: =IFERROR(AVERAGE(F20:F24),AVERAGE(F16:F24)) | G35: =IFERROR(AVERAGE(G20:G24),AVERAGE(G16:G24)) | H35: =IFERROR(AVERAGE(H20:H24),AVERAGE(H16:H24)) | I35: =IFERROR(AVERAGE(I20:I24),AVERAGE(I16:I24)) | J35: =IFERROR(AVERAGE(J20:J24),AVERAGE(J16:J24))
A36: weighted_5yr | B36: =IFERROR(SUMPRODUCT(B20:B24,B7:B11)/SUMPRODUCT((B20:B24<>"")*B7:B11),SUMPRODUCT(B16:B24,B3:B11)/SUMPRODUCT((B16:B24<>"")*B3:B11)) | C36: =IFERROR(SUMPRODUCT(C20:C24,C7:C11)/SUMPRODUCT((C20:C24<>"")*C7:C11),SUMPRODUCT(C16:C24,C3:C11)/SUMPRODUCT((C16:C24<>"")*C3:C11)) | D36: =IFERROR(SUMPRODUCT(D20:D24,D7:D11)/SUMPRODUCT((D20:D24<>"")*D7:D11),SUMPRODUCT(D16:D24,D3:D11)/SUMPRODUCT((D16:D24<>"")*D3:D11)) | E36: =IFERROR(SUMPRODUCT(E20:E24,E7:E11)/SUMPRODUCT((E20:E24<>"")*E7:E11),SUMPRODUCT(E16:E24,E3:E11)/SUMPRODUCT((E16:E24<>"")*E3:E11)) | F36: =IFERROR(SUMPRODUCT(F20:F24,F7:F11)/SUMPRODUCT((F20:F24<>"")*F7:F11),SUMPRODUCT(F16:F24,F3:F11)/SUMPRODUCT((F16:F24<>"")*F3:F11)) | G36: =IFERROR(SUMPRODUCT(G20:G24,G7:G11)/SUMPRODUCT((G20:G24<>"")*G7:G11),SUMPRODUCT(G16:G24,G3:G11)/SUMPRODUCT((G16:G24<>"")*G3:G11)) | H36: =IFERROR(SUMPRODUCT(H20:H24,H7:H11)/SUMPRODUCT((H20:H24<>"")*H7:H11),SUMPRODUCT(H16:H24,H3:H11)/SUMPRODUCT((H16:H24<>"")*H3:H11)) | I36: =IFERROR(SUMPRODUCT(I20:I24,I7:I11)/SUMPRODUCT((I20:I24<>"")*I7:I11),SUMPRODUCT(I16:I24,I3:I11)/SUMPRODUCT((I16:I24<>"")*I3:I11)) | J36: =IFERROR(SUMPRODUCT(J20:J24,J7:J11)/SUMPRODUCT((J20:J24<>"")*J7:J11),SUMPRODUCT(J16:J24,J3:J11)/SUMPRODUCT((J16:J24<>"")*J3:J11))
A37: exclude_high_low_5yr | B37: =IFERROR(TRIMMEAN(B20:B24,2/COUNT(B20:B24)),AVERAGE(B16:B24)) | C37: =IFERROR(TRIMMEAN(C20:C24,2/COUNT(C20:C24)),AVERAGE(C16:C24)) | D37: =IFERROR(TRIMMEAN(D20:D24,2/COUNT(D20:D24)),AVERAGE(D16:D24)) | E37: =IFERROR(TRIMMEAN(E20:E24,2/COUNT(E20:E24)),AVERAGE(E16:E24)) | F37: =IFERROR(TRIMMEAN(F20:F24,2/COUNT(F20:F24)),AVERAGE(F16:F24)) | G37: =IFERROR(TRIMMEAN(G20:G24,2/COUNT(G20:G24)),AVERAGE(G16:G24)) | H37: =IFERROR(TRIMMEAN(H20:H24,2/COUNT(H20:H24)),AVERAGE(H16:H24)) | I37: =IFERROR(TRIMMEAN(I20:I24,2/COUNT(I20:I24)),AVERAGE(I16:I24)) | J37: =IFERROR(TRIMMEAN(J20:J24,2/COUNT(J20:J24)),AVERAGE(J16:J24))
A38: simple_10yr | B38: =IFERROR(AVERAGE(B16:B24),AVERAGE(B16:B24)) | C38: =IFERROR(AVERAGE(C16:C24),AVERAGE(C16:C24)) | D38: =IFERROR(AVERAGE(D16:D24),AVERAGE(D16:D24)) | E38: =IFERROR(AVERAGE(E16:E24),AVERAGE(E16:E24)) | F38: =IFERROR(AVERAGE(F16:F24),AVERAGE(F16:F24)) | G38: =IFERROR(AVERAGE(G16:G24),AVERAGE(G16:G24)) | H38: =IFERROR(AVERAGE(H16:H24),AVERAGE(H16:H24)) | I38: =IFERROR(AVERAGE(I16:I24),AVERAGE(I16:I24)) | J38: =IFERROR(AVERAGE(J16:J24),AVERAGE(J16:J24))
A39: weighted_10yr | B39: =IFERROR(SUMPRODUCT(B16:B24,B3:B11)/SUMPRODUCT((B16:B24<>"")*B3:B11),SUMPRODUCT(B16:B24,B3:B11)/SUMPRODUCT((B16:B24<>"")*B3:B11)) | C39: =IFERROR(SUMPRODUCT(C16:C24,C3:C11)/SUMPRODUCT((C16:C24<>"")*C3:C11),SUMPRODUCT(C16:C24,C3:C11)/SUMPRODUCT((C16:C24<>"")*C3:C11)) | D39: =IFERROR(SUMPRODUCT(D16:D24,D3:D11)/SUMPRODUCT((D16:D24<>"")*D3:D11),SUMPRODUCT(D16:D24,D3:D11)/SUMPRODUCT((D16:D24<>"")*D3:D11)) | E39: =IFERROR(SUMPRODUCT(E16:E24,E3:E11)/SUMPRODUCT((E16:E24<>"")*E3:E11),SUMPRODUCT(E16:E24,E3:E11)/SUMPRODUCT((E16:E24<>"")*E3:E11)) | F39: =IFERROR(SUMPRODUCT(F16:F24,F3:F11)/SUMPRODUCT((F16:F24<>"")*F3:F11),SUMPRODUCT(F16:F24,F3:F11)/SUMPRODUCT((F16:F24<>"")*F3:F11)) | G39: =IFERROR(SUMPRODUCT(G16:G24,G3:G11)/SUMPRODUCT((G16:G24<>"")*G3:G11),SUMPRODUCT(G16:G24,G3:G11)/SUMPRODUCT((G16:G24<>"")*G3:G11)) | H39: =IFERROR(SUMPRODUCT(H16:H24,H3:H11)/SUMPRODUCT((H16:H24<>"")*H3:H11),SUMPRODUCT(H16:H24,H3:H11)/SUMPRODUCT((H16:H24<>"")*H3:H11)) | I39: =IFERROR(SUMPRODUCT(I16:I24,I3:I11)/SUMPRODUCT((I16:I24<>"")*I3:I11),SUMPRODUCT(I16:I24,I3:I11)/SUMPRODUCT((I16:I24<>"")*I3:I11)) | J39: =IFERROR(SUMPRODUCT(J16:J24,J3:J11)/SUMPRODUCT((J16:J24<>"")*J3:J11),SUMPRODUCT(J16:J24,J3:J11)/SUMPRODUCT((J16:J24<>"")*J3:J11))
A40: exclude_high_low_10yr | B40: =IFERROR(TRIMMEAN(B16:B24,2/COUNT(B16:B24)),AVERAGE(B16:B24)) | C40: =IFERROR(TRIMMEAN(C16:C24,2/COUNT(C16:C24)),AVERAGE(C16:C24)) | D40: =IFERROR(TRIMMEAN(D16:D24,2/COUNT(D16:D24)),AVERAGE(D16:D24)) | E40: =IFERROR(TRIMMEAN(E16:E24,2/COUNT(E16:E24)),AVERAGE(E16:E24)) | F40: =IFERROR(TRIMMEAN(F16:F24,2/COUNT(F16:F24)),AVERAGE(F16:F24)) | G40: =IFERROR(TRIMMEAN(G16:G24,2/COUNT(G16:G24)),AVERAGE(G16:G24)) | H40: =IFERROR(TRIMMEAN(H16:H24,2/COUNT(H16:H24)),AVERAGE(H16:H24)) | I40: =IFERROR(TRIMMEAN(I16:I24,2/COUNT(I16:I24)),AVERAGE(I16:I24)) | J40: =IFERROR(TRIMMEAN(J16:J24,2/COUNT(J16:J24)),AVERAGE(J16:J24))
A42: LDF Selections
B43: 12-24 | C43: 24-36 | D43: 36-48 | E43: 48-60 | F43: 60-72 | G43: 72-84 | H43: 84-96 | I43: 96-108 | J43: 108-120 | K43: Tail
...

Sheet CL - Paid Loss
A1: Paid Loss
B2: 12 | C2: 24 | D2: 36 | E2: 48 | F2: 60 | G2: 72 | H2: 84 | I2: 96 | J2: 108 | K2: 120
A3: 2015 | B3: 9247456.8 | C3: 16887332 | D3: 23000569 | E3: 27802346 | F3: 31644816 | G3: 35019498 | H3: 38226729 | I3: 40633313 | J3: 43136150 | K3: 45008438
A4: 2016 | B4: 12224784 | C4: 23009583 | D4: 31462134 | E4: 38324866 | F4: 44020226 | G4: 48826740 | H4: 52977180 | I4: 56150431 | J4: 59267698
A5: 2017 | B5: 7651942.9 | C5: 14311316 | D5: 19921864 | E5: 24002301 | F5: 27560045 | G5: 30585360 | H5: 33007873 | I5: 34907742
A6: 2018 | B6: 12066429 | C6: 22556336 | D6: 31035722 | E6: 37766431 | F6: 43524051 | G6: 48248010 | H6: 52422360
A7: 2019 | B7: 10064765 | C7: 18121547 | D7: 24840287 | E7: 29715357 | F7: 34177568 | G7: 37924648
A8: 2020 | B8: 8963797.6 | C8: 15917604 | D8: 22113680 | E8: 26981141 | F8: 30760500
A9: 2021 | B9: 15964354 | C9: 28485180 | D9: 38015719 | E9: 46187015
A10: 2022 | B10: 8984185.1 | C10: 16619562 | D10: 23102957
A11: 2023 | B11: 9774276.1 | C11: 17919594
A12: 2024 | B12: 13261356
A14: Age-to-Age Factors
B15: 12-24 | C15: 24-36 | D15: 36-48 | E15: 48-60 | F15: 60-72 | G15: 72-84 | H15: 84-96 | I15: 96-108 | J15: 108-120
A16: 2015 | B16: =C3/B3 | C16: =D3/C3 | D16: =E3/D3 | E16: =F3/E3 | F16: =G3/F3 | G16: =H3/G3 | H16: =I3/H3 | I16: =J3/I3 | J16: =K3/J3
A17: 2016 | B17: =C4/B4 | C17: =D4/C4 | D17: =E4/D4 | E17: =F4/E4 | F17: =G4/F4 | G17: =H4/G4 | H17: =I4/H4 | I17: =J4/I4
A18: 2017 | B18: =C5/B5 | C18: =D5/C5 | D18: =E5/D5 | E18: =F5/E5 | F18: =G5/F5 | G18: =H5/G5 | H18: =I5/H5
A19: 2018 | B19: =C6/B6 | C19: =D6/C6 | D19: =E6/D6 | E19: =F6/E6 | F19: =G6/F6 | G19: =H6/G6
A20: 2019 | B20: =C7/B7 | C20: =D7/C7 | D20: =E7/D7 | E20: =F7/E7 | F20: =G7/F7
A21: 2020 | B21: =C8/B8 | C21: =D8/C8 | D21: =E8/D8 | E21: =F8/E8
A22: 2021 | B22: =C9/B9 | C22: =D9/C9 | D22: =E9/D9
A23: 2022 | B23: =C10/B10 | C23: =D10/C10
A24: 2023 | B24: =C11/B11
A25: 2024
A27: Averages
A28: Metric | B28: 12-24 | C28: 24-36 | D28: 36-48 | E28: 48-60 | F28: 60-72 | G28: 72-84 | H28: 84-96 | I28: 96-108 | J28: 108-120 | K28: Tail
A29: simple_all | B29: =IFERROR(AVERAGE(B16:B24),AVERAGE(B16:B24)) | C29: =IFERROR(AVERAGE(C16:C24),AVERAGE(C16:C24)) | D29: =IFERROR(AVERAGE(D16:D24),AVERAGE(D16:D24)) | E29: =IFERROR(AVERAGE(E16:E24),AVERAGE(E16:E24)) | F29: =IFERROR(AVERAGE(F16:F24),AVERAGE(F16:F24)) | G29: =IFERROR(AVERAGE(G16:G24),AVERAGE(G16:G24)) | H29: =IFERROR(AVERAGE(H16:H24),AVERAGE(H16:H24)) | I29: =IFERROR(AVERAGE(I16:I24),AVERAGE(I16:I24)) | J29: =IFERROR(AVERAGE(J16:J24),AVERAGE(J16:J24))
A30: weighted_all | B30: =IFERROR(SUMPRODUCT(B16:B24,B3:B11)/SUMPRODUCT((B16:B24<>"")*B3:B11),SUMPRODUCT(B16:B24,B3:B11)/SUMPRODUCT((B16:B24<>"")*B3:B11)) | C30: =IFERROR(SUMPRODUCT(C16:C24,C3:C11)/SUMPRODUCT((C16:C24<>"")*C3:C11),SUMPRODUCT(C16:C24,C3:C11)/SUMPRODUCT((C16:C24<>"")*C3:C11)) | D30: =IFERROR(SUMPRODUCT(D16:D24,D3:D11)/SUMPRODUCT((D16:D24<>"")*D3:D11),SUMPRODUCT(D16:D24,D3:D11)/SUMPRODUCT((D16:D24<>"")*D3:D11)) | E30: =IFERROR(SUMPRODUCT(E16:E24,E3:E11)/SUMPRODUCT((E16:E24<>"")*E3:E11),SUMPRODUCT(E16:E24,E3:E11)/SUMPRODUCT((E16:E24<>"")*E3:E11)) | F30: =IFERROR(SUMPRODUCT(F16:F24,F3:F11)/SUMPRODUCT((F16:F24<>"")*F3:F11),SUMPRODUCT(F16:F24,F3:F11)/SUMPRODUCT((F16:F24<>"")*F3:F11)) | G30: =IFERROR(SUMPRODUCT(G16:G24,G3:G11)/SUMPRODUCT((G16:G24<>"")*G3:G11),SUMPRODUCT(G16:G24,G3:G11)/SUMPRODUCT((G16:G24<>"")*G3:G11)) | H30: =IFERROR(SUMPRODUCT(H16:H24,H3:H11)/SUMPRODUCT((H16:H24<>"")*H3:H11),SUMPRODUCT(H16:H24,H3:H11)/SUMPRODUCT((H16:H24<>"")*H3:H11)) | I30: =IFERROR(SUMPRODUCT(I16:I24,I3:I11)/SUMPRODUCT((I16:I24<>"")*I3:I11),SUMPRODUCT(I16:I24,I3:I11)/SUMPRODUCT((I16:I24<>"")*I3:I11)) | J30: =IFERROR(SUMPRODUCT(J16:J24,J3:J11)/SUMPRODUCT((J16:J24<>"")*J3:J11),SUMPRODUCT(J16:J24,J3:J11)/SUMPRODUCT((J16:J24<>"")*J3:J11))
A31: exclude_high_low_all | B31: =IFERROR(TRIMMEAN(B16:B24,2/COUNT(B16:B24)),AVERAGE(B16:B24)) | C31: =IFERROR(TRIMMEAN(C16:C24,2/COUNT(C16:C24)),AVERAGE(C16:C24)) | D31: =IFERROR(TRIMMEAN(D16:D24,2/COUNT(D16:D24)),AVERAGE(D16:D24)) | E31: =IFERROR(TRIMMEAN(E16:E24,2/COUNT(E16:E24)),AVERAGE(E16:E24)) | F31: =IFERROR(TRIMMEAN(F16:F24,2/COUNT(F16:F24)),AVERAGE(F16:F24)) | G31: =IFERROR(TRIMMEAN(G16:G24,2/COUNT(G16:G24)),AVERAGE(G16:G24)) | H31: =IFERROR(TRIMMEAN(H16:H24,2/COUNT(H16:H24)),AVERAGE(H16:H24)) | I31: =IFERROR(TRIMMEAN(I16:I24,2/COUNT(I16:I24)),AVERAGE(I16:I24)) | J31: =IFERROR(TRIMMEAN(J16:J24,2/COUNT(J16:J24)),AVERAGE(J16:J24))
A32: simple_3yr | B32: =IFERROR(AVERAGE(B22:B24),AVERAGE(B16:B24)) | C32: =IFERROR(AVERAGE(C22:C24),AVERAGE(C16:C24)) | D32: =IFERROR(AVERAGE(D22:D24),AVERAGE(D16:D24)) | E32: =IFERROR(AVERAGE(E22:E24),AVERAGE(E16:E24)) | F32: =IFERROR(AVERAGE(F22:F24),AVERAGE(F16:F24)) | G32: =IFERROR(AVERAGE(G22:G24),AVERAGE(G16:G24)) | H32: =IFERROR(AVERAGE(H22:H24),AVERAGE(H16:H24)) | I32: =IFERROR(AVERAGE(I22:I24),AVERAGE(I16:I24)) | J32: =IFERROR(AVERAGE(J22:J24),AVERAGE(J16:J24))
A33: weighted_3yr | B33: =IFERROR(SUMPRODUCT(B22:B24,B9:B11)/SUMPRODUCT((B22:B24<>"")*B9:B11),SUMPRODUCT(B16:B24,B3:B11)/SUMPRODUCT((B16:B24<>"")*B3:B11)) | C33: =IFERROR(SUMPRODUCT(C22:C24,C9:C11)/SUMPRODUCT((C22:C24<>"")*C9:C11),SUMPRODUCT(C16:C24,C3:C11)/SUMPRODUCT((C16:C24<>"")*C3:C11)) | D33: =IFERROR(SUMPRODUCT(D22:D24,D9:D11)/SUMPRODUCT((D22:D24<>"")*D9:D11),SUMPRODUCT(D16:D24,D3:D11)/SUMPRODUCT((D16:D24<>"")*D3:D11)) | E33: =IFERROR(SUMPRODUCT(E22:E24,E9:E11)/SUMPRODUCT((E22:E24<>"")*E9:E11),SUMPRODUCT(E16:E24,E3:E11)/SUMPRODUCT((E16:E24<>"")*E3:E11)) | F33: =IFERROR(SUMPRODUCT(F22:F24,F9:F11)/SUMPRODUCT((F22:F24<>"")*F9:F11),SUMPRODUCT(F16:F24,F3:F11)/SUMPRODUCT((F16:F24<>"")*F3:F11)) | G33: =IFERROR(SUMPRODUCT(G22:G24,G9:G11)/SUMPRODUCT((G22:G24<>"")*G9:G11),SUMPRODUCT(G16:G24,G3:G11)/SUMPRODUCT((G16:G24<>"")*G3:G11)) | H33: =IFERROR(SUMPRODUCT(H22:H24,H9:H11)/SUMPRODUCT((H22:H24<>"")*H9:H11),SUMPRODUCT(H16:H24,H3:H11)/SUMPRODUCT((H16:H24<>"")*H3:H11)) | I33: =IFERROR(SUMPRODUCT(I22:I24,I9:I11)/SUMPRODUCT((I22:I24<>"")*I9:I11),SUMPRODUCT(I16:I24,I3:I11)/SUMPRODUCT((I16:I24<>"")*I3:I11)) | J33: =IFERROR(SUMPRODUCT(J22:J24,J9:J11)/SUMPRODUCT((J22:J24<>"")*J9:J11),SUMPRODUCT(J16:J24,J3:J11)/SUMPRODUCT((J16:J24<>"")*J3:J11))
A34: exclude_high_low_3yr | B34: =IFERROR(TRIMMEAN(B22:B24,2/COUNT(B22:B24)),AVERAGE(B16:B24)) | C34: =IFERROR(TRIMMEAN(C22:C24,2/COUNT(C22:C24)),AVERAGE(C16:C24)) | D34: =IFERROR(TRIMMEAN(D22:D24,2/COUNT(D22:D24)),AVERAGE(D16:D24)) | E34: =IFERROR(TRIMMEAN(E22:E24,2/COUNT(E22:E24)),AVERAGE(E16:E24)) | F34: =IFERROR(TRIMMEAN(F22:F24,2/COUNT(F22:F24)),AVERAGE(F16:F24)) | G34: =IFERROR(TRIMMEAN(G22:G24,2/COUNT(G22:G24)),AVERAGE(G16:G24)) | H34: =IFERROR(TRIMMEAN(H22:H24,2/COUNT(H22:H24)),AVERAGE(H16:H24)) | I34: =IFERROR(TRIMMEAN(I22:I24,2/COUNT(I22:I24)),AVERAGE(I16:I24)) | J34: =IFERROR(TRIMMEAN(J22:J24,2/COUNT(J22:J24)),AVERAGE(J16:J24))
A35: simple_5yr | B35: =IFERROR(AVERAGE(B20:B24),AVERAGE(B16:B24)) | C35: =IFERROR(AVERAGE(C20:C24),AVERAGE(C16:C24)) | D35: =IFERROR(AVERAGE(D20:D24),AVERAGE(D16:D24)) | E35: =IFERROR(AVERAGE(E20:E24),AVERAGE(E16:E24)) | F35: =IFERROR(AVERAGE(F20:F24),AVERAGE(F16:F24)) | G35: =IFERROR(AVERAGE(G20:G24),AVERAGE(G16:G24)) | H35: =IFERROR(AVERAGE(H20:H24),AVERAGE(H16:H24)) | I35: =IFERROR(AVERAGE(I20:I24),AVERAGE(I16:I24)) | J35: =IFERROR(AVERAGE(J20:J24),AVERAGE(J16:J24))
A36: weighted_5yr | B36: =IFERROR(SUMPRODUCT(B20:B24,B7:B11)/SUMPRODUCT((B20:B24<>"")*B7:B11),SUMPRODUCT(B16:B24,B3:B11)/SUMPRODUCT((B16:B24<>"")*B3:B11)) | C36: =IFERROR(SUMPRODUCT(C20:C24,C7:C11)/SUMPRODUCT((C20:C24<>"")*C7:C11),SUMPRODUCT(C16:C24,C3:C11)/SUMPRODUCT((C16:C24<>"")*C3:C11)) | D36: =IFERROR(SUMPRODUCT(D20:D24,D7:D11)/SUMPRODUCT((D20:D24<>"")*D7:D11),SUMPRODUCT(D16:D24,D3:D11)/SUMPRODUCT((D16:D24<>"")*D3:D11)) | E36: =IFERROR(SUMPRODUCT(E20:E24,E7:E11)/SUMPRODUCT((E20:E24<>"")*E7:E11),SUMPRODUCT(E16:E24,E3:E11)/SUMPRODUCT((E16:E24<>"")*E3:E11)) | F36: =IFERROR(SUMPRODUCT(F20:F24,F7:F11)/SUMPRODUCT((F20:F24<>"")*F7:F11),SUMPRODUCT(F16:F24,F3:F11)/SUMPRODUCT((F16:F24<>"")*F3:F11)) | G36: =IFERROR(SUMPRODUCT(G20:G24,G7:G11)/SUMPRODUCT((G20:G24<>"")*G7:G11),SUMPRODUCT(G16:G24,G3:G11)/SUMPRODUCT((G16:G24<>"")*G3:G11)) | H36: =IFERROR(SUMPRODUCT(H20:H24,H7:H11)/SUMPRODUCT((H20:H24<>"")*H7:H11),SUMPRODUCT(H16:H24,H3:H11)/SUMPRODUCT((H16:H24<>"")*H3:H11)) | I36: =IFERROR(SUMPRODUCT(I20:I24,I7:I11)/SUMPRODUCT((I20:I24<>"")*I7:I11),SUMPRODUCT(I16:I24,I3:I11)/SUMPRODUCT((I16:I24<>"")*I3:I11)) | J36: =IFERROR(SUMPRODUCT(J20:J24,J7:J11)/SUMPRODUCT((J20:J24<>"")*J7:J11),SUMPRODUCT(J16:J24,J3:J11)/SUMPRODUCT((J16:J24<>"")*J3:J11))
A37: exclude_high_low_5yr | B37: =IFERROR(TRIMMEAN(B20:B24,2/COUNT(B20:B24)),AVERAGE(B16:B24)) | C37: =IFERROR(TRIMMEAN(C20:C24,2/COUNT(C20:C24)),AVERAGE(C16:C24)) | D37: =IFERROR(TRIMMEAN(D20:D24,2/COUNT(D20:D24)),AVERAGE(D16:D24)) | E37: =IFERROR(TRIMMEAN(E20:E24,2/COUNT(E20:E24)),AVERAGE(E16:E24)) | F37: =IFERROR(TRIMMEAN(F20:F24,2/COUNT(F20:F24)),AVERAGE(F16:F24)) | G37: =IFERROR(TRIMMEAN(G20:G24,2/COUNT(G20:G24)),AVERAGE(G16:G24)) | H37: =IFERROR(TRIMMEAN(H20:H24,2/COUNT(H20:H24)),AVERAGE(H16:H24)) | I37: =IFERROR(TRIMMEAN(I20:I24,2/COUNT(I20:I24)),AVERAGE(I16:I24)) | J37: =IFERROR(TRIMMEAN(J20:J24,2/COUNT(J20:J24)),AVERAGE(J16:J24))
A38: simple_10yr | B38: =IFERROR(AVERAGE(B16:B24),AVERAGE(B16:B24)) | C38: =IFERROR(AVERAGE(C16:C24),AVERAGE(C16:C24)) | D38: =IFERROR(AVERAGE(D16:D24),AVERAGE(D16:D24)) | E38: =IFERROR(AVERAGE(E16:E24),AVERAGE(E16:E24)) | F38: =IFERROR(AVERAGE(F16:F24),AVERAGE(F16:F24)) | G38: =IFERROR(AVERAGE(G16:G24),AVERAGE(G16:G24)) | H38: =IFERROR(AVERAGE(H16:H24),AVERAGE(H16:H24)) | I38: =IFERROR(AVERAGE(I16:I24),AVERAGE(I16:I24)) | J38: =IFERROR(AVERAGE(J16:J24),AVERAGE(J16:J24))
A39: weighted_10yr | B39: =IFERROR(SUMPRODUCT(B16:B24,B3:B11)/SUMPRODUCT((B16:B24<>"")*B3:B11),SUMPRODUCT(B16:B24,B3:B11)/SUMPRODUCT((B16:B24<>"")*B3:B11)) | C39: =IFERROR(SUMPRODUCT(C16:C24,C3:C11)/SUMPRODUCT((C16:C24<>"")*C3:C11),SUMPRODUCT(C16:C24,C3:C11)/SUMPRODUCT((C16:C24<>"")*C3:C11)) | D39: =IFERROR(SUMPRODUCT(D16:D24,D3:D11)/SUMPRODUCT((D16:D24<>"")*D3:D11),SUMPRODUCT(D16:D24,D3:D11)/SUMPRODUCT((D16:D24<>"")*D3:D11)) | E39: =IFERROR(SUMPRODUCT(E16:E24,E3:E11)/SUMPRODUCT((E16:E24<>"")*E3:E11),SUMPRODUCT(E16:E24,E3:E11)/SUMPRODUCT((E16:E24<>"")*E3:E11)) | F39: =IFERROR(SUMPRODUCT(F16:F24,F3:F11)/SUMPRODUCT((F16:F24<>"")*F3:F11),SUMPRODUCT(F16:F24,F3:F11)/SUMPRODUCT((F16:F24<>"")*F3:F11)) | G39: =IFERROR(SUMPRODUCT(G16:G24,G3:G11)/SUMPRODUCT((G16:G24<>"")*G3:G11),SUMPRODUCT(G16:G24,G3:G11)/SUMPRODUCT((G16:G24<>"")*G3:G11)) | H39: =IFERROR(SUMPRODUCT(H16:H24,H3:H11)/SUMPRODUCT((H16:H24<>"")*H3:H11),SUMPRODUCT(H16:H24,H3:H11)/SUMPRODUCT((H16:H24<>"")*H3:H11)) | I39: =IFERROR(SUMPRODUCT(I16:I24,I3:I11)/SUMPRODUCT((I16:I24<>"")*I3:I11),SUMPRODUCT(I16:I24,I3:I11)/SUMPRODUCT((I16:I24<>"")*I3:I11)) | J39: =IFERROR(SUMPRODUCT(J16:J24,J3:J11)/SUMPRODUCT((J16:J24<>"")*J3:J11),SUMPRODUCT(J16:J24,J3:J11)/SUMPRODUCT((J16:J24<>"")*J3:J11))
A40: exclude_high_low_10yr | B40: =IFERROR(TRIMMEAN(B16:B24,2/COUNT(B16:B24)),AVERAGE(B16:B24)) | C40: =IFERROR(TRIMMEAN(C16:C24,2/COUNT(C16:C24)),AVERAGE(C16:C24)) | D40: =IFERROR(TRIMMEAN(D16:D24,2/COUNT(D16:D24)),AVERAGE(D16:D24)) | E40: =IFERROR(TRIMMEAN(E16:E24,2/COUNT(E16:E24)),AVERAGE(E16:E24)) | F40: =IFERROR(TRIMMEAN(F16:F24,2/COUNT(F16:F24)),AVERAGE(F16:F24)) | G40: =IFERROR(TRIMMEAN(G16:G24,2/COUNT(G16:G24)),AVERAGE(G16:G24)) | H40: =IFERROR(TRIMMEAN(H16:H24,2/COUNT(H16:H24)),AVERAGE(H16:H24)) | I40: =IFERROR(TRIMMEAN(I16:I24,2/COUNT(I16:I24)),AVERAGE(I16:I24)) | J40: =IFERROR(TRIMMEAN(J16:J24,2/COUNT(J16:J24)),AVERAGE(J16:J24))
A42: LDF Selections
B43: 12-24 | C43: 24-36 | D43: 36-48 | E43: 48-60 | F43: 60-72 | G43: 72-84 | H43: 84-96 | I43: 96-108 | J43: 108-120 | K43: Tail
...

Sheet CL - Reported Count
A1: Reported Count
B2: 12 | C2: 24 | D2: 36 | E2: 48 | F2: 60 | G2: 72 | H2: 84 | I2: 96 | J2: 108 | K2: 120
A3: 2015 | B3: 1638 | C3: 2677 | D3: 3472 | E3: 4077 | F3: 4526 | G3: 4730 | H3: 4831 | I3: 4883 | J3: 4930 | K3: 4930
A4: 2016 | B4: 1636 | C4: 2723 | D4: 3474 | E4: 4156 | F4: 4555 | G4: 4743 | H4: 4846 | I4: 4894 | J4: 4943
A5: 2017 | B5: 1624 | C5: 2682 | D5: 3477 | E5: 4114 | F5: 4516 | G5: 4713 | H5: 4812 | I5: 4864
A6: 2018 | B6: 1697 | C6: 2736 | D6: 3560 | E6: 4204 | F6: 4592 | G6: 4773 | H6: 4886
A7: 2019 | B7: 1559 | C7: 2687 | D7: 3545 | E7: 4166 | F7: 4570 | G7: 4767
A8: 2020 | B8: 1624 | C8: 2750 | D8: 3494 | E8: 4155 | F8: 4597
A9: 2021 | B9: 1636 | C9: 2748 | D9: 3579 | E9: 4301
A10: 2022 | B10: 1720 | C10: 2783 | D10: 3568
A11: 2023 | B11: 1568 | C11: 2665
A12: 2024 | B12: 1712
A14: Age-to-Age Factors
B15: 12-24 | C15: 24-36 | D15: 36-48 | E15: 48-60 | F15: 60-72 | G15: 72-84 | H15: 84-96 | I15: 96-108 | J15: 108-120
A16: 2015 | B16: =C3/B3 | C16: =D3/C3 | D16: =E3/D3 | E16: =F3/E3 | F16: =G3/F3 | G16: =H3/G3 | H16: =I3/H3 | I16: =J3/I3 | J16: =K3/J3
A17: 2016 | B17: =C4/B4 | C17: =D4/C4 | D17: =E4/D4 | E17: =F4/E4 | F17: =G4/F4 | G17: =H4/G4 | H17: =I4/H4 | I17: =J4/I4
A18: 2017 | B18: =C5/B5 | C18: =D5/C5 | D18: =E5/D5 | E18: =F5/E5 | F18: =G5/F5 | G18: =H5/G5 | H18: =I5/H5
A19: 2018 | B19: =C6/B6 | C19: =D6/C6 | D19: =E6/D6 | E19: =F6/E6 | F19: =G6/F6 | G19: =H6/G6
A20: 2019 | B20: =C7/B7 | C20: =D7/C7 | D20: =E7/D7 | E20: =F7/E7 | F20: =G7/F7
A21: 2020 | B21: =C8/B8 | C21: =D8/C8 | D21: =E8/D8 | E21: =F8/E8
A22: 2021 | B22: =C9/B9 | C22: =D9/C9 | D22: =E9/D9
A23: 2022 | B23: =C10/B10 | C23: =D10/C10
A24: 2023 | B24: =C11/B11
A25: 2024
A27: Averages
A28: Metric | B28: 12-24 | C28: 24-36 | D28: 36-48 | E28: 48-60 | F28: 60-72 | G28: 72-84 | H28: 84-96 | I28: 96-108 | J28: 108-120 | K28: Tail
A29: simple_all | B29: =IFERROR(AVERAGE(B16:B24),AVERAGE(B16:B24)) | C29: =IFERROR(AVERAGE(C16:C24),AVERAGE(C16:C24)) | D29: =IFERROR(AVERAGE(D16:D24),AVERAGE(D16:D24)) | E29: =IFERROR(AVERAGE(E16:E24),AVERAGE(E16:E24)) | F29: =IFERROR(AVERAGE(F16:F24),AVERAGE(F16:F24)) | G29: =IFERROR(AVERAGE(G16:G24),AVERAGE(G16:G24)) | H29: =IFERROR(AVERAGE(H16:H24),AVERAGE(H16:H24)) | I29: =IFERROR(AVERAGE(I16:I24),AVERAGE(I16:I24)) | J29: =IFERROR(AVERAGE(J16:J24),AVERAGE(J16:J24))
A30: weighted_all | B30: =IFERROR(SUMPRODUCT(B16:B24,B3:B11)/SUMPRODUCT((B16:B24<>"")*B3:B11),SUMPRODUCT(B16:B24,B3:B11)/SUMPRODUCT((B16:B24<>"")*B3:B11)) | C30: =IFERROR(SUMPRODUCT(C16:C24,C3:C11)/SUMPRODUCT((C16:C24<>"")*C3:C11),SUMPRODUCT(C16:C24,C3:C11)/SUMPRODUCT((C16:C24<>"")*C3:C11)) | D30: =IFERROR(SUMPRODUCT(D16:D24,D3:D11)/SUMPRODUCT((D16:D24<>"")*D3:D11),SUMPRODUCT(D16:D24,D3:D11)/SUMPRODUCT((D16:D24<>"")*D3:D11)) | E30: =IFERROR(SUMPRODUCT(E16:E24,E3:E11)/SUMPRODUCT((E16:E24<>"")*E3:E11),SUMPRODUCT(E16:E24,E3:E11)/SUMPRODUCT((E16:E24<>"")*E3:E11)) | F30: =IFERROR(SUMPRODUCT(F16:F24,F3:F11)/SUMPRODUCT((F16:F24<>"")*F3:F11),SUMPRODUCT(F16:F24,F3:F11)/SUMPRODUCT((F16:F24<>"")*F3:F11)) | G30: =IFERROR(SUMPRODUCT(G16:G24,G3:G11)/SUMPRODUCT((G16:G24<>"")*G3:G11),SUMPRODUCT(G16:G24,G3:G11)/SUMPRODUCT((G16:G24<>"")*G3:G11)) | H30: =IFERROR(SUMPRODUCT(H16:H24,H3:H11)/SUMPRODUCT((H16:H24<>"")*H3:H11),SUMPRODUCT(H16:H24,H3:H11)/SUMPRODUCT((H16:H24<>"")*H3:H11)) | I30: =IFERROR(SUMPRODUCT(I16:I24,I3:I11)/SUMPRODUCT((I16:I24<>"")*I3:I11),SUMPRODUCT(I16:I24,I3:I11)/SUMPRODUCT((I16:I24<>"")*I3:I11)) | J30: =IFERROR(SUMPRODUCT(J16:J24,J3:J11)/SUMPRODUCT((J16:J24<>"")*J3:J11),SUMPRODUCT(J16:J24,J3:J11)/SUMPRODUCT((J16:J24<>"")*J3:J11))
A31: exclude_high_low_all | B31: =IFERROR(TRIMMEAN(B16:B24,2/COUNT(B16:B24)),AVERAGE(B16:B24)) | C31: =IFERROR(TRIMMEAN(C16:C24,2/COUNT(C16:C24)),AVERAGE(C16:C24)) | D31: =IFERROR(TRIMMEAN(D16:D24,2/COUNT(D16:D24)),AVERAGE(D16:D24)) | E31: =IFERROR(TRIMMEAN(E16:E24,2/COUNT(E16:E24)),AVERAGE(E16:E24)) | F31: =IFERROR(TRIMMEAN(F16:F24,2/COUNT(F16:F24)),AVERAGE(F16:F24)) | G31: =IFERROR(TRIMMEAN(G16:G24,2/COUNT(G16:G24)),AVERAGE(G16:G24)) | H31: =IFERROR(TRIMMEAN(H16:H24,2/COUNT(H16:H24)),AVERAGE(H16:H24)) | I31: =IFERROR(TRIMMEAN(I16:I24,2/COUNT(I16:I24)),AVERAGE(I16:I24)) | J31: =IFERROR(TRIMMEAN(J16:J24,2/COUNT(J16:J24)),AVERAGE(J16:J24))
A32: simple_3yr | B32: =IFERROR(AVERAGE(B22:B24),AVERAGE(B16:B24)) | C32: =IFERROR(AVERAGE(C22:C24),AVERAGE(C16:C24)) | D32: =IFERROR(AVERAGE(D22:D24),AVERAGE(D16:D24)) | E32: =IFERROR(AVERAGE(E22:E24),AVERAGE(E16:E24)) | F32: =IFERROR(AVERAGE(F22:F24),AVERAGE(F16:F24)) | G32: =IFERROR(AVERAGE(G22:G24),AVERAGE(G16:G24)) | H32: =IFERROR(AVERAGE(H22:H24),AVERAGE(H16:H24)) | I32: =IFERROR(AVERAGE(I22:I24),AVERAGE(I16:I24)) | J32: =IFERROR(AVERAGE(J22:J24),AVERAGE(J16:J24))
A33: weighted_3yr | B33: =IFERROR(SUMPRODUCT(B22:B24,B9:B11)/SUMPRODUCT((B22:B24<>"")*B9:B11),SUMPRODUCT(B16:B24,B3:B11)/SUMPRODUCT((B16:B24<>"")*B3:B11)) | C33: =IFERROR(SUMPRODUCT(C22:C24,C9:C11)/SUMPRODUCT((C22:C24<>"")*C9:C11),SUMPRODUCT(C16:C24,C3:C11)/SUMPRODUCT((C16:C24<>"")*C3:C11)) | D33: =IFERROR(SUMPRODUCT(D22:D24,D9:D11)/SUMPRODUCT((D22:D24<>"")*D9:D11),SUMPRODUCT(D16:D24,D3:D11)/SUMPRODUCT((D16:D24<>"")*D3:D11)) | E33: =IFERROR(SUMPRODUCT(E22:E24,E9:E11)/SUMPRODUCT((E22:E24<>"")*E9:E11),SUMPRODUCT(E16:E24,E3:E11)/SUMPRODUCT((E16:E24<>"")*E3:E11)) | F33: =IFERROR(SUMPRODUCT(F22:F24,F9:F11)/SUMPRODUCT((F22:F24<>"")*F9:F11),SUMPRODUCT(F16:F24,F3:F11)/SUMPRODUCT((F16:F24<>"")*F3:F11)) | G33: =IFERROR(SUMPRODUCT(G22:G24,G9:G11)/SUMPRODUCT((G22:G24<>"")*G9:G11),SUMPRODUCT(G16:G24,G3:G11)/SUMPRODUCT((G16:G24<>"")*G3:G11)) | H33: =IFERROR(SUMPRODUCT(H22:H24,H9:H11)/SUMPRODUCT((H22:H24<>"")*H9:H11),SUMPRODUCT(H16:H24,H3:H11)/SUMPRODUCT((H16:H24<>"")*H3:H11)) | I33: =IFERROR(SUMPRODUCT(I22:I24,I9:I11)/SUMPRODUCT((I22:I24<>"")*I9:I11),SUMPRODUCT(I16:I24,I3:I11)/SUMPRODUCT((I16:I24<>"")*I3:I11)) | J33: =IFERROR(SUMPRODUCT(J22:J24,J9:J11)/SUMPRODUCT((J22:J24<>"")*J9:J11),SUMPRODUCT(J16:J24,J3:J11)/SUMPRODUCT((J16:J24<>"")*J3:J11))
A34: exclude_high_low_3yr | B34: =IFERROR(TRIMMEAN(B22:B24,2/COUNT(B22:B24)),AVERAGE(B16:B24)) | C34: =IFERROR(TRIMMEAN(C22:C24,2/COUNT(C22:C24)),AVERAGE(C16:C24)) | D34: =IFERROR(TRIMMEAN(D22:D24,2/COUNT(D22:D24)),AVERAGE(D16:D24)) | E34: =IFERROR(TRIMMEAN(E22:E24,2/COUNT(E22:E24)),AVERAGE(E16:E24)) | F34: =IFERROR(TRIMMEAN(F22:F24,2/COUNT(F22:F24)),AVERAGE(F16:F24)) | G34: =IFERROR(TRIMMEAN(G22:G24,2/COUNT(G22:G24)),AVERAGE(G16:G24)) | H34: =IFERROR(TRIMMEAN(H22:H24,2/COUNT(H22:H24)),AVERAGE(H16:H24)) | I34: =IFERROR(TRIMMEAN(I22:I24,2/COUNT(I22:I24)),AVERAGE(I16:I24)) | J34: =IFERROR(TRIMMEAN(J22:J24,2/COUNT(J22:J24)),AVERAGE(J16:J24))
A35: simple_5yr | B35: =IFERROR(AVERAGE(B20:B24),AVERAGE(B16:B24)) | C35: =IFERROR(AVERAGE(C20:C24),AVERAGE(C16:C24)) | D35: =IFERROR(AVERAGE(D20:D24),AVERAGE(D16:D24)) | E35: =IFERROR(AVERAGE(E20:E24),AVERAGE(E16:E24)) | F35: =IFERROR(AVERAGE(F20:F24),AVERAGE(F16:F24)) | G35: =IFERROR(AVERAGE(G20:G24),AVERAGE(G16:G24)) | H35: =IFERROR(AVERAGE(H20:H24),AVERAGE(H16:H24)) | I35: =IFERROR(AVERAGE(I20:I24),AVERAGE(I16:I24)) | J35: =IFERROR(AVERAGE(J20:J24),AVERAGE(J16:J24))
A36: weighted_5yr | B36: =IFERROR(SUMPRODUCT(B20:B24,B7:B11)/SUMPRODUCT((B20:B24<>"")*B7:B11),SUMPRODUCT(B16:B24,B3:B11)/SUMPRODUCT((B16:B24<>"")*B3:B11)) | C36: =IFERROR(SUMPRODUCT(C20:C24,C7:C11)/SUMPRODUCT((C20:C24<>"")*C7:C11),SUMPRODUCT(C16:C24,C3:C11)/SUMPRODUCT((C16:C24<>"")*C3:C11)) | D36: =IFERROR(SUMPRODUCT(D20:D24,D7:D11)/SUMPRODUCT((D20:D24<>"")*D7:D11),SUMPRODUCT(D16:D24,D3:D11)/SUMPRODUCT((D16:D24<>"")*D3:D11)) | E36: =IFERROR(SUMPRODUCT(E20:E24,E7:E11)/SUMPRODUCT((E20:E24<>"")*E7:E11),SUMPRODUCT(E16:E24,E3:E11)/SUMPRODUCT((E16:E24<>"")*E3:E11)) | F36: =IFERROR(SUMPRODUCT(F20:F24,F7:F11)/SUMPRODUCT((F20:F24<>"")*F7:F11),SUMPRODUCT(F16:F24,F3:F11)/SUMPRODUCT((F16:F24<>"")*F3:F11)) | G36: =IFERROR(SUMPRODUCT(G20:G24,G7:G11)/SUMPRODUCT((G20:G24<>"")*G7:G11),SUMPRODUCT(G16:G24,G3:G11)/SUMPRODUCT((G16:G24<>"")*G3:G11)) | H36: =IFERROR(SUMPRODUCT(H20:H24,H7:H11)/SUMPRODUCT((H20:H24<>"")*H7:H11),SUMPRODUCT(H16:H24,H3:H11)/SUMPRODUCT((H16:H24<>"")*H3:H11)) | I36: =IFERROR(SUMPRODUCT(I20:I24,I7:I11)/SUMPRODUCT((I20:I24<>"")*I7:I11),SUMPRODUCT(I16:I24,I3:I11)/SUMPRODUCT((I16:I24<>"")*I3:I11)) | J36: =IFERROR(SUMPRODUCT(J20:J24,J7:J11)/SUMPRODUCT((J20:J24<>"")*J7:J11),SUMPRODUCT(J16:J24,J3:J11)/SUMPRODUCT((J16:J24<>"")*J3:J11))
A37: exclude_high_low_5yr | B37: =IFERROR(TRIMMEAN(B20:B24,2/COUNT(B20:B24)),AVERAGE(B16:B24)) | C37: =IFERROR(TRIMMEAN(C20:C24,2/COUNT(C20:C24)),AVERAGE(C16:C24)) | D37: =IFERROR(TRIMMEAN(D20:D24,2/COUNT(D20:D24)),AVERAGE(D16:D24)) | E37: =IFERROR(TRIMMEAN(E20:E24,2/COUNT(E20:E24)),AVERAGE(E16:E24)) | F37: =IFERROR(TRIMMEAN(F20:F24,2/COUNT(F20:F24)),AVERAGE(F16:F24)) | G37: =IFERROR(TRIMMEAN(G20:G24,2/COUNT(G20:G24)),AVERAGE(G16:G24)) | H37: =IFERROR(TRIMMEAN(H20:H24,2/COUNT(H20:H24)),AVERAGE(H16:H24)) | I37: =IFERROR(TRIMMEAN(I20:I24,2/COUNT(I20:I24)),AVERAGE(I16:I24)) | J37: =IFERROR(TRIMMEAN(J20:J24,2/COUNT(J20:J24)),AVERAGE(J16:J24))
A38: simple_10yr | B38: =IFERROR(AVERAGE(B16:B24),AVERAGE(B16:B24)) | C38: =IFERROR(AVERAGE(C16:C24),AVERAGE(C16:C24)) | D38: =IFERROR(AVERAGE(D16:D24),AVERAGE(D16:D24)) | E38: =IFERROR(AVERAGE(E16:E24),AVERAGE(E16:E24)) | F38: =IFERROR(AVERAGE(F16:F24),AVERAGE(F16:F24)) | G38: =IFERROR(AVERAGE(G16:G24),AVERAGE(G16:G24)) | H38: =IFERROR(AVERAGE(H16:H24),AVERAGE(H16:H24)) | I38: =IFERROR(AVERAGE(I16:I24),AVERAGE(I16:I24)) | J38: =IFERROR(AVERAGE(J16:J24),AVERAGE(J16:J24))
A39: weighted_10yr | B39: =IFERROR(SUMPRODUCT(B16:B24,B3:B11)/SUMPRODUCT((B16:B24<>"")*B3:B11),SUMPRODUCT(B16:B24,B3:B11)/SUMPRODUCT((B16:B24<>"")*B3:B11)) | C39: =IFERROR(SUMPRODUCT(C16:C24,C3:C11)/SUMPRODUCT((C16:C24<>"")*C3:C11),SUMPRODUCT(C16:C24,C3:C11)/SUMPRODUCT((C16:C24<>"")*C3:C11)) | D39: =IFERROR(SUMPRODUCT(D16:D24,D3:D11)/SUMPRODUCT((D16:D24<>"")*D3:D11),SUMPRODUCT(D16:D24,D3:D11)/SUMPRODUCT((D16:D24<>"")*D3:D11)) | E39: =IFERROR(SUMPRODUCT(E16:E24,E3:E11)/SUMPRODUCT((E16:E24<>"")*E3:E11),SUMPRODUCT(E16:E24,E3:E11)/SUMPRODUCT((E16:E24<>"")*E3:E11)) | F39: =IFERROR(SUMPRODUCT(F16:F24,F3:F11)/SUMPRODUCT((F16:F24<>"")*F3:F11),SUMPRODUCT(F16:F24,F3:F11)/SUMPRODUCT((F16:F24<>"")*F3:F11)) | G39: =IFERROR(SUMPRODUCT(G16:G24,G3:G11)/SUMPRODUCT((G16:G24<>"")*G3:G11),SUMPRODUCT(G16:G24,G3:G11)/SUMPRODUCT((G16:G24<>"")*G3:G11)) | H39: =IFERROR(SUMPRODUCT(H16:H24,H3:H11)/SUMPRODUCT((H16:H24<>"")*H3:H11),SUMPRODUCT(H16:H24,H3:H11)/SUMPRODUCT((H16:H24<>"")*H3:H11)) | I39: =IFERROR(SUMPRODUCT(I16:I24,I3:I11)/SUMPRODUCT((I16:I24<>"")*I3:I11),SUMPRODUCT(I16:I24,I3:I11)/SUMPRODUCT((I16:I24<>"")*I3:I11)) | J39: =IFERROR(SUMPRODUCT(J16:J24,J3:J11)/SUMPRODUCT((J16:J24<>"")*J3:J11),SUMPRODUCT(J16:J24,J3:J11)/SUMPRODUCT((J16:J24<>"")*J3:J11))
A40: exclude_high_low_10yr | B40: =IFERROR(TRIMMEAN(B16:B24,2/COUNT(B16:B24)),AVERAGE(B16:B24)) | C40: =IFERROR(TRIMMEAN(C16:C24,2/COUNT(C16:C24)),AVERAGE(C16:C24)) | D40: =IFERROR(TRIMMEAN(D16:D24,2/COUNT(D16:D24)),AVERAGE(D16:D24)) | E40: =IFERROR(TRIMMEAN(E16:E24,2/COUNT(E16:E24)),AVERAGE(E16:E24)) | F40: =IFERROR(TRIMMEAN(F16:F24,2/COUNT(F16:F24)),AVERAGE(F16:F24)) | G40: =IFERROR(TRIMMEAN(G16:G24,2/COUNT(G16:G24)),AVERAGE(G16:G24)) | H40: =IFERROR(TRIMMEAN(H16:H24,2/COUNT(H16:H24)),AVERAGE(H16:H24)) | I40: =IFERROR(TRIMMEAN(I16:I24,2/COUNT(I16:I24)),AVERAGE(I16:I24)) | J40: =IFERROR(TRIMMEAN(J16:J24,2/COUNT(J16:J24)),AVERAGE(J16:J24))
A42: LDF Selections
B43: 12-24 | C43: 24-36 | D43: 36-48 | E43: 48-60 | F43: 60-72 | G43: 72-84 | H43: 84-96 | I43: 96-108 | J43: 108-120 | K43: Tail
...

Sheet CL - Diag - Rptd Claims
A1: Reported Claims
B2: 12 | C2: 24 | D2: 36 | E2: 48 | F2: 60 | G2: 72 | H2: 84 | I2: 96 | J2: 108 | K2: 120
A3: 2015 | B3: 1638 | C3: 2677 | D3: 3472 | E3: 4077 | F3: 4526 | G3: 4730 | H3: 4831 | I3: 4883 | J3: 4930 | K3: 4930
A4: 2016 | B4: 1636 | C4: 2723 | D4: 3474 | E4: 4156 | F4: 4555 | G4: 4743 | H4: 4846 | I4: 4894 | J4: 4943
A5: 2017 | B5: 1624 | C5: 2682 | D5: 3477 | E5: 4114 | F5: 4516 | G5: 4713 | H5: 4812 | I5: 4864
A6: 2018 | B6: 1697 | C6: 2736 | D6: 3560 | E6: 4204 | F6: 4592 | G6: 4773 | H6: 4886
A7: 2019 | B7: 1559 | C7: 2687 | D7: 3545 | E7: 4166 | F7: 4570 | G7: 4767
A8: 2020 | B8: 1624 | C8: 2750 | D8: 3494 | E8: 4155 | F8: 4597
A9: 2021 | B9: 1636 | C9: 2748 | D9: 3579 | E9: 4301
A10: 2022 | B10: 1720 | C10: 2783 | D10: 3568
A11: 2023 | B11: 1568 | C11: 2665
A12: 2024 | B12: 1712

Sheet CL - Diag - Inc Severity
A1: Incurred Severity
B2: 12 | C2: 24 | D2: 36 | E2: 48 | F2: 60 | G2: 72 | H2: 84 | I2: 96 | J2: 108 | K2: 120
A3: 2015 | B3: 7098.4541 | C3: 7715.2158 | D3: 7749.6834 | E3: 7939.2853 | F3: 7958.4138 | G3: 8180.0714 | H3: 8499.0827 | I3: 8749.6564 | J3: 8948.6693 | K3: 9129.5005
A4: 2016 | B4: 9571.6151 | C4: 9915.6425 | D4: 10315.651 | E4: 10423.573 | F4: 10717.954 | G4: 11054.965 | H4: 11472.245 | I4: 11846.221 | J4: 12122.724
A5: 2017 | B5: 5387.136 | C5: 6169.5643 | D5: 6415.6021 | E5: 6516.9154 | F5: 6619.6704 | G5: 6808.6592 | H5: 7041.437 | I5: 7272.2886
A6: 2018 | B6: 8605.7618 | C6: 9915.0284 | D6: 10227.213 | E6: 10540.855 | F6: 10651.338 | G6: 10964.877 | H6: 11322.867
A7: 2019 | B7: 7599.8629 | C7: 8020.6149 | D7: 8064.2778 | E7: 8119.2937 | F7: 8214.3637 | G7: 8470.6732
A8: 2020 | B8: 6482.6603 | C8: 6991.5957 | D8: 7533.6513 | E8: 7589.0283 | F8: 7597.8125
A9: 2021 | B9: 11598.884 | C9: 12783.823 | D9: 12901.322 | E9: 12839.295
A10: 2022 | B10: 6560.2045 | C10: 7234.5554 | D10: 7579.0477
A11: 2023 | B11: 7700.7354 | C11: 8006.0142
A12: 2024 | B12: 9304.8621

Sheet CL - Diag - Paid Severity
A1: Paid Severity
B2: 12 | C2: 24 | D2: 36 | E2: 48 | F2: 60 | G2: 72 | H2: 84 | I2: 96 | J2: 108 | K2: 120
A3: 2015 | B3: 6794.6046 | C3: 7518.8479 | D3: 7942.1853 | E3: 7833.8534 | F3: 7881.6478 | G3: 8056.0152 | H3: 8321.0119 | I3: 8570.6207 | J3: 8833.9444 | K3: 9127.6491
A4: 2016 | B4: 9476.5764 | C4: 10477.952 | D4: 10849.012 | E4: 10841.546 | F4: 10974.876 | G4: 11242.629 | H4: 11531.82 | I4: 11848.582 | J4: 12125.143
A5: 2017 | B5: 5651.3611 | C5: 6693.7866 | D5: 7009.8043 | E5: 6957.1886 | F5: 7003.8235 | G5: 7134.4438 | H5: 7254.4775 | I5: 7420.8636
A6: 2018 | B6: 8539.5818 | C6: 9841.3331 | D6: 10362.511 | E6: 10522.828 | F6: 10749.334 | G6: 10967.95 | H6: 11220.539
A7: 2019 | B7: 7261.7351 | C7: 8050.4431 | D7: 8486.6031 | E7: 8429.8884 | F7: 8544.3919 | G7: 8708.3002
A8: 2020 | B8: 6453.418 | C8: 6808.2141 | D8: 7356.5136 | E8: 7591.7672 | F8: 7655.6744
A9: 2021 | B9: 10240.125 | C9: 11384.964 | D9: 11762.289 | E9: 12122.576
A10: 2022 | B10: 5740.6934 | C10: 6873.2679 | D10: 7409.5436
A11: 2023 | B11: 7415.991 | C11: 8093.7641
A12: 2024 | B12: 10154.178

Sheet CL - Diag - Paid to Incurred
A1: Paid To Incurred
B2: 12 | C2: 24 | D2: 36 | E2: 48 | F2: 60 | G2: 72 | H2: 84 | I2: 96 | J2: 108 | K2: 120
A3: 2015 | B3: 0.7953 | C3: 0.8176 | D3: 0.8548 | E3: 0.8589 | F3: 0.8785 | G3: 0.9051 | H3: 0.931 | I3: 0.9511 | J3: 0.9778 | K3: 1
A4: 2016 | B4: 0.7807 | C4: 0.8522 | D4: 0.8779 | E4: 0.8847 | F4: 0.9017 | G4: 0.9312 | H4: 0.9529 | I4: 0.9685 | J4: 0.9891
A5: 2017 | B5: 0.8746 | C5: 0.8649 | D5: 0.8931 | E5: 0.8953 | F5: 0.9219 | G5: 0.9531 | H5: 0.9742 | I5: 0.9869
A6: 2018 | B6: 0.8262 | C6: 0.8315 | D6: 0.8524 | E6: 0.8523 | F6: 0.8899 | G6: 0.9219 | H6: 0.9476
A7: 2019 | B7: 0.8495 | C7: 0.8409 | D7: 0.8689 | E7: 0.8785 | F7: 0.9104 | G7: 0.9392
A8: 2020 | B8: 0.8514 | C8: 0.8279 | D8: 0.8401 | E8: 0.8557 | F8: 0.8807
A9: 2021 | B9: 0.8413 | C9: 0.8109 | D9: 0.8233 | E9: 0.8364
A10: 2022 | B10: 0.7962 | C10: 0.8255 | D10: 0.8543
A11: 2023 | B11: 0.8095 | C11: 0.8399
A12: 2024 | B12: 0.8325

Sheet CL - Diag - Open Counts
A1: Open Counts
B2: 12 | C2: 24 | D2: 36 | E2: 48 | F2: 60 | G2: 72 | H2: 84 | I2: 96 | J2: 108 | K2: 120
A3: 2015 | B3: 277 | C3: 431 | D3: 576 | E3: 528 | F3: 511 | G3: 383 | H3: 237 | I3: 142 | J3: 47 | K3: -1
A4: 2016 | B4: 346 | C4: 527 | D4: 574 | E4: 621 | F4: 544 | G4: 400 | H4: 252 | I4: 155 | J4: 55
A5: 2017 | B5: 270 | C5: 544 | D5: 635 | E5: 664 | F5: 581 | G5: 426 | H5: 262 | I5: 160
A6: 2018 | B6: 284 | C6: 444 | D6: 565 | E6: 615 | F6: 543 | G6: 374 | H6: 214
A7: 2019 | B7: 173 | C7: 436 | D7: 618 | E7: 641 | F7: 570 | G7: 412
A8: 2020 | B8: 235 | C8: 412 | D8: 488 | E8: 601 | F8: 579
A9: 2021 | B9: 77 | C9: 246 | D9: 347 | E9: 491
A10: 2022 | B10: 155 | C10: 365 | D10: 450
A11: 2023 | B11: 250 | C11: 451
A12: 2024 | B12: 406

Sheet CL - Diag - Avg Case Rsrv
A1: Average Case Reserve
B2: 12 | C2: 24 | D2: 36 | E2: 48 | F2: 60 | G2: 72 | H2: 84 | I2: 96 | J2: 108 | K2: 120
A3: 2015 | B3: 8591.3754 | C3: 8738.5157 | D3: 6781.8266 | E3: 8647.9552 | F3: 8561.5749 | G3: 9588.0925 | H3: 11950.8 | I3: 14727.18 | J3: 20867.859 | K3: -0.03
A4: 2016 | B4: 9925.9502 | C4: 7572.5075 | D4: 7620.9716 | E4: 8044.2907 | F4: 8823.6287 | G4: 9017.4012 | H4: 10386.193 | I4: 11774.021 | J4: 11907.736
A5: 2017 | B5: 4062.0959 | C5: 4109.2935 | D5: 3756.1962 | E5: 4229.3513 | F5: 4017.8763 | G5: 3530.1649 | H5: 3341.6888 | I5: 2904.1845
A6: 2018 | B6: 8935.0304 | C6: 10295.456 | D6: 9510.0095 | E6: 10646.052 | F6: 9920.6168 | G6: 10928.731 | H6: 13556.867
A7: 2019 | B7: 10308.794 | C7: 7866.6164 | D7: 6064.0411 | E7: 6411.2649 | F7: 5898.3768 | G7: 5958.8635
A8: 2020 | B8: 6655.5009 | C8: 8032.2423 | D8: 8624.7901 | E8: 7572.8318 | F8: 7196.2771
A9: 2021 | B9: 39109.352 | C9: 27011.243 | D9: 23510.405 | E9: 18400.798
A10: 2022 | B10: 14834.623 | C10: 9627.9614 | D10: 8753.5229
A11: 2023 | B11: 9201.9078 | C11: 7575.2419
A12: 2024 | B12: 6572.8267

Sheet CL - Diag - Clm Closure Rt
A1: Claim Closure Rate
B2: 12 | C2: 24 | D2: 36 | E2: 48 | F2: 60 | G2: 72 | H2: 84 | I2: 96 | J2: 108 | K2: 120
A3: 2015 | B3: 0.8309 | C3: 0.839 | D3: 0.8341 | E3: 0.8705 | F3: 0.8871 | G3: 0.919 | H3: 0.9509 | I3: 0.9709 | J3: 0.9905 | K3: 1.0002
A4: 2016 | B4: 0.7885 | C4: 0.8065 | D4: 0.8348 | E4: 0.8506 | F4: 0.8806 | G4: 0.9157 | H4: 0.948 | I4: 0.9683 | J4: 0.9889
A5: 2017 | B5: 0.8337 | C5: 0.7972 | D5: 0.8174 | E5: 0.8386 | F5: 0.8713 | G5: 0.9096 | H5: 0.9456 | I5: 0.9671
A6: 2018 | B6: 0.8326 | C6: 0.8377 | D6: 0.8413 | E6: 0.8537 | F6: 0.8818 | G6: 0.9216 | H6: 0.9562
A7: 2019 | B7: 0.889 | C7: 0.8377 | D7: 0.8257 | E7: 0.8461 | F7: 0.8753 | G7: 0.9136
A8: 2020 | B8: 0.8553 | C8: 0.8502 | D8: 0.8603 | E8: 0.8554 | F8: 0.874
A9: 2021 | B9: 0.9529 | C9: 0.9105 | D9: 0.903 | E9: 0.8858
A10: 2022 | B10: 0.9099 | C10: 0.8688 | D10: 0.8739
A11: 2023 | B11: 0.8406 | C11: 0.8308
A12: 2024 | B12: 0.7629

Sheet CL - Diag - Incr Inc Svty
A1: Incremental Incurred Severity
B2: 12 | C2: 24 | D2: 36 | E2: 48 | F2: 60 | G2: 72 | H2: 84 | I2: 96 | J2: 108 | K2: 120
A3: 2015 | B3: 7098.4541 | C3: 8687.5504 | D3: 7865.7459 | E3: 9027.381 | F3: 8132.1039 | G3: 13097.827 | H3: 23438.92 | I3: 32028.918 | J3: 29624.843
A4: 2016 | B4: 9571.6151 | C4: 10433.424 | D4: 11766.014 | E4: 10973.313 | F4: 13784.233 | G4: 19220.323 | H4: 30687.38 | I4: 49602.15 | J4: 39739.185
A5: 2017 | B5: 5387.136 | C5: 7370.5697 | D5: 7245.6314 | E5: 7069.924 | F5: 7671.2475 | G5: 11141.011 | H5: 18123.074 | I5: 28634.937
A6: 2018 | B6: 8605.7618 | C6: 12053.455 | D6: 11263.786 | E6: 12274.652 | F6: 11848.437 | G6: 18919.388 | H6: 26444.015
A7: 2019 | B7: 7599.8629 | C7: 8602.1329 | D7: 8201.0171 | E7: 8433.3538 | F7: 9194.715 | G7: 14416.533
A8: 2020 | B8: 6482.6603 | C8: 7725.6199 | D8: 9537.2168 | E8: 7881.7474 | F8: 7680.388
A9: 2021 | B9: 11598.884 | C9: 14527.133 | D9: 13289.872 | E9: 12531.824
A10: 2022 | B10: 6560.2045 | C10: 8325.697 | D10: 8800.3497
A11: 2023 | B11: 7700.7354 | C11: 8442.3653
A12: 2024 | B12: 9304.8621

Sheet CL - Diag - Incr Paid Svty
A1: Incremental Paid Severity
B2: 12 | C2: 24 | D2: 36 | E2: 48 | F2: 60 | G2: 72 | H2: 84 | I2: 96 | J2: 108 | K2: 120
A3: 2015 | B3: 6794.6046 | C3: 8632.6278 | D3: 9404.9786 | E3: 7353.4109 | F3: 8245.6442 | G3: 10164.705 | H3: 12984.739 | I3: 16371.319 | J3: 17625.619 | K3: 39005.984
A4: 2016 | B4: 9476.5764 | C4: 11903.752 | D4: 12006.464 | E4: 10807.453 | F4: 11965.04 | G4: 14477.453 | H4: 16535.617 | I4: 21884.488 | J4: 20921.26
A5: 2017 | B5: 5651.3611 | C5: 8494.0981 | D5: 7969.5285 | E5: 6711.2449 | F5: 7335.5559 | G5: 8594.6447 | H5: 9211.0729 | I5: 12336.816
A6: 2018 | B6: 8539.5818 | C6: 11933.909 | D6: 12061.716 | E6: 11331.16 | F6: 12516.567 | G6: 13497.025 | H6: 15290.657
A7: 2019 | B7: 7261.7351 | C7: 9314.1994 | D7: 9938.9645 | E7: 8152.2897 | F7: 9394.1283 | G7: 10555.155
A8: 2020 | B8: 6453.418 | C8: 7327.5099 | D8: 9275.5622 | E8: 8882.2275 | F8: 8145.1702
A9: 2021 | B9: 10240.125 | C9: 13277.652 | D9: 13055.533 | E9: 14137.19
A10: 2022 | B10: 5740.6934 | C10: 8951.2036 | D10: 9261.993
A11: 2023 | B11: 7415.991 | C11: 9090.7562
A12: 2024 | B12: 10154.178

Sheet CL - Diag - Incr Closure Rt
A1: Incremental Closure Rate
B2: 12 | C2: 24 | D2: 36 | E2: 48 | F2: 60 | G2: 72 | H2: 84 | I2: 96 | J2: 108 | K2: 120
A3: 2015 | B3: 0.8309 | C3: 0.8518 | D3: 0.8176 | E3: 1.0793 | F3: 1.0379 | G3: 1.6275 | H3: 2.4455 | I3: 2.8269 | J3: 3.0213
A4: 2016 | B4: 0.7885 | C4: 0.8335 | D4: 0.9374 | E4: 0.9311 | F4: 1.193 | G4: 1.766 | H4: 2.4369 | I4: 3.0208 | J4: 3.0408
A5: 2017 | B5: 0.8337 | C5: 0.741 | D5: 0.8855 | E5: 0.9545 | F5: 1.2065 | G5: 1.7868 | H5: 2.6566 | I5: 2.9615
A6: 2018 | B6: 0.8326 | C6: 0.846 | D6: 0.8532 | E6: 0.9224 | F6: 1.1856 | G6: 1.9337 | H6: 2.4159
A7: 2019 | B7: 0.889 | C7: 0.7668 | D7: 0.7879 | E7: 0.963 | F7: 1.1757 | G7: 1.802
A8: 2020 | B8: 0.8553 | C8: 0.8428 | D8: 0.8978 | E8: 0.829 | F8: 1.0498
A9: 2021 | B9: 0.9529 | C9: 0.848 | D9: 0.8785 | E9: 0.8006
A10: 2022 | B10: 0.9099 | C10: 0.8024 | D10: 0.8917
A11: 2023 | B11: 0.8406 | C11: 0.8168
A12: 2024 | B12: 0.7629

Sheet CL - Closed Count - CV & Slopes
A1: Closed Count - CV & Slopes
A2: Metric | B2: 12-24 | C2: 24-36 | D2: 36-48 | E2: 48-60 | F2: 60-72 | G2: 72-84 | H2: 84-96 | I2: 96-108 | J2: 108-120 | K2: Tail
A3: cv_3yr | B3: 0.042 | C3: 0.0024 | D3: 0.0116 | E3: 0.003 | F3: 0.0015 | G3: 0.0022 | H3: 0.0011 | I3: 0.001
A4: cv_5yr | B4: 0.0353 | C4: 0.0066 | D4: 0.0124 | E4: 0.0042 | F4: 0.003 | G4: 0.0024 | H4: 0.0011 | I4: 0.001
A5: cv_10yr | B5: 0.0317 | C5: 0.0123 | D5: 0.0149 | E5: 0.0038 | F5: 0.003 | G5: 0.0024 | H5: 0.0011 | I5: 0.001
A6: slope_3yr | B6: 0.0375 | C6: 0.0019 | D6: -0.0127 | E6: 0.0012 | F6: -0.0003 | G6: 0.0022 | H6: 0.0009 | I6: 0.0014
A7: slope_5yr | B7: -0.0027 | C7: -0.0043 | D7: -0.0086 | E7: -0.0014 | F7: 0.0016 | G7: 0.0019 | H7: 0.0009 | I7: 0.0014
A8: slope_10yr | B8: -0.004 | C8: -0.0033 | D8: -0.008 | E8: -0.0004 | F8: 0.0016 | G8: 0.0019 | H8: 0.0009 | I8: 0.0014

Sheet CL - Incurred Loss - CV & Slope
A1: Incurred Loss - CV & Slopes
A2: Metric | B2: 12-24 | C2: 24-36 | D2: 36-48 | E2: 48-60 | F2: 60-72 | G2: 72-84 | H2: 84-96 | I2: 96-108 | J2: 108-120 | K2: Tail
A3: cv_3yr | B3: 0.0247 | C3: 0.0204 | D3: 0.0067 | E3: 0.0028 | F3: 0.0027 | G3: 0.0022 | H3: 0.0016 | I3: 0.0007
A4: cv_5yr | B4: 0.0187 | C4: 0.0154 | D4: 0.0102 | E4: 0.0081 | F4: 0.002 | G4: 0.0024 | H4: 0.0016 | I4: 0.0007
A5: cv_10yr | B5: 0.0289 | C5: 0.0156 | D5: 0.0088 | E5: 0.0072 | F5: 0.002 | G5: 0.0024 | H5: 0.0016 | I5: 0.0007
A6: slope_3yr | B6: -0.0421 | C6: -0.013 | D6: 0.0064 | E6: 0.002 | F6: 0.0012 | G6: -0.0016 | H6: 0.0017 | I6: 0.001
A7: slope_5yr | B7: -0.0146 | C7: -0.001 | D7: -0.0031 | E7: -0.0044 | F7: -0.0001 | G7: -0.0017 | H7: 0.0017 | I7: 0.001
A8: slope_10yr | B8: 0.0005 | C8: 0.0032 | D8: -0.0022 | E8: -0.0025 | F8: -0.0001 | G8: -0.0017 | H8: 0.0017 | I8: 0.001

Sheet CL - Paid Loss - CV & Slopes
A1: Paid Loss - CV & Slopes
A2: Metric | B2: 12-24 | C2: 24-36 | D2: 36-48 | E2: 48-60 | F2: 60-72 | G2: 72-84 | H2: 84-96 | I2: 96-108 | J2: 108-120 | K2: Tail
A3: cv_3yr | B3: 0.0187 | C3: 0.0232 | D3: 0.0103 | E3: 0.0057 | F3: 0.0006 | G3: 0.0036 | H3: 0.0026 | I3: 0.0041
A4: cv_5yr | B4: 0.0176 | C4: 0.0165 | D4: 0.0081 | E4: 0.0041 | F4: 0.0012 | G4: 0.0047 | H4: 0.0026 | I4: 0.0041
A5: cv_10yr | B5: 0.0213 | C5: 0.0139 | D5: 0.0071 | E5: 0.005 | F5: 0.0012 | G5: 0.0047 | H5: 0.0026 | I5: 0.0041
