Workbook

Sheet CL - Closed Count
A1: Closed Count
B2: 12 | C2: 24 | D2: 36 | E2: 48 | F2: 60 | G2: 72 | H2: 84 | I2: 96 | J2: 108 | K2: 120
A3: 2015 | B3: 1361 | C3: 2246 | D3: 2896 | E3: 3549 | F3: 4015 | G3: 4347 | H3: 4594 | I3: 4741 | J3: 4883 | K3: 4931
A4: 2016 | B4: 1290 | C4: 2196 | D4: 2900 | E4: 3535 | F4: 4011 | G4: 4343 | H4: 4594 | I4: 4739 | J4: 4888
A5: 2017 | B5: 1354 | C5: 2138 | D5: 2842 | E5: 3450 | F5: 3935 | G5: 4287 | H5: 4550 | I5: 4704
A6: 2018 | B6: 1413 | C6: 2292 | D6: 2995 | E6: 3589 | F6: 4049 | G6: 4399 | H6: 4672
A7: 2019 | B7: 1386 | C7: 2251 | D7: 2927 | E7: 3525 | F7: 4000 | G7: 4355
A8: 2020 | B8: 1389 | C8: 2338 | D8: 3006 | E8: 3554 | F8: 4018
A9: 2021 | B9: 1559 | C9: 2502 | D9: 3232 | E9: 3810
A10: 2022 | B10: 1565 | C10: 2418 | D10: 3118
A11: 2023 | B11: 1318 | C11: 2214
A12: 2024 | B12: 1306
A14: Age-to-Age Factors
B15: 12-24 | C15: 24-36 | D15: 36-48 | E15: 48-60 | F15: 60-72 | G15: 72-84 | H15: 84-96 | I15: 96-108 | J15: 108-120
A16: 2015 | B16: =C3/B3 -> 1.6502572 | C16: =D3/C3 -> 1.2894034 | D16: =E3/D3 -> 1.2254834 | E16: =F3/E3 -> 1.1313046 | F16: =G3/F3 -> 1.0826899 | G16: =H3/G3 -> 1.0568208 | H16: =I3/H3 -> 1.0319983 | I16: =J3/I3 -> 1.0299515 | J16: =K3/J3 -> 1.00983
A17: 2016 | B17: =C4/B4 -> 1.7023256 | C17: =D4/C4 -> 1.3205829 | D17: =E4/D4 -> 1.2189655 | E17: =F4/E4 -> 1.1346535 | F17: =G4/F4 -> 1.0827724 | G17: =H4/G4 -> 1.0577942 | H17: =I4/H4 -> 1.0315629 | I17: =J4/I4 -> 1.0314412
A18: 2017 | B18: =C5/B5 -> 1.5790251 | C18: =D5/C5 -> 1.3292797 | D18: =E5/D5 -> 1.2139338 | E18: =F5/E5 -> 1.1405797 | F18: =G5/F5 -> 1.0894536 | G18: =H5/G5 -> 1.0613483 | H18: =I5/H5 -> 1.0338462
A19: 2018 | B19: =C6/B6 -> 1.6220807 | C19: =D6/C6 -> 1.306719 | D19: =E6/D6 -> 1.1983306 | E19: =F6/E6 -> 1.1281694 | F19: =G6/F6 -> 1.0864411 | G19: =H6/G6 -> 1.0620596
A20: 2019 | B20: =C7/B7 -> 1.6240981 | C20: =D7/C7 -> 1.300311 | D20: =E7/D7 -> 1.2043047 | E20: =F7/E7 -> 1.1347518 | F20: =G7/F7 -> 1.08875
A21: 2020 | B21: =C8/B8 -> 1.6832253 | C21: =D8/C8 -> 1.2857143 | D21: =E8/D8 -> 1.1823021 | E21: =F8/E8 -> 1.1305571
A22: 2021 | B22: =C9/B9 -> 1.6048749 | C22: =D9/C9 -> 1.2917666 | D22: =E9/D9 -> 1.1788366
A23: 2022 | B23: =C10/B10 -> 1.5450479 | C23: =D10/C10 -> 1.2894955
A24: 2023 | B24: =C11/B11 -> 1.6798179
A25: 2024
A27: Averages
A28: Metric | B28: 12-24 | C28: 24-36 | D28: 36-48 | E28: 48-60 | F28: 60-72 | G28: 72-84 | H28: 84-96 | I28: 96-108 | J28: 108-120 | K28: Tail
A29: simple_all | B29: =IFERROR(AVERAGE(B16:B24),AVERAGE(B16:B24)) -> 1.6323059 | C29: =IFERROR(AVERAGE(C16:C24),AVERAGE(C16:C24)) -> 1.301659 | D29: =IFERROR(AVERAGE(D16:D24),AVERAGE(D16:D24)) -> 1.2031653 | E29: =IFERROR(AVERAGE(E16:E24),AVERAGE(E16:E24)) -> 1.133336 | F29: =IFERROR(AVERAGE(F16:F24),AVERAGE(F16:F24)) -> 1.0860214 | G29: =IFERROR(AVERAGE(G16:G24),AVERAGE(G16:G24)) -> 1.0595057 | H29: =IFERROR(AVERAGE(H16:H24),AVERAGE(H16:H24)) -> 1.0324691 | I29: =IFERROR(AVERAGE(I16:I24),AVERAGE(I16:I24)) -> 1.0306964 | J29: =IFERROR(AVERAGE(J16:J24),AVERAGE(J16:J24)) -> 1.00983
A30: weighted_all | B30: =IFERROR(SUMPRODUCT(B16:B24,B3:B11)/SUMPRODUCT((B16:B24<>"")*B3:B11),SUMPRODUCT(B16:B24,B3:B11)/SUMPRODUCT((B16:B24<>"")*B3:B11)) -> 1.629996 | C30: =IFERROR(SUMPRODUCT(C16:C24,C3:C11)/SUMPRODUCT((C16:C24<>"")*C3:C11),SUMPRODUCT(C16:C24,C3:C11)/SUMPRODUCT((C16:C24<>"")*C3:C11)) -> 1.3011262 | D30: =IFERROR(SUMPRODUCT(D16:D24,D3:D11)/SUMPRODUCT((D16:D24<>"")*D3:D11),SUMPRODUCT(D16:D24,D3:D11)/SUMPRODUCT((D16:D24<>"")*D3:D11)) -> 1.2026156 | E30: =IFERROR(SUMPRODUCT(E16:E24,E3:E11)/SUMPRODUCT((E16:E24<>"")*E3:E11),SUMPRODUCT(E16:E24,E3:E11)/SUMPRODUCT((E16:E24<>"")*E3:E11)) -> 1.1332893 | F30: =IFERROR(SUMPRODUCT(F16:F24,F3:F11)/SUMPRODUCT((F16:F24<>"")*F3:F11),SUMPRODUCT(F16:F24,F3:F11)/SUMPRODUCT((F16:F24<>"")*F3:F11)) -> 1.086007 | G30: =IFERROR(SUMPRODUCT(G16:G24,G3:G11)/SUMPRODUCT((G16:G24<>"")*G3:G11),SUMPRODUCT(G16:G24,G3:G11)/SUMPRODUCT((G16:G24<>"")*G3:G11)) -> 1.0595074 | H30: =IFERROR(SUMPRODUCT(H16:H24,H3:H11)/SUMPRODUCT((H16:H24<>"")*H3:H11),SUMPRODUCT(H16:H24,H3:H11)/SUMPRODUCT((H16:H24<>"")*H3:H11)) -> 1.0324647 | I30: =IFERROR(SUMPRODUCT(I16:I24,I3:I11)/SUMPRODUCT((I16:I24<>"")*I3:I11),SUMPRODUCT(I16:I24,I3:I11)/SUMPRODUCT((I16:I24<>"")*I3:I11)) -> 1.0306962 | J30: =IFERROR(SUMPRODUCT(J16:J24,J3:J11)/SUMPRODUCT((J16:J24<>"")*J3:J11),SUMPRODUCT(J16:J24,J3:J11)/SUMPRODUCT((J16:J24<>"")*J3:J11)) -> 1.00983
A31: exclude_high_low_all | B31: =IFERROR(TRIMMEAN(B16:B24,2/COUNT(B16:B24)),AVERAGE(B16:B24)) -> 1.6347685 | C31: =IFERROR(TRIMMEAN(C16:C24,2/COUNT(C16:C24)),AVERAGE(C16:C24)) -> 1.299713 | D31: =IFERROR(TRIMMEAN(D16:D24,2/COUNT(D16:D24)),AVERAGE(D16:D24)) -> 1.2035673 | E31: =IFERROR(TRIMMEAN(E16:E24,2/COUNT(E16:E24)),AVERAGE(E16:E24)) -> 1.1328167 | F31: =IFERROR(TRIMMEAN(F16:F24,2/COUNT(F16:F24)),AVERAGE(F16:F24)) -> 1.0859878 | G31: =IFERROR(TRIMMEAN(G16:G24,2/COUNT(G16:G24)),AVERAGE(G16:G24)) -> 1.0595712 | H31: =IFERROR(TRIMMEAN(H16:H24,2/COUNT(H16:H24)),AVERAGE(H16:H24)) -> 1.0319983 | I31: =IFERROR(TRIMMEAN(I16:I24,2/COUNT(I16:I24)),AVERAGE(I16:I24)) -> 1.0306964 | J31: =IFERROR(TRIMMEAN(J16:J24,2/COUNT(J16:J24)),AVERAGE(J16:J24)) -> 1.00983
A32: simple_3yr | B32: =IFERROR(AVERAGE(B22:B24),AVERAGE(B16:B24)) -> 1.6099136 | C32: =IFERROR(AVERAGE(C22:C24),AVERAGE(C16:C24)) -> 1.290631 | D32: =IFERROR(AVERAGE(D22:D24),AVERAGE(D16:D24)) -> 1.1788366 | E32: =IFERROR(AVERAGE(E22:E24),AVERAGE(E16:E24)) -> 1.133336 | F32: =IFERROR(AVERAGE(F22:F24),AVERAGE(F16:F24)) -> 1.0860214 | G32: =IFERROR(AVERAGE(G22:G24),AVERAGE(G16:G24)) -> 1.0595057 | H32: =IFERROR(AVERAGE(H22:H24),AVERAGE(H16:H24)) -> 1.0324691 | I32: =IFERROR(AVERAGE(I22:I24),AVERAGE(I16:I24)) -> 1.0306964 | J32: =IFERROR(AVERAGE(J22:J24),AVERAGE(J16:J24)) -> 1.00983
A33: weighted_3yr | B33: =IFERROR(SUMPRODUCT(B22:B24,B9:B11)/SUMPRODUCT((B22:B24<>"")*B9:B11),SUMPRODUCT(B16:B24,B3:B11)/SUMPRODUCT((B16:B24<>"")*B3:B11)) -> 1.6060333 | C33: =IFERROR(SUMPRODUCT(C22:C24,C9:C11)/SUMPRODUCT((C22:C24<>"")*C9:C11),SUMPRODUCT(C16:C24,C3:C11)/SUMPRODUCT((C16:C24<>"")*C3:C11)) -> 1.2906504 | D33: =IFERROR(SUMPRODUCT(D22:D24,D9:D11)/SUMPRODUCT((D22:D24<>"")*D9:D11),SUMPRODUCT(D16:D24,D3:D11)/SUMPRODUCT((D16:D24<>"")*D3:D11)) -> 1.1788366 | E33: =IFERROR(SUMPRODUCT(E22:E24,E9:E11)/SUMPRODUCT((E22:E24<>"")*E9:E11),SUMPRODUCT(E16:E24,E3:E11)/SUMPRODUCT((E16:E24<>"")*E3:E11)) -> 1.1332893 | F33: =IFERROR(SUMPRODUCT(F22:F24,F9:F11)/SUMPRODUCT((F22:F24<>"")*F9:F11),SUMPRODUCT(F16:F24,F3:F11)/SUMPRODUCT((F16:F24<>"")*F3:F11)) -> 1.086007 | G33: =IFERROR(SUMPRODUCT(G22:G24,G9:G11)/SUMPRODUCT((G22:G24<>"")*G9:G11),SUMPRODUCT(G16:G24,G3:G11)/SUMPRODUCT((G16:G24<>"")*G3:G11)) -> 1.0595074 | H33: =IFERROR(SUMPRODUCT(H22:H24,H9:H11)/SUMPRODUCT((H22:H24<>"")*H9:H11),SUMPRODUCT(H16:H24,H3:H11)/SUMPRODUCT((H16:H24<>"")*H3:H11)) -> 1.0324647 | I33: =IFERROR(SUMPRODUCT(I22:I24,I9:I11)/SUMPRODUCT((I22:I24<>"")*I9:I11),SUMPRODUCT(I16:I24,I3:I11)/SUMPRODUCT((I16:I24<>"")*I3:I11)) -> 1.0306962 | J33: =IFERROR(SUMPRODUCT(J22:J24,J9:J11)/SUMPRODUCT((J22:J24<>"")*J9:J11),SUMPRODUCT(J16:J24,J3:J11)/SUMPRODUCT((J16:J24<>"")*J3:J11)) -> 1.00983
A34: exclude_high_low_3yr | B34: =IFERROR(TRIMMEAN(B22:B24,2/COUNT(B22:B24)),AVERAGE(B16:B24)) -> 1.6048749 | C34: =IFERROR(TRIMMEAN(C22:C24,2/COUNT(C22:C24)),AVERAGE(C16:C24)) -> 1.301659 | D34: =IFERROR(TRIMMEAN(D22:D24,2/COUNT(D22:D24)),AVERAGE(D16:D24)) -> 1.2031653 | E34: =IFERROR(TRIMMEAN(E22:E24,2/COUNT(E22:E24)),AVERAGE(E16:E24)) -> 1.133336 | F34: =IFERROR(TRIMMEAN(F22:F24,2/COUNT(F22:F24)),AVERAGE(F16:F24)) -> 1.0860214 | G34: =IFERROR(TRIMMEAN(G22:G24,2/COUNT(G22:G24)),AVERAGE(G16:G24)) -> 1.0595057 | H34: =IFERROR(TRIMMEAN(H22:H24,2/COUNT(H22:H24)),AVERAGE(H16:H24)) -> 1.0324691 | I34: =IFERROR(TRIMMEAN(I22:I24,2/COUNT(I22:I24)),AVERAGE(I16:I24)) -> 1.0306964 | J34: =IFERROR(TRIMMEAN(J22:J24,2/COUNT(J22:J24)),AVERAGE(J16:J24)) -> 1.00983
A35: simple_5yr | B35: =IFERROR(AVERAGE(B20:B24),AVERAGE(B16:B24)) -> 1.6274128 | C35: =IFERROR(AVERAGE(C20:C24),AVERAGE(C16:C24)) -> 1.2918218 | D35: =IFERROR(AVERAGE(D20:D24),AVERAGE(D16:D24)) -> 1.1884811 | E35: =IFERROR(AVERAGE(E20:E24),AVERAGE(E16:E24)) -> 1.1326544 | F35: =IFERROR(AVERAGE(F20:F24),AVERAGE(F16:F24)) -> 1.08875 | G35: =IFERROR(AVERAGE(G20:G24),AVERAGE(G16:G24)) -> 1.0595057 | H35: =IFERROR(AVERAGE(H20:H24),AVERAGE(H16:H24)) -> 1.0324691 | I35: =IFERROR(AVERAGE(I20:I24),AVERAGE(I16:I24)) -> 1.0306964 | J35: =IFERROR(AVERAGE(J20:J24),AVERAGE(J16:J24)) -> 1.00983
A36: weighted_5yr | B36: =IFERROR(SUMPRODUCT(B20:B24,B7:B11)/SUMPRODUCT((B20:B24<>"")*B7:B11),SUMPRODUCT(B16:B24,B3:B11)/SUMPRODUCT((B16:B24<>"")*B3:B11)) -> 1.6243592 | C36: =IFERROR(SUMPRODUCT(C20:C24,C7:C11)/SUMPRODUCT((C20:C24<>"")*C7:C11),SUMPRODUCT(C16:C24,C3:C11)/SUMPRODUCT((C16:C24<>"")*C3:C11)) -> 1.2917236 | D36: =IFERROR(SUMPRODUCT(D20:D24,D7:D11)/SUMPRODUCT((D20:D24<>"")*D7:D11),SUMPRODUCT(D16:D24,D3:D11)/SUMPRODUCT((D16:D24<>"")*D3:D11)) -> 1.1881069 | E36: =IFERROR(SUMPRODUCT(E20:E24,E7:E11)/SUMPRODUCT((E20:E24<>"")*E7:E11),SUMPRODUCT(E16:E24,E3:E11)/SUMPRODUCT((E16:E24<>"")*E3:E11)) -> 1.1326459 | F36: =IFERROR(SUMPRODUCT(F20:F24,F7:F11)/SUMPRODUCT((F20:F24<>"")*F7:F11),SUMPRODUCT(F16:F24,F3:F11)/SUMPRODUCT((F16:F24<>"")*F3:F11)) -> 1.08875 | G36: =IFERROR(SUMPRODUCT(G20:G24,G7:G11)/SUMPRODUCT((G20:G24<>"")*G7:G11),SUMPRODUCT(G16:G24,G3:G11)/SUMPRODUCT((G16:G24<>"")*G3:G11)) -> 1.0595074 | H36: =IFERROR(SUMPRODUCT(H20:H24,H7:H11)/SUMPRODUCT((H20:H24<>"")*H7:H11),SUMPRODUCT(H16:H24,H3:H11)/SUMPRODUCT((H16:H24<>"")*H3:H11)) -> 1.0324647 | I36: =IFERROR(SUMPRODUCT(I20:I24,I7:I11)/SUMPRODUCT((I20:I24<>"")*I7:I11),SUMPRODUCT(I16:I24,I3:I11)/SUMPRODUCT((I16:I24<>"")*I3:I11)) -> 1.0306962 | J36: =IFERROR(SUMPRODUCT(J20:J24,J7:J11)/SUMPRODUCT((J20:J24<>"")*J7:J11),SUMPRODUCT(J16:J24,J3:J11)/SUMPRODUCT((J16:J24<>"")*J3:J11)) -> 1.00983
A37: exclude_high_low_5yr | B37: =IFERROR(TRIMMEAN(B20:B24,2/COUNT(B20:B24)),AVERAGE(B16:B24)) -> 1.6362636 | C37: =IFERROR(TRIMMEAN(C20:C24,2/COUNT(C20:C24)),AVERAGE(C16:C24)) -> 1.290631 | D37: =IFERROR(TRIMMEAN(D20:D24,2/COUNT(D20:D24)),AVERAGE(D16:D24)) -> 1.1823021 | E37: =IFERROR(TRIMMEAN(E20:E24,2/COUNT(E20:E24)),AVERAGE(E16:E24)) -> 1.133336 | F37: =IFERROR(TRIMMEAN(F20:F24,2/COUNT(F20:F24)),AVERAGE(F16:F24)) -> 1.0860214 | G37: =IFERROR(TRIMMEAN(G20:G24,2/COUNT(G20:G24)),AVERAGE(G16:G24)) -> 1.0595057 | H37: =IFERROR(TRIMMEAN(H20:H24,2/COUNT(H20:H24)),AVERAGE(H16:H24)) -> 1.0324691 | I37: =IFERROR(TRIMMEAN(I20:I24,2/COUNT(I20:I24)),AVERAGE(I16:I24)) -> 1.0306964 | J37: =IFERROR(TRIMMEAN(J20:J24,2/COUNT(J20:J24)),AVERAGE(J16:J24)) -> 1.00983
A38: simple_10yr | B38: =IFERROR(AVERAGE(B16:B24),AVERAGE(B16:B24)) -> 1.6323059 | C38: =IFERROR(AVERAGE(C16:C24),AVERAGE(C16:C24)) -> 1.301659 | D38: =IFERROR(AVERAGE(D16:D24),AVERAGE(D16:D24)) -> 1.2031653 | E38: =IFERROR(AVERAGE(E16:E24),AVERAGE(E16:E24)) -> 1.133336 | F38: =IFERROR(AVERAGE(F16:F24),AVERAGE(F16:F24)) -> 1.0860214 | G38: =IFERROR(AVERAGE(G16:G24),AVERAGE(G16:G24)) -> 1.0595057 | H38: =IFERROR(AVERAGE(H16:H24),AVERAGE(H16:H24)) -> 1.0324691 | I38: =IFERROR(AVERAGE(I16:I24),AVERAGE(I16:I24)) -> 1.0306964 | J38: =IFERROR(AVERAGE(J16:J24),AVERAGE(J16:J24)) -> 1.00983
A39: weighted_10yr | B39: =IFERROR(SUMPRODUCT(B16:B24,B3:B11)/SUMPRODUCT((B16:B24<>"")*B3:B11),SUMPRODUCT(B16:B24,B3:B11)/SUMPRODUCT((B16:B24<>"")*B3:B11)) -> 1.629996 | C39: =IFERROR(SUMPRODUCT(C16:C24,C3:C11)/SUMPRODUCT((C16:C24<>"")*C3:C11),SUMPRODUCT(C16:C24,C3:C11)/SUMPRODUCT((C16:C24<>"")*C3:C11)) -> 1.3011262 | D39: =IFERROR(SUMPRODUCT(D16:D24,D3:D11)/SUMPRODUCT((D16:D24<>"")*D3:D11),SUMPRODUCT(D16:D24,D3:D11)/SUMPRODUCT((D16:D24<>"")*D3:D11)) -> 1.2026156 | E39: =IFERROR(SUMPRODUCT(E16:E24,E3:E11)/SUMPRODUCT((E16:E24<>"")*E3:E11),SUMPRODUCT(E16:E24,E3:E11)/SUMPRODUCT((E16:E24<>"")*E3:E11)) -> 1.1332893 | F39: =IFERROR(SUMPRODUCT(F16:F24,F3:F11)/SUMPRODUCT((F16:F24<>"")*F3:F11),SUMPRODUCT(F16:F24,F3:F11)/SUMPRODUCT((F16:F24<>"")*F3:F11)) -> 1.086007 | G39: =IFERROR(SUMPRODUCT(G16:G24,G3:G11)/SUMPRODUCT((G16:G24<>"")*G3:G11),SUMPRODUCT(G16:G24,G3:G11)/SUMPRODUCT((G16:G24<>"")*G3:G11)) -> 1.0595074 | H39: =IFERROR(SUMPRODUCT(H16:H24,H3:H11)/SUMPRODUCT((H16:H24<>"")*H3:H11),SUMPRODUCT(H16:H24,H3:H11)/SUMPRODUCT((H16:H24<>"")*H3:H11)) -> 1.0324647 | I39: =IFERROR(SUMPRODUCT(I16:I24,I3:I11)/SUMPRODUCT((I16:I24<>"")*I3:I11),SUMPRODUCT(I16:I24,I3:I11)/SUMPRODUCT((I16:I24<>"")*I3:I11)) -> 1.0306962 | J39: =IFERROR(SUMPRODUCT(J16:J24,J3:J11)/SUMPRODUCT((J16:J24<>"")*J3:J11),SUMPRODUCT(J16:J24,J3:J11)/SUMPRODUCT((J16:J24<>"")*J3:J11)) -> 1.00983
A40: exclude_high_low_10yr | B40: =IFERROR(TRIMMEAN(B16:B24,2/COUNT(B16:B24)),AVERAGE(B16:B24)) -> 1.6347685 | C40: =IFERROR(TRIMMEAN(C16:C24,2/COUNT(C16:C24)),AVERAGE(C16:C24)) -> 1.299713 | D40: =IFERROR(TRIMMEAN(D16:D24,2/COUNT(D16:D24)),AVERAGE(D16:D24)) -> 1.2035673 | E40: =IFERROR(TRIMMEAN(E16:E24,2/COUNT(E16:E24)),AVERAGE(E16:E24)) -> 1.1328167 | F40: =IFERROR(TRIMMEAN(F16:F24,2/COUNT(F16:F24)),AVERAGE(F16:F24)) -> 1.0859878 | G40: =IFERROR(TRIMMEAN(G16:G24,2/COUNT(G16:G24)),AVERAGE(G16:G24)) -> 1.0595712 | H40: =IFERROR(TRIMMEAN(H16:H24,2/COUNT(H16:H24)),AVERAGE(H16:H24)) -> 1.0319983 | I40: =IFERROR(TRIMMEAN(I16:I24,2/COUNT(I16:I24)),AVERAGE(I16:I24)) -> 1.0306964 | J40: =IFERROR(TRIMMEAN(J16:J24,2/COUNT(J16:J24)),AVERAGE(J16:J24)) -> 1.00983
A42: LDF Selections
B43: 12-24 | C43: 24-36 | D43: 36-48 | E43: 48-60 | F43: 60-72 | G43: 72-84 | H43: 84-96 | I43: 96-108 | J43: 108-120 | K43: Tail
...

Sheet CL - Incurred Loss
A1: Incurred Loss
B2: 12 | C2: 24 | D2: 36 | E2: 48 | F2: 60 | G2: 72 | H2: 84 | I2: 96 | J2: 108 | K2: 120
A3: 2015 | B3: 11627268 | C3: 20653633 | D3: 26906901 | E3: 32368466 | F3: 36019781 | G3: 38691738 | H3: 41059068 | I3: 42724572 | J3: 44116940 | K3: 45008438
A4: 2016 | B4: 15659162 | C4: 27000294 | D4: 35836571 | E4: 43320371 | F4: 48820280 | G4: 52433700 | H4: 55594501 | I4: 57975404 | J4: 59922624
A5: 2017 | B5: 8748708.8 | C5: 16546772 | D5: 22307048 | E5: 26810590 | F5: 29894432 | G5: 32089211 | H5: 33883395 | I5: 35372412
A6: 2018 | B6: 14603978 | C6: 27127518 | D6: 36408877 | E6: 44313753 | F6: 48910946 | G6: 52335355 | H6: 55323529
A7: 2019 | B7: 11848186 | C7: 21551392 | D7: 28587865 | E7: 33824977 | F7: 37539642 | G7: 40379699
A8: 2020 | B8: 10527840 | C8: 19226888 | D8: 26322578 | E8: 31532413 | F8: 34927144
A9: 2021 | B9: 18975774 | C9: 35129946 | D9: 46173829 | E9: 55221806
A10: 2022 | B10: 11283552 | C10: 20133768 | D10: 27042042
A11: 2023 | B11: 12074753 | C11: 21336028
A12: 2024 | B12: 15929924
A14: Age-to-Age Factors
B15: 12-24 | C15: 24-36 | D15: 36-48 | E15: 48-60 | F15: 60-72 | G15: 72-84 | H15: 84-96 | I15: 96-108 | J15: 108-120
A16: 2015 | B16: =C3/B3 -> 1.77631 | C16: =D3/C3 -> 1.3027684 | D16: =E3/D3 -> 1.2029801 | E16: =F3/E3 -> 1.1128047 | F16: =G3/F3 -> 1.0741803 | G16: =H3/G3 -> 1.0611844 | H16: =I3/H3 -> 1.0405636 | I16: =J3/I3 -> 1.0325894 | J16: =K3/J3 -> 1.0202076
A17: 2016 | B17: =C4/B4 -> 1.724249 | C17: =D4/C4 -> 1.3272659 | D17: =E4/D4 -> 1.2088313 | E17: =F4/E4 -> 1.1269589 | F17: =G4/F4 -> 1.0740148 | G17: =H4/G4 -> 1.0602818 | H17: =I4/H4 -> 1.0428262 | I17: =J4/I4 -> 1.033587
A18: 2017 | B18: =C5/B5 -> 1.8913387 | C18: =D5/C5 -> 1.3481209 | D18: =E5/D5 -> 1.2018887 | E18: =F5/E5 -> 1.1150233 | F18: =G5/F5 -> 1.0734177 | G18: =H5/G5 -> 1.0559124 | H18: =I5/H5 -> 1.0439453
A19: 2018 | B19: =C6/B6 -> 1.8575431 | C19: =D6/C6 -> 1.3421382 | D19: =E6/D6 -> 1.217114 | E19: =F6/E6 -> 1.1037419 | F19: =G6/F6 -> 1.0700131 | G19: =H6/G6 -> 1.0570967
A20: 2019 | B20: =C7/B7 -> 1.8189613 | C20: =D7/C7 -> 1.3264974 | D20: =E7/D7 -> 1.1831936 | E20: =F7/E7 -> 1.1098202 | F20: =G7/F7 -> 1.0756549
A21: 2020 | B21: =C8/B8 -> 1.8262899 | C21: =D8/C8 -> 1.3690503 | D21: =E8/D8 -> 1.1979227 | E21: =F8/E8 -> 1.1076585
A22: 2021 | B22: =C9/B9 -> 1.851305 | C22: =D9/C9 -> 1.3143723 | D22: =E9/D9 -> 1.1959547
A23: 2022 | B23: =C10/B10 -> 1.7843466 | C23: =D10/C10 -> 1.3431188
A24: 2023 | B24: =C11/B11 -> 1.766995
A25: 2024
A27: Averages
A28: Metric | B28: 12-24 | C28: 24-36 | D28: 36-48 | E28: 48-60 | F28: 60-72 | G28: 72-84 | H28: 84-96 | I28: 96-108 | J28: 108-120 | K28: Tail
A29: simple_all | B29: =IFERROR(AVERAGE(B16:B24),AVERAGE(B16:B24)) -> 1.8108154 | C29: =IFERROR(AVERAGE(C16:C24),AVERAGE(C16:C24)) -> 1.3341665 | D29: =IFERROR(AVERAGE(D16:D24),AVERAGE(D16:D24)) -> 1.2011264 | E29: =IFERROR(AVERAGE(E16:E24),AVERAGE(E16:E24)) -> 1.1126679 | F29: =IFERROR(AVERAGE(F16:F24),AVERAGE(F16:F24)) -> 1.0734561 | G29: =IFERROR(AVERAGE(G16:G24),AVERAGE(G16:G24)) -> 1.0586188 | H29: =IFERROR(AVERAGE(H16:H24),AVERAGE(H16:H24)) -> 1.0424451 | I29: =IFERROR(AVERAGE(I16:I24),AVERAGE(I16:I24)) -> 1.0330882 | J29: =IFERROR(AVERAGE(J16:J24),AVERAGE(J16:J24)) -> 1.0202076
A30: weighted_all | B30: =IFERROR(SUMPRODUCT(B16:B24,B3:B11)/SUMPRODUCT((B16:B24<>"")*B3:B11),SUMPRODUCT(B16:B24,B3:B11)/SUMPRODUCT((B16:B24<>"")*B3:B11)) -> 1.8093424 | C30: =IFERROR(SUMPRODUCT(C16:C24,C3:C11)/SUMPRODUCT((C16:C24<>"")*C3:C11),SUMPRODUCT(C16:C24,C3:C11)/SUMPRODUCT((C16:C24<>"")*C3:C11)) -> 1.3320459 | D30: =IFERROR(SUMPRODUCT(D16:D24,D3:D11)/SUMPRODUCT((D16:D24<>"")*D3:D11),SUMPRODUCT(D16:D24,D3:D11)/SUMPRODUCT((D16:D24<>"")*D3:D11)) -> 1.2015277 | E30: =IFERROR(SUMPRODUCT(E16:E24,E3:E11)/SUMPRODUCT((E16:E24<>"")*E3:E11),SUMPRODUCT(E16:E24,E3:E11)/SUMPRODUCT((E16:E24<>"")*E3:E11)) -> 1.1128415 | F30: =IFERROR(SUMPRODUCT(F16:F24,F3:F11)/SUMPRODUCT((F16:F24<>"")*F3:F11),SUMPRODUCT(F16:F24,F3:F11)/SUMPRODUCT((F16:F24<>"")*F3:F11)) -> 1.0732888 | G30: =IFERROR(SUMPRODUCT(G16:G24,G3:G11)/SUMPRODUCT((G16:G24<>"")*G3:G11),SUMPRODUCT(G16:G24,G3:G11)/SUMPRODUCT((G16:G24<>"")*G3:G11)) -> 1.0587325 | H30: =IFERROR(SUMPRODUCT(H16:H24,H3:H11)/SUMPRODUCT((H16:H24<>"")*H3:H11),SUMPRODUCT(H16:H24,H3:H11)/SUMPRODUCT((H16:H24<>"")*H3:H11)) -> 1.042405 | I30: =IFERROR(SUMPRODUCT(I16:I24,I3:I11)/SUMPRODUCT((I16:I24<>"")*I3:I11),SUMPRODUCT(I16:I24,I3:I11)/SUMPRODUCT((I16:I24<>"")*I3:I11)) -> 1.0331637 | J30: =IFERROR(SUMPRODUCT(J16:J24,J3:J11)/SUMPRODUCT((J16:J24<>"")*J3:J11),SUMPRODUCT(J16:J24,J3:J11)/SUMPRODUCT((J16:J24<>"")*J3:J11)) -> 1.0202076
A31: exclude_high_low_all | B31: =IFERROR(TRIMMEAN(B16:B24,2/COUNT(B16:B24)),AVERAGE(B16:B24)) -> 1.8116787 | C31: =IFERROR(TRIMMEAN(C16:C24,2/COUNT(C16:C24)),AVERAGE(C16:C24)) -> 1.3335856 | D31: =IFERROR(TRIMMEAN(D16:D24,2/COUNT(D16:D24)),AVERAGE(D16:D24)) -> 1.2015155 | E31: =IFERROR(TRIMMEAN(E16:E24,2/COUNT(E16:E24)),AVERAGE(E16:E24)) -> 1.1113266 | F31: =IFERROR(TRIMMEAN(F16:F24,2/COUNT(F16:F24)),AVERAGE(F16:F24)) -> 1.0738709 | G31: =IFERROR(TRIMMEAN(G16:G24,2/COUNT(G16:G24)),AVERAGE(G16:G24)) -> 1.0586892 | H31: =IFERROR(TRIMMEAN(H16:H24,2/COUNT(H16:H24)),AVERAGE(H16:H24)) -> 1.0428262 | I31: =IFERROR(TRIMMEAN(I16:I24,2/COUNT(I16:I24)),AVERAGE(I16:I24)) -> 1.0330882 | J31: =IFERROR(TRIMMEAN(J16:J24,2/COUNT(J16:J24)),AVERAGE(J16:J24)) -> 1.0202076
A32: simple_3yr | B32: =IFERROR(AVERAGE(B22:B24),AVERAGE(B16:B24)) -> 1.8008822 | C32: =IFERROR(AVERAGE(C22:C24),AVERAGE(C16:C24)) -> 1.3287456 | D32: =IFERROR(AVERAGE(D22:D24),AVERAGE(D16:D24)) -> 1.1959547 | E32: =IFERROR(AVERAGE(E22:E24),AVERAGE(E16:E24)) -> 1.1126679 | F32: =IFERROR(AVERAGE(F22:F24),AVERAGE(F16:F24)) -> 1.0734561 | G32: =IFERROR(AVERAGE(G22:G24),AVERAGE(G16:G24)) -> 1.0586188 | H32: =IFERROR(AVERAGE(H22:H24),AVERAGE(H16:H24)) -> 1.0424451 | I32: =IFERROR(AVERAGE(I22:I24),AVERAGE(I16:I24)) -> 1.0330882 | J32: =IFERROR(AVERAGE(J22:J24),AVERAGE(J16:J24)) -> 1.0202076
A33: weighted_3yr | B33: =IFERROR(SUMPRODUCT(B22:B24,B9:B11)/SUMPRODUCT((B22:B24<>"")*B9:B11),SUMPRODUCT(B16:B24,B3:B11)/SUMPRODUCT((B16:B24<>"")*B3:B11)) -> 1.8094108 | C33: =IFERROR(SUMPRODUCT(C22:C24,C9:C11)/SUMPRODUCT((C22:C24<>"")*C9:C11),SUMPRODUCT(C16:C24,C3:C11)/SUMPRODUCT((C16:C24<>"")*C3:C11)) -> 1.3248453 | D33: =IFERROR(SUMPRODUCT(D22:D24,D9:D11)/SUMPRODUCT((D22:D24<>"")*D9:D11),SUMPRODUCT(D16:D24,D3:D11)/SUMPRODUCT((D16:D24<>"")*D3:D11)) -> 1.1959547 | E33: =IFERROR(SUMPRODUCT(E22:E24,E9:E11)/SUMPRODUCT((E22:E24<>"")*E9:E11),SUMPRODUCT(E16:E24,E3:E11)/SUMPRODUCT((E16:E24<>"")*E3:E11)) -> 1.1128415 | F33: =IFERROR(SUMPRODUCT(F22:F24,F9:F11)/SUMPRODUCT((F22:F24<>"")*F9:F11),SUMPRODUCT(F16:F24,F3:F11)/SUMPRODUCT((F16:F24<>"")*F3:F11)) -> 1.0732888 | G33: =IFERROR(SUMPRODUCT(G22:G24,G9:G11)/SUMPRODUCT((G22:G24<>"")*G9:G11),SUMPRODUCT(G16:G24,G3:G11)/SUMPRODUCT((G16:G24<>"")*G3:G11)) -> 1.0587325 | H33: =IFERROR(SUMPRODUCT(H22:H24,H9:H11)/SUMPRODUCT((H22:H24<>"")*H9:H11),SUMPRODUCT(H16:H24,H3:H11)/SUMPRODUCT((H16:H24<>"")*H3:H11)) -> 1.042405 | I33: =IFERROR(SUMPRODUCT(I22:I24,I9:I11)/SUMPRODUCT((I22:I24<>"")*I9:I11),SUMPRODUCT(I16:I24,I3:I11)/SUMPRODUCT((I16:I24<>"")*I3:I11)) -> 1.0331637 | J33: =IFERROR(SUMPRODUCT(J22:J24,J9:J11)/SUMPRODUCT((J22:J24<>"")*J9:J11),SUMPRODUCT(J16:J24,J3:J11)/SUMPRODUCT((J16:J24<>"")*J3:J11)) -> 1.0202076
A34: exclude_high_low_3yr | B34: =IFERROR(TRIMMEAN(B22:B24,2/COUNT(B22:B24)),AVERAGE(B16:B24)) -> 1.7843466 | C34: =IFERROR(TRIMMEAN(C22:C24,2/COUNT(C22:C24)),AVERAGE(C16:C24)) -> 1.3341665 | D34: =IFERROR(TRIMMEAN(D22:D24,2/COUNT(D22:D24)),AVERAGE(D16:D24)) -> 1.2011264 | E34: =IFERROR(TRIMMEAN(E22:E24,2/COUNT(E22:E24)),AVERAGE(E16:E24)) -> 1.1126679 | F34: =IFERROR(TRIMMEAN(F22:F24,2/COUNT(F22:F24)),AVERAGE(F16:F24)) -> 1.0734561 | G34: =IFERROR(TRIMMEAN(G22:G24,2/COUNT(G22:G24)),AVERAGE(G16:G24)) -> 1.0586188 | H34: =IFERROR(TRIMMEAN(H22:H24,2/COUNT(H22:H24)),AVERAGE(H16:H24)) -> 1.0424451 | I34: =IFERROR(TRIMMEAN(I22:I24,2/COUNT(I22:I24)),AVERAGE(I16:I24)) -> 1.0330882 | J34: =IFERROR(TRIMMEAN(J22:J24,2/COUNT(J22:J24)),AVERAGE(J16:J24)) -> 1.0202076
A35: simple_5yr | B35: =IFERROR(AVERAGE(B20:B24),AVERAGE(B16:B24)) -> 1.8095796 | C35: =IFERROR(AVERAGE(C20:C24),AVERAGE(C16:C24)) -> 1.3382597 | D35: =IFERROR(AVERAGE(D20:D24),AVERAGE(D16:D24)) -> 1.192357 | E35: =IFERROR(AVERAGE(E20:E24),AVERAGE(E16:E24)) -> 1.1087393 | F35: =IFERROR(AVERAGE(F20:F24),AVERAGE(F16:F24)) -> 1.0756549 | G35: =IFERROR(AVERAGE(G20:G24),AVERAGE(G16:G24)) -> 1.0586188 | H35: =IFERROR(AVERAGE(H20:H24),AVERAGE(H16:H24)) -> 1.0424451 | I35: =IFERROR(AVERAGE(I20:I24),AVERAGE(I16:I24)) -> 1.0330882 | J35: =IFERROR(AVERAGE(J20:J24),AVERAGE(J16:J24)) -> 1.0202076
A36: weighted_5yr | B36: =IFERROR(SUMPRODUCT(B20:B24,B7:B11)/SUMPRODUCT((B20:B24<>"")*B7:B11),SUMPRODUCT(B16:B24,B3:B11)/SUMPRODUCT((B16:B24<>"")*B3:B11)) -> 1.8139056 | C36: =IFERROR(SUMPRODUCT(C20:C24,C7:C11)/SUMPRODUCT((C20:C24<>"")*C7:C11),SUMPRODUCT(C16:C24,C3:C11)/SUMPRODUCT((C16:C24<>"")*C3:C11)) -> 1.3340655 | D36: =IFERROR(SUMPRODUCT(D20:D24,D7:D11)/SUMPRODUCT((D20:D24<>"")*D7:D11),SUMPRODUCT(D16:D24,D3:D11)/SUMPRODUCT((D16:D24<>"")*D3:D11)) -> 1.1928581 | E36: =IFERROR(SUMPRODUCT(E20:E24,E7:E11)/SUMPRODUCT((E20:E24<>"")*E7:E11),SUMPRODUCT(E16:E24,E3:E11)/SUMPRODUCT((E16:E24<>"")*E3:E11)) -> 1.1087772 | F36: =IFERROR(SUMPRODUCT(F20:F24,F7:F11)/SUMPRODUCT((F20:F24<>"")*F7:F11),SUMPRODUCT(F16:F24,F3:F11)/SUMPRODUCT((F16:F24<>"")*F3:F11)) -> 1.0756549 | G36: =IFERROR(SUMPRODUCT(G20:G24,G7:G11)/SUMPRODUCT((G20:G24<>"")*G7:G11),SUMPRODUCT(G16:G24,G3:G11)/SUMPRODUCT((G16:G24<>"")*G3:G11)) -> 1.0587325 | H36: =IFERROR(SUMPRODUCT(H20:H24,H7:H11)/SUMPRODUCT((H20:H24<>"")*H7:H11),SUMPRODUCT(H16:H24,H3:H11)/SUMPRODUCT((H16:H24<>"")*H3:H11)) -> 1.042405 | I36: =IFERROR(SUMPRODUCT(I20:I24,I7:I11)/SUMPRODUCT((I20:I24<>"")*I7:I11),SUMPRODUCT(I16:I24,I3:I11)/SUMPRODUCT((I16:I24<>"")*I3:I11)) -> 1.0331637 | J36: =IFERROR(SUMPRODUCT(J20:J24,J7:J11)/SUMPRODUCT((J20:J24<>"")*J7:J11),SUMPRODUCT(J16:J24,J3:J11)/SUMPRODUCT((J16:J24<>"")*J3:J11)) -> 1.0202076
A37: exclude_high_low_5yr | B37: =IFERROR(TRIMMEAN(B20:B24,2/COUNT(B20:B24)),AVERAGE(B16:B24)) -> 1.8098659 | C37: =IFERROR(TRIMMEAN(C20:C24,2/COUNT(C20:C24)),AVERAGE(C16:C24)) -> 1.3348081 | D37: =IFERROR(TRIMMEAN(D20:D24,2/COUNT(D20:D24)),AVERAGE(D16:D24)) -> 1.1959547 | E37: =IFERROR(TRIMMEAN(E20:E24,2/COUNT(E20:E24)),AVERAGE(E16:E24)) -> 1.1126679 | F37: =IFERROR(TRIMMEAN(F20:F24,2/COUNT(F20:F24)),AVERAGE(F16:F24)) -> 1.0734561 | G37: =IFERROR(TRIMMEAN(G20:G24,2/COUNT(G20:G24)),AVERAGE(G16:G24)) -> 1.0586188 | H37: =IFERROR(TRIMMEAN(H20:H24,2/COUNT(H20:H24)),AVERAGE(H16:H24)) -> 1.0424451 | I37: =IFERROR(TRIMMEAN(I20:I24,2/COUNT(I20:I24)),AVERAGE(I16:I24)) -> 1.0330882 | J37: =IFERROR(TRIMMEAN(J20:J24,2/COUNT(J20:J24)),AVERAGE(J16:J24)) -> 1.0202076
A38: simple_10yr | B38: =IFERROR(AVERAGE(B16:B24),AVERAGE(B16:B24)) -> 1.8108154 | C38: =IFERROR(AVERAGE(C16:C24),AVERAGE(C16:C24)) -> 1.3341665 | D38: =IFERROR(AVERAGE(D16:D24),AVERAGE(D16:D24)) -> 1.2011264 | E38: =IFERROR(AVERAGE(E16:E24),AVERAGE(E16:E24)) -> 1.1126679 | F38: =IFERROR(AVERAGE(F16:F24),AVERAGE(F16:F24)) -> 1.0734561 | G38: =IFERROR(AVERAGE(G16:G24),AVERAGE(G16:G24)) -> 1.0586188 | H38: =IFERROR(AVERAGE(H16:H24),AVERAGE(H16:H24)) -> 1.0424451 | I38: =IFERROR(AVERAGE(I16:I24),AVERAGE(I16:I24)) -> 1.0330882 | J38: =IFERROR(AVERAGE(J16:J24),AVERAGE(J16:J24)) -> 1.0202076
A39: weighted_10yr | B39: =IFERROR(SUMPRODUCT(B16:B24,B3:B11)/SUMPRODUCT((B16:B24<>"")*B3:B11),SUMPRODUCT(B16:B24,B3:B11)/SUMPRODUCT((B16:B24<>"")*B3:B11)) -> 1.8093424 | C39: =IFERROR(SUMPRODUCT(C16:C24,C3:C11)/SUMPRODUCT((C16:C24<>"")*C3:C11),SUMPRODUCT(C16:C24,C3:C11)/SUMPRODUCT((C16:C24<>"")*C3:C11)) -> 1.3320459 | D39: =IFERROR(SUMPRODUCT(D16:D24,D3:D11)/SUMPRODUCT((D16:D24<>"")*D3:D11),SUMPRODUCT(D16:D24,D3:D11)/SUMPRODUCT((D16:D24<>"")*D3:D11)) -> 1.2015277 | E39: =IFERROR(SUMPRODUCT(E16:E24,E3:E11)/SUMPRODUCT((E16:E24<>"")*E3:E11),SUMPRODUCT(E16:E24,E3:E11)/SUMPRODUCT((E16:E24<>"")*E3:E11)) -> 1.1128415 | F39: =IFERROR(SUMPRODUCT(F16:F24,F3:F11)/SUMPRODUCT((F16:F24<>"")*F3:F11),SUMPRODUCT(F16:F24,F3:F11)/SUMPRODUCT((F16:F24<>"")*F3:F11)) -> 1.0732888 | G39: =IFERROR(SUMPRODUCT(G16:G24,G3:G11)/SUMPRODUCT((G16:G24<>"")*G3:G11),SUMPRODUCT(G16:G24,G3:G11)/SUMPRODUCT((G16:G24<>"")*G3:G11)) -> 1.0587325 | H39: =IFERROR(SUMPRODUCT(H16:H24,H3:H11)/SUMPRODUCT((H16:H24<>"")*H3:H11),SUMPRODUCT(H16:H24,H3:H11)/SUMPRODUCT((H16:H24<>"")*H3:H11)) -> 1.042405 | I39: =IFERROR(SUMPRODUCT(I16:I24,I3:I11)/SUMPRODUCT((I16:I24<>"")*I3:I11),SUMPRODUCT(I16:I24,I3:I11)/SUMPRODUCT((I16:I24<>"")*I3:I11)) -> 1.0331637 | J39: =IFERROR(SUMPRODUCT(J16:J24,J3:J11)/SUMPRODUCT((J16:J24<>"")*J3:J11),SUMPRODUCT(J16:J24,J3:J11)/SUMPRODUCT((J16:J24<>"")*J3:J11)) -> 1.0202076
A40: exclude_high_low_10yr | B40: =IFERROR(TRIMMEAN(B16:B24,2/COUNT(B16:B24)),AVERAGE(B16:B24)) -> 1.8116787 | C40: =IFERROR(TRIMMEAN(C16:C24,2/COUNT(C16:C24)),AVERAGE(C16:C24)) -> 1.3335856 | D40: =IFERROR(TRIMMEAN(D16:D24,2/COUNT(D16:D24)),AVERAGE(D16:D24)) -> 1.2015155 | E40: =IFERROR(TRIMMEAN(E16:E24,2/COUNT(E16:E24)),AVERAGE(E16:E24)) -> 1.1113266 | F40: =IFERROR(TRIMMEAN(F16:F24,2/COUNT(F16:F24)),AVERAGE(F16:F24)) -> 1.0738709 | G40: =IFERROR(TRIMMEAN(G16:G24,2/COUNT(G16:G24)),AVERAGE(G16:G24)) -> 1.0586892 | H40: =IFERROR(TRIMMEAN(H16:H24,2/COUNT(H16:H24)),AVERAGE(H16:H24)) -> 1.0428262 | I40: =IFERROR(TRIMMEAN(I16:I24,2/COUNT(I16:I24)),AVERAGE(I16:I24)) -> 1.0330882 | J40: =IFERROR(TRIMMEAN(J16:J24,2/COUNT(J16:J24)),AVERAGE(J16:J24)) -> 1.0202076
A42: LDF Selections
B43: 12-24 | C43: 24-36 | D43: 36-48 | E43: 48-60 | F43: 60-72 | G43: 72-84 | H43: 84-96 | I43: 96-108 | J43: 108-120 | K43: Tail
...

Sheet CL - Paid Loss
A1: Paid Loss
B2: 12 | C2: 24 | D2: 36 | E2: 48 | F2: 60 | G2: 72 | H2: 84 | I2: 96 | J2: 108 | K2: 120
A3: 2015 | B3: 9247456.8 | C3: 16887332 | D3: 23000569 | E3: 27802346 | F3: 31644816 | G3: 35019498 | H3: 38226729 | I3: 40633313 | J3: 43136150 | K3: 45008438
A4: 2016 | B4: 12224784 | C4: 23009583 | D4: 31462134 | E4: 38324866 | F4: 44020226 | G4: 48826740 | H4: 52977180 | I4: 56150431 | J4: 59267698
A5: 2017 | B5: 7651942.9 | C5: 14311316 | D5: 19921864 | E5: 24002301 | F5: 27560045 | G5: 30585360 | H5: 33007873 | I5: 34907742
A6: 2018 | B6: 12066429 | C6: 22556336 | D6: 31035722 | E6: 37766431 | F6: 43524051 | G6: 48248010 | H6: 52422360
A7: 2019 | B7: 10064765 | C7: 18121547 | D7: 24840287 | E7: 29715357 | F7: 34177568 | G7: 37924648
A8: 2020 | B8: 8963797.6 | C8: 15917604 | D8: 22113680 | E8: 26981141 | F8: 30760500
A9: 2021 | B9: 15964354 | C9: 28485180 | D9: 38015719 | E9: 46187015
A10: 2022 | B10: 8984185.1 | C10: 16619562 | D10: 23102957
A11: 2023 | B11: 9774276.1 | C11: 17919594
A12: 2024 | B12: 13261356
A14: Age-to-Age Factors
B15: 12-24 | C15: 24-36 | D15: 36-48 | E15: 48-60 | F15: 60-72 | G15: 72-84 | H15: 84-96 | I15: 96-108 | J15: 108-120
A16: 2015 | B16: =C3/B3 -> 1.8261596 | C16: =D3/C3 -> 1.3620013 | D16: =E3/D3 -> 1.2087678 | E16: =F3/E3 -> 1.1382067 | F16: =G3/F3 -> 1.1066425 | G16: =H3/G3 -> 1.0915841 | H16: =I3/H3 -> 1.0629555 | I16: =J3/I3 -> 1.0615957 | J16: =K3/J3 -> 1.0434041
A17: 2016 | B17: =C4/B4 -> 1.8822078 | C17: =D4/C4 -> 1.3673491 | D17: =E4/D4 -> 1.2181267 | E17: =F4/E4 -> 1.1486074 | F17: =G4/F4 -> 1.1091888 | G17: =H4/G4 -> 1.0850034 | H17: =I4/H4 -> 1.0598984 | I17: =J4/I4 -> 1.0555164
A18: 2017 | B18: =C5/B5 -> 1.8702852 | C18: =D5/C5 -> 1.3920358 | D18: =E5/D5 -> 1.204822 | E18: =F5/E5 -> 1.1482251 | F18: =G5/F5 -> 1.1097718 | G18: =H5/G5 -> 1.079205 | H18: =I5/H5 -> 1.0575581
A19: 2018 | B19: =C6/B6 -> 1.8693464 | C19: =D6/C6 -> 1.3759204 | D19: =E6/D6 -> 1.2168697 | E19: =F6/E6 -> 1.1524534 | F19: =G6/F6 -> 1.1085367 | G19: =H6/G6 -> 1.0865186
A20: 2019 | B20: =C7/B7 -> 1.8004939 | C20: =D7/C7 -> 1.3707597 | D20: =E7/D7 -> 1.1962566 | E20: =F7/E7 -> 1.1501651 | F20: =G7/F7 -> 1.1096357
A21: 2020 | B21: =C8/B8 -> 1.7757657 | C21: =D8/C8 -> 1.3892593 | D21: =E8/D8 -> 1.2201108 | E21: =F8/E8 -> 1.1400741
A22: 2021 | B22: =C9/B9 -> 1.7842989 | C22: =D9/C9 -> 1.3345788 | D22: =E9/D9 -> 1.2149452
A23: 2022 | B23: =C10/B10 -> 1.8498686 | C23: =D10/C10 -> 1.3901063
A24: 2023 | B24: =C11/B11 -> 1.8333423
A25: 2024
A27: Averages
A28: Metric | B28: 12-24 | C28: 24-36 | D28: 36-48 | E28: 48-60 | F28: 60-72 | G28: 72-84 | H28: 84-96 | I28: 96-108 | J28: 108-120 | K28: Tail
A29: simple_all | B29: =IFERROR(AVERAGE(B16:B24),AVERAGE(B16:B24)) -> 1.8324187 | C29: =IFERROR(AVERAGE(C16:C24),AVERAGE(C16:C24)) -> 1.3727513 | D29: =IFERROR(AVERAGE(D16:D24),AVERAGE(D16:D24)) -> 1.2114141 | E29: =IFERROR(AVERAGE(E16:E24),AVERAGE(E16:E24)) -> 1.1462886 | F29: =IFERROR(AVERAGE(F16:F24),AVERAGE(F16:F24)) -> 1.1087551 | G29: =IFERROR(AVERAGE(G16:G24),AVERAGE(G16:G24)) -> 1.0855778 | H29: =IFERROR(AVERAGE(H16:H24),AVERAGE(H16:H24)) -> 1.0601374 | I29: =IFERROR(AVERAGE(I16:I24),AVERAGE(I16:I24)) -> 1.058556 | J29: =IFERROR(AVERAGE(J16:J24),AVERAGE(J16:J24)) -> 1.0434041
A30: weighted_all | B30: =IFERROR(SUMPRODUCT(B16:B24,B3:B11)/SUMPRODUCT((B16:B24<>"")*B3:B11),SUMPRODUCT(B16:B24,B3:B11)/SUMPRODUCT((B16:B24<>"")*B3:B11)) -> 1.830887 | C30: =IFERROR(SUMPRODUCT(C16:C24,C3:C11)/SUMPRODUCT((C16:C24<>"")*C3:C11),SUMPRODUCT(C16:C24,C3:C11)/SUMPRODUCT((C16:C24<>"")*C3:C11)) -> 1.369348 | D30: =IFERROR(SUMPRODUCT(D16:D24,D3:D11)/SUMPRODUCT((D16:D24<>"")*D3:D11),SUMPRODUCT(D16:D24,D3:D11)/SUMPRODUCT((D16:D24<>"")*D3:D11)) -> 1.2121408 | E30: =IFERROR(SUMPRODUCT(E16:E24,E3:E11)/SUMPRODUCT((E16:E24<>"")*E3:E11),SUMPRODUCT(E16:E24,E3:E11)/SUMPRODUCT((E16:E24<>"")*E3:E11)) -> 1.1467816 | F30: =IFERROR(SUMPRODUCT(F16:F24,F3:F11)/SUMPRODUCT((F16:F24<>"")*F3:F11),SUMPRODUCT(F16:F24,F3:F11)/SUMPRODUCT((F16:F24<>"")*F3:F11)) -> 1.1087598 | G30: =IFERROR(SUMPRODUCT(G16:G24,G3:G11)/SUMPRODUCT((G16:G24<>"")*G3:G11),SUMPRODUCT(G16:G24,G3:G11)/SUMPRODUCT((G16:G24<>"")*G3:G11)) -> 1.0857792 | H30: =IFERROR(SUMPRODUCT(H16:H24,H3:H11)/SUMPRODUCT((H16:H24<>"")*H3:H11),SUMPRODUCT(H16:H24,H3:H11)/SUMPRODUCT((H16:H24<>"")*H3:H11)) -> 1.0602173 | I30: =IFERROR(SUMPRODUCT(I16:I24,I3:I11)/SUMPRODUCT((I16:I24<>"")*I3:I11),SUMPRODUCT(I16:I24,I3:I11)/SUMPRODUCT((I16:I24<>"")*I3:I11)) -> 1.0580687 | J30: =IFERROR(SUMPRODUCT(J16:J24,J3:J11)/SUMPRODUCT((J16:J24<>"")*J3:J11),SUMPRODUCT(J16:J24,J3:J11)/SUMPRODUCT((J16:J24<>"")*J3:J11)) -> 1.0434041
A31: exclude_high_low_all | B31: =IFERROR(TRIMMEAN(B16:B24,2/COUNT(B16:B24)),AVERAGE(B16:B24)) -> 1.8333993 | C31: =IFERROR(TRIMMEAN(C16:C24,2/COUNT(C16:C24)),AVERAGE(C16:C24)) -> 1.3758993 | D31: =IFERROR(TRIMMEAN(D16:D24,2/COUNT(D16:D24)),AVERAGE(D16:D24)) -> 1.2127063 | E31: =IFERROR(TRIMMEAN(E16:E24,2/COUNT(E16:E24)),AVERAGE(E16:E24)) -> 1.146768 | F31: =IFERROR(TRIMMEAN(F16:F24,2/COUNT(F16:F24)),AVERAGE(F16:F24)) -> 1.1091204 | G31: =IFERROR(TRIMMEAN(G16:G24,2/COUNT(G16:G24)),AVERAGE(G16:G24)) -> 1.085761 | H31: =IFERROR(TRIMMEAN(H16:H24,2/COUNT(H16:H24)),AVERAGE(H16:H24)) -> 1.0598984 | I31: =IFERROR(TRIMMEAN(I16:I24,2/COUNT(I16:I24)),AVERAGE(I16:I24)) -> 1.058556 | J31: =IFERROR(TRIMMEAN(J16:J24,2/COUNT(J16:J24)),AVERAGE(J16:J24)) -> 1.0434041
A32: simple_3yr | B32: =IFERROR(AVERAGE(B22:B24),AVERAGE(B16:B24)) -> 1.8225033 | C32: =IFERROR(AVERAGE(C22:C24),AVERAGE(C16:C24)) -> 1.3623426 | D32: =IFERROR(AVERAGE(D22:D24),AVERAGE(D16:D24)) -> 1.2149452 | E32: =IFERROR(AVERAGE(E22:E24),AVERAGE(E16:E24)) -> 1.1462886 | F32: =IFERROR(AVERAGE(F22:F24),AVERAGE(F16:F24)) -> 1.1087551 | G32: =IFERROR(AVERAGE(G22:G24),AVERAGE(G16:G24)) -> 1.0855778 | H32: =IFERROR(AVERAGE(H22:H24),AVERAGE(H16:H24)) -> 1.0601374 | I32: =IFERROR(AVERAGE(I22:I24),AVERAGE(I16:I24)) -> 1.058556 | J32: =IFERROR(AVERAGE(J22:J24),AVERAGE(J16:J24)) -> 1.0434041
A33: weighted_3yr | B33: =IFERROR(SUMPRODUCT(B22:B24,B9:B11)/SUMPRODUCT((B22:B24<>"")*B9:B11),SUMPRODUCT(B16:B24,B3:B11)/SUMPRODUCT((B16:B24<>"")*B3:B11)) -> 1.8150699 | C33: =IFERROR(SUMPRODUCT(C22:C24,C9:C11)/SUMPRODUCT((C22:C24<>"")*C9:C11),SUMPRODUCT(C16:C24,C3:C11)/SUMPRODUCT((C16:C24<>"")*C3:C11)) -> 1.3550388 | D33: =IFERROR(SUMPRODUCT(D22:D24,D9:D11)/SUMPRODUCT((D22:D24<>"")*D9:D11),SUMPRODUCT(D16:D24,D3:D11)/SUMPRODUCT((D16:D24<>"")*D3:D11)) -> 1.2149452 | E33: =IFERROR(SUMPRODUCT(E22:E24,E9:E11)/SUMPRODUCT((E22:E24<>"")*E9:E11),SUMPRODUCT(E16:E24,E3:E11)/SUMPRODUCT((E16:E24<>"")*E3:E11)) -> 1.1467816 | F33: =IFERROR(SUMPRODUCT(F22:F24,F9:F11)/SUMPRODUCT((F22:F24<>"")*F9:F11),SUMPRODUCT(F16:F24,F3:F11)/SUMPRODUCT((F16:F24<>"")*F3:F11)) -> 1.1087598 | G33: =IFERROR(SUMPRODUCT(G22:G24,G9:G11)/SUMPRODUCT((G22:G24<>"")*G9:G11),SUMPRODUCT(G16:G24,G3:G11)/SUMPRODUCT((G16:G24<>"")*G3:G11)) -> 1.0857792 | H33: =IFERROR(SUMPRODUCT(H22:H24,H9:H11)/SUMPRODUCT((H22:H24<>"")*H9:H11),SUMPRODUCT(H16:H24,H3:H11)/SUMPRODUCT((H16:H24<>"")*H3:H11)) -> 1.0602173 | I33: =IFERROR(SUMPRODUCT(I22:I24,I9:I11)/SUMPRODUCT((I22:I24<>"")*I9:I11),SUMPRODUCT(I16:I24,I3:I11)/SUMPRODUCT((I16:I24<>"")*I3:I11)) -> 1.0580687 | J33: =IFERROR(SUMPRODUCT(J22:J24,J9:J11)/SUMPRODUCT((J22:J24<>"")*J9:J11),SUMPRODUCT(J16:J24,J3:J11)/SUMPRODUCT((J16:J24<>"")*J3:J11)) -> 1.0434041
A34: exclude_high_low_3yr | B34: =IFERROR(TRIMMEAN(B22:B24,2/COUNT(B22:B24)),AVERAGE(B16:B24)) -> 1.8333423 | C34: =IFERROR(TRIMMEAN(C22:C24,2/COUNT(C22:C24)),AVERAGE(C16:C24)) -> 1.3727513 | D34: =IFERROR(TRIMMEAN(D22:D24,2/COUNT(D22:D24)),AVERAGE(D16:D24)) -> 1.2114141 | E34: =IFERROR(TRIMMEAN(E22:E24,2/COUNT(E22:E24)),AVERAGE(E16:E24)) -> 1.1462886 | F34: =IFERROR(TRIMMEAN(F22:F24,2/COUNT(F22:F24)),AVERAGE(F16:F24)) -> 1.1087551 | G34: =IFERROR(TRIMMEAN(G22:G24,2/COUNT(G22:G24)),AVERAGE(G16:G24)) -> 1.0855778 | H34: =IFERROR(TRIMMEAN(H22:H24,2/COUNT(H22:H24)),AVERAGE(H16:H24)) -> 1.0601374 | I34: =IFERROR(TRIMMEAN(I22:I24,2/COUNT(I22:I24)),AVERAGE(I16:I24)) -> 1.058556 | J34: =IFERROR(TRIMMEAN(J22:J24,2/COUNT(J22:J24)),AVERAGE(J16:J24)) -> 1.0434041
A35: simple_5yr | B35: =IFERROR(AVERAGE(B20:B24),AVERAGE(B16:B24)) -> 1.8087539 | C35: =IFERROR(AVERAGE(C20:C24),AVERAGE(C16:C24)) -> 1.371176 | D35: =IFERROR(AVERAGE(D20:D24),AVERAGE(D16:D24)) -> 1.2104375 | E35: =IFERROR(AVERAGE(E20:E24),AVERAGE(E16:E24)) -> 1.1451196 | F35: =IFERROR(AVERAGE(F20:F24),AVERAGE(F16:F24)) -> 1.1096357 | G35: =IFERROR(AVERAGE(G20:G24),AVERAGE(G16:G24)) -> 1.0855778 | H35: =IFERROR(AVERAGE(H20:H24),AVERAGE(H16:H24)) -> 1.0601374 | I35: =IFERROR(AVERAGE(I20:I24),AVERAGE(I16:I24)) -> 1.058556 | J35: =IFERROR(AVERAGE(J20:J24),AVERAGE(J16:J24)) -> 1.0434041
A36: weighted_5yr | B36: =IFERROR(SUMPRODUCT(B20:B24,B7:B11)/SUMPRODUCT((B20:B24<>"")*B7:B11),SUMPRODUCT(B16:B24,B3:B11)/SUMPRODUCT((B16:B24<>"")*B3:B11)) -> 1.805786 | C36: =IFERROR(SUMPRODUCT(C20:C24,C7:C11)/SUMPRODUCT((C20:C24<>"")*C7:C11),SUMPRODUCT(C16:C24,C3:C11)/SUMPRODUCT((C16:C24<>"")*C3:C11)) -> 1.3655209 | D36: =IFERROR(SUMPRODUCT(D20:D24,D7:D11)/SUMPRODUCT((D20:D24<>"")*D7:D11),SUMPRODUCT(D16:D24,D3:D11)/SUMPRODUCT((D16:D24<>"")*D3:D11)) -> 1.2108261 | E36: =IFERROR(SUMPRODUCT(E20:E24,E7:E11)/SUMPRODUCT((E20:E24<>"")*E7:E11),SUMPRODUCT(E16:E24,E3:E11)/SUMPRODUCT((E16:E24<>"")*E3:E11)) -> 1.1453629 | F36: =IFERROR(SUMPRODUCT(F20:F24,F7:F11)/SUMPRODUCT((F20:F24<>"")*F7:F11),SUMPRODUCT(F16:F24,F3:F11)/SUMPRODUCT((F16:F24<>"")*F3:F11)) -> 1.1096357 | G36: =IFERROR(SUMPRODUCT(G20:G24,G7:G11)/SUMPRODUCT((G20:G24<>"")*G7:G11),SUMPRODUCT(G16:G24,G3:G11)/SUMPRODUCT((G16:G24<>"")*G3:G11)) -> 1.0857792 | H36: =IFERROR(SUMPRODUCT(H20:H24,H7:H11)/SUMPRODUCT((H20:H24<>"")*H7:H11),SUMPRODUCT(H16:H24,H3:H11)/SUMPRODUCT((H16:H24<>"")*H3:H11)) -> 1.0602173 | I36: =IFERROR(SUMPRODUCT(I20:I24,I7:I11)/SUMPRODUCT((I20:I24<>"")*I7:I11),SUMPRODUCT(I16:I24,I3:I11)/SUMPRODUCT((I16:I24<>"")*I3:I11)) -> 1.0580687 | J36: =IFERROR(SUMPRODUCT(J20:J24,J7:J11)/SUMPRODUCT((J20:J24<>"")*J7:J11),SUMPRODUCT(J16:J24,J3:J11)/SUMPRODUCT((J16:J24<>"")*J3:J11)) -> 1.0434041
A37: exclude_high_low_5yr | B37: =IFERROR(TRIMMEAN(B20:B24,2/COUNT(B20:B24)),AVERAGE(B16:B24)) -> 1.806045 | C37: =IFERROR(TRIMMEAN(C20:C24,2/COUNT(C20:C24)),AVERAGE(C16:C24)) -> 1.3800095 | D37: =IFERROR(TRIMMEAN(D20:D24,2/COUNT(D20:D24)),AVERAGE(D16:D24)) -> 1.2149452 | E37: =IFERROR(TRIMMEAN(E20:E24,2/COUNT(E20:E24)),AVERAGE(E16:E24)) -> 1.1462886 | F37: =IFERROR(TRIMMEAN(F20:F24,2/COUNT(F20:F24)),AVERAGE(F16:F24)) -> 1.1087551 | G37: =IFERROR(TRIMMEAN(G20:G24,2/COUNT(G20:G24)),AVERAGE(G16:G24)) -> 1.0855778 | H37: =IFERROR(TRIMMEAN(H20:H24,2/COUNT(H20:H24)),AVERAGE(H16:H24)) -> 1.0601374 | I37: =IFERROR(TRIMMEAN(I20:I24,2/COUNT(I20:I24)),AVERAGE(I16:I24)) -> 1.058556 | J37: =IFERROR(TRIMMEAN(J20:J24,2/COUNT(J20:J24)),AVERAGE(J16:J24)) -> 1.0434041
A38: simple_10yr | B38: =IFERROR(AVERAGE(B16:B24),AVERAGE(B16:B24)) -> 1.8324187 | C38: =IFERROR(AVERAGE(C16:C24),AVERAGE(C16:C24)) -> 1.3727513 | D38: =IFERROR(AVERAGE(D16:D24),AVERAGE(D16:D24)) -> 1.2114141 | E38: =IFERROR(AVERAGE(E16:E24),AVERAGE(E16:E24)) -> 1.1462886 | F38: =IFERROR(AVERAGE(F16:F24),AVERAGE(F16:F24)) -> 1.1087551 | G38: =IFERROR(AVERAGE(G16:G24),AVERAGE(G16:G24)) -> 1.0855778 | H38: =IFERROR(AVERAGE(H16:H24),AVERAGE(H16:H24)) -> 1.0601374 | I38: =IFERROR(AVERAGE(I16:I24),AVERAGE(I16:I24)) -> 1.058556 | J38: =IFERROR(AVERAGE(J16:J24),AVERAGE(J16:J24)) -> 1.0434041
A39: weighted_10yr | B39: =IFERROR(SUMPRODUCT(B16:B24,B3:B11)/SUMPRODUCT((B16:B24<>"")*B3:B11),SUMPRODUCT(B16:B24,B3:B11)/SUMPRODUCT((B16:B24<>"")*B3:B11)) -> 1.830887 | C39: =IFERROR(SUMPRODUCT(C16:C24,C3:C11)/SUMPRODUCT((C16:C24<>"")*C3:C11),SUMPRODUCT(C16:C24,C3:C11)/SUMPRODUCT((C16:C24<>"")*C3:C11)) -> 1.369348 | D39: =IFERROR(SUMPRODUCT(D16:D24,D3:D11)/SUMPRODUCT((D16:D24<>"")*D3:D11),SUMPRODUCT(D16:D24,D3:D11)/SUMPRODUCT((D16:D24<>"")*D3:D11)) -> 1.2121408 | E39: =IFERROR(SUMPRODUCT(E16:E24,E3:E11)/SUMPRODUCT((E16:E24<>"")*E3:E11),SUMPRODUCT(E16:E24,E3:E11)/SUMPRODUCT((E16:E24<>"")*E3:E11)) -> 1.1467816 | F39: =IFERROR(SUMPRODUCT(F16:F24,F3:F11)/SUMPRODUCT((F16:F24<>"")*F3:F11),SUMPRODUCT(F16:F24,F3:F11)/SUMPRODUCT((F16:F24<>"")*F3:F11)) -> 1.1087598 | G39: =IFERROR(SUMPRODUCT(G16:G24,G3:G11)/SUMPRODUCT((G16:G24<>"")*G3:G11),SUMPRODUCT(G16:G24,G3:G11)/SUMPRODUCT((G16:G24<>"")*G3:G11)) -> 1.0857792 | H39: =IFERROR(SUMPRODUCT(H16:H24,H3:H11)/SUMPRODUCT((H16:H24<>"")*H3:H11),SUMPRODUCT(H16:H24,H3:H11)/SUMPRODUCT((H16:H24<>"")*H3:H11)) -> 1.0602173 | I39: =IFERROR(SUMPRODUCT(I16:I24,I3:I11)/SUMPRODUCT((I16:I24<>"")*I3:I11),SUMPRODUCT(I16:I24,I3:I11)/SUMPRODUCT((I16:I24<>"")*I3:I11)) -> 1.0580687 | J39: =IFERROR(SUMPRODUCT(J16:J24,J3:J11)/SUMPRODUCT((J16:J24<>"")*J3:J11),SUMPRODUCT(J16:J24,J3:J11)/SUMPRODUCT((J16:J24<>"")*J3:J11)) -> 1.0434041
A40: exclude_high_low_10yr | B40: =IFERROR(TRIMMEAN(B16:B24,2/COUNT(B16:B24)),AVERAGE(B16:B24)) -> 1.8333993 | C40: =IFERROR(TRIMMEAN(C16:C24,2/COUNT(C16:C24)),AVERAGE(C16:C24)) -> 1.3758993 | D40: =IFERROR(TRIMMEAN(D16:D24,2/COUNT(D16:D24)),AVERAGE(D16:D24)) -> 1.2127063 | E40: =IFERROR(TRIMMEAN(E16:E24,2/COUNT(E16:E24)),AVERAGE(E16:E24)) -> 1.146768 | F40: =IFERROR(TRIMMEAN(F16:F24,2/COUNT(F16:F24)),AVERAGE(F16:F24)) -> 1.1091204 | G40: =IFERROR(TRIMMEAN(G16:G24,2/COUNT(G16:G24)),AVERAGE(G16:G24)) -> 1.085761 | H40: =IFERROR(TRIMMEAN(H16:H24,2/COUNT(H16:H24)),AVERAGE(H16:H24)) -> 1.0598984 | I40: =IFERROR(TRIMMEAN(I16:I24,2/COUNT(I16:I24)),AVERAGE(I16:I24)) -> 1.058556 | J40: =IFERROR(TRIMMEAN(J16:J24,2/COUNT(J16:J24)),AVERAGE(J16:J24)) -> 1.0434041
A42: LDF Selections
B43: 12-24 | C43: 24-36 | D43: 36-48 | E43: 48-60 | F43: 60-72 | G43: 72-84 | H43: 84-96 | I43: 96-108 | J43: 108-120 | K43: Tail
...

Sheet CL - Reported Count
A1: Reported Count
B2: 12 | C2: 24 | D2: 36 | E2: 48 | F2: 60 | G2: 72 | H2: 84 | I2: 96 | J2: 108 | K2: 120
A3: 2015 | B3: 1638 | C3: 2677 | D3: 3472 | E3: 4077 | F3: 4526 | G3: 4730 | H3: 4831 | I3: 4883 | J3: 4930 | K3: 4930
A4: 2016 | B4: 1636 | C4: 2723 | D4: 3474 | E4: 4156 | F4: 4555 | G4: 4743 | H4: 4846 | I4: 4894 | J4: 4943
A5: 2017 | B5: 1624 | C5: 2682 | D5: 3477 | E5: 4114 | F5: 4516 | G5: 4713 | H5: 4812 | I5: 4864
A6: 2018 | B6: 1697 | C6: 2736 | D6: 3560 | E6: 4204 | F6: 4592 | G6: 4773 | H6: 4886
A7: 2019 | B7: 1559 | C7: 2687 | D7: 3545 | E7: 4166 | F7: 4570 | G7: 4767
A8: 2020 | B8: 1624 | C8: 2750 | D8: 3494 | E8: 4155 | F8: 4597
A9: 2021 | B9: 1636 | C9: 2748 | D9: 3579 | E9: 4301
A10: 2022 | B10: 1720 | C10: 2783 | D10: 3568
A11: 2023 | B11: 1568 | C11: 2665
A12: 2024 | B12: 1712
A14: Age-to-Age Factors
B15: 12-24 | C15: 24-36 | D15: 36-48 | E15: 48-60 | F15: 60-72 | G15: 72-84 | H15: 84-96 | I15: 96-108 | J15: 108-120
A16: 2015 | B16: =C3/B3 -> 1.6343101 | C16: =D3/C3 -> 1.2969742 | D16: =E3/D3 -> 1.1742512 | E16: =F3/E3 -> 1.11013 | F16: =G3/F3 -> 1.0450729 | G16: =H3/G3 -> 1.0213531 | H16: =I3/H3 -> 1.0107638 | I16: =J3/I3 -> 1.0096252 | J16: =K3/J3 -> 1
A17: 2016 | B17: =C4/B4 -> 1.6644254 | C17: =D4/C4 -> 1.2757988 | D17: =E4/D4 -> 1.1963155 | E17: =F4/E4 -> 1.0960058 | F17: =G4/F4 -> 1.0412733 | G17: =H4/G4 -> 1.0217162 | H17: =I4/H4 -> 1.0099051 | I17: =J4/I4 -> 1.0100123
A18: 2017 | B18: =C5/B5 -> 1.6514778 | C18: =D5/C5 -> 1.2964206 | D18: =E5/D5 -> 1.1832039 | E18: =F5/E5 -> 1.0977151 | F18: =G5/F5 -> 1.0436227 | G18: =H5/G5 -> 1.0210057 | H18: =I5/H5 -> 1.0108063
A19: 2018 | B19: =C6/B6 -> 1.6122569 | C19: =D6/C6 -> 1.3011696 | D19: =E6/D6 -> 1.1808989 | E19: =F6/E6 -> 1.0922931 | F19: =G6/F6 -> 1.0394164 | G19: =H6/G6 -> 1.0236748
A20: 2019 | B20: =C7/B7 -> 1.7235407 | C20: =D7/C7 -> 1.3193152 | D20: =E7/D7 -> 1.1751763 | E20: =F7/E7 -> 1.0969755 | F20: =G7/F7 -> 1.0431072
A21: 2020 | B21: =C8/B8 -> 1.6933498 | C21: =D8/C8 -> 1.2705455 | D21: =E8/D8 -> 1.1891815 | E21: =F8/E8 -> 1.1063779
A22: 2021 | B22: =C9/B9 -> 1.6797066 | C22: =D9/C9 -> 1.3024017 | D22: =E9/D9 -> 1.2017323
A23: 2022 | B23: =C10/B10 -> 1.6180233 | C23: =D10/C10 -> 1.2820697
A24: 2023 | B24: =C11/B11 -> 1.6996173
A25: 2024
A27: Averages
A28: Metric | B28: 12-24 | C28: 24-36 | D28: 36-48 | E28: 48-60 | F28: 60-72 | G28: 72-84 | H28: 84-96 | I28: 96-108 | J28: 108-120 | K28: Tail
A29: simple_all | B29: =IFERROR(AVERAGE(B16:B24),AVERAGE(B16:B24)) -> 1.6640787 | C29: =IFERROR(AVERAGE(C16:C24),AVERAGE(C16:C24)) -> 1.2930869 | D29: =IFERROR(AVERAGE(D16:D24),AVERAGE(D16:D24)) -> 1.1858228 | E29: =IFERROR(AVERAGE(E16:E24),AVERAGE(E16:E24)) -> 1.0999162 | F29: =IFERROR(AVERAGE(F16:F24),AVERAGE(F16:F24)) -> 1.0424985 | G29: =IFERROR(AVERAGE(G16:G24),AVERAGE(G16:G24)) -> 1.0219375 | H29: =IFERROR(AVERAGE(H16:H24),AVERAGE(H16:H24)) -> 1.0104917 | I29: =IFERROR(AVERAGE(I16:I24),AVERAGE(I16:I24)) -> 1.0098187 | J29: =IFERROR(AVERAGE(J16:J24),AVERAGE(J16:J24)) -> 1
A30: weighted_all | B30: =IFERROR(SUMPRODUCT(B16:B24,B3:B11)/SUMPRODUCT((B16:B24<>"")*B3:B11),SUMPRODUCT(B16:B24,B3:B11)/SUMPRODUCT((B16:B24<>"")*B3:B11)) -> 1.6631071 | C30: =IFERROR(SUMPRODUCT(C16:C24,C3:C11)/SUMPRODUCT((C16:C24<>"")*C3:C11),SUMPRODUCT(C16:C24,C3:C11)/SUMPRODUCT((C16:C24<>"")*C3:C11)) -> 1.2929863 | D30: =IFERROR(SUMPRODUCT(D16:D24,D3:D11)/SUMPRODUCT((D16:D24<>"")*D3:D11),SUMPRODUCT(D16:D24,D3:D11)/SUMPRODUCT((D16:D24<>"")*D3:D11)) -> 1.1858461 | E30: =IFERROR(SUMPRODUCT(E16:E24,E3:E11)/SUMPRODUCT((E16:E24<>"")*E3:E11),SUMPRODUCT(E16:E24,E3:E11)/SUMPRODUCT((E16:E24<>"")*E3:E11)) -> 1.0998713 | F30: =IFERROR(SUMPRODUCT(F16:F24,F3:F11)/SUMPRODUCT((F16:F24<>"")*F3:F11),SUMPRODUCT(F16:F24,F3:F11)/SUMPRODUCT((F16:F24<>"")*F3:F11)) -> 1.0424887 | G30: =IFERROR(SUMPRODUCT(G16:G24,G3:G11)/SUMPRODUCT((G16:G24<>"")*G3:G11),SUMPRODUCT(G16:G24,G3:G11)/SUMPRODUCT((G16:G24<>"")*G3:G11)) -> 1.0219421 | H30: =IFERROR(SUMPRODUCT(H16:H24,H3:H11)/SUMPRODUCT((H16:H24<>"")*H3:H11),SUMPRODUCT(H16:H24,H3:H11)/SUMPRODUCT((H16:H24<>"")*H3:H11)) -> 1.0104907 | I30: =IFERROR(SUMPRODUCT(I16:I24,I3:I11)/SUMPRODUCT((I16:I24<>"")*I3:I11),SUMPRODUCT(I16:I24,I3:I11)/SUMPRODUCT((I16:I24<>"")*I3:I11)) -> 1.009819 | J30: =IFERROR(SUMPRODUCT(J16:J24,J3:J11)/SUMPRODUCT((J16:J24<>"")*J3:J11),SUMPRODUCT(J16:J24,J3:J11)/SUMPRODUCT((J16:J24<>"")*J3:J11)) -> 1
A31: exclude_high_low_all | B31: =IFERROR(TRIMMEAN(B16:B24,2/COUNT(B16:B24)),AVERAGE(B16:B24)) -> 1.6629872 | C31: =IFERROR(TRIMMEAN(C16:C24,2/COUNT(C16:C24)),AVERAGE(C16:C24)) -> 1.2924724 | D31: =IFERROR(TRIMMEAN(D16:D24,2/COUNT(D16:D24)),AVERAGE(D16:D24)) -> 1.1849552 | E31: =IFERROR(TRIMMEAN(E16:E24,2/COUNT(E16:E24)),AVERAGE(E16:E24)) -> 1.0992686 | F31: =IFERROR(TRIMMEAN(F16:F24,2/COUNT(F16:F24)),AVERAGE(F16:F24)) -> 1.0426677 | G31: =IFERROR(TRIMMEAN(G16:G24,2/COUNT(G16:G24)),AVERAGE(G16:G24)) -> 1.0215346 | H31: =IFERROR(TRIMMEAN(H16:H24,2/COUNT(H16:H24)),AVERAGE(H16:H24)) -> 1.0107638 | I31: =IFERROR(TRIMMEAN(I16:I24,2/COUNT(I16:I24)),AVERAGE(I16:I24)) -> 1.0098187 | J31: =IFERROR(TRIMMEAN(J16:J24,2/COUNT(J16:J24)),AVERAGE(J16:J24)) -> 1
A32: simple_3yr | B32: =IFERROR(AVERAGE(B22:B24),AVERAGE(B16:B24)) -> 1.6657824 | C32: =IFERROR(AVERAGE(C22:C24),AVERAGE(C16:C24)) -> 1.2922357 | D32: =IFERROR(AVERAGE(D22:D24),AVERAGE(D16:D24)) -> 1.2017323 | E32: =IFERROR(AVERAGE(E22:E24),AVERAGE(E16:E24)) -> 1.0999162 | F32: =IFERROR(AVERAGE(F22:F24),AVERAGE(F16:F24)) -> 1.0424985 | G32: =IFERROR(AVERAGE(G22:G24),AVERAGE(G16:G24)) -> 1.0219375 | H32: =IFERROR(AVERAGE(H22:H24),AVERAGE(H16:H24)) -> 1.0104917 | I32: =IFERROR(AVERAGE(I22:I24),AVERAGE(I16:I24)) -> 1.0098187 | J32: =IFERROR(AVERAGE(J22:J24),AVERAGE(J16:J24)) -> 1
A33: weighted_3yr | B33: =IFERROR(SUMPRODUCT(B22:B24,B9:B11)/SUMPRODUCT((B22:B24<>"")*B9:B11),SUMPRODUCT(B16:B24,B3:B11)/SUMPRODUCT((B16:B24<>"")*B3:B11)) -> 1.6645004 | C33: =IFERROR(SUMPRODUCT(C22:C24,C9:C11)/SUMPRODUCT((C22:C24<>"")*C9:C11),SUMPRODUCT(C16:C24,C3:C11)/SUMPRODUCT((C16:C24<>"")*C3:C11)) -> 1.2921714 | D33: =IFERROR(SUMPRODUCT(D22:D24,D9:D11)/SUMPRODUCT((D22:D24<>"")*D9:D11),SUMPRODUCT(D16:D24,D3:D11)/SUMPRODUCT((D16:D24<>"")*D3:D11)) -> 1.2017323 | E33: =IFERROR(SUMPRODUCT(E22:E24,E9:E11)/SUMPRODUCT((E22:E24<>"")*E9:E11),SUMPRODUCT(E16:E24,E3:E11)/SUMPRODUCT((E16:E24<>"")*E3:E11)) -> 1.0998713 | F33: =IFERROR(SUMPRODUCT(F22:F24,F9:F11)/SUMPRODUCT((F22:F24<>"")*F9:F11),SUMPRODUCT(F16:F24,F3:F11)/SUMPRODUCT((F16:F24<>"")*F3:F11)) -> 1.0424887 | G33: =IFERROR(SUMPRODUCT(G22:G24,G9:G11)/SUMPRODUCT((G22:G24<>"")*G9:G11),SUMPRODUCT(G16:G24,G3:G11)/SUMPRODUCT((G16:G24<>"")*G3:G11)) -> 1.0219421 | H33: =IFERROR(SUMPRODUCT(H22:H24,H9:H11)/SUMPRODUCT((H22:H24<>"")*H9:H11),SUMPRODUCT(H16:H24,H3:H11)/SUMPRODUCT((H16:H24<>"")*H3:H11)) -> 1.0104907 | I33: =IFERROR(SUMPRODUCT(I22:I24,I9:I11)/SUMPRODUCT((I22:I24<>"")*I9:I11),SUMPRODUCT(I16:I24,I3:I11)/SUMPRODUCT((I16:I24<>"")*I3:I11)) -> 1.009819 | J33: =IFERROR(SUMPRODUCT(J22:J24,J9:J11)/SUMPRODUCT((J22:J24<>"")*J9:J11),SUMPRODUCT(J16:J24,J3:J11)/SUMPRODUCT((J16:J24<>"")*J3:J11)) -> 1
A34: exclude_high_low_3yr | B34: =IFERROR(TRIMMEAN(B22:B24,2/COUNT(B22:B24)),AVERAGE(B16:B24)) -> 1.6797066 | C34: =IFERROR(TRIMMEAN(C22:C24,2/COUNT(C22:C24)),AVERAGE(C16:C24)) -> 1.2930869 | D34: =IFERROR(TRIMMEAN(D22:D24,2/COUNT(D22:D24)),AVERAGE(D16:D24)) -> 1.1858228 | E34: =IFERROR(TRIMMEAN(E22:E24,2/COUNT(E22:E24)),AVERAGE(E16:E24)) -> 1.0999162 | F34: =IFERROR(TRIMMEAN(F22:F24,2/COUNT(F22:F24)),AVERAGE(F16:F24)) -> 1.0424985 | G34: =IFERROR(TRIMMEAN(G22:G24,2/COUNT(G22:G24)),AVERAGE(G16:G24)) -> 1.0219375 | H34: =IFERROR(TRIMMEAN(H22:H24,2/COUNT(H22:H24)),AVERAGE(H16:H24)) -> 1.0104917 | I34: =IFERROR(TRIMMEAN(I22:I24,2/COUNT(I22:I24)),AVERAGE(I16:I24)) -> 1.0098187 | J34: =IFERROR(TRIMMEAN(J22:J24,2/COUNT(J22:J24)),AVERAGE(J16:J24)) -> 1
A35: simple_5yr | B35: =IFERROR(AVERAGE(B20:B24),AVERAGE(B16:B24)) -> 1.6828475 | C35: =IFERROR(AVERAGE(C20:C24),AVERAGE(C16:C24)) -> 1.293583 | D35: =IFERROR(AVERAGE(D20:D24),AVERAGE(D16:D24)) -> 1.1886967 | E35: =IFERROR(AVERAGE(E20:E24),AVERAGE(E16:E24)) -> 1.1016767 | F35: =IFERROR(AVERAGE(F20:F24),AVERAGE(F16:F24)) -> 1.0431072 | G35: =IFERROR(AVERAGE(G20:G24),AVERAGE(G16:G24)) -> 1.0219375 | H35: =IFERROR(AVERAGE(H20:H24),AVERAGE(H16:H24)) -> 1.0104917 | I35: =IFERROR(AVERAGE(I20:I24),AVERAGE(I16:I24)) -> 1.0098187 | J35: =IFERROR(AVERAGE(J20:J24),AVERAGE(J16:J24)) -> 1
A36: weighted_5yr | B36: =IFERROR(SUMPRODUCT(B20:B24,B7:B11)/SUMPRODUCT((B20:B24<>"")*B7:B11),SUMPRODUCT(B16:B24,B3:B11)/SUMPRODUCT((B16:B24<>"")*B3:B11)) -> 1.6816332 | C36: =IFERROR(SUMPRODUCT(C20:C24,C7:C11)/SUMPRODUCT((C20:C24<>"")*C7:C11),SUMPRODUCT(C16:C24,C3:C11)/SUMPRODUCT((C16:C24<>"")*C3:C11)) -> 1.293399 | D36: =IFERROR(SUMPRODUCT(D20:D24,D7:D11)/SUMPRODUCT((D20:D24<>"")*D7:D11),SUMPRODUCT(D16:D24,D3:D11)/SUMPRODUCT((D16:D24<>"")*D3:D11)) -> 1.1887361 | E36: =IFERROR(SUMPRODUCT(E20:E24,E7:E11)/SUMPRODUCT((E20:E24<>"")*E7:E11),SUMPRODUCT(E16:E24,E3:E11)/SUMPRODUCT((E16:E24<>"")*E3:E11)) -> 1.1016705 | F36: =IFERROR(SUMPRODUCT(F20:F24,F7:F11)/SUMPRODUCT((F20:F24<>"")*F7:F11),SUMPRODUCT(F16:F24,F3:F11)/SUMPRODUCT((F16:F24<>"")*F3:F11)) -> 1.0431072 | G36: =IFERROR(SUMPRODUCT(G20:G24,G7:G11)/SUMPRODUCT((G20:G24<>"")*G7:G11),SUMPRODUCT(G16:G24,G3:G11)/SUMPRODUCT((G16:G24<>"")*G3:G11)) -> 1.0219421 | H36: =IFERROR(SUMPRODUCT(H20:H24,H7:H11)/SUMPRODUCT((H20:H24<>"")*H7:H11),SUMPRODUCT(H16:H24,H3:H11)/SUMPRODUCT((H16:H24<>"")*H3:H11)) -> 1.0104907 | I36: =IFERROR(SUMPRODUCT(I20:I24,I7:I11)/SUMPRODUCT((I20:I24<>"")*I7:I11),SUMPRODUCT(I16:I24,I3:I11)/SUMPRODUCT((I16:I24<>"")*I3:I11)) -> 1.009819 | J36: =IFERROR(SUMPRODUCT(J20:J24,J7:J11)/SUMPRODUCT((J20:J24<>"")*J7:J11),SUMPRODUCT(J16:J24,J3:J11)/SUMPRODUCT((J16:J24<>"")*J3:J11)) -> 1
A37: exclude_high_low_5yr | B37: =IFERROR(TRIMMEAN(B20:B24,2/COUNT(B20:B24)),AVERAGE(B16:B24)) -> 1.6908912 | C37: =IFERROR(TRIMMEAN(C20:C24,2/COUNT(C20:C24)),AVERAGE(C16:C24)) -> 1.2922357 | D37: =IFERROR(TRIMMEAN(D20:D24,2/COUNT(D20:D24)),AVERAGE(D16:D24)) -> 1.1891815 | E37: =IFERROR(TRIMMEAN(E20:E24,2/COUNT(E20:E24)),AVERAGE(E16:E24)) -> 1.0999162 | F37: =IFERROR(TRIMMEAN(F20:F24,2/COUNT(F20:F24)),AVERAGE(F16:F24)) -> 1.0424985 | G37: =IFERROR(TRIMMEAN(G20:G24,2/COUNT(G20:G24)),AVERAGE(G16:G24)) -> 1.0219375 | H37: =IFERROR(TRIMMEAN(H20:H24,2/COUNT(H20:H24)),AVERAGE(H16:H24)) -> 1.0104917 | I37: =IFERROR(TRIMMEAN(I20:I24,2/COUNT(I20:I24)),AVERAGE(I16:I24)) -> 1.0098187 | J37: =IFERROR(TRIMMEAN(J20:J24,2/COUNT(J20:J24)),AVERAGE(J16:J24)) -> 1
A38: simple_10yr | B38: =IFERROR(AVERAGE(B16:B24),AVERAGE(B16:B24)) -> 1.6640787 | C38: =IFERROR(AVERAGE(C16:C24),AVERAGE(C16:C24)) -> 1.2930869 | D38: =IFERROR(AVERAGE(D16:D24),AVERAGE(D16:D24)) -> 1.1858228 | E38: =IFERROR(AVERAGE(E16:E24),AVERAGE(E16:E24)) -> 1.0999162 | F38: =IFERROR(AVERAGE(F16:F24),AVERAGE(F16:F24)) -> 1.0424985 | G38: =IFERROR(AVERAGE(G16:G24),AVERAGE(G16:G24)) -> 1.0219375 | H38: =IFERROR(AVERAGE(H16:H24),AVERAGE(H16:H24)) -> 1.0104917 | I38: =IFERROR(AVERAGE(I16:I24),AVERAGE(I16:I24)) -> 1.0098187 | J38: =IFERROR(AVERAGE(J16:J24),AVERAGE(J16:J24)) -> 1
A39: weighted_10yr | B39: =IFERROR(SUMPRODUCT(B16:B24,B3:B11)/SUMPRODUCT((B16:B24<>"")*B3:B11),SUMPRODUCT(B16:B24,B3:B11)/SUMPRODUCT((B16:B24<>"")*B3:B11)) -> 1.6631071 | C39: =IFERROR(SUMPRODUCT(C16:C24,C3:C11)/SUMPRODUCT((C16:C24<>"")*C3:C11),SUMPRODUCT(C16:C24,C3:C11)/SUMPRODUCT((C16:C24<>"")*C3:C11)) -> 1.2929863 | D39: =IFERROR(SUMPRODUCT(D16:D24,D3:D11)/SUMPRODUCT((D16:D24<>"")*D3:D11),SUMPRODUCT(D16:D24,D3:D11)/SUMPRODUCT((D16:D24<>"")*D3:D11)) -> 1.1858461 | E39: =IFERROR(SUMPRODUCT(E16:E24,E3:E11)/SUMPRODUCT((E16:E24<>"")*E3:E11),SUMPRODUCT(E16:E24,E3:E11)/SUMPRODUCT((E16:E24<>"")*E3:E11)) -> 1.0998713 | F39: =IFERROR(SUMPRODUCT(F16:F24,F3:F11)/SUMPRODUCT((F16:F24<>"")*F3:F11),SUMPRODUCT(F16:F24,F3:F11)/SUMPRODUCT((F16:F24<>"")*F3:F11)) -> 1.0424887 | G39: =IFERROR(SUMPRODUCT(G16:G24,G3:G11)/SUMPRODUCT((G16:G24<>"")*G3:G11),SUMPRODUCT(G16:G24,G3:G11)/SUMPRODUCT((G16:G24<>"")*G3:G11)) -> 1.0219421 | H39: =IFERROR(SUMPRODUCT(H16:H24,H3:H11)/SUMPRODUCT((H16:H24<>"")*H3:H11),SUMPRODUCT(H16:H24,H3:H11)/SUMPRODUCT((H16:H24<>"")*H3:H11)) -> 1.0104907 | I39: =IFERROR(SUMPRODUCT(I16:I24,I3:I11)/SUMPRODUCT((I16:I24<>"")*I3:I11),SUMPRODUCT(I16:I24,I3:I11)/SUMPRODUCT((I16:I24<>"")*I3:I11)) -> 1.009819 | J39: =IFERROR(SUMPRODUCT(J16:J24,J3:J11)/SUMPRODUCT((J16:J24<>"")*J3:J11),SUMPRODUCT(J16:J24,J3:J11)/SUMPRODUCT((J16:J24<>"")*J3:J11)) -> 1
A40: exclude_high_low_10yr | B40: =IFERROR(TRIMMEAN(B16:B24,2/COUNT(B16:B24)),AVERAGE(B16:B24)) -> 1.6629872 | C40: =IFERROR(TRIMMEAN(C16:C24,2/COUNT(C16:C24)),AVERAGE(C16:C24)) -> 1.2924724 | D40: =IFERROR(TRIMMEAN(D16:D24,2/COUNT(D16:D24)),AVERAGE(D16:D24)) -> 1.1849552 | E40: =IFERROR(TRIMMEAN(E16:E24,2/COUNT(E16:E24)),AVERAGE(E16:E24)) -> 1.0992686 | F40: =IFERROR(TRIMMEAN(F16:F24,2/COUNT(F16:F24)),AVERAGE(F16:F24)) -> 1.0426677 | G40: =IFERROR(TRIMMEAN(G16:G24,2/COUNT(G16:G24)),AVERAGE(G16:G24)) -> 1.0215346 | H40: =IFERROR(TRIMMEAN(H16:H24,2/COUNT(H16:H24)),AVERAGE(H16:H24)) -> 1.0107638 | I40: =IFERROR(TRIMMEAN(I16:I24,2/COUNT(I16:I24)),AVERAGE(I16:I24)) -> 1.0098187 | J40: =IFERROR(TRIMMEAN(J16:J24,2/COUNT(J16:J24)),AVERAGE(J16:J24)) -> 1
A42: LDF Selections
B43: 12-24 | C43: 24-36 | D43: 36-48 | E43: 48-60 | F43: 60-72 | G43: 72-84 | H43: 84-96 | I43: 96-108 | J43: 108-120 | K43: Tail
...

Sheet CL - Diag - Rptd Claims
A1: Reported Claims
B2: 12 | C2: 24 | D2: 36 | E2: 48 | F2: 60 | G2: 72 | H2: 84 | I2: 96 | J2: 108 | K2: 120
A3: 2015 | B3: 1638 | C3: 2677 | D3: 3472 | E3: 4077 | F3: 4526 | G3: 4730 | H3: 4831 | I3: 4883 | J3: 4930 | K3: 4930
A4: 2016 | B4: 1636 | C4: 2723 | D4: 3474 | E4: 4156 | F4: 4555 | G4: 4743 | H4: 4846 | I4: 4894 | J4: 4943
A5: 2017 | B5: 1624 | C5: 2682 | D5: 3477 | E5: 4114 | F5: 4516 | G5: 4713 | H5: 4812 | I5: 4864
A6: 2018 | B6: 1697 | C6: 2736 | D6: 3560 | E6: 4204 | F6: 4592 | G6: 4773 | H6: 4886
A7: 2019 | B7: 1559 | C7: 2687 | D7: 3545 | E7: 4166 | F7: 4570 | G7: 4767
A8: 2020 | B8: 1624 | C8: 2750 | D8: 3494 | E8: 4155 | F8: 4597
A9: 2021 | B9: 1636 | C9: 2748 | D9: 3579 | E9: 4301
A10: 2022 | B10: 1720 | C10: 2783 | D10: 3568
A11: 2023 | B11: 1568 | C11: 2665
A12: 2024 | B12: 1712

Sheet CL - Diag - Inc Severity
A1: Incurred Severity
B2: 12 | C2: 24 | D2: 36 | E2: 48 | F2: 60 | G2: 72 | H2: 84 | I2: 96 | J2: 108 | K2: 120
A3: 2015 | B3: 7098.4541 | C3: 7715.2158 | D3: 7749.6834 | E3: 7939.2853 | F3: 7958.4138 | G3: 8180.0714 | H3: 8499.0827 | I3: 8749.6564 | J3: 8948.6693 | K3: 9129.5005
A4: 2016 | B4: 9571.6151 | C4: 9915.6425 | D4: 10315.651 | E4: 10423.573 | F4: 10717.954 | G4: 11054.965 | H4: 11472.245 | I4: 11846.221 | J4: 12122.724
A5: 2017 | B5: 5387.136 | C5: 6169.5643 | D5: 6415.6021 | E5: 6516.9154 | F5: 6619.6704 | G5: 6808.6592 | H5: 7041.437 | I5: 7272.2886
A6: 2018 | B6: 8605.7618 | C6: 9915.0284 | D6: 10227.213 | E6: 10540.855 | F6: 10651.338 | G6: 10964.877 | H6: 11322.867
A7: 2019 | B7: 7599.8629 | C7: 8020.6149 | D7: 8064.2778 | E7: 8119.2937 | F7: 8214.3637 | G7: 8470.6732
A8: 2020 | B8: 6482.6603 | C8: 6991.5957 | D8: 7533.6513 | E8: 7589.0283 | F8: 7597.8125
A9: 2021 | B9: 11598.884 | C9: 12783.823 | D9: 12901.322 | E9: 12839.295
A10: 2022 | B10: 6560.2045 | C10: 7234.5554 | D10: 7579.0477
A11: 2023 | B11: 7700.7354 | C11: 8006.0142
A12: 2024 | B12: 9304.8621

Sheet CL - Diag - Paid Severity
A1: Paid Severity
B2: 12 | C2: 24 | D2: 36 | E2: 48 | F2: 60 | G2: 72 | H2: 84 | I2: 96 | J2: 108 | K2: 120
A3: 2015 | B3: 6794.6046 | C3: 7518.8479 | D3: 7942.1853 | E3: 7833.8534 | F3: 7881.6478 | G3: 8056.0152 | H3: 8321.0119 | I3: 8570.6207 | J3: 8833.9444 | K3: 9127.6491
A4: 2016 | B4: 9476.5764 | C4: 10477.952 | D4: 10849.012 | E4: 10841.546 | F4: 10974.876 | G4: 11242.629 | H4: 11531.82 | I4: 11848.582 | J4: 12125.143
A5: 2017 | B5: 5651.3611 | C5: 6693.7866 | D5: 7009.8043 | E5: 6957.1886 | F5: 7003.8235 | G5: 7134.4438 | H5: 7254.4775 | I5: 7420.8636
A6: 2018 | B6: 8539.5818 | C6: 9841.3331 | D6: 10362.511 | E6: 10522.828 | F6: 10749.334 | G6: 10967.95 | H6: 11220.539
A7: 2019 | B7: 7261.7351 | C7: 8050.4431 | D7: 8486.6031 | E7: 8429.8884 | F7: 8544.3919 | G7: 8708.3002
A8: 2020 | B8: 6453.418 | C8: 6808.2141 | D8: 7356.5136 | E8: 7591.7672 | F8: 7655.6744
A9: 2021 | B9: 10240.125 | C9: 11384.964 | D9: 11762.289 | E9: 12122.576
A10: 2022 | B10: 5740.6934 | C10: 6873.2679 | D10: 7409.5436
A11: 2023 | B11: 7415.991 | C11: 8093.7641
A12: 2024 | B12: 10154.178

Sheet CL - Diag - Paid to Incurred
A1: Paid To Incurred
B2: 12 | C2: 24 | D2: 36 | E2: 48 | F2: 60 | G2: 72 | H2: 84 | I2: 96 | J2: 108 | K2: 120
A3: 2015 | B3: 0.7953 | C3: 0.8176 | D3: 0.8548 | E3: 0.8589 | F3: 0.8785 | G3: 0.9051 | H3: 0.931 | I3: 0.9511 | J3: 0.9778 | K3: 1
A4: 2016 | B4: 0.7807 | C4: 0.8522 | D4: 0.8779 | E4: 0.8847 | F4: 0.9017 | G4: 0.9312 | H4: 0.9529 | I4: 0.9685 | J4: 0.9891
A5: 2017 | B5: 0.8746 | C5: 0.8649 | D5: 0.8931 | E5: 0.8953 | F5: 0.9219 | G5: 0.9531 | H5: 0.9742 | I5: 0.9869
A6: 2018 | B6: 0.8262 | C6: 0.8315 | D6: 0.8524 | E6: 0.8523 | F6: 0.8899 | G6: 0.9219 | H6: 0.9476
A7: 2019 | B7: 0.8495 | C7: 0.8409 | D7: 0.8689 | E7: 0.8785 | F7: 0.9104 | G7: 0.9392
A8: 2020 | B8: 0.8514 | C8: 0.8279 | D8: 0.8401 | E8: 0.8557 | F8: 0.8807
A9: 2021 | B9: 0.8413 | C9: 0.8109 | D9: 0.8233 | E9: 0.8364
A10: 2022 | B10: 0.7962 | C10: 0.8255 | D10: 0.8543
A11: 2023 | B11: 0.8095 | C11: 0.8399
A12: 2024 | B12: 0.8325

Sheet CL - Diag - Open Counts
A1: Open Counts
B2: 12 | C2: 24 | D2: 36 | E2: 48 | F2: 60 | G2: 72 | H2: 84 | I2: 96 | J2: 108 | K2: 120
A3: 2015 | B3: 277 | C3: 431 | D3: 576 | E3: 528 | F3: 511 | G3: 383 | H3: 237 | I3: 142 | J3: 47 | K3: -1
A4: 2016 | B4: 346 | C4: 527 | D4: 574 | E4: 621 | F4: 544 | G4: 400 | H4: 252 | I4: 155 | J4: 55
A5: 2017 | B5: 270 | C5: 544 | D5: 635 | E5: 664 | F5: 581 | G5: 426 | H5: 262 | I5: 160
A6: 2018 | B6: 284 | C6: 444 | D6: 565 | E6: 615 | F6: 543 | G6: 374 | H6: 214
A7: 2019 | B7: 173 | C7: 436 | D7: 618 | E7: 641 | F7: 570 | G7: 412
A8: 2020 | B8: 235 | C8: 412 | D8: 488 | E8: 601 | F8: 579
A9: 2021 | B9: 77 | C9: 246 | D9: 347 | E9: 491
A10: 2022 | B10: 155 | C10: 365 | D10: 450
A11: 2023 | B11: 250 | C11: 451
A12: 2024 | B12: 406

Sheet CL - Diag - Avg Case Rsrv
A1: Average Case Reserve
B2: 12 | C2: 24 | D2: 36 | E2: 48 | F2: 60 | G2: 72 | H2: 84 | I2: 96 | J2: 108 | K2: 120
A3: 2015 | B3: 8591.3754 | C3: 8738.5157 | D3: 6781.8266 | E3: 8647.9552 | F3: 8561.5749 | G3: 9588.0925 | H3: 11950.8 | I3: 14727.18 | J3: 20867.859 | K3: -0.03
A4: 2016 | B4: 9925.9502 | C4: 7572.5075 | D4: 7620.9716 | E4: 8044.2907 | F4: 8823.6287 | G4: 9017.4012 | H4: 10386.193 | I4: 11774.021 | J4: 11907.736
A5: 2017 | B5: 4062.0959 | C5: 4109.2935 | D5: 3756.1962 | E5: 4229.3513 | F5: 4017.8763 | G5: 3530.1649 | H5: 3341.6888 | I5: 2904.1845
A6: 2018 | B6: 8935.0304 | C6: 10295.456 | D6: 9510.0095 | E6: 10646.052 | F6: 9920.6168 | G6: 10928.731 | H6: 13556.867
A7: 2019 | B7: 10308.794 | C7: 7866.6164 | D7: 6064.0411 | E7: 6411.2649 | F7: 5898.3768 | G7: 5958.8635
