Workbook

Sheet Notes
A1: Reserve Analysis - Complete Analysis
A2: Workbook Information
A3: Created: | B3: April 27, 2026 01:20 PM
A4: Description: | B4: Complete actuarial reserve analysis combining selections, ultimates, and diagnostics
A6: Table of Contents
A7: Name | B7: Description
A8: Loss Selection | B8: Actuary-selected ultimates for loss measures. Compare CL/BF/IE methods and record final selection.
A9: Incurred CL | B9: Chain Ladder method results. Ultimate = Actual × CDF. IBNR = Ultimate − Actual. Unpaid = Ultimate − latest paid (proxy measure).
A10: Paid CL | B10: Chain Ladder method results. Ultimate = Actual × CDF. IBNR = Ultimate − Actual. Unpaid = Ultimate − latest paid (proxy measure).
A11: Incurred BF | B11: Bornhuetter-Ferguson method. Blends Initial Expected with emerged experience. % Unreported = 1 − 1/CDF. Ultimate = (IE × % Unreported) + Actual.
A12: Paid BF | B12: Bornhuetter-Ferguson method. Blends Initial Expected with emerged experience. % Unreported = 1 − 1/CDF. Ultimate = (IE × % Unreported) + Actual.
A13: Incurred IE | B13: Initial Expected method. Ultimate = Exposure × Selected Loss Rate (ELR). ELR back-calculated from IE ultimate and exposure.
A14: Paid IE | B14: Initial Expected method. Ultimate = Exposure × Selected Loss Rate (ELR). ELR back-calculated from IE ultimate and exposure.
A15: Count Selection | B15: Analysis results
A16: Closed CL | B16: Chain Ladder method results. Ultimate = Actual × CDF. IBNR = Ultimate − Actual. Unpaid = Ultimate − latest paid (proxy measure).
A17: Reported CL | B17: Chain Ladder method results. Ultimate = Actual × CDF. IBNR = Ultimate − Actual. Unpaid = Ultimate − latest paid (proxy measure).
A18: Reported BF | B18: Bornhuetter-Ferguson method. Blends Initial Expected with emerged experience. % Unreported = 1 − 1/CDF. Ultimate = (IE × % Unreported) + Actual.
... A37: Diagnostics | B37: Post-selection reasonableness checks. Severity = Ultimate Loss / Ultimate Count. Loss Rate and Frequency require Exposure.

Sheet Loss Selection
A1: Accident Period | B1: Current Age | C1: Incurred | D1: Paid | E1: Incurred CL | F1: Paid CL | G1: Initial Expected | H1: Incurred BF | I1: Paid BF | J1: Selected Ultimate | K1: IBNR | L1: Unpaid | M1: Selected Reasoning
A2: 2001 | B2: 287 | C2: ='Incurred CL'!C2 | D2: ='Paid CL'!C2 | E2: ='Incurred CL'!E2 | F2: ='Paid CL'!E2 | G2: ='[Ultimates.xlsx]Losses'!G2 | H2: ='Incurred BF'!H2 | I2: ='Paid BF'!H2 | J2: =IFERROR(IF(INDEX('[Ultimates.xlsx]Losses'!$A:$Z,2,MATCH("User Selection",'[Ultimates.xlsx]Losses'!$1:$1,0))<>"",INDEX('[Ultimates.xlsx]Losses'!$A:$Z,2,MATCH("User Selection",'[Ultimates.xlsx]Losses'!$1:$1,0)),INDEX('[Ultimates.xlsx]Losses'!$A:$Z,2,MATCH("Rules-Based AI Selection",'[Ultimates.xlsx]Losses'!$1:$1,0))),"") | K2: =J2-C2 | L2: =J2-D2 | M2: =IFERROR(IF(INDEX('[Ultimates.xlsx]Losses'!$A:$Z,2,MATCH("User Selection",'[Ultimates.xlsx]Losses'!$1:$1,0))<>"",INDEX('[Ultimates.xlsx]Losses'!$A:$Z,2,MATCH("User Reasoning",'[Ultimates.xlsx]Losses'!$1:$1,0)),INDEX('[Ultimates.xlsx]Losses'!$A:$Z,2,MATCH("Rules-Based AI Reasoning",'[Ultimates.xlsx]Losses'!$1:$1,0))),"")
A3: 2002 | B3: 275 | C3: ='Incurred CL'!C3 | D3: ='Paid CL'!C3 | E3: ='Incurred CL'!E3 | F3: ='Paid CL'!E3 | G3: ='[Ultimates.xlsx]Losses'!G3 | H3: ='Incurred BF'!H3 | I3: ='Paid BF'!H3 | J3: =IFERROR(IF(INDEX('[Ultimates.xlsx]Losses'!$A:$Z,3,MATCH("User Selection",'[Ultimates.xlsx]Losses'!$1:$1,0))<>"",INDEX('[Ultimates.xlsx]Losses'!$A:$Z,3,MATCH("User Selection",'[Ultimates.xlsx]Losses'!$1:$1,0)),INDEX('[Ultimates.xlsx]Losses'!$A:$Z,3,MATCH("Rules-Based AI Selection",'[Ultimates.xlsx]Losses'!$1:$1,0))),"") | K3: =J3-C3 | L3: =J3-D3 | M3: =IFERROR(IF(INDEX('[Ultimates.xlsx]Losses'!$A:$Z,3,MATCH("User Selection",'[Ultimates.xlsx]Losses'!$1:$1,0))<>"",INDEX('[Ultimates.xlsx]Losses'!$A:$Z,3,MATCH("User Reasoning",'[Ultimates.xlsx]Losses'!$1:$1,0)),INDEX('[Ultimates.xlsx]Losses'!$A:$Z,3,MATCH("Rules-Based AI Reasoning",'[Ultimates.xlsx]Losses'!$1:$1,0))),"")
A4: 2003 | B4: 263 | C4: ='Incurred CL'!C4 | D4: ='Paid CL'!C4 | E4: ='Incurred CL'!E4 | F4: ='Paid CL'!E4 | G4: ='[Ultimates.xlsx]Losses'!G4 | H4: ='Incurred BF'!H4 | I4: ='Paid BF'!H4 | J4: =IFERROR(IF(INDEX('[Ultimates.xlsx]Losses'!$A:$Z,4,MATCH("User Selection",'[Ultimates.xlsx]Losses'!$1:$1,0))<>"",INDEX('[Ultimates.xlsx]Losses'!$A:$Z,4,MATCH("User Selection",'[Ultimates.xlsx]Losses'!$1:$1,0)),INDEX('[Ultimates.xlsx]Losses'!$A:$Z,4,MATCH("Rules-Based AI Selection",'[Ultimates.xlsx]Losses'!$1:$1,0))),"") | K4: =J4-C4 | L4: =J4-D4 | M4: =IFERROR(IF(INDEX('[Ultimates.xlsx]Losses'!$A:$Z,4,MATCH("User Selection",'[Ultimates.xlsx]Losses'!$1:$1,0))<>"",INDEX('[Ultimates.xlsx]Losses'!$A:$Z,4,MATCH("User Reasoning",'[Ultimates.xlsx]Losses'!$1:$1,0)),INDEX('[Ultimates.xlsx]Losses'!$A:$Z,4,MATCH("Rules-Based AI Reasoning",'[Ultimates.xlsx]Losses'!$1:$1,0))),"")
A5: 2004 | B5: 251 | C5: ='Incurred CL'!C5 | D5: ='Paid CL'!C5 | E5: ='Incurred CL'!E5 | F5: ='Paid CL'!E5 | G5: ='[Ultimates.xlsx]Losses'!G5 | H5: ='Incurred BF'!H5 | I5: ='Paid BF'!H5 | J5: =IFERROR(IF(INDEX('[Ultimates.xlsx]Losses'!$A:$Z,5,MATCH("User Selection",'[Ultimates.xlsx]Losses'!$1:$1,0))<>"",INDEX('[Ultimates.xlsx]Losses'!$A:$Z,5,MATCH("User Selection",'[Ultimates.xlsx]Losses'!$1:$1,0)),INDEX('[Ultimates.xlsx]Losses'!$A:$Z,5,MATCH("Rules-Based AI Selection",'[Ultimates.xlsx]Losses'!$1:$1,0))),"") | K5: =J5-C5 | L5: =J5-D5 | M5: =IFERROR(IF(INDEX('[Ultimates.xlsx]Losses'!$A:$Z,5,MATCH("User Selection",'[Ultimates.xlsx]Losses'!$1:$1,0))<>"",INDEX('[Ultimates.xlsx]Losses'!$A:$Z,5,MATCH("User Reasoning",'[Ultimates.xlsx]Losses'!$1:$1,0)),INDEX('[Ultimates.xlsx]Losses'!$A:$Z,5,MATCH("Rules-Based AI Reasoning",'[Ultimates.xlsx]Losses'!$1:$1,0))),"")
A6: 2005 | B6: 239 | C6: ='Incurred CL'!C6 | D6: ='Paid CL'!C6 | E6: ='Incurred CL'!E6 | F6: ='Paid CL'!E6 | G6: ='[Ultimates.xlsx]Losses'!G6 | H6: ='Incurred BF'!H6 | I6: ='Paid BF'!H6 | J6: =IFERROR(IF(INDEX('[Ultimates.xlsx]Losses'!$A:$Z,6,MATCH("User Selection",'[Ultimates.xlsx]Losses'!$1:$1,0))<>"",INDEX('[Ultimates.xlsx]Losses'!$A:$Z,6,MATCH("User Selection",'[Ultimates.xlsx]Losses'!$1:$1,0)),INDEX('[Ultimates.xlsx]Losses'!$A:$Z,6,MATCH("Rules-Based AI Selection",'[Ultimates.xlsx]Losses'!$1:$1,0))),"") | K6: =J6-C6 | L6: =J6-D6 | M6: =IFERROR(IF(INDEX('[Ultimates.xlsx]Losses'!$A:$Z,6,MATCH("User Selection",'[Ultimates.xlsx]Losses'!$1:$1,0))<>"",INDEX('[Ultimates.xlsx]Losses'!$A:$Z,6,MATCH("User Reasoning",'[Ultimates.xlsx]Losses'!$1:$1,0)),INDEX('[Ultimates.xlsx]Losses'!$A:$Z,6,MATCH("Rules-Based AI Reasoning",'[Ultimates.xlsx]Losses'!$1:$1,0))),"")
A7: 2006 | B7: 227 | C7: ='Incurred CL'!C7 | D7: ='Paid CL'!C7 | E7: ='Incurred CL'!E7 | F7: ='Paid CL'!E7 | G7: ='[Ultimates.xlsx]Losses'!G7 | H7: ='Incurred BF'!H7 | I7: ='Paid BF'!H7 | J7: =IFERROR(IF(INDEX('[Ultimates.xlsx]Losses'!$A:$Z,7,MATCH("User Selection",'[Ultimates.xlsx]Losses'!$1:$1,0))<>"",INDEX('[Ultimates.xlsx]Losses'!$A:$Z,7,MATCH("User Selection",'[Ultimates.xlsx]Losses'!$1:$1,0)),INDEX('[Ultimates.xlsx]Losses'!$A:$Z,7,MATCH("Rules-Based AI Selection",'[Ultimates.xlsx]Losses'!$1:$1,0))),"") | K7: =J7-C7 | L7: =J7-D7 | M7: =IFERROR(IF(INDEX('[Ultimates.xlsx]Losses'!$A:$Z,7,MATCH("User Selection",'[Ultimates.xlsx]Losses'!$1:$1,0))<>"",INDEX('[Ultimates.xlsx]Losses'!$A:$Z,7,MATCH("User Reasoning",'[Ultimates.xlsx]Losses'!$1:$1,0)),INDEX('[Ultimates.xlsx]Losses'!$A:$Z,7,MATCH("Rules-Based AI Reasoning",'[Ultimates.xlsx]Losses'!$1:$1,0))),"")
A8: 2007 | B8: 215 | C8: ='Incurred CL'!C8 | D8: ='Paid CL'!C8 | E8: ='Incurred CL'!E8 | F8: ='Paid CL'!E8 | G8: ='[Ultimates.xlsx]Losses'!G8 | H8: ='Incurred BF'!H8 | I8: ='Paid BF'!H8 | J8: =IFERROR(IF(INDEX('[Ultimates.xlsx]Losses'!$A:$Z,8,MATCH("User Selection",'[Ultimates.xlsx]Losses'!$1:$1,0))<>"",INDEX('[Ultimates.xlsx]Losses'!$A:$Z,8,MATCH("User Selection",'[Ultimates.xlsx]Losses'!$1:$1,0)),INDEX('[Ultimates.xlsx]Losses'!$A:$Z,8,MATCH("Rules-Based AI Selection",'[Ultimates.xlsx]Losses'!$1:$1,0))),"") | K8: =J8-C8 | L8: =J8-D8 | M8: =IFERROR(IF(INDEX('[Ultimates.xlsx]Losses'!$A:$Z,8,MATCH("User Selection",'[Ultimates.xlsx]Losses'!$1:$1,0))<>"",INDEX('[Ultimates.xlsx]Losses'!$A:$Z,8,MATCH("User Reasoning",'[Ultimates.xlsx]Losses'!$1:$1,0)),INDEX('[Ultimates.xlsx]Losses'!$A:$Z,8,MATCH("Rules-Based AI Reasoning",'[Ultimates.xlsx]Losses'!$1:$1,0))),"")
A9: 2008 | B9: 203 | C9: ='Incurred CL'!C9 | D9: ='Paid CL'!C9 | E9: ='Incurred CL'!E9 | F9: ='Paid CL'!E9 | G9: ='[Ultimates.xlsx]Losses'!G9 | H9: ='Incurred BF'!H9 | I9: ='Paid BF'!H9 | J9: =IFERROR(IF(INDEX('[Ultimates.xlsx]Losses'!$A:$Z,9,MATCH("User Selection",'[Ultimates.xlsx]Losses'!$1:$1,0))<>"",INDEX('[Ultimates.xlsx]Losses'!$A:$Z,9,MATCH("User Selection",'[Ultimates.xlsx]Losses'!$1:$1,0)),INDEX('[Ultimates.xlsx]Losses'!$A:$Z,9,MATCH("Rules-Based AI Selection",'[Ultimates.xlsx]Losses'!$1:$1,0))),"") | K9: =J9-C9 | L9: =J9-D9 | M9: =IFERROR(IF(INDEX('[Ultimates.xlsx]Losses'!$A:$Z,9,MATCH("User Selection",'[Ultimates.xlsx]Losses'!$1:$1,0))<>"",INDEX('[Ultimates.xlsx]Losses'!$A:$Z,9,MATCH("User Reasoning",'[Ultimates.xlsx]Losses'!$1:$1,0)),INDEX('[Ultimates.xlsx]Losses'!$A:$Z,9,MATCH("Rules-Based AI Reasoning",'[Ultimates.xlsx]Losses'!$1:$1,0))),"")
A10: 2009 | B10: 191 | C10: ='Incurred CL'!C10 | D10: ='Paid CL'!C10 | E10: ='Incurred CL'!E10 | F10: ='Paid CL'!E10 | G10: ='[Ultimates.xlsx]Losses'!G10 | H10: ='Incurred BF'!H10 | I10: ='Paid BF'!H10 | J10: =IFERROR(IF(INDEX('[Ultimates.xlsx]Losses'!$A:$Z,10,MATCH("User Selection",'[Ultimates.xlsx]Losses'!$1:$1,0))<>"",INDEX('[Ultimates.xlsx]Losses'!$A:$Z,10,MATCH("User Selection",'[Ultimates.xlsx]Losses'!$1:$1,0)),INDEX('[Ultimates.xlsx]Losses'!$A:$Z,10,MATCH("Rules-Based AI Selection",'[Ultimates.xlsx]Losses'!$1:$1,0))),"") | K10: =J10-C10 | L10: =J10-D10 | M10: =IFERROR(IF(INDEX('[Ultimates.xlsx]Losses'!$A:$Z,10,MATCH("User Selection",'[Ultimates.xlsx]Losses'!$1:$1,0))<>"",INDEX('[Ultimates.xlsx]Losses'!$A:$Z,10,MATCH("User Reasoning",'[Ultimates.xlsx]Losses'!$1:$1,0)),INDEX('[Ultimates.xlsx]Losses'!$A:$Z,10,MATCH("Rules-Based AI Reasoning",'[Ultimates.xlsx]Losses'!$1:$1,0))),"")
A11: 2010 | B11: 179 | C11: ='Incurred CL'!C11 | D11: ='Paid CL'!C11 | E11: ='Incurred CL'!E11 | F11: ='Paid CL'!E11 | G11: ='[Ultimates.xlsx]Losses'!G11 | H11: ='Incurred BF'!H11 | I11: ='Paid BF'!H11 | J11: =IFERROR(IF(INDEX('[Ultimates.xlsx]Losses'!$A:$Z,11,MATCH("User Selection",'[Ultimates.xlsx]Losses'!$1:$1,0))<>"",INDEX('[Ultimates.xlsx]Losses'!$A:$Z,11,MATCH("User Selection",'[Ultimates.xlsx]Losses'!$1:$1,0)),INDEX('[Ultimates.xlsx]Losses'!$A:$Z,11,MATCH("Rules-Based AI Selection",'[Ultimates.xlsx]Losses'!$1:$1,0))),"") | K11: =J11-C11 | L11: =J11-D11 | M11: =IFERROR(IF(INDEX('[Ultimates.xlsx]Losses'!$A:$Z,11,MATCH("User Selection",'[Ultimates.xlsx]Losses'!$1:$1,0))<>"",INDEX('[Ultimates.xlsx]Losses'!$A:$Z,11,MATCH("User Reasoning",'[Ultimates.xlsx]Losses'!$1:$1,0)),INDEX('[Ultimates.xlsx]Losses'!$A:$Z,11,MATCH("Rules-Based AI Reasoning",'[Ultimates.xlsx]Losses'!$1:$1,0))),"")
A12: 2011 | B12: 167 | C12: ='Incurred CL'!C12 | D12: ='Paid CL'!C12 | E12: ='Incurred CL'!E12 | F12: ='Paid CL'!E12 | G12: ='[Ultimates.xlsx]Losses'!G12 | H12: ='Incurred BF'!H12 | I12: ='Paid BF'!H12 | J12: =IFERROR(IF(INDEX('[Ultimates.xlsx]Losses'!$A:$Z,12,MATCH("User Selection",'[Ultimates.xlsx]Losses'!$1:$1,0))<>"",INDEX('[Ultimates.xlsx]Losses'!$A:$Z,12,MATCH("User Selection",'[Ultimates.xlsx]Losses'!$1:$1,0)),INDEX('[Ultimates.xlsx]Losses'!$A:$Z,12,MATCH("Rules-Based AI Selection",'[Ultimates.xlsx]Losses'!$1:$1,0))),"") | K12: =J12-C12 | L12: =J12-D12 | M12: =IFERROR(IF(INDEX('[Ultimates.xlsx]Losses'!$A:$Z,12,MATCH("User Selection",'[Ultimates.xlsx]Losses'!$1:$1,0))<>"",INDEX('[Ultimates.xlsx]Losses'!$A:$Z,12,MATCH("User Reasoning",'[Ultimates.xlsx]Losses'!$1:$1,0)),INDEX('[Ultimates.xlsx]Losses'!$A:$Z,12,MATCH("Rules-Based AI Reasoning",'[Ultimates.xlsx]Losses'!$1:$1,0))),"")
A13: 2012 | B13: 155 | C13: ='Incurred CL'!C13 | D13: ='Paid CL'!C13 | E13: ='Incurred CL'!E13 | F13: ='Paid CL'!E13 | G13: ='[Ultimates.xlsx]Losses'!G13 | H13: ='Incurred BF'!H13 | I13: ='Paid BF'!H13 | J13: =IFERROR(IF(INDEX('[Ultimates.xlsx]Losses'!$A:$Z,13,MATCH("User Selection",'[Ultimates.xlsx]Losses'!$1:$1,0))<>"",INDEX('[Ultimates.xlsx]Losses'!$A:$Z,13,MATCH("User Selection",'[Ultimates.xlsx]Losses'!$1:$1,0)),INDEX('[Ultimates.xlsx]Losses'!$A:$Z,13,MATCH("Rules-Based AI Selection",'[Ultimates.xlsx]Losses'!$1:$1,0))),"") | K13: =J13-C13 | L13: =J13-D13 | M13: =IFERROR(IF(INDEX('[Ultimates.xlsx]Losses'!$A:$Z,13,MATCH("User Selection",'[Ultimates.xlsx]Losses'!$1:$1,0))<>"",INDEX('[Ultimates.xlsx]Losses'!$A:$Z,13,MATCH("User Reasoning",'[Ultimates.xlsx]Losses'!$1:$1,0)),INDEX('[Ultimates.xlsx]Losses'!$A:$Z,13,MATCH("Rules-Based AI Reasoning",'[Ultimates.xlsx]Losses'!$1:$1,0))),"")
A14: 2013 | B14: 143 | C14: ='Incurred CL'!C14 | D14: ='Paid CL'!C14 | E14: ='Incurred CL'!E14 | F14: ='Paid CL'!E14 | G14: ='[Ultimates.xlsx]Losses'!G14 | H14: ='Incurred BF'!H14 | I14: ='Paid BF'!H14 | J14: =IFERROR(IF(INDEX('[Ultimates.xlsx]Losses'!$A:$Z,14,MATCH("User Selection",'[Ultimates.xlsx]Losses'!$1:$1,0))<>"",INDEX('[Ultimates.xlsx]Losses'!$A:$Z,14,MATCH("User Selection",'[Ultimates.xlsx]Losses'!$1:$1,0)),INDEX('[Ultimates.xlsx]Losses'!$A:$Z,14,MATCH("Rules-Based AI Selection",'[Ultimates.xlsx]Losses'!$1:$1,0))),"") | K14: =J14-C14 | L14: =J14-D14 | M14: =IFERROR(IF(INDEX('[Ultimates.xlsx]Losses'!$A:$Z,14,MATCH("User Selection",'[Ultimates.xlsx]Losses'!$1:$1,0))<>"",INDEX('[Ultimates.xlsx]Losses'!$A:$Z,14,MATCH("User Reasoning",'[Ultimates.xlsx]Losses'!$1:$1,0)),INDEX('[Ultimates.xlsx]Losses'!$A:$Z,14,MATCH("Rules-Based AI Reasoning",'[Ultimates.xlsx]Losses'!$1:$1,0))),"")
A15: 2014 | B15: 131 | C15: ='Incurred CL'!C15 | D15: ='Paid CL'!C15 | E15: ='Incurred CL'!E15 | F15: ='Paid CL'!E15 | G15: ='[Ultimates.xlsx]Losses'!G15 | H15: ='Incurred BF'!H15 | I15: ='Paid BF'!H15 | J15: =IFERROR(IF(INDEX('[Ultimates.xlsx]Losses'!$A:$Z,15,MATCH("User Selection",'[Ultimates.xlsx]Losses'!$1:$1,0))<>"",INDEX('[Ultimates.xlsx]Losses'!$A:$Z,15,MATCH("User Selection",'[Ultimates.xlsx]Losses'!$1:$1,0)),INDEX('[Ultimates.xlsx]Losses'!$A:$Z,15,MATCH("Rules-Based AI Selection",'[Ultimates.xlsx]Losses'!$1:$1,0))),"") | K15: =J15-C15 | L15: =J15-D15 | M15: =IFERROR(IF(INDEX('[Ultimates.xlsx]Losses'!$A:$Z,15,MATCH("User Selection",'[Ultimates.xlsx]Losses'!$1:$1,0))<>"",INDEX('[Ultimates.xlsx]Losses'!$A:$Z,15,MATCH("User Reasoning",'[Ultimates.xlsx]Losses'!$1:$1,0)),INDEX('[Ultimates.xlsx]Losses'!$A:$Z,15,MATCH("Rules-Based AI Reasoning",'[Ultimates.xlsx]Losses'!$1:$1,0))),"")
A16: 2015 | B16: 119 | C16: ='Incurred CL'!C16 | D16: ='Paid CL'!C16 | E16: ='Incurred CL'!E16 | F16: ='Paid CL'!E16 | G16: ='[Ultimates.xlsx]Losses'!G16 | H16: ='Incurred BF'!H16 | I16: ='Paid BF'!H16 | J16: =IFERROR(IF(INDEX('[Ultimates.xlsx]Losses'!$A:$Z,16,MATCH("User Selection",'[Ultimates.xlsx]Losses'!$1:$1,0))<>"",INDEX('[Ultimates.xlsx]Losses'!$A:$Z,16,MATCH("User Selection",'[Ultimates.xlsx]Losses'!$1:$1,0)),INDEX('[Ultimates.xlsx]Losses'!$A:$Z,16,MATCH("Rules-Based AI Selection",'[Ultimates.xlsx]Losses'!$1:$1,0))),"") | K16: =J16-C16 | L16: =J16-D16 | M16: =IFERROR(IF(INDEX('[Ultimates.xlsx]Losses'!$A:$Z,16,MATCH("User Selection",'[Ultimates.xlsx]Losses'!$1:$1,0))<>"",INDEX('[Ultimates.xlsx]Losses'!$A:$Z,16,MATCH("User Reasoning",'[Ultimates.xlsx]Losses'!$1:$1,0)),INDEX('[Ultimates.xlsx]Losses'!$A:$Z,16,MATCH("Rules-Based AI Reasoning",'[Ultimates.xlsx]Losses'!$1:$1,0))),"")
A17: 2016 | B17: 107 | C17: ='Incurred CL'!C17 | D17: ='Paid CL'!C17 | E17: ='Incurred CL'!E17 | F17: ='Paid CL'!E17 | G17: ='[Ultimates.xlsx]Losses'!G17 | H17: ='Incurred BF'!H17 | I17: ='Paid BF'!H17 | J17: =IFERROR(IF(INDEX('[Ultimates.xlsx]Losses'!$A:$Z,17,MATCH("User Selection",'[Ultimates.xlsx]Losses'!$1:$1,0))<>"",INDEX('[Ultimates.xlsx]Losses'!$A:$Z,17,MATCH("User Selection",'[Ultimates.xlsx]Losses'!$1:$1,0)),INDEX('[Ultimates.xlsx]Losses'!$A:$Z,17,MATCH("Rules-Based AI Selection",'[Ultimates.xlsx]Losses'!$1:$1,0))),"") | K17: =J17-C17 | L17: =J17-D17 | M17: =IFERROR(IF(INDEX('[Ultimates.xlsx]Losses'!$A:$Z,17,MATCH("User Selection",'[Ultimates.xlsx]Losses'!$1:$1,0))<>"",INDEX('[Ultimates.xlsx]Losses'!$A:$Z,17,MATCH("User Reasoning",'[Ultimates.xlsx]Losses'!$1:$1,0)),INDEX('[Ultimates.xlsx]Losses'!$A:$Z,17,MATCH("Rules-Based AI Reasoning",'[Ultimates.xlsx]Losses'!$1:$1,0))),"")
A18: 2017 | B18: 95 | C18: ='Incurred CL'!C18 | D18: ='Paid CL'!C18 | E18: ='Incurred CL'!E18 | F18: ='Paid CL'!E18 | G18: ='[Ultimates.xlsx]Losses'!G18 | H18: ='Incurred BF'!H18 | I18: ='Paid BF'!H18 | J18: =IFERROR(IF(INDEX('[Ultimates.xlsx]Losses'!$A:$Z,18,MATCH("User Selection",'[Ultimates.xlsx]Losses'!$1:$1,0))<>"",INDEX('[Ultimates.xlsx]Losses'!$A:$Z,18,MATCH("User Selection",'[Ultimates.xlsx]Losses'!$1:$1,0)),INDEX('[Ultimates.xlsx]Losses'!$A:$Z,18,MATCH("Rules-Based AI Selection",'[Ultimates.xlsx]Losses'!$1:$1,0))),"") | K18: =J18-C18 | L18: =J18-D18 | M18: =IFERROR(IF(INDEX('[Ultimates.xlsx]Losses'!$A:$Z,18,MATCH("User Selection",'[Ultimates.xlsx]Losses'!$1:$1,0))<>"",INDEX('[Ultimates.xlsx]Losses'!$A:$Z,18,MATCH("User Reasoning",'[Ultimates.xlsx]Losses'!$1:$1,0)),INDEX('[Ultimates.xlsx]Losses'!$A:$Z,18,MATCH("Rules-Based AI Reasoning",'[Ultimates.xlsx]Losses'!$1:$1,0))),"")
A19: 2018 | B19: 83 | C19: ='Incurred CL'!C19 | D19: ='Paid CL'!C19 | E19: ='Incurred CL'!E19 | F19: ='Paid CL'!E19 | G19: ='[Ultimates.xlsx]Losses'!G19 | H19: ='Incurred BF'!H19 | I19: ='Paid BF'!H19 | J19: =IFERROR(IF(INDEX('[Ultimates.xlsx]Losses'!$A:$Z,19,MATCH("User Selection",'[Ultimates.xlsx]Losses'!$1:$1,0))<>"",INDEX('[Ultimates.xlsx]Losses'!$A:$Z,19,MATCH("User Selection",'[Ultimates.xlsx]Losses'!$1:$1,0)),INDEX('[Ultimates.xlsx]Losses'!$A:$Z,19,MATCH("Rules-Based AI Selection",'[Ultimates.xlsx]Losses'!$1:$1,0))),"") | K19: =J19-C19 | L19: =J19-D19 | M19: =IFERROR(IF(INDEX('[Ultimates.xlsx]Losses'!$A:$Z,19,MATCH("User Selection",'[Ultimates.xlsx]Losses'!$1:$1,0))<>"",INDEX('[Ultimates.xlsx]Losses'!$A:$Z,19,MATCH("User Reasoning",'[Ultimates.xlsx]Losses'!$1:$1,0)),INDEX('[Ultimates.xlsx]Losses'!$A:$Z,19,MATCH("Rules-Based AI Reasoning",'[Ultimates.xlsx]Losses'!$1:$1,0))),"")
A20: 2019 | B20: 71 | C20: ='Incurred CL'!C20 | D20: ='Paid CL'!C20 | E20: ='Incurred CL'!E20 | F20: ='Paid CL'!E20 | G20: ='[Ultimates.xlsx]Losses'!G20 | H20: ='Incurred BF'!H20 | I20: ='Paid BF'!H20 | J20: =IFERROR(IF(INDEX('[Ultimates.xlsx]Losses'!$A:$Z,20,MATCH("User Selection",'[Ultimates.xlsx]Losses'!$1:$1,0))<>"",INDEX('[Ultimates.xlsx]Losses'!$A:$Z,20,MATCH("User Selection",'[Ultimates.xlsx]Losses'!$1:$1,0)),INDEX('[Ultimates.xlsx]Losses'!$A:$Z,20,MATCH("Rules-Based AI Selection",'[Ultimates.xlsx]Losses'!$1:$1,0))),"") | K20: =J20-C20 | L20: =J20-D20 | M20: =IFERROR(IF(INDEX('[Ultimates.xlsx]Losses'!$A:$Z,20,MATCH("User Selection",'[Ultimates.xlsx]Losses'!$1:$1,0))<>"",INDEX('[Ultimates.xlsx]Losses'!$A:$Z,20,MATCH("User Reasoning",'[Ultimates.xlsx]Losses'!$1:$1,0)),INDEX('[Ultimates.xlsx]Losses'!$A:$Z,20,MATCH("Rules-Based AI Reasoning",'[Ultimates.xlsx]Losses'!$1:$1,0))),"")
A21: 2020 | B21: 59 | C21: ='Incurred CL'!C21 | D21: ='Paid CL'!C21 | E21: ='Incurred CL'!E21 | F21: ='Paid CL'!E21 | G21: ='[Ultimates.xlsx]Losses'!G21 | H21: ='Incurred BF'!H21 | I21: ='Paid BF'!H21 | J21: =IFERROR(IF(INDEX('[Ultimates.xlsx]Losses'!$A:$Z,21,MATCH("User Selection",'[Ultimates.xlsx]Losses'!$1:$1,0))<>"",INDEX('[Ultimates.xlsx]Losses'!$A:$Z,21,MATCH("User Selection",'[Ultimates.xlsx]Losses'!$1:$1,0)),INDEX('[Ultimates.xlsx]Losses'!$A:$Z,21,MATCH("Rules-Based AI Selection",'[Ultimates.xlsx]Losses'!$1:$1,0))),"") | K21: =J21-C21 | L21: =J21-D21 | M21: =IFERROR(IF(INDEX('[Ultimates.xlsx]Losses'!$A:$Z,21,MATCH("User Selection",'[Ultimates.xlsx]Losses'!$1:$1,0))<>"",INDEX('[Ultimates.xlsx]Losses'!$A:$Z,21,MATCH("User Reasoning",'[Ultimates.xlsx]Losses'!$1:$1,0)),INDEX('[Ultimates.xlsx]Losses'!$A:$Z,21,MATCH("Rules-Based AI Reasoning",'[Ultimates.xlsx]Losses'!$1:$1,0))),"")
A22: 2021 | B22: 47 | C22: ='Incurred CL'!C22 | D22: ='Paid CL'!C22 | E22: ='Incurred CL'!E22 | F22: ='Paid CL'!E22 | G22: ='[Ultimates.xlsx]Losses'!G22 | H22: ='Incurred BF'!H22 | I22: ='Paid BF'!H22 | J22: =IFERROR(IF(INDEX('[Ultimates.xlsx]Losses'!$A:$Z,22,MATCH("User Selection",'[Ultimates.xlsx]Losses'!$1:$1,0))<>"",INDEX('[Ultimates.xlsx]Losses'!$A:$Z,22,MATCH("User Selection",'[Ultimates.xlsx]Losses'!$1:$1,0)),INDEX('[Ultimates.xlsx]Losses'!$A:$Z,22,MATCH("Rules-Based AI Selection",'[Ultimates.xlsx]Losses'!$1:$1,0))),"") | K22: =J22-C22 | L22: =J22-D22 | M22: =IFERROR(IF(INDEX('[Ultimates.xlsx]Losses'!$A:$Z,22,MATCH("User Selection",'[Ultimates.xlsx]Losses'!$1:$1,0))<>"",INDEX('[Ultimates.xlsx]Losses'!$A:$Z,22,MATCH("User Reasoning",'[Ultimates.xlsx]Losses'!$1:$1,0)),INDEX('[Ultimates.xlsx]Losses'!$A:$Z,22,MATCH("Rules-Based AI Reasoning",'[Ultimates.xlsx]Losses'!$1:$1,0))),"")
A23: 2022 | B23: 35 | C23: ='Incurred CL'!C23 | D23: ='Paid CL'!C23 | E23: ='Incurred CL'!E23 | F23: ='Paid CL'!E23 | G23: ='[Ultimates.xlsx]Losses'!G23 | H23: ='Incurred BF'!H23 | I23: ='Paid BF'!H23 | J23: =IFERROR(IF(INDEX('[Ultimates.xlsx]Losses'!$A:$Z,23,MATCH("User Selection",'[Ultimates.xlsx]Losses'!$1:$1,0))<>"",INDEX('[Ultimates.xlsx]Losses'!$A:$Z,23,MATCH("User Selection",'[Ultimates.xlsx]Losses'!$1:$1,0)),INDEX('[Ultimates.xlsx]Losses'!$A:$Z,23,MATCH("Rules-Based AI Selection",'[Ultimates.xlsx]Losses'!$1:$1,0))),"") | K23: =J23-C23 | L23: =J23-D23 | M23: =IFERROR(IF(INDEX('[Ultimates.xlsx]Losses'!$A:$Z,23,MATCH("User Selection",'[Ultimates.xlsx]Losses'!$1:$1,0))<>"",INDEX('[Ultimates.xlsx]Losses'!$A:$Z,23,MATCH("User Reasoning",'[Ultimates.xlsx]Losses'!$1:$1,0)),INDEX('[Ultimates.xlsx]Losses'!$A:$Z,23,MATCH("Rules-Based AI Reasoning",'[Ultimates.xlsx]Losses'!$1:$1,0))),"")
A24: 2023 | B24: 23 | C24: ='Incurred CL'!C24 | D24: ='Paid CL'!C24 | E24: ='Incurred CL'!E24 | F24: ='Paid CL'!E24 | G24: ='[Ultimates.xlsx]Losses'!G24 | H24: ='Incurred BF'!H24 | I24: ='Paid BF'!H24 | J24: =IFERROR(IF(INDEX('[Ultimates.xlsx]Losses'!$A:$Z,24,MATCH("User Selection",'[Ultimates.xlsx]Losses'!$1:$1,0))<>"",INDEX('[Ultimates.xlsx]Losses'!$A:$Z,24,MATCH("User Selection",'[Ultimates.xlsx]Losses'!$1:$1,0)),INDEX('[Ultimates.xlsx]Losses'!$A:$Z,24,MATCH("Rules-Based AI Selection",'[Ultimates.xlsx]Losses'!$1:$1,0))),"") | K24: =J24-C24 | L24: =J24-D24 | M24: =IFERROR(IF(INDEX('[Ultimates.xlsx]Losses'!$A:$Z,24,MATCH("User Selection",'[Ultimates.xlsx]Losses'!$1:$1,0))<>"",INDEX('[Ultimates.xlsx]Losses'!$A:$Z,24,MATCH("User Reasoning",'[Ultimates.xlsx]Losses'!$1:$1,0)),INDEX('[Ultimates.xlsx]Losses'!$A:$Z,24,MATCH("Rules-Based AI Reasoning",'[Ultimates.xlsx]Losses'!$1:$1,0))),"")
A25: 2024 | B25: 11 | C25: ='Incurred CL'!C25 | D25: ='Paid CL'!C25 | E25: ='Incurred CL'!E25 | F25: ='Paid CL'!E25 | G25: ='[Ultimates.xlsx]Losses'!G25 | H25: ='Incurred BF'!H25 | I25: ='Paid BF'!H25 | J25: =IFERROR(IF(INDEX('[Ultimates.xlsx]Losses'!$A:$Z,25,MATCH("User Selection",'[Ultimates.xlsx]Losses'!$1:$1,0))<>"",INDEX('[Ultimates.xlsx]Losses'!$A:$Z,25,MATCH("User Selection",'[Ultimates.xlsx]Losses'!$1:$1,0)),INDEX('[Ultimates.xlsx]Losses'!$A:$Z,25,MATCH("Rules-Based AI Selection",'[Ultimates.xlsx]Losses'!$1:$1,0))),"") | K25: =J25-C25 | L25: =J25-D25 | M25: =IFERROR(IF(INDEX('[Ultimates.xlsx]Losses'!$A:$Z,25,MATCH("User Selection",'[Ultimates.xlsx]Losses'!$1:$1,0))<>"",INDEX('[Ultimates.xlsx]Losses'!$A:$Z,25,MATCH("User Reasoning",'[Ultimates.xlsx]Losses'!$1:$1,0)),INDEX('[Ultimates.xlsx]Losses'!$A:$Z,25,MATCH("Rules-Based AI Reasoning",'[Ultimates.xlsx]Losses'!$1:$1,0))),"")
A27: Total | C27: =SUM(C2:C25) | D27: =SUM(D2:D25) | E27: =SUM(E2:E25) | F27: =SUM(F2:F25) | G27: =SUM(G2:G25) | H27: =SUM(H2:H25) | I27: =SUM(I2:I25) | J27: =SUM(J2:J25) | ... L27: =SUM(L2:L25)

Sheet Incurred CL
A1: Accident Period | B1: Current Age | C1: Incurred | D1: CDF | E1: Ultimate | F1: IBNR | G1: Unpaid
A2: 2001 | B2: 287 | C2: 3163773.7 | D2: 1.0367246 | E2: =C2*D2 | F2: =E2-C2 | G2: =E2-'Paid CL'!C2
A3: 2002 | B3: 275 | C3: 2327733.8 | D3: 1.0490616 | E3: =C3*D3 | F3: =E3-C3 | G3: =E3-'Paid CL'!C3
A4: 2003 | B4: 263 | C4: 1778091.6 | D4: 1.0490616 | E4: =C4*D4 | F4: =E4-C4 | G4: =E4-'Paid CL'!C4
A5: 2004 | B5: 251 | C5: 1122614.7 | D5: 1.066476 | E5: =C5*D5 | F5: =E5-C5 | G5: =E5-'Paid CL'!C5
A6: 2005 | B6: 239 | C6: 2242149.1 | D6: 1.0710619 | E6: =C6*D6 | F6: =E6-C6 | G6: =E6-'Paid CL'!C6
A7: 2006 | B7: 227 | C7: 1517636.8 | D7: 1.0801659 | E7: =C7*D7 | F7: =E7-C7 | G7: =E7-'Paid CL'!C7
A8: 2007 | B8: 215 | C8: 4810774.6 | D8: 1.0801659 | E8: =C8*D8 | F8: =E8-C8 | G8: =E8-'Paid CL'!C8
A9: 2008 | B9: 203 | C9: 1378427.9 | D9: 1.0823262 | E9: =C9*D9 | F9: =E9-C9 | G9: =E9-'Paid CL'!C9
A10: 2009 | B10: 191 | C10: 1169581.1 | D10: 1.0916342 | E10: =C10*D10 | F10: =E10-C10 | G10: =E10-'Paid CL'!C10
A11: 2010 | B11: 179 | C11: 1277672.1 | D11: 1.0967649 | E11: =C11*D11 | F11: =E11-C11 | G11: =E11-'Paid CL'!C11
A12: 2011 | B12: 167 | C12: 1916081.6 | D12: 1.1077326 | E12: =C12*D12 | F12: =E12-C12 | G12: =E12-'Paid CL'!C12
A13: 2012 | B13: 155 | C13: 1363753.4 | D13: 1.1081757 | E13: =C13*D13 | F13: =E13-C13 | G13: =E13-'Paid CL'!C13
... A25: 2024 | B25: 11 | C25: 890155.22 | D25: 3.8999266 | E25: =C25*D25 | F25: =E25-C25 | G25: =E25-'Paid CL'!C25
A27: Total | C27: =SUM(C2:C25) | E27: =SUM(E2:E25) | F27: =SUM(F2:F25) | G27: =SUM(G2:G25)

Sheet Paid CL
A1: Accident Period | B1: Current Age | C1: Paid | D1: CDF | E1: Ultimate | F1: IBNR | G1: Unpaid
A2: 2001 | B2: 287 | C2: 3042294.7 | D2: 1.0039 | E2: =C2*D2 | F2: =E2-C2 | G2: =E2-C2
A3: 2002 | B3: 275 | C3: 2199646.2 | D3: 1.0078152 | E3: =C3*D3 | F3: =E3-C3 | G3: =E3-C3
A4: 2003 | B4: 263 | C4: 1778091.6 | D4: 1.0154746 | E4: =C4*D4 | F4: =E4-C4 | G4: =E4-C4
A5: 2004 | B5: 251 | C5: 1122614.7 | D5: 1.0212628 | E5: =C5*D5 | F5: =E5-C5 | G5: =E5-C5
A6: 2005 | B6: 239 | C6: 2242149.1 | D6: 1.0257564 | E6: =C6*D6 | F6: =E6-C6 | G6: =E6-C6
A7: 2006 | B7: 227 | C7: 1462141 | D7: 1.0282182 | E7: =C7*D7 | F7: =E7-C7 | G7: =E7-C7
A8: 2007 | B8: 215 | C8: 4790693.2 | D8: 1.0326395 | E8: =C8*D8 | F8: =E8-C8 | G8: =E8-C8
A9: 2008 | B9: 203 | C9: 1378427.9 | D9: 1.0350146 | E9: =C9*D9 | F9: =E9-C9 | G9: =E9-C9
A10: 2009 | B10: 191 | C10: 1169581.1 | D10: 1.0481593 | E10: =C10*D10 | F10: =E10-C10 | G10: =E10-C10
A11: 2010 | B11: 179 | C11: 1277672.1 | D11: 1.0582216 | E11: =C11*D11 | F11: =E11-C11 | G11: =E11-C11
A12: 2011 | B12: 167 | C12: 1892658.3 | D12: 1.0667932 | E12: =C12*D12 | F12: =E12-C12 | G12: =E12-C12
A13: 2012 | B13: 155 | C13: 1194236.9 | D13: 1.0740474 | E13: =C13*D13 | F13: =E13-C13 | G13: =E13-C13
... A25: 2024 | B25: 11 | C25: 355247.76 | D25: 7.2616478 | E25: =C25*D25 | F25: =E25-C25 | G25: =E25-C25
A27: Total | C27: =SUM(C2:C25) | E27: =SUM(E2:E25) | F27: =SUM(F2:F25) | G27: =SUM(G2:G25)

Sheet Incurred BF
A1: Accident Period | B1: Current Age | C1: Initial Expected | D1: CDF | E1: % Unreported | F1: Unreported | G1: Incurred | H1: Ultimate | I1: IBNR | J1: Unpaid
A2: 2001 | B2: 287 | C2: 3163773.7 | D2: 1.0367246 | E2: =1-(1/D2) | F2: =C2*E2 | G2: 3163773.7 | H2: =F2+G2 | I2: =H2-G2 | J2: =H2-'Paid CL'!C2
A3: 2002 | B3: 275 | C3: 2904344.3 | D3: 1.0490616 | E3: =1-(1/D3) | F3: =C3*E3 | G3: 2327733.8 | H3: =F3+G3 | I3: =H3-G3 | J3: =H3-'Paid CL'!C3
A4: 2003 | B4: 263 | C4: 2633272.1 | D4: 1.0490616 | E4: =1-(1/D4) | F4: =C4*E4 | G4: 1778091.6 | H4: =F4+G4 | I4: =H4-G4 | J4: =H4-'Paid CL'!C4
A5: 2004 | B5: 251 | C5: 1678711 | D5: 1.066476 | E5: =1-(1/D5) | F5: =C5*E5 | G5: 1122614.7 | H5: =F5+G5 | I5: =H5-G5 | J5: =H5-'Paid CL'!C5
A6: 2005 | B6: 239 | C6: 1712285.2 | D6: 1.0710619 | E6: =1-(1/D6) | F6: =C6*E6 | G6: 2242149.1 | H6: =F6+G6 | I6: =H6-G6 | J6: =H6-'Paid CL'!C6
A7: 2006 | B7: 227 | C7: 1746530.9 | D7: 1.0801659 | E7: =1-(1/D7) | F7: =C7*E7 | G7: 1517636.8 | H7: =F7+G7 | I7: =H7-G7 | J7: =H7-'Paid CL'!C7
A8: 2007 | B8: 215 | C8: 2850338.4 | D8: 1.0801659 | E8: =1-(1/D8) | F8: =C8*E8 | G8: 4810774.6 | H8: =F8+G8 | I8: =H8-G8 | J8: =H8-'Paid CL'!C8
A9: 2008 | B9: 203 | C9: 2543927.1 | D9: 1.0823262 | E9: =1-(1/D9) | F9: =C9*E9 | G9: 1378427.9 | H9: =F9+G9 | I9: =H9-G9 | J9: =H9-'Paid CL'!C9
A10: 2009 | B10: 191 | C10: 2594805.6 | D10: 1.0916342 | E10: =1-(1/D10) | F10: =C10*E10 | G10: 1169581.1 | H10: =F10+G10 | I10: =H10-G10 | J10: =H10-'Paid CL'!C10
A11: 2010 | B11: 179 | C11: 1134300.7 | D11: 1.0967649 | E11: =1-(1/D11) | F11: =C11*E11 | G11: 1277672.1 | H11: =F11+G11 | I11: =H11-G11 | J11: =H11-'Paid CL'!C11
A12: 2011 | B12: 167 | C12: 1542649 | D12: 1.1077326 | E12: =1-(1/D12) | F12: =C12*E12 | G12: 1916081.6 | H12: =F12+G12 | I12: =H12-G12 | J12: =H12-'Paid CL'!C12
A13: 2012 | B13: 155 | C13: 1573502 | D13: 1.1081757 | E13: =1-(1/D13) | F13: =C13*E13 | G13: 1363753.4 | H13: =F13+G13 | I13: =H13-G13 | J13: =H13-'Paid CL'!C13
... A25: 2024 | B25: 11 | C25: 997790.48 | D25: 3.8999266 | E25: =1-(1/D25) | F25: =C25*E25 | G25: 890155.22 | H25: =F25+G25 | I25: =H25-G25 | J25: =H25-'Paid CL'!C25
A27: Total | C27: =SUM(C2:C25) | E27: =SUM(F2:F25)/SUM(C2:C25) | F27: =SUM(F2:F25) | G27: =SUM(G2:G25) | H27: =SUM(H2:H25) | I27: =SUM(I2:I25) | J27: =SUM(J2:J25)

Sheet Paid BF
A1: Accident Period | B1: Current Age | C1: Initial Expected | D1: CDF | E1: % Unreported | F1: Unreported | G1: Paid | H1: Ultimate | I1: IBNR | J1: Unpaid
A2: 2001 | B2: 287 | C2: 3163773.7 | D2: 1.0039 | E2: =1-(1/D2) | F2: =C2*E2 | G2: 3042294.7 | H2: =F2+G2 | I2: =H2-G2 | J2: =H2-G2
A3: 2002 | B3: 275 | C3: 2904344.3 | D3: 1.0078152 | E3: =1-(1/D3) | F3: =C3*E3 | G3: 2199646.2 | H3: =F3+G3 | I3: =H3-G3 | J3: =H3-G3
A4: 2003 | B4: 263 | C4: 2633272.1 | D4: 1.0154746 | E4: =1-(1/D4) | F4: =C4*E4 | G4: 1778091.6 | H4: =F4+G4 | I4: =H4-G4 | J4: =H4-G4
A5: 2004 | B5: 251 | C5: 1678711 | D5: 1.0212628 | E5: =1-(1/D5) | F5: =C5*E5 | G5: 1122614.7 | H5: =F5+G5 | I5: =H5-G5 | J5: =H5-G5
A6: 2005 | B6: 239 | C6: 1712285.2 | D6: 1.0257564 | E6: =1-(1/D6) | F6: =C6*E6 | G6: 2242149.1 | H6: =F6+G6 | I6: =H6-G6 | J6: =H6-G6
A7: 2006 | B7: 227 | C7: 1746530.9 | D7: 1.0282182 | E7: =1-(1/D7) | F7: =C7*E7 | G7: 1462141 | H7: =F7+G7 | I7: =H7-G7 | J7: =H7-G7
A8: 2007 | B8: 215 | C8: 2850338.4 | D8: 1.0326395 | E8: =1-(1/D8) | F8: =C8*E8 | G8: 4790693.2 | H8: =F8+G8 | I8: =H8-G8 | J8: =H8-G8
A9: 2008 | B9: 203 | C9: 2543927.1 | D9: 1.0350146 | E9: =1-(1/D9) | F9: =C9*E9 | G9: 1378427.9 | H9: =F9+G9 | I9: =H9-G9 | J9: =H9-G9
A10: 2009 | B10: 191 | C10: 2594805.6 | D10: 1.0481593 | E10: =1-(1/D10) | F10: =C10*E10 | G10: 1169581.1 | H10: =F10+G10 | I10: =H10-G10 | J10: =H10-G10
A11: 2010 | B11: 179 | C11: 1134300.7 | D11: 1.0582216 | E11: =1-(1/D11) | F11: =C11*E11 | G11: 1277672.1 | H11: =F11+G11 | I11: =H11-G11 | J11: =H11-G11
A12: 2011 | B12: 167 | C12: 1542649 | D12: 1.0667932 | E12: =1-(1/D12) | F12: =C12*E12 | G12: 1892658.3 | H12: =F12+G12 | I12: =H12-G12 | J12: =H12-G12
A13: 2012 | B13: 155 | C13: 1573502 | D13: 1.0740474 | E13: =1-(1/D13) | F13: =C13*E13 | G13: 1194236.9 | H13: =F13+G13 | I13: =H13-G13 | J13: =H13-G13
... A25: 2024 | B25: 11 | C25: 997790.48 | D25: 7.2616478 | E25: =1-(1/D25) | F25: =C25*E25 | G25: 355247.76 | H25: =F25+G25 | I25: =H25-G25 | J25: =H25-G25
A27: Total | C27: =SUM(C2:C25) | E27: =SUM(F2:F25)/SUM(C2:C25) | F27: =SUM(F2:F25) | G27: =SUM(G2:G25) | H27: =SUM(H2:H25) | I27: =SUM(I2:I25) | J27: =SUM(J2:J25)

Sheet Incurred IE
A1: Accident Period | B1: Current Age | C1: Exposure | D1: Selected Loss Rate | E1: IE Ultimate
A2: 2001 | B2: 287 | C2: 3.1637737e+08 | D2: 0.01 | E2: 3163773.7
A3: 2002 | B3: 275 | C3: 3.2270492e+08 | D3: 0.009 | E3: 2904344.3
A4: 2003 | B4: 263 | C4: 3.2915902e+08 | D4: 0.008 | E4: 2633272.1
A5: 2004 | B5: 251 | C5: 335742196 | D5: 0.005 | E5: 1678711
A6: 2005 | B6: 239 | C6: 342457040 | D6: 0.005 | E6: 1712285.2
A7: 2006 | B7: 227 | C7: 3.4930618e+08 | D7: 0.005 | E7: 1746530.9
A8: 2007 | B8: 215 | C8: 3.562923e+08 | D8: 0.008 | E8: 2850338.4
A9: 2008 | B9: 203 | C9: 3.6341815e+08 | D9: 0.007 | E9: 2543927.1
A10: 2009 | B10: 191 | C10: 3.7068651e+08 | D10: 0.007 | E10: 2594805.6
A11: 2010 | B11: 179 | C11: 3.7810024e+08 | D11: 0.003 | E11: 1134300.7
A12: 2011 | B12: 167 | C12: 3.8566225e+08 | D12: 0.004 | E12: 1542649
A13: 2012 | B13: 155 | C13: 3.9337549e+08 | D13: 0.004 | E13: 1573502
... A25: 2024 | B25: 11 | C25: 4.9889524e+08 | D25: 0.002 | E25: 997790.48

Sheet Paid IE
A1: Accident Period | B1: Current Age | C1: Exposure | D1: Selected Loss Rate | E1: IE Ultimate
A2: 2001 | B2: 287 | C2: 3.1637737e+08 | D2: 0.01 | E2: 3163773.7
A3: 2002 | B3: 275 | C3: 3.2270492e+08 | D3: 0.009 | E3: 2904344.3
A4: 2003 | B4: 263 | C4: 3.2915902e+08 | D4: 0.008 | E4: 2633272.1
A5: 2004 | B5: 251 | C5: 335742196 | D5: 0.005 | E5: 1678711
A6: 2005 | B6: 239 | C6: 342457040 | D6: 0.005 | E6: 1712285.2
A7: 2006 | B7: 227 | C7: 3.4930618e+08 | D7: 0.005 | E7: 1746530.9
A8: 2007 | B8: 215 | C8: 3.562923e+08 | D8: 0.008 | E8: 2850338.4
A9: 2008 | B9: 203 | C9: 3.6341815e+08 | D9: 0.007 | E9: 2543927.1
A10: 2009 | B10: 191 | C10: 3.7068651e+08 | D10: 0.007 | E10: 2594805.6
A11: 2010 | B11: 179 | C11: 3.7810024e+08 | D11: 0.003 | E11: 1134300.7
A12: 2011 | B12: 167 | C12: 3.8566225e+08 | D12: 0.004 | E12: 1542649
A13: 2012 | B13: 155 | C13: 3.9337549e+08 | D13: 0.004 | E13: 1573502
... A25: 2024 | B25: 11 | C25: 4.9889524e+08 | D25: 0.002 | E25: 997790.48

Sheet Count Selection
A1: Accident Period | B1: Current Age | C1: Reported | D1: Reported CL | E1: Initial Expected | F1: Reported BF | G1: Selected Ultimate | H1: IBNR | I1: Unpaid | J1: Selected Reasoning
A2: 2001 | B2: 287 | C2: ='Reported CL'!C2 | D2: ='Reported CL'!E2 | E2: ='[Ultimates.xlsx]Counts'!E2 | F2: ='Reported BF'!H2 | G2: =IFERROR(IF(INDEX('[Ultimates.xlsx]Counts'!$A:$Z,2,MATCH("User Selection",'[Ultimates.xlsx]Counts'!$1:$1,0))<>"",INDEX('[Ultimates.xlsx]Counts'!$A:$Z,2,MATCH("User Selection",'[Ultimates.xlsx]Counts'!$1:$1,0)),INDEX('[Ultimates.xlsx]Counts'!$A:$Z,2,MATCH("Rules-Based AI Selection",'[Ultimates.xlsx]Counts'!$1:$1,0))),"") | H2: =G2-C2 | I2: =G2-C2 | J2: =IFERROR(IF(INDEX('[Ultimates.xlsx]Counts'!$A:$Z,2,MATCH("User Selection",'[Ultimates.xlsx]Counts'!$1:$1,0))<>"",INDEX('[Ultimates.xlsx]Counts'!$A:$Z,2,MATCH("User Reasoning",'[Ultimates.xlsx]Counts'!$1:$1,0)),INDEX('[Ultimates.xlsx]Counts'!$A:$Z,2,MATCH("Rules-Based AI Reasoning",'[Ultimates.xlsx]Counts'!$1:$1,0))),"")
A3: 2002 | B3: 275 | C3: ='Reported CL'!C3 | D3: ='Reported CL'!E3 | E3: ='[Ultimates.xlsx]Counts'!E3 | F3: ='Reported BF'!H3 | G3: =IFERROR(IF(INDEX('[Ultimates.xlsx]Counts'!$A:$Z,3,MATCH("User Selection",'[Ultimates.xlsx]Counts'!$1:$1,0))<>"",INDEX('[Ultimates.xlsx]Counts'!$A:$Z,3,MATCH("User Selection",'[Ultimates.xlsx]Counts'!$1:$1,0)),INDEX('[Ultimates.xlsx]Counts'!$A:$Z,3,MATCH("Rules-Based AI Selection",'[Ultimates.xlsx]Counts'!$1:$1,0))),"") | H3: =G3-C3 | I3: =G3-C3 | J3: =IFERROR(IF(INDEX('[Ultimates.xlsx]Counts'!$A:$Z,3,MATCH("User Selection",'[Ultimates.xlsx]Counts'!$1:$1,0))<>"",INDEX('[Ultimates.xlsx]Counts'!$A:$Z,3,MATCH("User Reasoning",'[Ultimates.xlsx]Counts'!$1:$1,0)),INDEX('[Ultimates.xlsx]Counts'!$A:$Z,3,MATCH("Rules-Based AI Reasoning",'[Ultimates.xlsx]Counts'!$1:$1,0))),"")
A4: 2003 | B4: 263 | C4: ='Reported CL'!C4 | D4: ='Reported CL'!E4 | E4: ='[Ultimates.xlsx]Counts'!E4 | F4: ='Reported BF'!H4 | G4: =IFERROR(IF(INDEX('[Ultimates.xlsx]Counts'!$A:$Z,4,MATCH("User Selection",'[Ultimates.xlsx]Counts'!$1:$1,0))<>"",INDEX('[Ultimates.xlsx]Counts'!$A:$Z,4,MATCH("User Selection",'[Ultimates.xlsx]Counts'!$1:$1,0)),INDEX('[Ultimates.xlsx]Counts'!$A:$Z,4,MATCH("Rules-Based AI Selection",'[Ultimates.xlsx]Counts'!$1:$1,0))),"") | H4: =G4-C4 | I4: =G4-C4 | J4: =IFERROR(IF(INDEX('[Ultimates.xlsx]Counts'!$A:$Z,4,MATCH("User Selection",'[Ultimates.xlsx]Counts'!$1:$1,0))<>"",INDEX('[Ultimates.xlsx]Counts'!$A:$Z,4,MATCH("User Reasoning",'[Ultimates.xlsx]Counts'!$1:$1,0)),INDEX('[Ultimates.xlsx]Counts'!$A:$Z,4,MATCH("Rules-Based AI Reasoning",'[Ultimates.xlsx]Counts'!$1:$1,0))),"")
A5: 2004 | B5: 251 | C5: ='Reported CL'!C5 | D5: ='Reported CL'!E5 | E5: ='[Ultimates.xlsx]Counts'!E5 | F5: ='Reported BF'!H5 | G5: =IFERROR(IF(INDEX('[Ultimates.xlsx]Counts'!$A:$Z,5,MATCH("User Selection",'[Ultimates.xlsx]Counts'!$1:$1,0))<>"",INDEX('[Ultimates.xlsx]Counts'!$A:$Z,5,MATCH("User Selection",'[Ultimates.xlsx]Counts'!$1:$1,0)),INDEX('[Ultimates.xlsx]Counts'!$A:$Z,5,MATCH("Rules-Based AI Selection",'[Ultimates.xlsx]Counts'!$1:$1,0))),"") | H5: =G5-C5 | I5: =G5-C5 | J5: =IFERROR(IF(INDEX('[Ultimates.xlsx]Counts'!$A:$Z,5,MATCH("User Selection",'[Ultimates.xlsx]Counts'!$1:$1,0))<>"",INDEX('[Ultimates.xlsx]Counts'!$A:$Z,5,MATCH("User Reasoning",'[Ultimates.xlsx]Counts'!$1:$1,0)),INDEX('[Ultimates.xlsx]Counts'!$A:$Z,5,MATCH("Rules-Based AI Reasoning",'[Ultimates.xlsx]Counts'!$1:$1,0))),"")
A6: 2005 | B6: 239 | C6: ='Reported CL'!C6 | D6: ='Reported CL'!E6 | E6: ='[Ultimates.xlsx]Counts'!E6 | F6: ='Reported BF'!H6 | G6: =IFERROR(IF(INDEX('[Ultimates.xlsx]Counts'!$A:$Z,6,MATCH("User Selection",'[Ultimates.xlsx]Counts'!$1:$1,0))<>"",INDEX('[Ultimates.xlsx]Counts'!$A:$Z,6,MATCH("User Selection",'[Ultimates.xlsx]Counts'!$1:$1,0)),INDEX('[Ultimates.xlsx]Counts'!$A:$Z,6,MATCH("Rules-Based AI Selection",'[Ultimates.xlsx]Counts'!$1:$1,0))),"") | H6: =G6-C6 | I6: =G6-C6 | J6: =IFERROR(IF(INDEX('[Ultimates.xlsx]Counts'!$A:$Z,6,MATCH("User Selection",'[Ultimates.xlsx]Counts'!$1:$1,0))<>"",INDEX('[Ultimates.xlsx]Counts'!$A:$Z,6,MATCH("User Reasoning",'[Ultimates.xlsx]Counts'!$1:$1,0)),INDEX('[Ultimates.xlsx]Counts'!$A:$Z,6,MATCH("Rules-Based AI Reasoning",'[Ultimates.xlsx]Counts'!$1:$1,0))),"")
A7: 2006 | B7: 227 | C7: ='Reported CL'!C7 | D7: ='Reported CL'!E7 | E7: ='[Ultimates.xlsx]Counts'!E7 | F7: ='Reported BF'!H7 | G7: =IFERROR(IF(INDEX('[Ultimates.xlsx]Counts'!$A:$Z,7,MATCH("User Selection",'[Ultimates.xlsx]Counts'!$1:$1,0))<>"",INDEX('[Ultimates.xlsx]Counts'!$A:$Z,7,MATCH("User Selection",'[Ultimates.xlsx]Counts'!$1:$1,0)),INDEX('[Ultimates.xlsx]Counts'!$A:$Z,7,MATCH("Rules-Based AI Selection",'[Ultimates.xlsx]Counts'!$1:$1,0))),"") | H7: =G7-C7 | I7: =G7-C7 | J7: =IFERROR(IF(INDEX('[Ultimates.xlsx]Counts'!$A:$Z,7,MATCH("User Selection",'[Ultimates.xlsx]Counts'!$1:$1,0))<>"",INDEX('[Ultimates.xlsx]Counts'!$A:$Z,7,MATCH("User Reasoning",'[Ultimates.xlsx]Counts'!$1:$1,0)),INDEX('[Ultimates.xlsx]Counts'!$A:$Z,7,MATCH("Rules-Based AI Reasoning",'[Ultimates.xlsx]Counts'!$1:$1,0))),"")
A8: 2007 | B8: 215 | C8: ='Reported CL'!C8 | D8: ='Reported CL'!E8 | E8: ='[Ultimates.xlsx]Counts'!E8 | F8: ='Reported BF'!H8 | G8: =IFERROR(IF(INDEX('[Ultimates.xlsx]Counts'!$A:$Z,8,MATCH("User Selection",'[Ultimates.xlsx]Counts'!$1:$1,0))<>"",INDEX('[Ultimates.xlsx]Counts'!$A:$Z,8,MATCH("User Selection",'[Ultimates.xlsx]Counts'!$1:$1,0)),INDEX('[Ultimates.xlsx]Counts'!$A:$Z,8,MATCH("Rules-Based AI Selection",'[Ultimates.xlsx]Counts'!$1:$1,0))),"") | H8: =G8-C8 | I8: =G8-C8 | J8: =IFERROR(IF(INDEX('[Ultimates.xlsx]Counts'!$A:$Z,8,MATCH("User Selection",'[Ultimates.xlsx]Counts'!$1:$1,0))<>"",INDEX('[Ultimates.xlsx]Counts'!$A:$Z,8,MATCH("User Reasoning",'[Ultimates.xlsx]Counts'!$1:$1,0)),INDEX('[Ultimates.xlsx]Counts'!$A:$Z,8,MATCH("Rules-Based AI Reasoning",'[Ultimates.xlsx]Counts'!$1:$1,0))),"")
A9: 2008 | B9: 203 | C9: ='Reported CL'!C9 | D9: ='Reported CL'!E9 | E9: ='[Ultimates.xlsx]Counts'!E9 | F9: ='Reported BF'!H9 | G9: =IFERROR(IF(INDEX('[Ultimates.xlsx]Counts'!$A:$Z,9,MATCH("User Selection",'[Ultimates.xlsx]Counts'!$1:$1,0))<>"",INDEX('[Ultimates.xlsx]Counts'!$A:$Z,9,MATCH("User Selection",'[Ultimates.xlsx]Counts'!$1:$1,0)),INDEX('[Ultimates.xlsx]Counts'!$A:$Z,9,MATCH("Rules-Based AI Selection",'[Ultimates.xlsx]Counts'!$1:$1,0))),"") | H9: =G9-C9 | I9: =G9-C9 | J9: =IFERROR(IF(INDEX('[Ultimates.xlsx]Counts'!$A:$Z,9,MATCH("User Selection",'[Ultimates.xlsx]Counts'!$1:$1,0))<>"",INDEX('[Ultimates.xlsx]Counts'!$A:$Z,9,MATCH("User Reasoning",'[Ultimates.xlsx]Counts'!$1:$1,0)),INDEX('[Ultimates.xlsx]Counts'!$A:$Z,9,MATCH("Rules-Based AI Reasoning",'[Ultimates.xlsx]Counts'!$1:$1,0))),"")
A10: 2009 | B10: 191 | C10: ='Reported CL'!C10 | D10: ='Reported CL'!E10 | E10: ='[Ultimates.xlsx]Counts'!E10 | F10: ='Reported BF'!H10 | G10: =IFERROR(IF(INDEX('[Ultimates.xlsx]Counts'!$A:$Z,10,MATCH("User Selection",'[Ultimates.xlsx]Counts'!$1:$1,0))<>"",INDEX('[Ultimates.xlsx]Counts'!$A:$Z,10,MATCH("User Selection",'[Ultimates.xlsx]Counts'!$1:$1,0)),INDEX('[Ultimates.xlsx]Counts'!$A:$Z,10,MATCH("Rules-Based AI Selection",'[Ultimates.xlsx]Counts'!$1:$1,0))),"") | H10: =G10-C10 | I10: =G10-C10 | J10: =IFERROR(IF(INDEX('[Ultimates.xlsx]Counts'!$A:$Z,10,MATCH("User Selection",'[Ultimates.xlsx]Counts'!$1:$1,0))<>"",INDEX('[Ultimates.xlsx]Counts'!$A:$Z,10,MATCH("User Reasoning",'[Ultimates.xlsx]Counts'!$1:$1,0)),INDEX('[Ultimates.xlsx]Counts'!$A:$Z,10,MATCH("Rules-Based AI Reasoning",'[Ultimates.xlsx]Counts'!$1:$1,0))),"")
A11: 2010 | B11: 179 | C11: ='Reported CL'!C11 | D11: ='Reported CL'!E11 | E11: ='[Ultimates.xlsx]Counts'!E11 | F11: ='Reported BF'!H11 | G11: =IFERROR(IF(INDEX('[Ultimates.xlsx]Counts'!$A:$Z,11,MATCH("User Selection",'[Ultimates.xlsx]Counts'!$1:$1,0))<>"",INDEX('[Ultimates.xlsx]Counts'!$A:$Z,11,MATCH("User Selection",'[Ultimates.xlsx]Counts'!$1:$1,0)),INDEX('[Ultimates.xlsx]Counts'!$A:$Z,11,MATCH("Rules-Based AI Selection",'[Ultimates.xlsx]Counts'!$1:$1,0))),"") | H11: =G11-C11 | I11: =G11-C11 | J11: =IFERROR(IF(INDEX('[Ultimates.xlsx]Counts'!$A:$Z,11,MATCH("User Selection",'[Ultimates.xlsx]Counts'!$1:$1,0))<>"",INDEX('[Ultimates.xlsx]Counts'!$A:$Z,11,MATCH("User Reasoning",'[Ultimates.xlsx]Counts'!$1:$1,0)),INDEX('[Ultimates.xlsx]Counts'!$A:$Z,11,MATCH("Rules-Based AI Reasoning",'[Ultimates.xlsx]Counts'!$1:$1,0))),"")
A12: 2011 | B12: 167 | C12: ='Reported CL'!C12 | D12: ='Reported CL'!E12 | E12: ='[Ultimates.xlsx]Counts'!E12 | F12: ='Reported BF'!H12 | G12: =IFERROR(IF(INDEX('[Ultimates.xlsx]Counts'!$A:$Z,12,MATCH("User Selection",'[Ultimates.xlsx]Counts'!$1:$1,0))<>"",INDEX('[Ultimates.xlsx]Counts'!$A:$Z,12,MATCH("User Selection",'[Ultimates.xlsx]Counts'!$1:$1,0)),INDEX('[Ultimates.xlsx]Counts'!$A:$Z,12,MATCH("Rules-Based AI Selection",'[Ultimates.xlsx]Counts'!$1:$1,0))),"") | H12: =G12-C12 | I12: =G12-C12 | J12: =IFERROR(IF(INDEX('[Ultimates.xlsx]Counts'!$A:$Z,12,MATCH("User Selection",'[Ultimates.xlsx]Counts'!$1:$1,0))<>"",INDEX('[Ultimates.xlsx]Counts'!$A:$Z,12,MATCH("User Reasoning",'[Ultimates.xlsx]Counts'!$1:$1,0)),INDEX('[Ultimates.xlsx]Counts'!$A:$Z,12,MATCH("Rules-Based AI Reasoning",'[Ultimates.xlsx]Counts'!$1:$1,0))),"")
A13: 2012 | B13: 155 | C13: ='Reported CL'!C13 | D13: ='Reported CL'!E13 | E13: ='[Ultimates.xlsx]Counts'!E13 | F13: ='Reported BF'!H13 | G13: =IFERROR(IF(INDEX('[Ultimates.xlsx]Counts'!$A:$Z,13,MATCH("User Selection",'[Ultimates.xlsx]Counts'!$1:$1,0))<>"",INDEX('[Ultimates.xlsx]Counts'!$A:$Z,13,MATCH("User Selection",'[Ultimates.xlsx]Counts'!$1:$1,0)),INDEX('[Ultimates.xlsx]Counts'!$A:$Z,13,MATCH("Rules-Based AI Selection",'[Ultimates.xlsx]Counts'!$1:$1,0))),"") | H13: =G13-C13 | I13: =G13-C13 | J13: =IFERROR(IF(INDEX('[Ultimates.xlsx]Counts'!$A:$Z,13,MATCH("User Selection",'[Ultimates.xlsx]Counts'!$1:$1,0))<>"",INDEX('[Ultimates.xlsx]Counts'!$A:$Z,13,MATCH("User Reasoning",'[Ultimates.xlsx]Counts'!$1:$1,0)),INDEX('[Ultimates.xlsx]Counts'!$A:$Z,13,MATCH("Rules-Based AI Reasoning",'[Ultimates.xlsx]Counts'!$1:$1,0))),"")
A14: 2013 | B14: 143 | C14: ='Reported CL'!C14 | D14: ='Reported CL'!E14 | E14: ='[Ultimates.xlsx]Counts'!E14 | F14: ='Reported BF'!H14 | G14: =IFERROR(IF(INDEX('[Ultimates.xlsx]Counts'!$A:$Z,14,MATCH("User Selection",'[Ultimates.xlsx]Counts'!$1:$1,0))<>"",INDEX('[Ultimates.xlsx]Counts'!$A:$Z,14,MATCH("User Selection",'[Ultimates.xlsx]Counts'!$1:$1,0)),INDEX('[Ultimates.xlsx]Counts'!$A:$Z,14,MATCH("Rules-Based AI Selection",'[Ultimates.xlsx]Counts'!$1:$1,0))),"") | H14: =G14-C14 | I14: =G14-C14 | J14: =IFERROR(IF(INDEX('[Ultimates.xlsx]Counts'!$A:$Z,14,MATCH("User Selection",'[Ultimates.xlsx]Counts'!$1:$1,0))<>"",INDEX('[Ultimates.xlsx]Counts'!$A:$Z,14,MATCH("User Reasoning",'[Ultimates.xlsx]Counts'!$1:$1,0)),INDEX('[Ultimates.xlsx]Counts'!$A:$Z,14,MATCH("Rules-Based AI Reasoning",'[Ultimates.xlsx]Counts'!$1:$1,0))),"")
A15: 2014 | B15: 131 | C15: ='Reported CL'!C15 | D15: ='Reported CL'!E15 | E15: ='[Ultimates.xlsx]Counts'!E15 | F15: ='Reported BF'!H15 | G15: =IFERROR(IF(INDEX('[Ultimates.xlsx]Counts'!$A:$Z,15,MATCH("User Selection",'[Ultimates.xlsx]Counts'!$1:$1,0))<>"",INDEX('[Ultimates.xlsx]Counts'!$A:$Z,15,MATCH("User Selection",'[Ultimates.xlsx]Counts'!$1:$1,0)),INDEX('[Ultimates.xlsx]Counts'!$A:$Z,15,MATCH("Rules-Based AI Selection",'[Ultimates.xlsx]Counts'!$1:$1,0))),"") | H15: =G15-C15 | I15: =G15-C15 | J15: =IFERROR(IF(INDEX('[Ultimates.xlsx]Counts'!$A:$Z,15,MATCH("User Selection",'[Ultimates.xlsx]Counts'!$1:$1,0))<>"",INDEX('[Ultimates.xlsx]Counts'!$A:$Z,15,MATCH("User Reasoning",'[Ultimates.xlsx]Counts'!$1:$1,0)),INDEX('[Ultimates.xlsx]Counts'!$A:$Z,15,MATCH("Rules-Based AI Reasoning",'[Ultimates.xlsx]Counts'!$1:$1,0))),"")
A16: 2015 | B16: 119 | C16: ='Reported CL'!C16 | D16: ='Reported CL'!E16 | E16: ='[Ultimates.xlsx]Counts'!E16 | F16: ='Reported BF'!H16 | G16: =IFERROR(IF(INDEX('[Ultimates.xlsx]Counts'!$A:$Z,16,MATCH("User Selection",'[Ultimates.xlsx]Counts'!$1:$1,0))<>"",INDEX('[Ultimates.xlsx]Counts'!$A:$Z,16,MATCH("User Selection",'[Ultimates.xlsx]Counts'!$1:$1,0)),INDEX('[Ultimates.xlsx]Counts'!$A:$Z,16,MATCH("Rules-Based AI Selection",'[Ultimates.xlsx]Counts'!$1:$1,0))),"") | H16: =G16-C16 | I16: =G16-C16 | J16: =IFERROR(IF(INDEX('[Ultimates.xlsx]Counts'!$A:$Z,16,MATCH("User Selection",'[Ultimates.xlsx]Counts'!$1:$1,0))<>"",INDEX('[Ultimates.xlsx]Counts'!$A:$Z,16,MATCH("User Reasoning",'[Ultimates.xlsx]Counts'!$1:$1,0)),INDEX('[Ultimates.xlsx]Counts'!$A:$Z,16,MATCH("Rules-Based AI Reasoning",'[Ultimates.xlsx]Counts'!$1:$1,0))),"")
A17: 2016 | B17: 107 | C17: ='Reported CL'!C17 | D17: ='Reported CL'!E17 | E17: ='[Ultimates.xlsx]Counts'!E17 | F17: ='Reported BF'!H17 | G17: =IFERROR(IF(INDEX('[Ultimates.xlsx]Counts'!$A:$Z,17,MATCH("User Selection",'[Ultimates.xlsx]Counts'!$1:$1,0))<>"",INDEX('[Ultimates.xlsx]Counts'!$A:$Z,17,MATCH("User Selection",'[Ultimates.xlsx]Counts'!$1:$1,0)),INDEX('[Ultimates.xlsx]Counts'!$A:$Z,17,MATCH("Rules-Based AI Selection",'[Ultimates.xlsx]Counts'!$1:$1,0))),"") | H17: =G17-C17 | I17: =G17-C17 | J17: =IFERROR(IF(INDEX('[Ultimates.xlsx]Counts'!$A:$Z,17,MATCH("User Selection",'[Ultimates.xlsx]Counts'!$1:$1,0))<>"",INDEX('[Ultimates.xlsx]Counts'!$A:$Z,17,MATCH("User Reasoning",'[Ultimates.xlsx]Counts'!$1:$1,0)),INDEX('[Ultimates.xlsx]Counts'!$A:$Z,17,MATCH("Rules-Based AI Reasoning",'[Ultimates.xlsx]Counts'!$1:$1,0))),"")
A18: 2017 | B18: 95 | C18: ='Reported CL'!C18 | D18: ='Reported CL'!E18 | E18: ='[Ultimates.xlsx]Counts'!E18 | F18: ='Reported BF'!H18 | G18: =IFERROR(IF(INDEX('[Ultimates.xlsx]Counts'!$A:$Z,18,MATCH("User Selection",'[Ultimates.xlsx]Counts'!$1:$1,0))<>"",INDEX('[Ultimates.xlsx]Counts'!$A:$Z,18,MATCH("User Selection",'[Ultimates.xlsx]Counts'!$1:$1,0)),INDEX('[Ultimates.xlsx]Counts'!$A:$Z,18,MATCH("Rules-Based AI Selection",'[Ultimates.xlsx]Counts'!$1:$1,0))),"") | H18: =G18-C18 | I18: =G18-C18 | J18: =IFERROR(IF(INDEX('[Ultimates.xlsx]Counts'!$A:$Z,18,MATCH("User Selection",'[Ultimates.xlsx]Counts'!$1:$1,0))<>"",INDEX('[Ultimates.xlsx]Counts'!$A:$Z,18,MATCH("User Reasoning",'[Ultimates.xlsx]Counts'!$1:$1,0)),INDEX('[Ultimates.xlsx]Counts'!$A:$Z,18,MATCH("Rules-Based AI Reasoning",'[Ultimates.xlsx]Counts'!$1:$1,0))),"")
A19: 2018 | B19: 83 | C19: ='Reported CL'!C19 | D19: ='Reported CL'!E19 | E19: ='[Ultimates.xlsx]Counts'!E19 | F19: ='Reported BF'!H19 | G19: =IFERROR(IF(INDEX('[Ultimates.xlsx]Counts'!$A:$Z,19,MATCH("User Selection",'[Ultimates.xlsx]Counts'!$1:$1,0))<>"",INDEX('[Ultimates.xlsx]Counts'!$A:$Z,19,MATCH("User Selection",'[Ultimates.xlsx]Counts'!$1:$1,0)),INDEX('[Ultimates.xlsx]Counts'!$A:$Z,19,MATCH("Rules-Based AI Selection",'[Ultimates.xlsx]Counts'!$1:$1,0))),"") | H19: =G19-C19 | I19: =G19-C19 | J19: =IFERROR(IF(INDEX('[Ultimates.xlsx]Counts'!$A:$Z,19,MATCH("User Selection",'[Ultimates.xlsx]Counts'!$1:$1,0))<>"",INDEX('[Ultimates.xlsx]Counts'!$A:$Z,19,MATCH("User Reasoning",'[Ultimates.xlsx]Counts'!$1:$1,0)),INDEX('[Ultimates.xlsx]Counts'!$A:$Z,19,MATCH("Rules-Based AI Reasoning",'[Ultimates.xlsx]Counts'!$1:$1,0))),"")
A20: 2019 | B20: 71 | C20: ='Reported CL'!C20 | D20: ='Reported CL'!E20 | E20: ='[Ultimates.xlsx]Counts'!E20 | F20: ='Reported BF'!H20 | G20: =IFERROR(IF(INDEX('[Ultimates.xlsx]Counts'!$A:$Z,20,MATCH("User Selection",'[Ultimates.xlsx]Counts'!$1:$1,0))<>"",INDEX('[Ultimates.xlsx]Counts'!$A:$Z,20,MATCH("User Selection",'[Ultimates.xlsx]Counts'!$1:$1,0)),INDEX('[Ultimates.xlsx]Counts'!$A:$Z,20,MATCH("Rules-Based AI Selection",'[Ultimates.xlsx]Counts'!$1:$1,0))),"") | H20: =G20-C20 | I20: =G20-C20 | J20: =IFERROR(IF(INDEX('[Ultimates.xlsx]Counts'!$A:$Z,20,MATCH("User Selection",'[Ultimates.xlsx]Counts'!$1:$1,0))<>"",INDEX('[Ultimates.xlsx]Counts'!$A:$Z,20,MATCH("User Reasoning",'[Ultimates.xlsx]Counts'!$1:$1,0)),INDEX('[Ultimates.xlsx]Counts'!$A:$Z,20,MATCH("Rules-Based AI Reasoning",'[Ultimates.xlsx]Counts'!$1:$1,0))),"")
A21: 2020 | B21: 59 | C21: ='Reported CL'!C21 | D21: ='Reported CL'!E21 | E21: ='[Ultimates.xlsx]Counts'!E21 | F21: ='Reported BF'!H21 | G21: =IFERROR(IF(INDEX('[Ultimates.xlsx]Counts'!$A:$Z,21,MATCH("User Selection",'[Ultimates.xlsx]Counts'!$1:$1,0))<>"",INDEX('[Ultimates.xlsx]Counts'!$A:$Z,21,MATCH("User Selection",'[Ultimates.xlsx]Counts'!$1:$1,0)),INDEX('[Ultimates.xlsx]Counts'!$A:$Z,21,MATCH("Rules-Based AI Selection",'[Ultimates.xlsx]Counts'!$1:$1,0))),"") | H21: =G21-C21 | I21: =G21-C21 | J21: =IFERROR(IF(INDEX('[Ultimates.xlsx]Counts'!$A:$Z,21,MATCH("User Selection",'[Ultimates.xlsx]Counts'!$1:$1,0))<>"",INDEX('[Ultimates.xlsx]Counts'!$A:$Z,21,MATCH("User Reasoning",'[Ultimates.xlsx]Counts'!$1:$1,0)),INDEX('[Ultimates.xlsx]Counts'!$A:$Z,21,MATCH("Rules-Based AI Reasoning",'[Ultimates.xlsx]Counts'!$1:$1,0))),"")
A22: 2021 | B22: 47 | C22: ='Reported CL'!C22 | D22: ='Reported CL'!E22 | E22: ='[Ultimates.xlsx]Counts'!E22 | F22: ='Reported BF'!H22 | G22: =IFERROR(IF(INDEX('[Ultimates.xlsx]Counts'!$A:$Z,22,MATCH("User Selection",'[Ultimates.xlsx]Counts'!$1:$1,0))<>"",INDEX('[Ultimates.xlsx]Counts'!$A:$Z,22,MATCH("User Selection",'[Ultimates.xlsx]Counts'!$1:$1,0)),INDEX('[Ultimates.xlsx]Counts'!$A:$Z,22,MATCH("Rules-Based AI Selection",'[Ultimates.xlsx]Counts'!$1:$1,0))),"") | H22: =G22-C22 | I22: =G22-C22 | J22: =IFERROR(IF(INDEX('[Ultimates.xlsx]Counts'!$A:$Z,22,MATCH("User Selection",'[Ultimates.xlsx]Counts'!$1:$1,0))<>"",INDEX('[Ultimates.xlsx]Counts'!$A:$Z,22,MATCH("User Reasoning",'[Ultimates.xlsx]Counts'!$1:$1,0)),INDEX('[Ultimates.xlsx]Counts'!$A:$Z,22,MATCH("Rules-Based AI Reasoning",'[Ultimates.xlsx]Counts'!$1:$1,0))),"")
A23: 2022 | B23: 35 | C23: ='Reported CL'!C23 | D23: ='Reported CL'!E23 | E23: ='[Ultimates.xlsx]Counts'!E23 | F23: ='Reported BF'!H23 | G23: =IFERROR(IF(INDEX('[Ultimates.xlsx]Counts'!$A:$Z,23,MATCH("User Selection",'[Ultimates.xlsx]Counts'!$1:$1,0))<>"",INDEX('[Ultimates.xlsx]Counts'!$A:$Z,23,MATCH("User Selection",'[Ultimates.xlsx]Counts'!$1:$1,0)),INDEX('[Ultimates.xlsx]Counts'!$A:$Z,23,MATCH("Rules-Based AI Selection",'[Ultimates.xlsx]Counts'!$1:$1,0))),"") | H23: =G23-C23 | I23: =G23-C23 | J23: =IFERROR(IF(INDEX('[Ultimates.xlsx]Counts'!$A:$Z,23,MATCH("User Selection",'[Ultimates.xlsx]Counts'!$1:$1,0))<>"",INDEX('[Ultimates.xlsx]Counts'!$A:$Z,23,MATCH("User Reasoning",'[Ultimates.xlsx]Counts'!$1:$1,0)),INDEX('[Ultimates.xlsx]Counts'!$A:$Z,23,MATCH("Rules-Based AI Reasoning",'[Ultimates.xlsx]Counts'!$1:$1,0))),"")
A24: 2023 | B24: 23 | C24: ='Reported CL'!C24 | D24: ='Reported CL'!E24 | E24: ='[Ultimates.xlsx]Counts'!E24 | F24: ='Reported BF'!H24 | G24: =IFERROR(IF(INDEX('[Ultimates.xlsx]Counts'!$A:$Z,24,MATCH("User Selection",'[Ultimates.xlsx]Counts'!$1:$1,0))<>"",INDEX('[Ultimates.xlsx]Counts'!$A:$Z,24,MATCH("User Selection",'[Ultimates.xlsx]Counts'!$1:$1,0)),INDEX('[Ultimates.xlsx]Counts'!$A:$Z,24,MATCH("Rules-Based AI Selection",'[Ultimates.xlsx]Counts'!$1:$1,0))),"") | H24: =G24-C24 | I24: =G24-C24 | J24: =IFERROR(IF(INDEX('[Ultimates.xlsx]Counts'!$A:$Z,24,MATCH("User Selection",'[Ultimates.xlsx]Counts'!$1:$1,0))<>"",INDEX('[Ultimates.xlsx]Counts'!$A:$Z,24,MATCH("User Reasoning",'[Ultimates.xlsx]Counts'!$1:$1,0)),INDEX('[Ultimates.xlsx]Counts'!$A:$Z,24,MATCH("Rules-Based AI Reasoning",'[Ultimates.xlsx]Counts'!$1:$1,0))),"")
A25: 2024 | B25: 11 | C25: ='Reported CL'!C25 | D25: ='Reported CL'!E25 | E25: ='[Ultimates.xlsx]Counts'!E25 | F25: ='Reported BF'!H25 | G25: =IFERROR(IF(INDEX('[Ultimates.xlsx]Counts'!$A:$Z,25,MATCH("User Selection",'[Ultimates.xlsx]Counts'!$1:$1,0))<>"",INDEX('[Ultimates.xlsx]Counts'!$A:$Z,25,MATCH("User Selection",'[Ultimates.xlsx]Counts'!$1:$1,0)),INDEX('[Ultimates.xlsx]Counts'!$A:$Z,25,MATCH("Rules-Based AI Selection",'[Ultimates.xlsx]Counts'!$1:$1,0))),"") | H25: =G25-C25 | I25: =G25-C25 | J25: =IFERROR(IF(INDEX('[Ultimates.xlsx]Counts'!$A:$Z,25,MATCH("User Selection",'[Ultimates.xlsx]Counts'!$1:$1,0))<>"",INDEX('[Ultimates.xlsx]Counts'!$A:$Z,25,MATCH("User Reasoning",'[Ultimates.xlsx]Counts'!$1:$1,0)),INDEX('[Ultimates.xlsx]Counts'!$A:$Z,25,MATCH("Rules-Based AI Reasoning",'[Ultimates.xlsx]Counts'!$1:$1,0))),"")
A27: Total | C27: =SUM(C2:C25) | D27: =SUM(D2:D25) | E27: =SUM(E2:E25) | F27: =SUM(F2:F25) | G27: =SUM(G2:G25) | H27: =SUM(H2:H25) | I27: =SUM(I2:I25)

Sheet Closed CL
A1: Accident Period | B1: Current Age | C1: Closed | D1: CDF | E1: Ultimate | F1: IBNR | G1: Unpaid
A2: 2001 | B2: None | E2: =C2*D2 | F2: =E2-C2 | G2: =E2-C2
A3: 2002 | B3: None | E3: =C3*D3 | F3: =E3-C3 | G3: =E3-C3
A4: 2003 | B4: None | E4: =C4*D4 | F4: =E4-C4 | G4: =E4-C4
A5: 2004 | B5: None | E5: =C5*D5 | F5: =E5-C5 | G5: =E5-C5
A6: 2005 | B6: None | E6: =C6*D6 | F6: =E6-C6 | G6: =E6-C6
A7: 2006 | B7: None | E7: =C7*D7 | F7: =E7-C7 | G7: =E7-C7
A8: 2007 | B8: None | E8: =C8*D8 | F8: =E8-C8 | G8: =E8-C8
A9: 2008 | B9: None | E9: =C9*D9 | F9: =E9-C9 | G9: =E9-C9
A10: 2009 | B10: None | E10: =C10*D10 | F10: =E10-C10 | G10: =E10-C10
A11: 2010 | B11: None | E11: =C11*D11 | F11: =E11-C11 | G11: =E11-C11
A12: 2011 | B12: None | E12: =C12*D12 | F12: =E12-C12 | G12: =E12-C12
A13: 2012 | B13: None | E13: =C13*D13 | F13: =E13-C13 | G13: =E13-C13
... A25: 2024 | B25: None | E25: =C25*D25 | F25: =E25-C25 | G25: =E25-C25
A27: Total | C27: =SUM(C2:C25) | E27: =SUM(E2:E25) | F27: =SUM(F2:F25) | G27: =SUM(G2:G25)

Sheet Reported CL
A1: Accident Period | B1: Current Age | C1: Reported | D1: CDF | E1: Ultimate | F1: IBNR | G1: Unpaid
A2: 2001 | B2: 287 | C2: 700.7076 | D2: 1 | E2: =C2*D2 | F2: =E2-C2 | G2: =E2-'Closed CL'!C2
A3: 2002 | B3: 275 | C3: 651.8824 | D3: 1 | E3: =C3*D3 | F3: =E3-C3 | G3: =E3-'Closed CL'!C3
A4: 2003 | B4: 263 | C4: 551.5928 | D4: 1 | E4: =C4*D4 | F4: =E4-C4 | G4: =E4-'Closed CL'!C4
A5: 2004 | B5: 251 | C5: 642.6452 | D5: 1 | E5: =C5*D5 | F5: =E5-C5 | G5: =E5-'Closed CL'!C5
A6: 2005 | B6: 239 | C6: 641.3256 | D6: 1 | E6: =C6*D6 | F6: =E6-C6 | G6: =E6-'Closed CL'!C6
A7: 2006 | B7: 227 | C7: 497.4892 | D7: 1 | E7: =C7*D7 | F7: =E7-C7 | G7: =E7-'Closed CL'!C7
A8: 2007 | B8: 215 | C8: 476.3756 | D8: 1 | E8: =C8*D8 | F8: =E8-C8 | G8: =E8-'Closed CL'!C8
A9: 2008 | B9: 203 | C9: 328.5804 | D9: 1 | E9: =C9*D9 | F9: =E9-C9 | G9: =E9-'Closed CL'!C9
A10: 2009 | B10: 191 | C10: 321.9824 | D10: 1 | E10: =C10*D10 | F10: =E10-C10 | G10: =E10-'Closed CL'!C10
A11: 2010 | B11: 179 | C11: 271.8376 | D11: 1 | E11: =C11*D11 | F11: =E11-C11 | G11: =E11-'Closed CL'!C11
A12: 2011 | B12: 167 | C12: 345.7352 | D12: 1 | E12: =C12*D12 | F12: =E12-C12 | G12: =E12-'Closed CL'!C12
A13: 2012 | B13: 155 | C13: 261.2808 | D13: 1 | E13: =C13*D13 | F13: =E13-C13 | G13: =E13-'Closed CL'!C13
... A25: 2024 | B25: 11 | C25: 256.0024 | D25: 1.1146471 | E25: =C25*D25 | F25: =E25-C25 | G25: =E25-'Closed CL'!C25
A27: Total | C27: =SUM(C2:C25) | E27: =SUM(E2:E25) | F27: =SUM(F2:F25) | G27: =SUM(G2:G25)

Sheet Reported BF
A1: Accident Period | B1: Current Age | C1: Initial Expected | D1: CDF | E1: % Unreported | F1: Unreported | G1: Reported | H1: Ultimate | I1: IBNR | J1: Unpaid
A2: 2001 | B2: 287 | C2: 700.77587 | D2: 1 | E2: =1-(1/D2) | F2: =C2*E2 | G2: 700.7076 | H2: =F2+G2 | I2: =H2-G2 | J2: =H2-'Closed CL'!C2
A3: 2002 | B3: 275 | C3: 683.16631 | D3: 1 | E3: =1-(1/D3) | F3: =C3*E3 | G3: 651.8824 | H3: =F3+G3 | I3: =H3-G3 | J3: =H3-'Closed CL'!C3
A4: 2003 | B4: 263 | C4: 648.44326 | D4: 1 | E4: =1-(1/D4) | F4: =C4*E4 | G4: 551.5928 | H4: =F4+G4 | I4: =H4-G4 | J4: =H4-'Closed CL'!C4
A5: 2004 | B5: 251 | C5: 627.83791 | D5: 1 | E5: =1-(1/D5) | F5: =C5*E5 | G5: 642.6452 | H5: =F5+G5 | I5: =H5-G5 | J5: =H5-'Closed CL'!C5
A6: 2005 | B6: 239 | C6: 623.61427 | D6: 1 | E6: =1-(1/D6) | F6: =C6*E6 | G6: 641.3256 | H6: =F6+G6 | I6: =H6-G6 | J6: =H6-'Closed CL'!C6
A7: 2006 | B7: 227 | C7: 606.74484 | D7: 1 | E7: =1-(1/D7) | F7: =C7*E7 | G7: 497.4892 | H7: =F7+G7 | I7: =H7-G7 | J7: =H7-'Closed CL'!C7
A8: 2007 | B8: 215 | C8: 550.47161 | D8: 1 | E8: =1-(1/D8) | F8: =C8*E8 | G8: 476.3756 | H8: =F8+G8 | I8: =H8-G8 | J8: =H8-'Closed CL'!C8
A9: 2008 | B9: 203 | C9: 444.09698 | D9: 1 | E9: =1-(1/D9) | F9: =C9*E9 | G9: 328.5804 | H9: =F9+G9 | I9: =H9-G9 | J9: =H9-'Closed CL'!C9
A10: 2009 | B10: 191 | C10: 384.40191 | D10: 1 | E10: =1-(1/D10) | F10: =C10*E10 | G10: 321.9824 | H10: =F10+G10 | I10: =H10-G10 | J10: =H10-'Closed CL'!C10
A11: 2010 | B11: 179 | C11: 314.2013 | D11: 1 | E11: =1-(1/D11) | F11: =C11*E11 | G11: 271.8376 | H11: =F11+G11 | I11: =H11-G11 | J11: =H11-'Closed CL'!C11
A12: 2011 | B12: 167 | C12: 319.32834 | D12: 1 | E12: =1-(1/D12) | F12: =C12*E12 | G12: 345.7352 | H12: =F12+G12 | I12: =H12-G12 | J12: =H12-'Closed CL'!C12
A13: 2012 | B13: 155 | C13: 298.96538 | D13: 1 | E13: =1-(1/D13) | F13: =C13*E13 | G13: 261.2808 | H13: =F13+G13 | I13: =H13-G13 | J13: =H13-'Closed CL'!C13
... A25: 2024 | B25: 11 | C25: 292.35261 | D25: 1.1146471 | E25: =1-(1/D25) | F25: =C25*E25 | G25: 256.0024 | H25: =F25+G25 | I25: =H25-G25 | J25: =H25-'Closed CL'!C25
A27: Total | C27: =SUM(C2:C25) | E27: =SUM(F2:F25)/SUM(C2:C25) | F27: =SUM(F2:F25) | G27: =SUM(G2:G25) | H27: =SUM(H2:H25) | I27: =SUM(I2:I25) | J27: =SUM(J2:J25)

Sheet Closed IE
A1: Accident Period | B1: Current Age | C1: Exposure | D1: Selected Loss Rate | E1: IE Ultimate
A2: 2001 | B2: None | C2: 3.1637737e+08 | D2: 2.215e-06 | E2: 700.77587
A3: 2002 | B3: None | C3: 3.2270492e+08 | D3: 2.117e-06 | E3: 683.16631
A4: 2003 | B4: None | C4: 3.2915902e+08 | D4: 1.97e-06 | E4: 648.44326
A5: 2004 | B5: None | C5: 335742196 | D5: 1.87e-06 | E5: 627.83791
A6: 2005 | B6: None | C6: 342457040 | D6: 1.821e-06 | E6: 623.61427
A7: 2006 | B7: None | C7: 3.4930618e+08 | D7: 1.737e-06 | E7: 606.74484
A8: 2007 | B8: None | C8: 3.562923e+08 | D8: 1.545e-06 | E8: 550.47161
A9: 2008 | B9: None | C9: 3.6341815e+08 | D9: 1.222e-06 | E9: 444.09698
A10: 2009 | B10: None | C10: 3.7068651e+08 | D10: 1.037e-06 | E10: 384.40191
A11: 2010 | B11: None | C11: 3.7810024e+08 | D11: 8.31e-07 | E11: 314.2013
A12: 2011 | B12: None | C12: 3.8566225e+08 | D12: 8.28e-07 | E12: 319.32834
A13: 2012 | B13: None | C13: 3.9337549e+08 | D13: 7.6e-07 | E13: 298.96538
... A25: 2024 | B25: None | C25: 4.9889524e+08 | D25: 5.86e-07 | E25: 292.35261

Sheet Reported IE
A1: Accident Period | B1: Current Age | C1: Exposure | D1: Selected Loss Rate | E1: IE Ultimate
A2: 2001 | B2: 287 | C2: 3.1637737e+08 | D2: 2.215e-06 | E2: 700.77587
A3: 2002 | B3: 275 | C3: 3.2270492e+08 | D3: 2.117e-06 | E3: 683.16631
A4: 2003 | B4: 263 | C4: 3.2915902e+08 | D4: 1.97e-06 | E4: 648.44326
A5: 2004 | B5: 251 | C5: 335742196 | D5: 1.87e-06 | E5: 627.83791
A6: 2005 | B6: 239 | C6: 342457040 | D6: 1.821e-06 | E6: 623.61427
A7: 2006 | B7: 227 | C7: 3.4930618e+08 | D7: 1.737e-06 | E7: 606.74484
A8: 2007 | B8: 215 | C8: 3.562923e+08 | D8: 1.545e-06 | E8: 550.47161
A9: 2008 | B9: 203 | C9: 3.6341815e+08 | D9: 1.222e-06 | E9: 444.09698
A10: 2009 | B10: 191 | C10: 3.7068651e+08 | D10: 1.037e-06 | E10: 384.40191
